File: project1/data/Packing_Peanuts_Instron/Starch_1.is_comp_RawData/Specimen_RawData_1.csv
Time,Extension,Load
(sec),(mm),(N)
0.00000,-0.00027,-0.00655
0.20000,-0.01307,-0.02163
0.40000,-0.03827,-0.02419
0.60000,-0.05933,-0.01779
0.80000,-0.08013,-0.03104
1.00000,-0.10027,-0.02948
1.20000,-0.12027,-0.02628
1.40000,-0.14067,-0.03412
1.60000,-0.16053,-0.02484
1.80000,-0.18013,-0.03567
2.00000,-0.20040,-0.03179
2.20000,-0.22053,-0.03333
2.40000,-0.24027,-0.04370
2.60000,-0.26027,-0.03310
2.80000,-0.28067,-0.03805
3.00000,-0.30040,-0.04590
3.20000,-0.32040,-0.04240
3.40000,-0.34040,-0.04579
3.60000,-0.36013,-0.03438
3.80000,-0.38027,-0.04150
4.00000,-0.40067,-0.05249
4.20000,-0.42040,-0.05370
4.40000,-0.44027,-0.04996
4.60000,-0.46053,-0.05551
4.80000,-0.48027,-0.05597
5.00000,-0.50027,-0.06391
5.20000,-0.52040,-0.06307
5.40000,-0.54000,-0.06624
5.60000,-0.56027,-0.06068
5.80000,-0.58067,-0.06859
6.00000,-0.60027,-0.07177
6.20000,-0.62013,-0.07733
6.40000,-0.64040,-0.08072
6.60000,-0.66040,-0.07043
6.80000,-0.68053,-0.08113
7.00000,-0.70053,-0.07805
7.20000,-0.72026,-0.07844
7.40000,-0.74026,-0.07819
7.60000,-0.76040,-0.07519
7.80000,-0.78053,-0.08407
8.00000,-0.80040,-0.08705
8.20000,-0.82040,-0.09021
8.40000,-0.84040,-0.09325
8.60000,-0.86013,-0.08905
8.80000,-0.88040,-0.10172
9.00000,-0.90040,-0.10452
9.20000,-0.92013,-0.10836
9.40000,-0.94040,-0.10748
9.60000,-0.96053,-0.10656
9.80000,-0.98026,-0.11371
10.00000,-1.00013,-0.12452
10.20000,-1.02040,-0.11827
10.40000,-1.04026,-0.12684
10.60000,-1.06053,-0.12333
10.80000,-1.08053,-0.13218
11.00000,-1.10013,-0.14261
11.20000,-1.12040,-0.13808
11.40000,-1.14040,-0.14747
11.60000,-1.16026,-0.14394
11.80000,-1.18026,-0.15442
12.00000,-1.20026,-0.15087
12.20000,-1.22040,-0.15289
12.40000,-1.24040,-0.16495
12.60000,-1.26040,-0.16380
12.80000,-1.28013,-0.17362
13.00000,-1.30013,-0.17285
13.20000,-1.32053,-0.18586
13.40000,-1.34040,-0.17853
13.60000,-1.36053,-0.18347
13.80000,-1.38040,-0.18376
14.00000,-1.40026,-0.19119
14.20000,-1.42013,-0.19256
14.40000,-1.44066,-0.19798
14.60000,-1.46040,-0.20353
14.80000,-1.48013,-0.20910
15.00000,-1.50053,-0.21449
15.20000,-1.52026,-0.21437
15.40000,-1.54026,-0.22189
15.60000,-1.56013,-0.22014
15.80000,-1.58013,-0.23980
16.00000,-1.60040,-0.23674
16.20000,-1.62053,-0.24858
16.40000,-1.64040,-0.24380
16.60000,-1.66013,-0.24018
16.80000,-1.68026,-0.25627
17.00000,-1.70026,-0.26047
17.20000,-1.72040,-0.26170
17.40000,-1.74053,-0.27882
17.60000,-1.76040,-0.27044
17.80000,-1.78026,-0.27612
18.00000,-1.80053,-0.28581
18.20000,-1.82053,-0.29096
18.40000,-1.84040,-0.30501
18.60000,-1.86013,-0.30740
18.80000,-1.88040,-0.31502
19.00000,-1.90040,-0.33216
19.20000,-1.92040,-0.33667
19.40000,-1.94053,-0.34759
19.60000,-1.96013,-0.35077
19.80000,-1.98040,-0.36290
20.00000,-2.00066,-0.38184
20.20000,-2.02040,-0.38639
20.40000,-2.04013,-0.39707
20.60000,-2.06053,-0.40445
20.80000,-2.08013,-0.42397
21.00000,-2.10026,-0.43690
21.20000,-2.12053,-0.44967
21.40000,-2.14013,-0.46977
21.60000,-2.16039,-0.49026
21.80000,-2.18066,-0.52355
22.00000,-2.20026,-0.53998
22.20000,-2.22026,-0.54074
22.40000,-2.24026,-0.56053
22.60000,-2.26053,-0.57026
22.80000,-2.28039,-0.59687
23.00000,-2.30066,-0.61053
23.20000,-2.32026,-0.61927
23.40000,-2.34026,-0.64147
23.60000,-2.36039,-0.65755
23.80000,-2.38053,-0.68250
24.00000,-2.40039,-0.69762
24.20000,-2.42026,-0.71709
24.40000,-2.44053,-0.75282
24.60000,-2.46039,-0.77499
24.80000,-2.48053,-0.83702
25.00000,-2.50039,-0.88919
25.20000,-2.52013,-0.89327
25.40000,-2.54039,-0.93402
25.60000,-2.56053,-0.94599
25.80000,-2.58039,-0.97404
26.00000,-2.60026,-1.02768
26.20000,-2.62026,-1.06936
26.40000,-2.64013,-1.11446
26.60000,-2.66053,-1.14400
26.80000,-2.68053,-1.18965
27.00000,-2.70013,-1.25468
27.20000,-2.72026,-1.29599
27.40000,-2.74039,-1.37888
27.60000,-2.76026,-1.41123
27.80000,-2.78026,-1.47181
28.00000,-2.80053,-1.55722
28.20000,-2.82026,-1.61865
28.40000,-2.84039,-1.67306
28.60000,-2.86066,-1.74606
28.80000,-2.88013,-1.81876
29.00000,-2.90013,-1.85304
29.20000,-2.92066,-1.93909
29.40000,-2.94053,-1.96645
29.60000,-2.96039,-2.04828
29.80000,-2.98039,-2.12866
30.00000,-3.00026,-1.73176
30.20000,-3.02026,-1.83846
30.40000,-3.04066,-1.89661
30.60000,-3.06053,-2.00476
30.80000,-3.08013,-2.15349
31.00000,-3.10053,-2.28176
31.20000,-3.12039,-2.36077
31.40000,-3.14026,-2.44785
31.60000,-3.16026,-2.46420
31.80000,-3.18013,-2.49039
32.00000,-3.20026,-2.56077
32.20000,-3.22066,-2.63884
32.40000,-3.24039,-2.73229
32.60000,-3.25999,-2.79088
32.80000,-3.28039,-2.86518
33.00000,-3.30026,-2.94081
33.20000,-3.32039,-3.01257
33.40000,-3.34053,-3.12038
33.60000,-3.36039,-3.20020
33.80000,-3.38026,-3.29657
34.00000,-3.40039,-3.10130
34.20000,-3.42052,-3.08257
34.40000,-3.44026,-3.16325
34.60000,-3.46026,-3.24894
34.80000,-3.48066,-3.32938
35.00000,-3.50039,-3.44588
35.20000,-3.52052,-3.50920
35.40000,-3.54039,-3.59774
35.60000,-3.56012,-3.70634
35.80000,-3.58039,-3.81998
36.00000,-3.60066,-3.91035
36.20000,-3.62039,-4.00502
36.40000,-3.64012,-4.11837
36.60000,-3.66039,-4.21906
36.80000,-3.68026,-4.30949
37.00000,-3.70026,-4.40916
37.20000,-3.72039,-4.51313
37.40000,-3.74012,-4.61929
37.60000,-3.76026,-4.71177
37.80000,-3.78066,-4.81215
38.00000,-3.80039,-4.89710
38.20000,-3.82026,-4.93186
38.40000,-3.84039,-5.01777
38.60000,-3.86039,-5.08912
38.80000,-3.88039,-5.14432
39.00000,-3.90066,-5.17112
39.20000,-3.92012,-5.26001
39.40000,-3.94026,-5.37140
39.60000,-3.96052,-5.49038
39.80000,-3.98052,-5.57796
40.00000,-4.00039,-5.67778
40.20000,-4.02039,-5.77263
40.40000,-4.04052,-5.86358
40.60000,-4.06026,-5.97415
40.80000,-4.08052,-6.09598
41.00000,-4.10039,-6.18840
41.20000,-4.12026,-6.28325
41.40000,-4.14039,-6.37737
41.60000,-4.16052,-6.46408
41.80000,-4.18039,-6.51032
42.00000,-4.20026,-6.58400
42.20000,-4.22012,-6.68257
42.40000,-4.24026,-6.75265
42.60000,-4.26052,-6.81070
42.80000,-4.28052,-6.85424
43.00000,-4.30012,-6.90073
43.20000,-4.32026,-6.93368
43.40000,-4.34039,-6.97634
43.60000,-4.36026,-6.99399
43.80000,-4.38039,-7.06865
44.00000,-4.40039,-7.14613
44.20000,-4.42039,-7.16938
44.40000,-4.44039,-6.37908
44.60000,-4.46066,-6.60417
44.80000,-4.48012,-6.81842
45.00000,-4.50026,-6.98067
45.20000,-4.52066,-7.12770
45.40000,-4.54039,-7.22696
45.60000,-4.56039,-7.29633
45.80000,-4.58039,-7.36877
46.00000,-4.60026,-7.43564
46.20000,-4.62026,-7.49373
46.40000,-4.64066,-7.53613
46.60000,-4.66052,-7.55753
46.80000,-4.68012,-7.55668
47.00000,-4.70052,-7.08993
47.20000,-4.72026,-7.06142
47.40000,-4.74025,-7.11549
47.60000,-4.76026,-7.18442
47.80000,-4.78012,-7.26845
48.00000,-4.80039,-7.31596
48.20000,-4.82052,-7.39637
48.40000,-4.84039,-7.49066
48.60000,-4.86012,-7.53556
48.80000,-4.88039,-7.59602
49.00000,-4.90025,-7.62139
49.20000,-4.92039,-7.65065
49.40000,-4.94052,-7.68779
49.60000,-4.96025,-7.71153
49.80000,-4.98025,-7.70060
50.00000,-5.00052,-7.73534
50.20000,-5.02039,-7.74271
50.40000,-5.04025,-7.75786
50.60000,-5.06025,-7.74966
50.80000,-5.08052,-7.80786
51.00000,-5.10039,-7.85740
51.20000,-5.12052,-7.72652
51.40000,-5.14039,-7.78023
51.60000,-5.15999,-7.83923
51.80000,-5.18039,-7.89869
52.00000,-5.20065,-7.94170
52.20000,-5.22039,-7.97282
52.40000,-5.24025,-8.00302
52.60000,-5.26039,-8.02677
52.80000,-5.28025,-8.06738
53.00000,-5.30039,-8.09052
53.20000,-5.32052,-8.06230
53.40000,-5.34012,-8.06806
53.60000,-5.36039,-8.02508
53.80000,-5.38052,-8.07146
54.00000,-5.40039,-8.06949
54.20000,-5.42025,-8.07667
54.40000,-5.44039,-8.09721
54.60000,-5.46052,-8.11453
54.80000,-5.48039,-8.11577
55.00000,-5.50052,-8.05440
55.20000,-5.52012,-8.02913
55.40000,-5.54025,-8.00007
55.60000,-5.56039,-7.99511
55.80000,-5.58052,-7.91700
56.00000,-5.60039,-7.91372
56.20000,-5.62039,-7.91498
56.40000,-5.64052,-7.90103
56.60000,-5.66025,-7.78321
56.80000,-5.68052,-7.76560
57.00000,-5.70039,-7.80237
57.20000,-5.72012,-7.83866
57.40000,-5.74039,-7.84175
57.60000,-5.76052,-7.86342
57.80000,-5.78039,-7.88683
58.00000,-5.80012,-7.91978
58.20000,-5.82025,-7.93031
58.40000,-5.84025,-7.93224
58.60000,-5.86052,-7.77304
58.80000,-5.88039,-7.76635
59.00000,-5.90012,-7.76952
59.20000,-5.92039,-7.80844
59.40000,-5.94039,-7.84352
59.60000,-5.96025,-7.88600
59.80000,-5.98052,-7.94724
60.00000,-6.00039,-8.00581
60.20000,-6.02039,-8.05837
60.40000,-6.04052,-8.12169
60.60000,-6.06052,-8.16871
60.80000,-6.08012,-8.21771
61.00000,-6.10012,-8.25002
61.20000,-6.12065,-8.27353
61.40000,-6.14038,-8.31556
61.60000,-6.16038,-8.35917
61.80000,-6.18039,-8.41153
62.00000,-6.20012,-8.46360
62.20000,-6.22025,-8.51942
62.40000,-6.24052,-8.58735
62.60000,-6.26038,-8.63376
62.80000,-6.28012,-8.64968
63.00000,-6.30052,-8.71442
63.20000,-6.32025,-8.77873
63.40000,-6.34025,-8.85690
63.60000,-6.36025,-8.91990
63.80000,-6.38025,-9.00842
64.00000,-6.40038,-9.08404
64.20000,-6.42065,-9.16049
64.40000,-6.44052,-9.22639
64.60001,-6.46012,-9.28410
64.80000,-6.48025,-9.34847
65.00000,-6.50038,-9.40858
65.20000,-6.52052,-9.37981
65.40000,-6.54052,-9.46628
65.60001,-6.56038,-9.53418
65.80000,-6.58025,-9.59831
66.00000,-6.60052,-9.63174
66.20001,-6.62052,-9.67722
66.40000,-6.64025,-9.74728
66.60001,-6.66025,-9.79097
66.80000,-6.68052,-9.84995
67.00000,-6.70038,-9.88989
67.20001,-6.72052,-9.92420
67.40000,-6.74052,-9.87337
67.60001,-6.76012,-9.82832
67.80000,-6.78038,-7.08997
68.00000,-6.80065,-7.33161
68.20001,-6.82025,-7.45219
68.40000,-6.84025,-7.58029
68.60001,-6.86052,-7.66090
68.80000,-6.88025,-7.70577
69.00000,-6.90025,-7.72961
69.20001,-6.92038,-7.80827
69.40000,-6.94012,-7.85768
69.60001,-6.96038,-7.91875
69.80000,-6.98052,-8.02904
70.00000,-7.00038,-8.13241
70.20001,-7.02025,-8.24430
70.40000,-7.04038,-8.31703
70.60001,-7.06052,-8.44248
70.80000,-7.08052,-8.54912
71.00000,-7.10065,-8.65032
71.20001,-7.12025,-8.70805
71.40000,-7.14025,-8.75242
71.60001,-7.16038,-8.77297
71.80000,-7.18052,-8.59260
72.00000,-7.20038,-8.71121
72.20001,-7.22025,-8.83323
72.40000,-7.24038,-8.96579
72.60001,-7.26025,-9.11564
72.80000,-7.28052,-9.27084
73.00000,-7.30052,-9.42759
73.20001,-7.32012,-9.56263
73.40000,-7.34038,-9.67539
73.60001,-7.36052,-9.77118
73.80000,-7.38038,-9.85457
74.00000,-7.40025,-9.86701
74.20001,-7.42025,-9.88504
74.40000,-7.44012,-9.80772
74.60001,-7.46052,-9.83955
74.80000,-7.48052,-9.85989
75.00000,-7.50011,-9.84849
75.20001,-7.52038,-9.82873
75.40000,-7.54038,-9.79976
75.60001,-7.56025,-9.88527
75.80000,-7.58038,-9.99479
76.00000,-7.60038,-10.08139
76.20001,-7.62051,-10.16061
76.40000,-7.64038,-10.23095
76.60001,-7.66051,-10.28877
76.80000,-7.68025,-10.37727
77.00000,-7.70025,-10.45023
77.20001,-7.72051,-10.52795
77.40000,-7.74051,-10.55253
77.60001,-7.76038,-10.60025
77.80000,-7.78038,-10.61088
78.00000,-7.80038,-10.57910
78.20001,-7.82025,-10.63042
78.40000,-7.84065,-10.69133
78.60001,-7.86051,-10.74215
78.80000,-7.88011,-10.80116
79.00000,-7.90038,-10.77359
79.20001,-7.92038,-8.32586
79.40000,-7.94038,-7.80243
79.60001,-7.96011,-7.83511
79.80000,-7.98011,-7.92557
80.00000,-8.00038,-7.87977
80.20001,-8.02065,-7.92963
80.40000,-8.04038,-7.99019
80.60001,-8.06011,-8.03122
80.80000,-8.08025,-7.99095
81.00001,-8.10038,-8.04167
81.20001,-8.12038,-8.06756
81.40000,-8.14051,-8.12235
81.60001,-8.16038,-8.13795
81.80000,-8.18011,-8.18530
82.00001,-8.20038,-8.19102
82.20001,-8.22051,-7.86377
82.40000,-8.24025,-7.97661
82.60001,-8.26025,-7.98485
82.80000,-8.28051,-8.03831
83.00001,-8.30038,-8.09486
83.20001,-8.32038,-8.12774
83.40000,-8.34051,-8.19346
83.60001,-8.36011,-8.21310
83.80000,-8.38025,-8.28014
84.00001,-8.40065,-8.33144
84.20001,-8.42038,-8.37457
84.40000,-8.44011,-8.40184
84.60001,-8.46051,-8.41381
84.80000,-8.48011,-8.46651
85.00001,-8.50038,-8.47008
85.20001,-8.52051,-7.94193
85.40000,-8.54011,-8.01440
85.60001,-8.56011,-8.09217
85.80000,-8.58065,-8.12279
86.00001,-8.60038,-8.12174
86.20001,-8.62011,-8.12949
86.40000,-8.64038,-8.16851
86.60001,-8.66038,-8.12323
86.80000,-8.68038,-8.17218
87.00001,-8.70065,-8.24233
87.20001,-8.72025,-8.32189
87.40000,-8.74025,-8.47179
87.60001,-8.76038,-8.53102
87.80000,-8.78051,-8.60096
88.00001,-8.80038,-8.63150
88.20001,-8.82038,-8.60504
88.40000,-8.84051,-8.64965
88.60001,-8.86011,-8.69787
88.80000,-8.88038,-8.71705
89.00001,-8.90038,-8.78905
89.20001,-8.92024,-8.84982
89.40000,-8.94038,-8.94449
89.60001,-8.96038,-9.01275
89.80000,-8.98038,-9.10522
90.00001,-9.00024,-9.07940
90.20001,-9.02024,-8.90797
90.40000,-9.04011,-8.95226
90.60001,-9.06051,-8.99378
90.80000,-9.08051,-8.98675
91.00001,-9.10011,-8.69658
91.20001,-9.12024,-8.73326
91.40000,-9.14051,-8.77252
91.60001,-9.16024,-8.78214
91.80000,-9.18038,-8.86458
92.00001,-9.20038,-8.90435
92.20001,-9.22038,-8.96547
92.40000,-9.24038,-9.09023
92.60001,-9.26064,-9.18280
92.80000,-9.28011,-9.23190
93.00001,-9.30011,-9.40226
93.20001,-9.32064,-9.35162
93.40000,-9.34038,-9.45885
93.60001,-9.36038,-9.47656
93.80000,-9.38051,-9.56417
94.00001,-9.40011,-9.58615
94.20001,-9.42024,-9.63129
94.40000,-9.44064,-9.69880
94.60001,-9.46038,-9.73010
94.80000,-9.48011,-9.77404
95.00001,-9.50051,-9.74797
95.20001,-9.52024,-9.80960
95.40000,-9.54024,-9.83619
95.60001,-9.56024,-9.90396
95.80000,-9.58011,-9.83989
96.00001,-9.60038,-9.84173
96.20001,-9.62064,-9.79328
96.40000,-9.64038,-9.86881
96.60001,-9.66011,-9.92760
96.80000,-9.68038,-9.93317
97.00001,-9.70024,-9.96633
97.20001,-9.72038,-9.86946
97.40000,-9.74064,-9.92510
97.60001,-9.76038,-9.91441
97.80000,-9.78024,-9.88522
98.00001,-9.80038,-9.89841
98.20001,-9.82038,-9.93511
98.40000,-9.84038,-9.98994
98.60001,-9.86024,-9.97079
98.80000,-9.88038,-10.02557
99.00001,-9.90038,-10.10673
99.20001,-9.92051,-10.16882
99.40000,-9.94051,-10.22681
99.60001,-9.96011,-10.16103
99.80000,-9.98038,-10.23121
100.00001,-10.00064,-10.19080
100.20001,-10.02038,-10.28188
100.40000,-10.04024,-10.27863
100.60001,-10.06051,-10.27421
100.80000,-10.08011,-10.32324
101.00001,-10.10038,-10.30726
101.20001,-10.12038,-10.34147
101.40000,-10.14011,-10.33658
101.60001,-10.16038,-10.40832
101.80000,-10.18051,-10.34815
102.00001,-10.20024,-10.40050
102.20001,-10.22024,-10.36275
102.40000,-10.24038,-10.42696
102.60001,-10.26038,-10.42690
102.80000,-10.28038,-10.37604
103.00001,-10.30064,-10.40051
103.20001,-10.32024,-10.28969
103.40000,-10.34011,-10.32489
103.60001,-10.36038,-10.24890
103.80000,-10.38051,-10.35136
104.00001,-10.40037,-10.26560
104.20001,-10.42037,-10.29875
104.40000,-10.44051,-10.35300
104.60001,-10.46024,-10.23110
104.80000,-10.48051,-10.27978
105.00001,-10.50037,-10.36431
105.20001,-10.52024,-10.31096
105.40000,-10.54037,-10.37739
105.60001,-10.56037,-10.27746
105.80000,-10.58037,-10.33235
106.00001,-10.60037,-10.25381
106.20001,-10.62024,-10.21476
106.40000,-10.64011,-10.24765
106.60001,-10.66064,-10.27022
106.80000,-10.68037,-10.26245
107.00001,-10.70011,-10.19368
107.20001,-10.72037,-10.19701
107.40000,-10.74024,-10.26295
107.60001,-10.76024,-10.17703
107.80000,-10.78051,-10.15125
108.00001,-10.80037,-10.15409
108.20001,-10.82051,-10.11621
108.40000,-10.84051,-10.12630
108.60001,-10.86051,-10.07997
108.80000,-10.88024,-10.02769
109.00001,-10.90024,-10.11555
109.20001,-10.92064,-10.11482
109.40000,-10.94037,-10.04668
109.60001,-10.96051,-10.08539
109.80000,-10.98051,-10.01224
110.00001,-11.00024,-9.98819
110.20001,-11.02037,-10.03310
110.40000,-11.04064,-10.01512
110.60001,-11.06051,-9.95777
110.80000,-11.08024,-9.94745
111.00001,-11.10051,-9.98806
111.20001,-11.12051,-9.97556
111.40000,-11.14037,-9.92853
111.60001,-11.16024,-9.90962
111.80000,-11.18024,-9.96594
112.00001,-11.20024,-9.94497
112.20001,-11.22051,-9.97480
112.40000,-11.24064,-9.98487
112.60001,-11.26011,-10.03437
112.80000,-11.28037,-10.01773
113.00001,-11.30037,-10.00227
113.20001,-11.32051,-10.03564
113.40001,-11.34051,-10.00125
113.60001,-11.36051,-10.00055
113.80000,-11.38037,-10.01341
114.00001,-11.40037,-10.06830
114.20001,-11.42051,-10.00692
114.40001,-11.44024,-10.07026
114.60001,-11.46024,-10.05829
114.80000,-11.48051,-10.05320
115.00001,-11.50024,-10.08040
115.20001,-11.52064,-10.14118
115.40001,-11.54064,-10.12423
115.60001,-11.56010,-10.04227
115.80000,-11.58037,-10.10699
116.00001,-11.60064,-10.08926
116.20001,-11.62037,-10.09484
116.40001,-11.64024,-10.10031
116.60001,-11.66051,-10.11396
116.80000,-11.68037,-10.15210
117.00001,-11.70037,-10.18712
117.20001,-11.72050,-10.15714
117.40001,-11.74024,-10.18642
117.60001,-11.76037,-10.18818
117.80000,-11.78051,-10.14601
118.00001,-11.80024,-10.21226
118.20001,-11.82024,-10.23442
118.40001,-11.84037,-10.26600
118.60001,-11.86050,-10.28425
118.80000,-11.88024,-10.26983
119.00001,-11.90050,-10.38801
119.20001,-11.92024,-10.39941
119.40001,-11.94024,-10.41155
119.60001,-11.96037,-10.32234
119.80000,-11.98050,-10.32882
120.00001,-12.00037,-10.32735
120.20001,-12.02037,-10.35131
120.40001,-12.04064,-10.30426
120.60001,-12.06037,-10.34225
120.80000,-12.08050,-10.34300
121.00001,-12.10050,-10.35066
121.20001,-12.12010,-10.39267
121.40001,-12.14050,-10.34494
121.60001,-12.16064,-10.39042
121.80000,-12.18024,-10.42287
122.00001,-12.20037,-10.45772
122.20001,-12.22024,-10.33047
122.40001,-12.24024,-10.35261
122.60001,-12.26050,-10.31994
122.80000,-12.28064,-10.39203
123.00001,-12.30024,-10.36588
123.20001,-12.32037,-10.40277
123.40001,-12.34050,-10.41535
123.60001,-12.36024,-10.39482
123.80000,-12.38037,-10.43137
124.00001,-12.40050,-10.43020
124.20001,-12.42050,-10.42287
124.40001,-12.44037,-10.41811
124.60001,-12.46064,-10.40377
124.80000,-12.48024,-10.48138
125.00001,-12.50024,-10.45187
125.20001,-12.52050,-10.45348
125.40001,-12.54037,-10.50402
125.60001,-12.56050,-10.50838
125.80000,-12.58050,-10.50106
126.00001,-12.60037,-10.54482
126.20001,-12.62024,-10.54030
126.40001,-12.64050,-10.53508
126.60001,-12.66050,-10.53523
126.80000,-12.68010,-10.58072
127.00001,-12.70050,-10.58864
127.20001,-12.72037,-10.56037
127.40001,-12.74037,-10.56813
127.60001,-12.76024,-10.60071
127.80000,-12.78010,-10.61115
128.00000,-12.80037,-10.63630
128.20002,-12.82050,-10.63452
128.40001,-12.84050,-10.65747
128.60001,-12.86010,-10.63027
128.80000,-12.88037,-10.67795
129.00000,-12.90037,-10.64370
129.20002,-12.92050,-10.69191
129.40001,-12.94050,-10.70952
129.60001,-12.96037,-10.72234
129.80000,-12.98037,-10.74578
130.00000,-13.00037,-10.73592
130.20002,-13.02050,-10.81264
130.40001,-13.04024,-10.83104
130.60001,-13.06037,-10.84056
130.80000,-13.08064,-10.90745
131.00000,-13.10050,-10.87382
131.20002,-13.12050,-10.87177
131.40002,-13.14050,-10.79141
131.60000,-13.16010,-10.81553
131.80000,-13.18037,-10.80685
132.00000,-13.20063,-10.88818
132.20002,-13.22037,-10.90069
132.40002,-13.24023,-10.90256
132.60000,-13.26050,-10.93605
132.80000,-13.28023,-10.98400
133.00000,-13.30037,-11.00716
133.20002,-13.32050,-11.01399
133.40002,-13.34010,-11.03185
133.60000,-13.36037,-11.05814
133.80000,-13.38063,-11.08454
134.00000,-13.40037,-11.09503
134.20002,-13.42037,-11.06443
134.40002,-13.44037,-11.12480
134.60000,-13.46050,-11.11520
134.80000,-13.48037,-11.12316
135.00000,-13.50063,-11.17905
135.20002,-13.52037,-11.15685
135.40002,-13.54010,-11.19293
135.60000,-13.56037,-11.19594
135.80000,-13.58050,-11.22626
136.00000,-13.60037,-11.23236
136.20002,-13.62037,-11.25709
136.40002,-13.64050,-11.26798
136.60000,-13.66037,-11.29783
136.80000,-13.68050,-11.34005
137.00000,-13.70050,-11.37483
137.20002,-13.72023,-11.41958
137.40002,-13.74037,-11.44404
137.60000,-13.76063,-11.45927
137.80000,-13.78037,-11.49116
138.00000,-13.80023,-11.50059
138.20002,-13.82037,-11.54190
138.40002,-13.84023,-11.57833
138.60000,-13.86050,-11.62627
138.80000,-13.88050,-11.65462
139.00000,-13.90023,-11.68934
139.20002,-13.92037,-11.71589
139.40002,-13.94050,-11.73569
139.60000,-13.96023,-11.76307
139.80000,-13.98037,-11.82569
140.00000,-14.00037,-11.85122
140.20002,-14.02050,-11.88537
140.40002,-14.04050,-11.90155
140.60000,-14.06063,-11.91693
140.80000,-14.08023,-11.94911
141.00000,-14.10023,-11.99911
141.20002,-14.12063,-12.04508
141.40002,-14.14050,-12.08573
141.60000,-14.16050,-12.10483
141.80000,-14.18050,-12.17171
142.00000,-14.20037,-12.20495
142.20002,-14.22023,-12.24930
142.40002,-14.24063,-12.28790
142.60000,-14.26050,-12.29315
142.80000,-14.28010,-12.35315
143.00000,-14.30063,-12.40764
143.20002,-14.32037,-12.42879
143.40002,-14.34037,-12.45604
143.60000,-14.36023,-12.48260
143.80000,-14.38010,-12.54779
144.00000,-14.40036,-12.58218
144.20002,-14.42063,-12.63671
144.40002,-14.44063,-12.68246
144.60000,-14.46010,-12.71112
144.80000,-14.48050,-12.73188
145.00000,-14.50036,-12.79819
145.20002,-14.52036,-12.83492
145.40002,-14.54050,-12.88863
145.60000,-14.56050,-12.75065
145.80000,-14.58023,-12.83910
146.00000,-14.60050,-12.89968
146.20002,-14.62050,-12.92919
146.40002,-14.64023,-12.99673
146.60000,-14.66023,-13.02588
146.80000,-14.68050,-13.05934
147.00000,-14.70036,-13.13488
147.20002,-14.72050,-13.18342
147.40002,-14.74050,-13.24152
147.60000,-14.76010,-13.27709
147.80000,-14.78036,-13.32915
148.00000,-14.80063,-13.37758
148.20002,-14.82050,-13.42532
148.40002,-14.84023,-13.43835
148.60000,-14.86050,-13.49954
148.80000,-14.88023,-13.55015
149.00000,-14.90023,-13.61238
149.20002,-14.92050,-13.68169
149.40002,-14.94023,-13.73694
149.60000,-14.96023,-13.78895
149.80000,-14.98050,-13.84487
150.00000,-15.00036,-13.88898
150.20002,-15.02023,-13.94637
150.40002,-15.04036,-14.00254
150.60000,-15.06050,-14.04893
150.80000,-15.08036,-14.10821
151.00000,-15.10063,-14.18201
151.20002,-15.12023,-14.22773
151.40002,-15.14023,-14.27166
151.60000,-15.16050,-14.31614
151.80000,-15.18036,-14.38260
152.00000,-15.20036,-14.43780
152.20002,-15.22036,-14.49412
152.40002,-15.24050,-14.57405
152.60000,-15.26023,-14.63908
152.80000,-15.28063,-14.70677
153.00000,-15.30036,-14.75909
153.20002,-15.32010,-14.80451
153.40002,-15.34050,-14.87755
153.60000,-15.36050,-14.94398
153.80000,-15.38036,-15.00024
154.00000,-15.40036,-15.03735
154.20002,-15.42023,-15.11426
154.40002,-15.44023,-15.17367
154.60000,-15.46063,-15.22774
154.80000,-15.48063,-15.30283
155.00000,-15.50023,-15.35935
155.20002,-15.52036,-15.44626
155.40002,-15.54036,-15.52061
155.60000,-15.56023,-15.56111
155.80000,-15.58036,-15.65912
156.00000,-15.60036,-15.74226
156.20002,-15.62050,-15.80382
156.40002,-15.64036,-15.89214
156.60000,-15.66063,-15.96018
156.80000,-15.68036,-16.03161
157.00000,-15.70023,-16.11596
157.20002,-15.72063,-16.22048
157.40002,-15.74050,-16.30675
157.60000,-15.76036,-16.37362
157.80000,-15.78050,-16.45624
158.00000,-15.80023,-16.52719
158.20002,-15.82036,-16.59058
158.40002,-15.84063,-16.66863
158.60000,-15.86049,-16.74399
158.80000,-15.88023,-16.84469
159.00000,-15.90049,-16.90699
159.20002,-15.92036,-16.98339
159.40002,-15.94023,-17.06788
159.60000,-15.96036,-17.14016
159.80000,-15.98009,-17.24465
160.00000,-16.00023,-17.32128
160.20002,-16.02063,-17.42612
160.25202,-16.02569,-17.43897