File: project1/data/Packing_Peanuts_Instron/Starch_1.is_comp_RawData/Specimen_RawData_2.csv
Time,Extension,Load
(sec),(mm),(N)
0.00000,0.00027,-0.00675
0.20000,-0.01520,-0.01532
0.40000,-0.03880,-0.01461
0.60000,-0.05947,-0.00488
0.80000,-0.07973,-0.01378
1.00000,-0.09973,-0.02511
1.20000,-0.11960,-0.01020
1.40000,-0.13973,-0.01378
1.60000,-0.16000,-0.00950
1.80000,-0.18000,-0.02496
2.00000,-0.19973,-0.02706
2.20000,-0.21960,-0.02164
2.40000,-0.24000,-0.02560
2.60000,-0.25987,-0.02234
2.80000,-0.28000,-0.03056
3.00000,-0.30000,-0.02863
3.20000,-0.31960,-0.02579
3.40000,-0.33987,-0.03174
3.60000,-0.36000,-0.02486
3.80000,-0.37973,-0.03805
4.00000,-0.39973,-0.03600
4.20000,-0.42000,-0.04276
4.40000,-0.44000,-0.03844
4.60000,-0.45987,-0.03804
4.80000,-0.48000,-0.04713
5.00000,-0.49960,-0.05040
5.20000,-0.51973,-0.05474
5.40000,-0.54013,-0.05334
5.60000,-0.55987,-0.05352
5.80000,-0.57987,-0.05622
6.00000,-0.59973,-0.05504
6.20000,-0.61973,-0.06121
6.40000,-0.63987,-0.06838
6.60000,-0.65987,-0.07136
6.80000,-0.67973,-0.07878
7.00000,-0.69973,-0.07210
7.20000,-0.72000,-0.08747
7.40000,-0.73986,-0.08325
7.60000,-0.75973,-0.08990
7.80000,-0.77973,-0.10339
8.00000,-0.80000,-0.11350
8.20000,-0.81986,-0.11234
8.40000,-0.84013,-0.12569
8.60000,-0.86000,-0.12721
8.80000,-0.87960,-0.13216
9.00000,-0.89986,-0.14124
9.20000,-0.91986,-0.15354
9.40000,-0.93986,-0.15880
9.60000,-0.96013,-0.16782
9.80000,-0.97986,-0.17622
10.00000,-0.99973,-0.19303
10.20000,-1.01986,-0.20930
10.40000,-1.03986,-0.22104
10.60000,-1.05973,-0.23349
10.80000,-1.07986,-0.24424
11.00000,-1.10000,-0.26603
11.20000,-1.11986,-0.28092
11.40000,-1.13973,-0.30402
11.60000,-1.15960,-0.30918
11.80000,-1.17973,-0.33404
12.00000,-1.20000,-0.35308
12.20000,-1.22000,-0.36995
12.40000,-1.23986,-0.38641
12.60000,-1.25960,-0.39477
12.80000,-1.27986,-0.41937
13.00000,-1.29986,-0.44565
13.20000,-1.31973,-0.47422
13.40000,-1.34000,-0.49756
13.60000,-1.36000,-0.52172
13.80000,-1.37986,-0.55117
14.00000,-1.40000,-0.58320
14.20000,-1.41973,-0.60925
14.40000,-1.43960,-0.64381
14.60000,-1.46000,-0.67735
14.80000,-1.48000,-0.71839
15.00000,-1.50000,-0.75211
15.20000,-1.52000,-0.77080
15.40000,-1.53973,-0.81116
15.60000,-1.55973,-0.81726
15.80000,-1.57986,-0.84119
16.00000,-1.60000,-0.86460
16.20000,-1.61973,-0.89461
16.40000,-1.63986,-0.92577
16.60000,-1.65986,-0.93977
16.80000,-1.67986,-0.97643
17.00000,-1.69960,-1.01863
17.20000,-1.71960,-1.06309
17.40000,-1.73960,-1.10717
17.60000,-1.75986,-1.15055
17.80000,-1.78000,-1.19319
18.00000,-1.79960,-1.22483
18.20000,-1.81960,-1.26064
18.40000,-1.84000,-1.29431
18.60000,-1.85986,-1.34809
18.80000,-1.88000,-1.40428
19.00000,-1.90000,-1.44986
19.20000,-1.91973,-1.50444
19.40000,-1.93973,-1.55129
19.60000,-1.96000,-1.55775
19.80000,-1.97973,-1.62506
20.00000,-1.99973,-1.69050
20.20000,-2.02000,-1.76483
20.40000,-2.04000,-1.83405
20.60000,-2.05986,-1.88664
20.80000,-2.07999,-1.92971
21.00000,-2.09946,-1.99196
21.20000,-2.11973,-2.04695
21.40000,-2.14013,-2.11887
21.60000,-2.16013,-2.15877
21.80000,-2.17973,-2.21581
22.00000,-2.19973,-2.25889
22.20000,-2.21973,-2.30187
22.40000,-2.23986,-2.35297
22.60000,-2.25999,-2.38933
22.80000,-2.27973,-2.44580
23.00000,-2.29959,-2.49780
23.20000,-2.31999,-2.54453
23.40000,-2.33999,-2.50777
23.60000,-2.35973,-2.56683
23.80000,-2.37959,-2.60816
24.00000,-2.39986,-2.65006
24.20000,-2.41986,-2.69736
24.40000,-2.43999,-2.73394
24.60000,-2.45986,-2.76655
24.80000,-2.47959,-2.82892
25.00000,-2.49986,-2.89906
25.20000,-2.51999,-2.96485
25.40000,-2.53986,-3.02951
25.60000,-2.55986,-3.08818
25.80000,-2.57999,-3.14049
26.00000,-2.59973,-3.18341
26.20000,-2.61986,-3.23865
26.40000,-2.63999,-3.27147
26.60000,-2.65959,-3.32152
26.80000,-2.67999,-3.39999
27.00000,-2.69999,-3.46467
27.20000,-2.71986,-3.53822
27.40000,-2.73973,-3.60900
27.60000,-2.75973,-3.67842
27.80000,-2.77959,-3.75632
28.00000,-2.79999,-3.81853
28.20000,-2.82013,-3.87910
28.40000,-2.83986,-3.94046
28.60000,-2.85959,-4.00620
28.80000,-2.87999,-4.08060
29.00000,-2.89973,-3.95987
29.20000,-2.91973,-4.02953
29.40000,-2.93999,-4.12046
29.60000,-2.95999,-4.19562
29.80000,-2.97986,-4.27595
30.00000,-2.99999,-4.35538
30.20000,-3.01973,-4.43665
30.40000,-3.03946,-4.51565
30.60000,-3.05973,-4.57833
30.80000,-3.07986,-4.65291
31.00000,-3.09999,-4.69287
31.20000,-3.11999,-4.75423
31.40000,-3.13959,-4.83763
31.60000,-3.15973,-4.88455
31.80000,-3.17999,-4.95013
32.00000,-3.19999,-4.99937
32.20000,-3.21959,-5.06566
32.40000,-3.23986,-5.12944
32.60000,-3.25986,-5.17430
32.80000,-3.27973,-5.25356
33.00000,-3.29959,-5.31283
33.20000,-3.31973,-5.36787
33.40000,-3.33973,-5.39959
33.60000,-3.35986,-5.44254
33.80000,-3.38013,-5.51394
34.00000,-3.39973,-5.58771
34.20000,-3.41959,-5.64270
34.40000,-3.43986,-5.70771
34.60000,-3.45972,-5.77771
34.80000,-3.47986,-5.86091
35.00000,-3.49986,-5.92814
35.20000,-3.51959,-5.98516
35.40000,-3.53972,-6.03514
35.60000,-3.55999,-6.01955
35.80000,-3.57986,-6.07000
36.00000,-3.59972,-6.14834
36.20000,-3.61999,-6.22141
36.40000,-3.63999,-6.28889
36.60000,-3.65999,-6.35882
36.80000,-3.67999,-6.40709
37.00000,-3.69946,-6.43502
37.20000,-3.71959,-6.49336
37.40000,-3.73999,-6.55070
37.60000,-3.75999,-6.55648
37.80000,-3.77972,-6.58521
38.00000,-3.79972,-6.57933
38.20000,-3.81972,-6.64171
38.40000,-3.83972,-6.69728
38.60000,-3.85999,-6.72937
38.80000,-3.87972,-6.75737
39.00000,-3.89972,-6.73810
39.20000,-3.91999,-6.77585
39.40000,-3.93986,-6.81393
39.60000,-3.95972,-6.83452
39.80000,-3.97959,-6.88658
40.00000,-3.99999,-6.88813
40.20000,-4.01972,-6.91126
40.40000,-4.03999,-6.94359
40.60000,-4.05986,-6.96186
40.80000,-4.07959,-6.97236
41.00000,-4.09972,-7.00155
41.20000,-4.12012,-7.02889
41.40000,-4.13986,-6.99483
41.60000,-4.15986,-7.00538
41.80000,-4.17999,-7.03715
42.00000,-4.19972,-7.05797
42.20000,-4.21986,-7.07990
42.40000,-4.23999,-7.11059
42.60000,-4.25959,-7.13374
42.80000,-4.27986,-7.14030
43.00000,-4.29999,-7.18548
43.20000,-4.31986,-7.20456
43.40000,-4.33972,-7.24977
43.60000,-4.35959,-7.27113
43.80000,-4.37972,-7.31731
44.00000,-4.39986,-7.35132
44.20000,-4.42012,-7.38693
44.40000,-4.43972,-7.43835
44.60000,-4.45959,-7.47851
44.80000,-4.47999,-7.53591
45.00000,-4.49972,-7.57984
45.20000,-4.51972,-7.60394
45.40000,-4.53986,-7.63596
45.60000,-4.55999,-7.67150
45.80000,-4.57986,-7.70719
46.00000,-4.59999,-7.73462
46.20000,-4.61972,-7.77542
46.40000,-4.63959,-7.79975
46.60000,-4.66012,-7.81205
46.80000,-4.67999,-7.84172
47.00000,-4.69999,-7.85522
47.20000,-4.71999,-7.88413
47.40000,-4.73972,-7.84702
47.60000,-4.75959,-7.85936
47.80000,-4.77986,-7.90933
48.00000,-4.79999,-7.94658
48.20000,-4.81972,-7.97773
48.40000,-4.83985,-8.00950
48.60000,-4.85999,-8.02418
48.80000,-4.87985,-8.05213
49.00000,-4.89972,-8.08863
49.20000,-4.91972,-8.11688
49.40000,-4.93972,-8.13795
49.60000,-4.95985,-8.05548
49.80000,-4.98012,-8.04205
50.00000,-4.99972,-8.06283
50.20000,-5.01959,-8.06163
50.40000,-5.03985,-8.05246
50.60000,-5.05985,-8.04221
50.80000,-5.07999,-8.02385
51.00000,-5.09999,-8.03301
51.20000,-5.11959,-8.05800
51.40000,-5.13985,-8.05400
51.60000,-5.15999,-8.03758
51.80000,-5.17972,-8.03624
52.00000,-5.19959,-8.06434
52.20000,-5.21999,-8.06193
52.40000,-5.23999,-8.09039
52.60000,-5.25999,-8.07144
52.80000,-5.27999,-8.06898
53.00000,-5.29945,-8.10034
53.20000,-5.31972,-8.09441
53.40000,-5.33999,-8.12851
53.60000,-5.35999,-8.15062
53.80000,-5.37985,-8.19045
54.00000,-5.39972,-8.19112
54.20000,-5.41972,-8.22320
54.40000,-5.43972,-8.25429
54.60000,-5.45999,-8.25563
54.80000,-5.47985,-8.26204
55.00000,-5.49972,-8.26950
55.20000,-5.51999,-8.29265
55.40000,-5.53999,-8.31459
55.60000,-5.55959,-8.32401
55.80000,-5.57972,-8.36502
56.00000,-5.59999,-8.36171
56.20000,-5.61985,-8.39488
56.40000,-5.63999,-8.42554
56.60000,-5.65985,-8.42816
56.80000,-5.67945,-8.46999
57.00000,-5.69985,-8.46263
57.20000,-5.71999,-8.20153
57.40000,-5.73985,-8.22350
57.60000,-5.75985,-8.26267
57.80000,-5.77972,-8.29943
58.00000,-5.79972,-8.31122
58.20000,-5.81985,-8.22442
58.40000,-5.83999,-8.23973
58.60000,-5.85959,-8.25924
58.80000,-5.87985,-8.28395
59.00000,-5.89999,-8.32140
59.20000,-5.91985,-8.34732
59.40000,-5.93972,-8.37862
59.60000,-5.95959,-8.40819
59.80000,-5.97972,-8.43838
60.00000,-5.99999,-8.46883
60.20000,-6.01999,-8.49092
60.40000,-6.03972,-8.50258
60.60000,-6.05959,-8.53438
60.80000,-6.07999,-8.57268
61.00000,-6.09972,-8.57202
61.20000,-6.11972,-8.59209
61.40000,-6.13985,-8.61809
61.60000,-6.15985,-8.63629
61.80000,-6.17985,-8.66698
62.00000,-6.20012,-8.68831
62.20000,-6.21972,-8.70243
62.40000,-6.23945,-8.72649
62.60000,-6.25998,-8.74520
62.80000,-6.27998,-8.76465
63.00000,-6.29998,-8.79893
63.20000,-6.31998,-8.82515
63.40000,-6.33972,-8.83158
63.60000,-6.35958,-8.84692
63.80000,-6.37985,-8.88389
64.00000,-6.39998,-8.90700
64.20000,-6.41958,-8.93437
64.40000,-6.43985,-8.96232
64.60001,-6.45985,-8.97742
64.80000,-6.47985,-8.99961
65.00000,-6.49972,-9.01392
65.20000,-6.51972,-9.03938
65.40000,-6.53972,-9.05990
65.60001,-6.56012,-9.05833
65.80000,-6.57998,-9.08497
66.00000,-6.59972,-9.10036
66.20001,-6.61958,-9.11533
66.40000,-6.63985,-9.14190
66.60001,-6.65998,-9.03517
66.80000,-6.67998,-9.04997
67.00000,-6.69985,-9.06856
67.20001,-6.71958,-9.07864
67.40000,-6.73998,-9.07343
67.60001,-6.75998,-8.79660
67.80000,-6.77985,-8.81115
68.00000,-6.79958,-8.83504
68.20001,-6.81998,-8.85813
68.40000,-6.83998,-8.87782
68.60001,-6.85998,-8.91239
68.80000,-6.87998,-8.93324
69.00000,-6.89945,-8.96083
69.20001,-6.91958,-8.98067
69.40000,-6.93998,-9.00631
69.60001,-6.95998,-9.02750
69.80000,-6.97972,-9.07014
70.00000,-6.99972,-9.09291
70.20001,-7.01972,-9.08238
70.40000,-7.03985,-9.03666
70.60001,-7.05998,-9.06936
70.80000,-7.07985,-9.09854
71.00000,-7.09958,-9.12752
71.20001,-7.11998,-9.15387
71.40000,-7.13985,-9.17775
71.60001,-7.15972,-9.19180
71.80000,-7.17972,-9.22555
72.00000,-7.19998,-9.24180
72.20001,-7.21985,-9.26635
72.40000,-7.24012,-9.29650
72.60001,-7.25998,-9.30730
72.80000,-7.27958,-9.30642
73.00000,-7.29985,-9.31713
73.20001,-7.31998,-9.32998
73.40000,-7.33985,-9.34656
73.60001,-7.35985,-9.33598
73.80000,-7.37985,-9.36831
74.00000,-7.39972,-9.38779
74.20001,-7.41985,-9.25096
74.40000,-7.43998,-9.29216
74.60001,-7.45958,-9.30194
74.80000,-7.47985,-9.34944
75.00000,-7.49998,-9.37482
75.20001,-7.51998,-9.40572
75.40000,-7.53971,-9.43490
75.60001,-7.55958,-9.44466
75.80000,-7.57971,-9.49179
76.00000,-7.59985,-9.53184
76.20001,-7.62011,-9.52681
76.40000,-7.63985,-9.51135
76.60001,-7.65958,-9.52141
76.80000,-7.67998,-9.56472
77.00000,-7.69971,-9.56928
77.20001,-7.71985,-9.56692
77.40000,-7.73985,-9.58812
77.60001,-7.75985,-9.61725
77.80000,-7.77971,-9.64056
78.00000,-7.80011,-9.68080
78.20001,-7.81971,-9.72418
78.40000,-7.83958,-9.77832
78.60001,-7.85985,-9.80228
78.80000,-7.87998,-9.82824
79.00000,-7.89985,-9.85653
79.20001,-7.91998,-9.88388
79.40000,-7.93971,-9.88553
79.60001,-7.95958,-9.91607
79.80000,-7.97998,-9.94624
80.00000,-8.00011,-9.94915
80.20001,-8.01958,-9.98582
80.40000,-8.03985,-10.02080
80.60001,-8.05998,-10.04958
80.80000,-8.07971,-10.09323
81.00001,-8.09971,-10.09477
81.20001,-8.11958,-10.11945
81.40000,-8.13958,-10.14662
81.60001,-8.15998,-10.16417
81.80000,-8.18011,-10.19653
82.00001,-8.19971,-9.84937
82.20001,-8.21958,-9.89156
82.40000,-8.23998,-9.93864
82.60001,-8.25985,-9.96388
82.80000,-8.27998,-10.01882
83.00001,-8.29998,-10.05578
83.20001,-8.31971,-10.07412
83.40000,-8.33971,-10.10718
83.60001,-8.35998,-10.14087
83.80000,-8.37985,-10.16567
84.00001,-8.39971,-10.16914
84.20001,-8.41998,-10.20636
84.40000,-8.43985,-10.25247
84.60001,-8.45998,-10.26759
84.80000,-8.47998,-10.26617
85.00001,-8.49945,-10.29658
85.20001,-8.51971,-10.31582
85.40000,-8.53998,-10.33275
85.60001,-8.55998,-10.32791
85.80000,-8.57971,-10.30043
86.00001,-8.59971,-10.31683
86.20001,-8.61971,-10.34185
86.40000,-8.63971,-10.36669
86.60001,-8.65985,-10.36062
86.80000,-8.67958,-10.36650
87.00001,-8.69971,-10.25660
87.20001,-8.72011,-10.22257
87.40000,-8.73998,-10.25402
87.60001,-8.75971,-10.26996
87.80000,-8.77971,-10.31514
88.00001,-8.79998,-10.34596
88.20001,-8.81985,-10.36044
88.40000,-8.84011,-10.39845
88.60001,-8.85984,-10.41242
88.80000,-8.87958,-10.45808
89.00001,-8.89985,-10.49901
89.20001,-8.91998,-10.52905
89.40000,-8.93984,-10.55964
89.60001,-8.95984,-10.57002
89.80000,-8.97998,-10.58407
90.00001,-8.99971,-10.57992
90.20001,-9.01985,-10.59734
90.40000,-9.03998,-10.47801
90.60001,-9.05958,-10.48548
90.80000,-9.07984,-10.51586
91.00001,-9.09984,-10.54186
91.20001,-9.11998,-10.56866
91.40000,-9.13984,-10.58755
91.60001,-9.15971,-10.61673
91.80000,-9.17958,-10.64666
92.00001,-9.19998,-10.67815
92.20001,-9.22011,-10.69843
92.40000,-9.23971,-10.61036
92.60001,-9.25971,-10.62492
92.80000,-9.27998,-10.50582
93.00001,-9.29971,-10.50344
93.20001,-9.31971,-10.54440
93.40000,-9.33984,-10.52506
93.60001,-9.35998,-10.55777
93.80000,-9.37984,-10.59951
94.00001,-9.40011,-10.59814
94.20001,-9.41971,-10.27861
94.40000,-9.43944,-10.33848
94.60001,-9.45998,-10.40863
94.80000,-9.47998,-10.41174
95.00001,-9.49984,-10.41467
95.20001,-9.52011,-10.45223
95.40000,-9.53971,-10.43538
95.60001,-9.55958,-10.40889
95.80000,-9.57998,-10.41640
96.00001,-9.59998,-10.45300
96.20001,-9.61958,-10.48853
96.40000,-9.63998,-10.51719
96.60001,-9.65984,-10.54750
96.80000,-9.67971,-10.57115
97.00001,-9.69971,-10.58558
97.20001,-9.71971,-10.63945
97.40000,-9.73971,-10.68119
97.60001,-9.75984,-10.71726
97.80000,-9.78011,-10.75730
98.00001,-9.79984,-10.80490
98.20001,-9.81958,-10.81417
98.40000,-9.83998,-10.85849
98.60001,-9.85971,-10.89726
98.80000,-9.87998,-10.92624
99.00001,-9.89998,-10.95457
99.20001,-9.91958,-10.97783
99.40000,-9.93984,-10.91851
99.60001,-9.96011,-10.88973
99.80000,-9.97984,-10.94729
100.00001,-9.99971,-10.97102
100.20001,-10.01998,-11.00967
100.40000,-10.04011,-11.01979
100.60001,-10.05984,-10.96115
100.80000,-10.07998,-10.99410
101.00001,-10.09958,-11.03821
101.20001,-10.11971,-11.06455
101.40000,-10.13998,-11.11387
101.60001,-10.15984,-11.15918
101.80000,-10.17971,-10.85391
102.00001,-10.19971,-10.91781
102.20001,-10.21971,-10.96930
102.40000,-10.23984,-11.02376
102.60001,-10.25984,-11.06106
102.80000,-10.27984,-11.13487
103.00001,-10.29971,-11.18820
103.20001,-10.31998,-11.23846
103.40000,-10.33997,-11.26531
103.60001,-10.35971,-11.25187
103.80000,-10.37971,-11.31160
104.00001,-10.39984,-11.38113
104.20001,-10.41984,-11.43675
104.40000,-10.44011,-11.44080
104.60001,-10.45997,-11.50996
104.80000,-10.47957,-11.54784
105.00001,-10.49971,-11.61103
105.20001,-10.51997,-11.67261
105.40000,-10.53984,-11.70626
105.60001,-10.55984,-11.65355
105.80000,-10.57984,-11.64525
106.00001,-10.59971,-11.68203
106.20001,-10.61984,-11.70840
106.40000,-10.63997,-11.76846
106.60001,-10.65957,-11.80904
106.80000,-10.67984,-11.86704
107.00001,-10.69997,-11.90123
107.20001,-10.71984,-11.91305
107.40000,-10.73971,-11.91198
107.60001,-10.75957,-11.87961
107.80000,-10.77971,-11.93407
108.00001,-10.79984,-11.96684
108.20001,-10.82011,-12.00743
108.40000,-10.83971,-12.01712
108.60001,-10.85971,-12.03235
108.80000,-10.87997,-12.05050
109.00001,-10.89971,-12.08573
109.20001,-10.91984,-12.11203
109.40000,-10.93997,-12.14029
109.60001,-10.95997,-12.14492
109.80000,-10.97984,-12.13934
110.00001,-10.99997,-12.19670
110.20001,-11.01971,-12.25005
110.40000,-11.03957,-12.25837
110.60001,-11.05997,-12.23818
110.80000,-11.07984,-12.12271
111.00001,-11.09984,-12.16105
111.20001,-11.12011,-12.22413
111.40000,-11.13971,-12.22615
111.60001,-11.15957,-12.24740
111.80000,-11.17997,-11.61898
112.00001,-11.20011,-11.66435
112.20001,-11.21971,-11.70163
112.40000,-11.23997,-11.75823
112.60001,-11.25984,-11.80087
112.80000,-11.27984,-11.86464
113.00001,-11.29984,-11.92341
113.20001,-11.31957,-11.99180
113.40001,-11.33971,-12.06579
113.60001,-11.35997,-12.12292
113.80000,-11.37997,-12.18624
114.00001,-11.39971,-12.25341
114.20001,-11.41957,-12.32035
114.40001,-11.43984,-12.32744
114.60001,-11.45984,-12.37054
114.80000,-11.47997,-12.41640
115.00001,-11.50011,-12.42531
115.20001,-11.51970,-12.48363
115.40001,-11.53984,-12.55083
115.60001,-11.55997,-12.60485
115.80000,-11.57971,-12.61408
116.00001,-11.59970,-12.66986
116.20001,-11.62011,-12.70643
116.40001,-11.63984,-12.71512
116.60001,-11.65997,-12.73468
116.80000,-11.68010,-12.78693
117.00001,-11.69957,-12.79787
117.20001,-11.71970,-12.85834
117.40001,-11.73997,-12.92731
117.60001,-11.75997,-12.99050
117.80000,-11.77984,-13.06147
118.00001,-11.79984,-13.12667
118.20001,-11.81970,-13.19293
118.40001,-11.83970,-13.21413
118.60001,-11.85997,-13.28592
118.80000,-11.87970,-13.36714
119.00001,-11.89970,-13.41055
119.20001,-11.91997,-13.45829
119.40001,-11.93984,-13.26133
119.60001,-11.95970,-13.36711
119.80000,-11.97970,-13.48130
120.00001,-11.99997,-13.55439
120.20001,-12.01984,-13.60752
120.40001,-12.04010,-13.68965
120.60001,-12.05984,-13.71966
120.80000,-12.07957,-13.67968
121.00001,-12.09984,-13.74179
121.20001,-12.11997,-13.81908
121.40001,-12.13984,-13.86963
121.60001,-12.15984,-13.90033
121.80000,-12.17997,-13.73656
122.00001,-12.19984,-13.77527
122.20001,-12.21997,-13.80438
122.40001,-12.23997,-13.88216
122.60001,-12.25970,-13.94351
122.80000,-12.27997,-14.02734
123.00001,-12.29997,-14.08851
123.20001,-12.31997,-14.11950
123.40001,-12.33984,-14.13482
123.60001,-12.35957,-14.07691
123.80000,-12.37970,-13.99833
124.00001,-12.39984,-14.07250
124.20001,-12.41997,-14.07948
124.40001,-12.43997,-14.14204
124.60001,-12.45970,-14.18021
124.80000,-12.47997,-14.07678
125.00001,-12.49984,-14.14129
125.20001,-12.51984,-14.21417
125.40001,-12.53997,-14.30349
125.60001,-12.55997,-14.36415
125.80000,-12.57984,-14.42539
126.00001,-12.60010,-14.51329
126.20001,-12.61970,-14.35735
126.40001,-12.63944,-14.45454
126.60001,-12.65997,-14.54406
126.80000,-12.67997,-14.52684
127.00001,-12.69984,-14.59160
127.20001,-12.72010,-14.68064
127.40001,-12.73984,-14.74737
127.60001,-12.75970,-14.79292
127.80000,-12.77984,-14.88178
128.00000,-12.80010,-14.95436
128.20002,-12.81970,-15.03243
128.40001,-12.83997,-15.10926
128.60001,-12.85997,-15.18074
128.80000,-12.87997,-15.26687
129.00000,-12.89984,-15.33562
129.20002,-12.91970,-15.09585
129.40001,-12.93983,-15.19837
129.60001,-12.95997,-15.29954
129.80000,-12.97997,-15.34908
130.00000,-12.99970,-15.43888
130.20002,-13.01970,-15.48237
130.40001,-13.03997,-15.55051
130.60001,-13.05983,-15.61813
130.80000,-13.07984,-15.50279
131.00000,-13.09997,-15.57429
131.20002,-13.11970,-15.67080
131.40002,-13.13997,-15.76386
131.60000,-13.15997,-15.65498
131.80000,-13.17970,-15.50127
132.00000,-13.19970,-15.61529
132.20002,-13.21997,-15.76301
132.40002,-13.23997,-15.90090
132.60000,-13.25997,-15.97401
132.80000,-13.28010,-16.10026
133.00000,-13.29943,-16.05363
133.20002,-13.31970,-16.15116
133.40002,-13.34010,-16.21108
133.60000,-13.36010,-16.05132
133.80000,-13.37957,-16.15290
134.00000,-13.39983,-16.27923
134.20002,-13.41983,-16.35531
134.40002,-13.43970,-16.45275
134.60000,-13.45997,-16.53145
134.80000,-13.47983,-16.43070
135.00000,-13.49983,-16.50788
135.20002,-13.51997,-16.58443
135.40002,-13.53997,-16.63094
135.60000,-13.55970,-16.68859
135.80000,-13.57970,-16.76788
136.00000,-13.59997,-16.85783
136.20002,-13.61997,-16.87935
136.40002,-13.63997,-16.98026
136.60000,-13.65997,-17.01243
136.80000,-13.67970,-17.09653
137.00000,-13.69983,-17.16433
137.20002,-13.71997,-17.12107
137.40002,-13.73970,-17.19139
137.60000,-13.75983,-16.92151
137.80000,-13.77997,-17.07518
138.00000,-13.79983,-17.17413
138.20002,-13.81983,-17.30052
138.40002,-13.83997,-17.42011
138.60000,-13.85957,-17.45034
138.80000,-13.87983,-17.43454
139.00000,-13.90010,-17.59333
139.20002,-13.91997,-17.65362
139.40002,-13.93983,-17.69939
139.60000,-13.95970,-17.84924
139.80000,-13.97957,-17.93345
140.00000,-13.99983,-18.01027
140.20002,-14.02010,-17.91782
140.40002,-14.03983,-18.00974
140.60000,-14.05970,-18.10300
140.80000,-14.07997,-18.17148
141.00000,-14.09970,-18.24042
141.20002,-14.11970,-18.35959
141.40002,-14.13997,-18.44963
141.60000,-14.15997,-18.30021
141.80000,-14.17983,-17.57148
142.00000,-14.20010,-17.59834
142.20002,-14.21983,-17.74596
142.40002,-14.23957,-17.90964
142.60000,-14.25997,-18.04349
142.80000,-14.27997,-18.16150
143.00000,-14.30010,-18.22874
143.20002,-14.31996,-18.32187
143.40002,-14.33970,-18.19093
143.60000,-14.35970,-18.32964
143.80000,-14.37997,-18.50278
144.00000,-14.39996,-18.59250
144.20002,-14.41970,-18.74539
144.40002,-14.43983,-18.87843
144.60000,-14.45983,-18.98567
144.80000,-14.47983,-19.10933
145.00000,-14.49970,-19.22080
145.20002,-14.51970,-19.22654
145.40002,-14.53970,-19.28337
145.60000,-14.55996,-19.35453
145.80000,-14.58023,-19.08275
146.00000,-14.59970,-19.05997
146.20002,-14.61956,-18.99526
146.40002,-14.63996,-19.08125
146.60000,-14.65983,-19.02479
146.80000,-14.67996,-19.06885
147.00000,-14.70010,-18.76768
147.20002,-14.71983,-18.71087
147.40002,-14.73983,-18.80777
147.60000,-14.75996,-18.84674
147.80000,-14.77983,-18.86538
148.00000,-14.79970,-18.93156
148.20002,-14.82010,-18.99412
148.40002,-14.83996,-19.04425
148.60000,-14.85996,-19.14362
148.80000,-14.88010,-19.28927
149.00000,-14.89943,-19.42309
149.20002,-14.91970,-19.48603
149.40002,-14.94010,-19.70218
149.60000,-14.95996,-19.77067
149.80000,-14.97970,-19.79862
150.00000,-14.99970,-20.00218
150.20002,-15.01970,-20.14030
150.40002,-15.03983,-20.17653
150.60000,-15.05996,-20.24850
150.80000,-15.07983,-20.25572
151.00000,-15.09983,-20.43213
151.20002,-15.12010,-20.50235
151.40002,-15.13996,-20.58721
151.60000,-15.15970,-20.65369
151.80000,-15.17970,-20.70461
152.00000,-15.19996,-20.81480
152.20002,-15.21996,-20.92591
152.40002,-15.24010,-21.05767
152.60000,-15.25996,-21.15606
152.80000,-15.27956,-21.23571
153.00000,-15.29983,-21.22334
153.20002,-15.31996,-21.36776
153.40002,-15.33983,-21.45416
153.60000,-15.35996,-21.52131
153.80000,-15.37996,-21.55572
154.00000,-15.39983,-21.64966
154.20002,-15.41983,-21.46832
154.40002,-15.43996,-21.61356
154.60000,-15.45956,-21.69174
154.80000,-15.47983,-21.72511
155.00000,-15.50010,-21.95521
155.20002,-15.51996,-22.14441
155.40002,-15.53983,-22.28897
155.60000,-15.55956,-22.48438
155.80000,-15.57969,-22.69873
156.00000,-15.59996,-22.83467
156.20002,-15.62009,-23.03872
156.40002,-15.63983,-23.14164
156.60000,-15.65970,-23.28972
156.80000,-15.67996,-23.46578
157.00000,-15.69983,-23.44768
157.20002,-15.71983,-23.54686
157.40002,-15.73983,-23.80365
157.60000,-15.75996,-23.99854
157.80000,-15.77969,-24.13815
158.00000,-15.80009,-24.26344
158.20002,-15.81969,-24.44897
158.40002,-15.83956,-24.57802
158.60000,-15.85996,-24.49123
158.80000,-15.87983,-24.45721
159.00000,-15.89996,-24.63125
159.20002,-15.92010,-24.81275
159.40002,-15.93969,-24.98751
159.60000,-15.95969,-25.07029
159.80000,-15.97996,-25.08596
160.00000,-16.00009,-25.25494
160.20002,-16.01969,-25.16148
160.26400,-16.02636,-25.16216