File: project1/data/Packing_Peanuts_Instron/Starch_1.is_comp_RawData/Specimen_RawData_3.csv
Time,Extension,Load
(sec),(mm),(N)
0.00000,0.00000,-0.00470
0.20000,-0.01440,-0.02005
0.40000,-0.03853,-0.01991
0.60000,-0.05960,-0.01483
0.80000,-0.07973,-0.03633
1.00000,-0.09973,-0.03415
1.20000,-0.12013,-0.04061
1.40000,-0.14013,-0.03776
1.60000,-0.15973,-0.04549
1.80000,-0.18013,-0.05265
2.00000,-0.20000,-0.05304
2.20000,-0.22000,-0.05593
2.40000,-0.23987,-0.07178
2.60000,-0.25973,-0.06067
2.80000,-0.27987,-0.07038
3.00000,-0.30013,-0.07300
3.20000,-0.32000,-0.07241
3.40000,-0.33960,-0.08336
3.60000,-0.35987,-0.07852
3.80000,-0.38013,-0.07947
4.00000,-0.40000,-0.09006
4.20000,-0.42013,-0.09789
4.40000,-0.44000,-0.09759
4.60000,-0.45987,-0.09298
4.80000,-0.47987,-0.10514
5.00000,-0.50013,-0.10426
5.20000,-0.51987,-0.11246
5.40000,-0.53987,-0.11376
5.60000,-0.56027,-0.11146
5.80000,-0.58000,-0.11711
6.00000,-0.60013,-0.12109
6.20000,-0.62027,-0.12626
6.40000,-0.63960,-0.13495
6.60000,-0.65987,-0.12558
6.80000,-0.68013,-0.14050
7.00000,-0.70000,-0.14005
7.20000,-0.71986,-0.14239
7.40000,-0.74000,-0.14360
7.60000,-0.76000,-0.14152
7.80000,-0.78000,-0.14600
8.00000,-0.80000,-0.16091
8.20000,-0.81973,-0.16258
8.40000,-0.84000,-0.16454
8.60000,-0.86013,-0.16931
8.80000,-0.88000,-0.17413
9.00000,-0.89986,-0.18222
9.20000,-0.92000,-0.18499
9.40000,-0.94000,-0.18713
9.60000,-0.96000,-0.19258
9.80000,-0.98026,-0.20553
10.00000,-0.99973,-0.21965
10.20000,-1.01973,-0.21486
10.40000,-1.04000,-0.22484
10.60000,-1.06013,-0.22511
10.80000,-1.08000,-0.23640
11.00000,-1.10000,-0.24309
11.20000,-1.12013,-0.24751
11.40000,-1.13986,-0.26111
11.60000,-1.16000,-0.26409
11.80000,-1.18000,-0.27766
12.00000,-1.19960,-0.28842
12.20000,-1.22000,-0.28910
12.40000,-1.24000,-0.29676
12.60000,-1.26000,-0.29489
12.80000,-1.27986,-0.30939
13.00000,-1.29973,-0.31774
13.20000,-1.31986,-0.32215
13.40000,-1.34013,-0.33703
13.60000,-1.36013,-0.33958
13.80000,-1.37986,-0.35461
14.00000,-1.39986,-0.35492
14.20000,-1.42013,-0.36515
14.40000,-1.44000,-0.37040
14.60000,-1.46000,-0.37453
14.80000,-1.48000,-0.38232
15.00000,-1.50000,-0.38791
15.20000,-1.52000,-0.39973
15.40000,-1.54026,-0.39446
15.60000,-1.55986,-0.39290
15.80000,-1.57960,-0.37914
16.00000,-1.60013,-0.36738
16.20000,-1.62000,-0.37263
16.40000,-1.64000,-0.38143
16.60000,-1.66013,-0.38405
16.80000,-1.67973,-0.40323
17.00000,-1.69986,-0.40584
17.20000,-1.72013,-0.43023
17.40000,-1.74013,-0.44570
17.60000,-1.75973,-0.44587
17.80000,-1.78013,-0.47479
18.00000,-1.80000,-0.47656
18.20000,-1.82000,-0.47971
18.40000,-1.83973,-0.49695
18.60000,-1.85960,-0.49076
18.80000,-1.87986,-0.51153
19.00000,-1.90013,-0.53244
19.20000,-1.92000,-0.54578
19.40000,-1.93986,-0.56762
19.60000,-1.95986,-0.58192
19.80000,-1.98000,-0.60440
20.00000,-2.00013,-0.63213
20.20000,-2.02013,-0.65742
20.40000,-2.04013,-0.67227
20.60000,-2.05986,-0.69203
20.80000,-2.08013,-0.71859
21.00000,-2.09999,-0.72650
21.20000,-2.11986,-0.75787
21.40000,-2.13999,-0.79268
21.60000,-2.16013,-0.81805
21.80000,-2.18013,-0.85670
22.00000,-2.20013,-0.87256
22.20000,-2.22013,-0.90781
22.40000,-2.23959,-0.94280
22.60000,-2.25986,-0.96456
22.80000,-2.28013,-1.01037
23.00000,-2.30013,-1.02774
23.20000,-2.31973,-1.05289
23.40000,-2.33986,-1.08132
23.60000,-2.35986,-1.11671
23.80000,-2.37999,-1.15015
24.00000,-2.40013,-1.18133
24.20000,-2.41986,-1.20043
24.40000,-2.43986,-1.22582
24.60000,-2.46013,-1.25660
24.80000,-2.47999,-1.29527
25.00000,-2.49973,-1.32970
25.20000,-2.51973,-1.36352
25.40000,-2.53999,-1.41432
25.60000,-2.56013,-1.44959
25.80000,-2.58013,-1.50305
26.00000,-2.59999,-1.53989
26.20000,-2.61973,-1.56943
26.40000,-2.63999,-1.62849
26.60000,-2.66026,-1.68293
26.80000,-2.67999,-1.73950
27.00000,-2.69999,-1.80863
27.20000,-2.71999,-1.84587
27.40000,-2.73986,-1.89083
27.60000,-2.76013,-1.93982
27.80000,-2.78013,-1.99646
28.00000,-2.79973,-2.04695
28.20000,-2.81986,-2.07707
28.40000,-2.84013,-2.11210
28.60000,-2.85999,-2.16813
28.80000,-2.87986,-2.22117
29.00000,-2.89973,-2.26822
29.20000,-2.91973,-2.32471
29.40000,-2.93999,-2.40600
29.60000,-2.96013,-2.44335
29.80000,-2.97986,-2.51760
30.00000,-2.99986,-2.56603
30.20000,-3.02013,-2.63812
30.40000,-3.03999,-2.70628
30.60000,-3.05999,-2.74892
30.80000,-3.07999,-2.81473
31.00000,-3.09999,-2.88944
31.20000,-3.11986,-2.96930
31.40000,-3.14026,-3.05405
31.60000,-3.15999,-3.11834
31.80000,-3.17973,-3.17810
32.00000,-3.19999,-3.21478
32.20000,-3.21999,-3.28154
32.40000,-3.24013,-3.35157
32.60000,-3.26013,-3.38557
32.80000,-3.27986,-3.40893
33.00000,-3.29986,-3.42565
33.20000,-3.32013,-3.46098
33.40000,-3.34013,-3.20235
33.60000,-3.35973,-3.31099
33.80000,-3.38013,-3.41805
34.00000,-3.39986,-3.48017
34.20000,-3.41986,-3.55148
34.40000,-3.43986,-3.63343
34.60000,-3.45972,-3.71257
34.80000,-3.47986,-3.80219
35.00000,-3.49999,-3.88632
35.20000,-3.52012,-3.95906
35.40000,-3.53972,-4.04182
35.60000,-3.55972,-4.11836
35.80000,-3.57999,-4.21234
36.00000,-3.59999,-4.27513
36.20000,-3.62012,-4.34962
36.40000,-3.64012,-4.41850
36.60000,-3.65972,-4.49559
36.80000,-3.67999,-4.57097
37.00000,-3.70026,-4.63584
37.20000,-3.71986,-4.71819
37.40000,-3.73986,-4.79486
37.60000,-3.76026,-4.88273
37.80000,-3.77999,-4.97093
38.00000,-3.79999,-5.06220
38.20000,-3.82012,-5.14331
38.40000,-3.83959,-5.15364
38.60000,-3.85986,-5.20871
38.80000,-3.88026,-5.27599
39.00000,-3.89999,-5.33543
39.20000,-3.91986,-5.35035
39.40000,-3.93999,-5.39717
39.60000,-3.95986,-5.45680
39.80000,-3.97986,-5.45974
40.00000,-4.00012,-5.54362
40.20000,-4.01986,-5.60175
40.40000,-4.03986,-5.57334
40.60000,-4.06012,-5.61317
40.80000,-4.07999,-5.64664
41.00000,-4.09986,-5.68560
41.20000,-4.11972,-5.75156
41.40000,-4.14012,-5.80220
41.60000,-4.15999,-5.87123
41.80000,-4.18012,-5.93004
42.00000,-4.19999,-5.98123
42.20000,-4.21972,-6.03944
42.40000,-4.23999,-6.09274
42.60000,-4.26012,-6.10389
42.80000,-4.27986,-6.15305
43.00000,-4.29999,-6.20433
43.20000,-4.31999,-6.25153
43.40000,-4.33986,-6.30381
43.60000,-4.36012,-6.32553
43.80000,-4.38012,-6.36337
44.00000,-4.39972,-6.38301
44.20000,-4.41999,-6.38620
44.40000,-4.44026,-6.41908
44.60000,-4.45999,-6.46100
44.80000,-4.47986,-6.49323
45.00000,-4.49972,-6.54430
45.20000,-4.51972,-6.59571
45.40000,-4.54012,-6.65941
45.60000,-4.56012,-6.71749
45.80000,-4.57986,-6.77851
46.00000,-4.59999,-6.83113
46.20000,-4.61999,-6.87854
46.40000,-4.63986,-6.91775
46.60000,-4.65986,-5.74474
46.80000,-4.67999,-5.73199
47.00000,-4.69999,-5.79332
47.20000,-4.71999,-5.87900
47.40000,-4.74025,-5.97035
47.60000,-4.75986,-6.02049
47.80000,-4.77959,-6.08508
48.00000,-4.80012,-6.08580
48.20000,-4.81999,-6.14164
48.40000,-4.83999,-6.13510
48.60000,-4.85999,-6.15983
48.80000,-4.87985,-6.18435
49.00000,-4.89985,-6.22661
49.20000,-4.92025,-6.21672
49.40000,-4.93999,-6.25291
49.60000,-4.95972,-6.29091
49.80000,-4.98012,-6.31411
50.00000,-4.99999,-6.33684
50.20000,-5.01985,-6.38080
50.40000,-5.03985,-6.42146
50.60000,-5.05985,-6.45924
50.80000,-5.07985,-6.40547
51.00000,-5.10012,-6.43041
51.20000,-5.12012,-6.47737
51.40000,-5.13972,-6.51164
51.60000,-5.15985,-6.52822
51.80000,-5.17999,-6.55043
52.00000,-5.19999,-6.52169
52.20000,-5.22012,-6.53740
52.40000,-5.23999,-6.54058
52.60000,-5.25985,-6.58089
52.80000,-5.27999,-6.58012
53.00000,-5.30012,-6.61363
53.20000,-5.31985,-6.65746
53.40000,-5.33972,-6.67276
53.60000,-5.36012,-6.70754
53.80000,-5.37999,-6.73560
54.00000,-5.40012,-6.69851
54.20000,-5.42012,-6.72344
54.40000,-5.43972,-6.72740
54.60000,-5.45985,-6.79040
54.80000,-5.48012,-6.80447
55.00000,-5.50012,-6.82464
55.20000,-5.51985,-6.84514
55.40000,-5.53999,-6.83824
55.60000,-5.55985,-6.85537
55.80000,-5.57999,-6.62209
56.00000,-5.59999,-6.60235
56.20000,-5.61972,-6.62481
56.40000,-5.63985,-6.54663
56.60000,-5.66012,-6.56748
56.80000,-5.67999,-6.60752
57.00000,-5.69972,-6.62376
57.20000,-5.71985,-6.64611
57.40000,-5.73999,-6.68676
57.60000,-5.76012,-6.71363
57.80000,-5.78025,-6.74439
58.00000,-5.79999,-6.78032
58.20000,-5.81972,-6.81450
58.40000,-5.83999,-6.83482
58.60000,-5.86012,-6.86668
58.80000,-5.87999,-6.90762
59.00000,-5.89999,-6.91396
59.20000,-5.92012,-6.94490
59.40000,-5.93985,-6.94228
59.60000,-5.95999,-6.97549
59.80000,-5.98012,-6.98574
60.00000,-5.99959,-7.02364
60.20000,-6.01999,-7.06464
60.40000,-6.03999,-7.07678
60.60000,-6.05999,-7.07041
60.80000,-6.07985,-7.05097
61.00000,-6.09972,-7.03960
61.20000,-6.11985,-7.04950
61.40000,-6.14012,-7.09079
61.60000,-6.16012,-7.12008
61.80000,-6.17985,-7.16546
62.00000,-6.19998,-7.18822
62.20000,-6.21998,-7.08194
62.40000,-6.23985,-7.10291
62.60000,-6.25985,-7.09659
62.80000,-6.27998,-7.11835
63.00000,-6.30012,-7.09479
63.20000,-6.31998,-7.13743
63.40000,-6.34025,-7.14164
63.60000,-6.35985,-7.16056
63.80000,-6.37972,-7.18843
64.00000,-6.40025,-7.15610
64.20000,-6.41998,-7.15745
64.40000,-6.43998,-7.18785
64.60001,-6.45998,-7.22476
64.80000,-6.47985,-7.22056
65.00000,-6.49985,-7.24512
65.20000,-6.52012,-7.27616
65.40000,-6.54012,-7.25331
65.60001,-6.55972,-7.26559
65.80000,-6.58012,-7.32076
66.00000,-6.59998,-7.33310
66.20001,-6.61998,-7.36771
66.40000,-6.63985,-7.33831
66.60001,-6.65972,-7.23988
66.80000,-6.67985,-7.14845
67.00000,-6.70012,-7.18802
67.20001,-6.72012,-7.21306
67.40000,-6.73972,-7.24231
67.60001,-6.75985,-7.24872
67.80000,-6.77998,-7.20598
68.00000,-6.79998,-7.21240
68.20001,-6.82012,-7.13238
68.40000,-6.84012,-7.04689
68.60001,-6.85985,-7.06412
68.80000,-6.87985,-7.05923
69.00000,-6.90012,-7.07728
69.20001,-6.91985,-6.97944
69.40000,-6.93985,-6.99416
69.60001,-6.96012,-6.96350
69.80000,-6.97998,-6.96663
70.00000,-6.99998,-6.75041
70.20001,-7.02025,-6.63083
70.40000,-7.03972,-6.62337
70.60001,-7.05985,-6.62446
70.80000,-7.08025,-6.65586
71.00000,-7.10012,-6.64885
71.20001,-7.11972,-6.64948
71.40000,-7.13998,-6.68514
71.60001,-7.15985,-6.73266
71.80000,-7.17998,-6.77846
72.00000,-7.20012,-6.82029
72.20001,-7.21972,-6.85441
72.40000,-7.23985,-6.85753
72.60001,-7.26012,-6.85835
72.80000,-7.27998,-6.80853
73.00000,-7.29985,-6.80667
73.20001,-7.31985,-6.84490
73.40000,-7.33998,-6.87317
73.60001,-7.35998,-6.91244
73.80000,-7.38025,-6.91301
74.00000,-7.39998,-6.96331
74.20001,-7.41972,-7.01243
74.40000,-7.43998,-7.00089
74.60001,-7.46012,-7.02740
74.80000,-7.47998,-7.00125
75.00000,-7.49998,-6.99341
75.20001,-7.52012,-7.02198
75.40000,-7.53985,-7.05696
75.60001,-7.56011,-7.08524
75.80000,-7.57998,-7.11859
76.00000,-7.59971,-7.11575
76.20001,-7.62011,-7.15216
76.40000,-7.64011,-7.18698
76.60001,-7.65998,-7.19232
76.80000,-7.67998,-7.21417
77.00000,-7.69971,-7.24243
77.20001,-7.71985,-7.25268
77.40000,-7.74011,-7.27883
77.60001,-7.76025,-7.30390
77.80000,-7.77985,-7.31669
78.00000,-7.79998,-7.34819
78.20001,-7.81998,-7.35976
78.40000,-7.83985,-7.38057
78.60001,-7.85998,-7.38940
78.80000,-7.87985,-7.36403
79.00000,-7.89998,-7.34028
79.20001,-7.91998,-7.37554
79.40000,-7.94025,-7.37654
79.60001,-7.95985,-7.37824
79.80000,-7.97971,-7.43463
80.00000,-8.00011,-7.45695
80.20001,-8.01998,-7.47590
80.40000,-8.03998,-7.50469
80.60001,-8.06011,-7.52881
80.80000,-8.07985,-7.56838
81.00001,-8.09985,-7.61323
81.20001,-8.12011,-7.58549
81.40000,-8.13998,-7.63055
81.60001,-8.15971,-7.65330
81.80000,-8.17998,-7.69600
82.00001,-8.19998,-7.72919
82.20001,-8.21985,-7.75337
82.40000,-8.23998,-7.77559
82.60001,-8.25985,-7.74795
82.80000,-8.27985,-7.79960
83.00001,-8.30011,-7.22934
83.20001,-8.31998,-7.29664
83.40000,-8.33985,-7.30935
83.60001,-8.35985,-7.32577
83.80000,-8.38011,-7.34849
84.00001,-8.40011,-7.37930
84.20001,-8.42011,-7.39163
84.40000,-8.44011,-7.40947
84.60001,-8.45998,-7.42429
84.80000,-8.47998,-7.45177
85.00001,-8.50011,-7.43191
85.20001,-8.51985,-7.38494
85.40000,-8.53985,-7.44702
85.60001,-8.56011,-7.50523
85.80000,-8.57998,-7.55765
86.00001,-8.59998,-7.60085
86.20001,-8.62011,-7.63831
86.40000,-8.63958,-7.67937
86.60001,-8.65985,-7.58243
86.80000,-8.68011,-7.51618
87.00001,-8.70011,-7.53072
87.20001,-8.71985,-7.53211
87.40000,-8.73998,-7.49904
87.60001,-8.75985,-7.52693
87.80000,-8.77985,-7.58047
88.00001,-8.80011,-7.61927
88.20001,-8.81985,-7.65714
88.40000,-8.83985,-7.68923
88.60001,-8.86011,-7.72362
88.80000,-8.88011,-7.71227
89.00001,-8.89971,-7.69625
89.20001,-8.91998,-7.74362
89.40000,-8.94011,-7.78207
89.60001,-8.95998,-7.81883
89.80000,-8.98011,-7.86799
90.00001,-8.99998,-7.90128
90.20001,-9.01985,-7.90933
90.40000,-9.03998,-7.92064
90.60001,-9.06011,-7.91789
90.80000,-9.07998,-7.97792
91.00001,-9.09984,-7.99895
91.20001,-9.12011,-8.01770
91.40000,-9.13998,-8.03359
91.60001,-9.16011,-8.04477
91.80000,-9.17998,-8.01990
92.00001,-9.19971,-8.05255
92.20001,-9.21998,-8.08429
92.40000,-9.24011,-8.10019
92.60001,-9.25998,-8.12444
92.80000,-9.27984,-8.13620
93.00001,-9.29984,-8.09246
93.20001,-9.31971,-8.09882
93.40000,-9.33998,-8.11576
93.60001,-9.36011,-8.11227
93.80000,-9.37984,-8.15287
94.00001,-9.39998,-8.19117
94.20001,-9.42011,-8.22577
94.40000,-9.43984,-8.13788
94.60001,-9.45998,-8.18123
94.80000,-9.47984,-8.13848
95.00001,-9.49998,-8.17978
95.20001,-9.51998,-8.17144
95.40000,-9.54011,-8.06052
95.60001,-9.55971,-8.08753
95.80000,-9.57971,-8.14907
96.00001,-9.60024,-8.19804
96.20001,-9.61998,-8.24581
96.40000,-9.63998,-8.20557
96.60001,-9.65998,-8.25641
96.80000,-9.67984,-8.27368
97.00001,-9.69984,-8.31872
97.20001,-9.72011,-8.33457
97.40000,-9.74011,-8.38011
97.60001,-9.75971,-8.40660
97.80000,-9.77998,-8.35675
98.00001,-9.79998,-8.38929
98.20001,-9.81984,-8.43600
98.40000,-9.83984,-8.45111
98.60001,-9.85971,-8.48290
98.80000,-9.87984,-8.51860
99.00001,-9.90011,-8.25476
99.20001,-9.92011,-8.29972
99.40000,-9.93971,-8.37559
99.60001,-9.95971,-8.42977
99.80000,-9.97998,-8.32213
100.00001,-9.99998,-8.40041
100.20001,-10.02011,-8.46524
100.40000,-10.04011,-8.51663
100.60001,-10.05984,-8.55977
100.80000,-10.07998,-8.60622
101.00001,-10.10011,-8.60103
101.20001,-10.11984,-8.65975
101.40000,-10.13984,-8.68624
101.60001,-10.16024,-8.74014
101.80000,-10.17998,-8.79141
102.00001,-10.20011,-8.83988
102.20001,-10.22011,-8.86776
102.40000,-10.23971,-8.93817
102.60001,-10.25984,-8.98194
102.80000,-10.28024,-8.96998
103.00001,-10.29984,-9.01130
103.20001,-10.31984,-9.05419
103.40000,-10.33997,-9.08728
103.60001,-10.35984,-9.11219
103.80000,-10.37984,-9.15573
104.00001,-10.40011,-9.14278
104.20001,-10.41971,-9.12585
104.40000,-10.43984,-9.18589
104.60001,-10.46011,-9.21179
104.80000,-10.47997,-9.24901
105.00001,-10.49984,-9.24656
105.20001,-10.51984,-9.14301
105.40000,-10.54011,-9.17154
105.60001,-10.55997,-9.20444
105.80000,-10.58011,-9.25250
106.00001,-10.59997,-9.28704
106.20001,-10.61984,-9.31870
106.40000,-10.63997,-9.35140
106.60001,-10.66011,-9.38532
106.80000,-10.67984,-9.37919
107.00001,-10.69997,-8.99445
107.20001,-10.72011,-9.06027
107.40000,-10.73984,-9.05847
107.60001,-10.75997,-9.03152
107.80000,-10.77997,-9.05683
108.00001,-10.79957,-9.09148
108.20001,-10.81997,-9.18751
108.40000,-10.84011,-9.28620
108.60001,-10.85997,-9.34831
108.80000,-10.87984,-9.42913
109.00001,-10.89971,-9.46019
109.20001,-10.91984,-9.53316
109.40000,-10.94011,-9.53917
109.60001,-10.95997,-9.58316
109.80000,-10.97971,-9.62752
110.00001,-10.99997,-9.59525
110.20001,-11.02011,-9.61252
110.40000,-11.03997,-9.62399
110.60001,-11.05997,-9.50052
110.80000,-11.07997,-9.45263
111.00001,-11.09997,-9.50324
111.20001,-11.11997,-9.53725
111.40000,-11.14024,-9.45694
111.60001,-11.15984,-9.47115
111.80000,-11.17957,-9.37987
112.00001,-11.20024,-9.28895
112.20001,-11.21997,-9.03221
112.40000,-11.23997,-9.01664
112.60001,-11.25997,-9.00435
112.80000,-11.27997,-8.99438
113.00001,-11.29984,-9.05597
113.20001,-11.32011,-8.97029
113.40001,-11.34011,-9.02329
113.60001,-11.35971,-8.99235
113.80000,-11.38011,-9.00401
114.00001,-11.39984,-9.04811
114.20001,-11.41984,-9.04815
114.40001,-11.43984,-8.99305
114.60001,-11.45971,-9.04347
114.80000,-11.47984,-9.04291
115.00001,-11.50011,-9.09900
115.20001,-11.52011,-9.12391
115.40001,-11.53971,-9.12625
115.60001,-11.55984,-9.14787
115.80000,-11.58010,-8.72669
116.00001,-11.60011,-8.78377
116.20001,-11.61997,-8.75588
116.40001,-11.63997,-8.75977
116.60001,-11.65984,-8.81552
116.80000,-11.67997,-8.82614
117.00001,-11.70010,-8.64099
117.20001,-11.71984,-8.63790
117.40001,-11.73984,-8.64164
117.60001,-11.76010,-8.51077
117.80000,-11.77997,-8.56251
118.00001,-11.80010,-8.56561
118.20001,-11.82010,-8.58594
118.40001,-11.83970,-8.62635
118.60001,-11.85984,-8.64692
118.80000,-11.88010,-8.69982
119.00001,-11.89997,-8.67938
119.20001,-11.91997,-8.67705
119.40001,-11.93997,-8.70097
119.60001,-11.95984,-8.74779
119.80000,-11.97984,-8.75166
120.00001,-12.00010,-8.78711
120.20001,-12.01984,-8.70141
120.40001,-12.03997,-8.68396
120.60001,-12.06010,-8.67500
120.80000,-12.07997,-8.75480
121.00001,-12.09984,-8.82331
121.20001,-12.11984,-8.85321
121.40001,-12.13997,-8.93914
121.60001,-12.16010,-9.00872
121.80000,-12.18024,-9.02637
122.00001,-12.19997,-9.06875
122.20001,-12.21970,-9.16258
122.40001,-12.23997,-9.26493
122.60001,-12.26010,-9.36070
122.80000,-12.27984,-9.39089
123.00001,-12.29997,-9.47754
123.20001,-12.32010,-9.53817
123.40001,-12.33997,-9.58735
123.60001,-12.36010,-9.58500
123.80000,-12.37997,-9.66922
124.00001,-12.39984,-9.68708
124.20001,-12.41997,-9.73584
124.40001,-12.44010,-9.81039
124.60001,-12.45997,-9.88153
124.80000,-12.47997,-9.96515
125.00001,-12.49984,-10.03258
125.20001,-12.51984,-9.98288
125.40001,-12.53997,-10.06288
125.60001,-12.55997,-10.13285
125.80000,-12.57984,-10.17833
126.00001,-12.59997,-10.22657
126.20001,-12.62010,-10.25125
126.40001,-12.63984,-10.31685
126.60001,-12.65997,-10.31729
126.80000,-12.67997,-10.29335
127.00001,-12.70010,-10.23269
127.20001,-12.72010,-10.30180
127.40001,-12.74024,-10.38154
127.60001,-12.75984,-10.42670
127.80000,-12.77970,-10.49716
128.00000,-12.80010,-10.55396
128.20002,-12.82010,-10.58063
128.40001,-12.84010,-10.63239
128.60001,-12.86010,-10.67328
128.80000,-12.87984,-10.65599
129.00000,-12.89984,-10.73996
129.20002,-12.92024,-10.81999
129.40001,-12.94010,-10.86957
129.60001,-12.95970,-10.88656
129.80000,-12.98010,-10.92123
130.00000,-12.99997,-11.01154
130.20002,-13.01997,-11.09164
130.40001,-13.03983,-11.16890
130.60001,-13.05970,-11.22894
130.80000,-13.07984,-11.29593
131.00000,-13.10010,-11.37627
131.20002,-13.11997,-11.40270
131.40002,-13.13983,-11.46448
131.60000,-13.15997,-11.52707
131.80000,-13.17997,-11.61391
132.00000,-13.20010,-11.65076
132.20002,-13.22010,-11.75389
132.40002,-13.23997,-11.75350
132.60000,-13.25997,-11.81226
132.80000,-13.28010,-11.89492
133.00000,-13.30010,-11.92627
133.20002,-13.31983,-11.99118
133.40002,-13.33997,-12.00417
133.60000,-13.36010,-11.85194
133.80000,-13.37997,-11.77003
134.00000,-13.39997,-11.62507
134.20002,-13.42023,-11.73621
134.40002,-13.43970,-11.85382
134.60000,-13.45997,-11.96124
134.80000,-13.48010,-12.09245
135.00000,-13.49997,-12.12704
135.20002,-13.51997,-12.22891
135.40002,-13.53997,-12.28049
135.60000,-13.55997,-12.35912
135.80000,-13.57997,-12.26337
136.00000,-13.59997,-12.37628
136.20002,-13.61970,-12.47890
136.40002,-13.63997,-12.56466
136.60000,-13.66010,-12.62118
136.80000,-13.68010,-12.21062
137.00000,-13.69983,-12.26670
137.20002,-13.71983,-12.38100
137.40002,-13.74010,-12.52313
137.60000,-13.75997,-12.59348
137.80000,-13.78023,-12.65593
138.00000,-13.79983,-12.72381
138.20002,-13.81983,-12.73651
138.40002,-13.83997,-12.84555
138.60000,-13.86023,-12.91960
138.80000,-13.87997,-13.01769
139.00000,-13.89997,-13.08555
139.20002,-13.92010,-13.10647
139.40002,-13.93997,-13.14688
139.60000,-13.96010,-13.20031
139.80000,-13.98010,-13.17068
140.00000,-13.99970,-13.28085
140.20002,-14.02010,-13.37097
140.40002,-14.04010,-13.39532
140.60000,-14.06010,-13.37896
140.80000,-14.07997,-13.37235
141.00000,-14.09983,-13.29535
141.20002,-14.11983,-13.29854
141.40002,-14.14023,-13.29828
141.60000,-14.16023,-13.21316
141.80000,-14.17983,-13.33827
142.00000,-14.19997,-13.45222
142.20002,-14.22010,-13.54149
142.40002,-14.23997,-13.65142
142.60000,-14.25997,-13.71693
142.80000,-14.27997,-13.70270
143.00000,-14.29997,-13.83887
143.20002,-14.31983,-13.95310
143.40002,-14.34023,-14.03257
143.60000,-14.35983,-14.09684
143.80000,-14.37970,-14.23439
144.00000,-14.40023,-14.37348
144.20002,-14.41996,-14.43940
144.40002,-14.44010,-14.31494
144.60000,-14.46010,-14.29905
144.80000,-14.47996,-14.25526
145.00000,-14.49983,-14.36523
145.20002,-14.52010,-14.52554
145.40002,-14.54010,-14.63424
145.60000,-14.55983,-14.72877
145.80000,-14.58010,-14.86511
146.00000,-14.59996,-14.98342
146.20002,-14.61996,-15.10931
146.40002,-14.63983,-15.18213
146.60000,-14.65970,-14.88838
146.80000,-14.67983,-14.57545
147.00000,-14.70010,-14.82940
147.20002,-14.72010,-15.04729
147.40002,-14.73983,-15.21383
147.60000,-14.75983,-15.26093
147.80000,-14.77996,-15.34155
148.00000,-14.79996,-15.41544
148.20002,-14.82010,-15.47144
148.40002,-14.84010,-15.58336
148.60000,-14.85996,-15.72540
148.80000,-14.87996,-15.86220
149.00000,-14.90023,-16.00999
149.20002,-14.91996,-16.02176
149.40002,-14.93983,-15.89093
149.60000,-14.96010,-15.99302
149.80000,-14.98010,-16.12773
150.00000,-15.00010,-15.61307
150.20002,-15.02010,-15.71220
150.40002,-15.03970,-15.79116
150.60000,-15.05996,-15.88663
150.80000,-15.08010,-16.04871
151.00000,-15.09996,-16.03777
151.20002,-15.11983,-15.75167
151.40002,-15.14010,-15.90711
151.60000,-15.15996,-16.01502
151.80000,-15.17983,-16.14567
152.00000,-15.20010,-16.23679
152.20002,-15.21983,-16.35691
152.40002,-15.23996,-16.49087
152.60000,-15.26023,-16.60523
152.80000,-15.27996,-16.61700
153.00000,-15.29983,-16.69146
153.20002,-15.31983,-16.79395
153.40002,-15.34023,-16.87200
153.60000,-15.35996,-16.90702
153.80000,-15.38023,-16.69277
154.00000,-15.39996,-16.73132
154.20002,-15.41983,-16.83346
154.40002,-15.43996,-16.94608
154.60000,-15.46023,-17.07427
154.80000,-15.47996,-17.20949
155.00000,-15.49996,-17.24716
155.20002,-15.52010,-17.36681
155.40002,-15.53996,-17.34912
155.60000,-15.56010,-17.09810
155.80000,-15.58010,-16.91554
156.00000,-15.59970,-16.98525
156.20002,-15.61996,-17.06920
156.40002,-15.64023,-17.16005
156.60000,-15.65996,-17.10938
156.80000,-15.67983,-17.08381
157.00000,-15.69983,-17.12376
157.20002,-15.71983,-17.11161
157.40002,-15.74009,-17.23491
157.60000,-15.76010,-17.32261
157.80000,-15.77983,-17.28905
158.00000,-15.79996,-17.23125
158.20002,-15.82023,-16.25962
158.40002,-15.83983,-16.07952
158.60000,-15.85983,-16.03402
158.80000,-15.87996,-16.06804
159.00000,-15.90009,-15.81203
159.20002,-15.91996,-15.57613
159.40002,-15.94023,-15.59003
159.60000,-15.95983,-15.59635
159.80000,-15.97969,-15.52563
160.00000,-16.00009,-15.53048
160.20002,-16.02009,-15.18816
160.32200,-16.03223,-15.20007