File: project1/data/Packing_Peanuts_Instron/Starch_1.is_comp_RawData/Specimen_RawData_4.csv
Time,Extension,Load
(sec),(mm),(N)
0.00000,0.00000,0.00050
0.20000,-0.01520,-0.01995
0.40000,-0.03840,-0.02426
0.60000,-0.05947,-0.02307
0.80000,-0.07973,-0.02948
1.00000,-0.10013,-0.03137
1.20000,-0.12000,-0.03416
1.40000,-0.13987,-0.03427
1.60000,-0.16027,-0.02618
1.80000,-0.18000,-0.03346
2.00000,-0.20013,-0.03969
2.20000,-0.22027,-0.04066
2.40000,-0.23973,-0.05309
2.60000,-0.26000,-0.03941
2.80000,-0.28027,-0.05468
3.00000,-0.30013,-0.04904
3.20000,-0.31987,-0.05724
3.40000,-0.34013,-0.05833
3.60000,-0.36000,-0.05155
3.80000,-0.38013,-0.05964
4.00000,-0.40013,-0.06878
4.20000,-0.41987,-0.07100
4.40000,-0.43987,-0.07053
4.60000,-0.46027,-0.06430
4.80000,-0.48013,-0.07119
5.00000,-0.49987,-0.07594
5.20000,-0.51987,-0.07352
5.40000,-0.54013,-0.07563
5.60000,-0.56013,-0.08140
5.80000,-0.58027,-0.09810
6.00000,-0.60000,-0.09715
6.20000,-0.61973,-0.10526
6.40000,-0.64013,-0.10602
6.60000,-0.66027,-0.10363
6.80000,-0.68013,-0.11373
7.00000,-0.70013,-0.11566
7.20000,-0.72013,-0.11675
7.40000,-0.73986,-0.11487
7.60000,-0.76013,-0.11352
7.80000,-0.78013,-0.12005
8.00000,-0.79973,-0.12632
8.20000,-0.82013,-0.12689
8.40000,-0.84013,-0.12713
8.60000,-0.86000,-0.12113
8.80000,-0.88000,-0.13374
9.00000,-0.89973,-0.13366
9.20000,-0.91986,-0.13803
9.40000,-0.94013,-0.14486
9.60000,-0.96013,-0.13639
9.80000,-0.97986,-0.15190
10.00000,-1.00000,-0.14726
10.20000,-1.02026,-0.15740
10.40000,-1.04000,-0.16018
10.60000,-1.06000,-0.15239
10.80000,-1.08000,-0.17365
11.00000,-1.10013,-0.16868
11.20000,-1.12013,-0.17912
11.40000,-1.14026,-0.18820
11.60000,-1.16000,-0.17413
11.80000,-1.17973,-0.19220
12.00000,-1.20013,-0.19927
12.20000,-1.22013,-0.19877
12.40000,-1.24013,-0.19604
12.60000,-1.26013,-0.19572
12.80000,-1.27986,-0.21223
13.00000,-1.30000,-0.21271
13.20000,-1.32013,-0.21754
13.40000,-1.34026,-0.22578
13.60000,-1.35986,-0.21888
13.80000,-1.38026,-0.23542
14.00000,-1.40013,-0.23734
14.20000,-1.42000,-0.24803
14.40000,-1.43986,-0.25391
14.60000,-1.45973,-0.25241
14.80000,-1.47986,-0.26544
15.00000,-1.50013,-0.27503
15.20000,-1.52026,-0.27689
15.40000,-1.53986,-0.28924
15.60000,-1.55986,-0.28817
15.80000,-1.58000,-0.30039
16.00000,-1.60013,-0.31196
16.20000,-1.62013,-0.31128
16.40000,-1.64013,-0.32360
16.60000,-1.66000,-0.31922
16.80000,-1.68013,-0.34149
17.00000,-1.70013,-0.33758
17.20000,-1.72000,-0.35244
17.40000,-1.74000,-0.36317
17.60000,-1.76026,-0.36439
17.80000,-1.78013,-0.37663
18.00000,-1.80013,-0.38893
18.20000,-1.82013,-0.39717
18.40000,-1.83973,-0.40632
18.60000,-1.85986,-0.40948
18.80000,-1.88026,-0.42717
19.00000,-1.90013,-0.43365
19.20000,-1.91986,-0.44577
19.40000,-1.93986,-0.45121
19.60000,-1.96000,-0.45035
19.80000,-1.98000,-0.46567
20.00000,-2.00026,-0.47445
20.20000,-2.02000,-0.48773
20.40000,-2.04000,-0.49307
20.60000,-2.06026,-0.49318
20.80000,-2.08013,-0.48740
21.00000,-2.09986,-0.49737
21.20000,-2.11986,-0.50188
21.40000,-2.14013,-0.51807
21.60000,-2.16013,-0.51900
21.80000,-2.18026,-0.54201
22.00000,-2.19999,-0.55437
22.20000,-2.21986,-0.56120
22.40000,-2.23999,-0.56685
22.60000,-2.26013,-0.57762
22.80000,-2.28013,-0.60022
23.00000,-2.30013,-0.61236
23.20000,-2.32013,-0.61744
23.40000,-2.33986,-0.62811
23.60000,-2.36026,-0.63772
23.80000,-2.38013,-0.65498
24.00000,-2.39986,-0.67106
24.20000,-2.41999,-0.67249
24.40000,-2.44013,-0.68800
24.60000,-2.45999,-0.68945
24.80000,-2.47999,-0.70613
25.00000,-2.49973,-0.71600
25.20000,-2.51986,-0.72835
25.40000,-2.54013,-0.74530
25.60000,-2.56026,-0.74300
25.80000,-2.57986,-0.76529
26.00000,-2.59986,-0.76959
26.20000,-2.62013,-0.77674
26.40000,-2.63999,-0.79242
26.60000,-2.65999,-0.79478
26.80000,-2.68013,-0.81600
27.00000,-2.70013,-0.83605
27.20000,-2.72013,-0.85134
27.40000,-2.74013,-0.86250
27.60000,-2.75999,-0.87568
27.80000,-2.77973,-0.89647
28.00000,-2.80013,-0.92082
28.20000,-2.81999,-0.92958
28.40000,-2.84013,-0.94593
28.60000,-2.86013,-0.95091
28.80000,-2.87986,-0.96323
29.00000,-2.89986,-0.98321
29.20000,-2.92013,-1.00756
29.40000,-2.94026,-1.02330
29.60000,-2.95986,-1.03874
29.80000,-2.98013,-1.06780
30.00000,-2.99999,-1.08349
30.20000,-3.01999,-1.10161
30.40000,-3.03999,-1.12001
30.60000,-3.05986,-1.13146
30.80000,-3.07986,-1.15477
31.00000,-3.10013,-1.17760
31.20000,-3.12013,-1.19082
31.40000,-3.13986,-1.21951
31.60000,-3.15986,-1.23176
31.80000,-3.18013,-1.25667
32.00000,-3.19999,-1.28298
32.20000,-3.22013,-1.29876
32.40000,-3.24026,-1.32590
32.60000,-3.25986,-1.34624
32.80000,-3.28013,-1.37449
33.00000,-3.30026,-1.40849
33.20000,-3.31986,-1.42831
33.40000,-3.33986,-1.45226
33.60000,-3.36026,-1.46639
33.80000,-3.38013,-1.49408
34.00000,-3.39999,-1.52216
34.20000,-3.42012,-1.54563
34.40000,-3.43972,-1.57584
34.60000,-3.45986,-1.59044
34.80000,-3.48039,-1.62449
35.00000,-3.49999,-1.66752
35.20000,-3.51986,-1.69927
35.40000,-3.53999,-1.73735
35.60000,-3.55986,-1.76625
35.80000,-3.57999,-1.79500
36.00000,-3.60012,-1.83154
36.20000,-3.61999,-1.86547
36.40000,-3.63999,-1.87912
36.60000,-3.66012,-1.91212
36.80000,-3.68012,-1.94935
37.00000,-3.69986,-1.99187
37.20000,-3.71986,-2.02247
37.40000,-3.74026,-2.05374
37.60000,-3.76012,-2.08221
37.80000,-3.78012,-2.12727
38.00000,-3.80012,-2.14992
38.20000,-3.81986,-2.16971
38.40000,-3.83999,-2.21251
38.60000,-3.86012,-2.23583
38.80000,-3.87999,-2.28574
39.00000,-3.90012,-2.31489
39.20000,-3.92012,-2.35718
39.40000,-3.93986,-2.39764
39.60000,-3.96012,-2.43011
39.80000,-3.98012,-2.46674
40.00000,-3.99986,-2.49966
40.20000,-4.02012,-2.52700
40.40000,-4.04026,-2.56016
40.60000,-4.06012,-2.57747
40.80000,-4.07986,-2.62872
41.00000,-4.09986,-2.66148
41.20000,-4.11986,-2.69840
41.40000,-4.14012,-2.73264
41.60000,-4.16026,-2.72993
41.80000,-4.17986,-2.74872
42.00000,-4.19999,-2.77479
42.20000,-4.22012,-2.81027
42.40000,-4.23999,-2.84960
42.60000,-4.25999,-2.86880
42.80000,-4.28012,-2.93172
43.00000,-4.29999,-2.96666
43.20000,-4.32012,-3.00441
43.40000,-4.34026,-3.04277
43.60000,-4.35999,-3.07107
43.80000,-4.37972,-3.12467
44.00000,-4.40012,-3.16638
44.20000,-4.41999,-3.19952
44.40000,-4.44012,-3.23827
44.60000,-4.46012,-3.28555
44.80000,-4.47999,-3.34817
45.00000,-4.49999,-3.37691
45.20000,-4.52012,-3.42329
45.40000,-4.54012,-3.45588
45.60000,-4.55986,-3.49482
45.80000,-4.58012,-3.54373
46.00000,-4.60012,-3.57755
46.20000,-4.61999,-3.62286
46.40000,-4.63999,-3.67440
46.60000,-4.65986,-3.72054
46.80000,-4.67986,-3.76336
47.00000,-4.70012,-3.80369
47.20000,-4.72026,-3.85364
47.40000,-4.73985,-3.89910
47.60000,-4.75986,-3.93050
47.80000,-4.78012,-3.97838
48.00000,-4.80012,-4.01200
48.20000,-4.82012,-4.05177
48.40000,-4.84012,-4.08697
48.60000,-4.85999,-4.11068
48.80000,-4.87999,-4.14363
49.00000,-4.90012,-4.17374
49.20000,-4.91999,-4.21696
49.40000,-4.93985,-4.25160
49.60000,-4.96025,-4.28541
49.80000,-4.98012,-4.33105
50.00000,-5.00012,-4.36830
50.20000,-5.02025,-4.39686
50.40000,-5.03972,-4.42877
50.60000,-5.05999,-4.45670
50.80000,-5.08012,-4.49763
51.00000,-5.10012,-4.52643
51.20000,-5.11999,-4.55166
51.40000,-5.13999,-4.59415
51.60000,-5.15999,-4.62954
51.80000,-5.17999,-4.66135
52.00000,-5.20012,-4.70263
52.20000,-5.21985,-4.72560
52.40000,-5.23985,-4.73844
52.60000,-5.26012,-4.76355
52.80000,-5.28012,-4.78305
53.00000,-5.29985,-4.80543
53.20000,-5.31985,-4.81677
53.40000,-5.33999,-4.83499
53.60000,-5.36012,-4.85789
53.80000,-5.38039,-4.88730
54.00000,-5.39999,-4.91181
54.20000,-5.41985,-4.92746
54.40000,-5.43999,-4.95286
54.60000,-5.46025,-4.97389
54.80000,-5.47999,-4.98606
55.00000,-5.50012,-5.01865
55.20000,-5.52025,-5.03642
55.40000,-5.53999,-5.05908
55.60000,-5.56012,-5.07859
55.80000,-5.58012,-5.10855
56.00000,-5.59972,-5.14375
56.20000,-5.62012,-5.15227
56.40000,-5.64012,-5.16127
56.60000,-5.66012,-5.16912
56.80000,-5.67999,-5.18036
57.00000,-5.69985,-5.21462
57.20000,-5.71985,-5.20848
57.40000,-5.74012,-5.22341
57.60000,-5.76012,-5.23980
57.80000,-5.77999,-5.27647
58.00000,-5.79999,-5.30582
58.20000,-5.82025,-5.33131
58.40000,-5.83999,-5.35452
58.60000,-5.85999,-5.36335
58.80000,-5.88012,-5.39870
59.00000,-5.90012,-5.41980
59.20000,-5.91999,-5.44879
59.40000,-5.94025,-5.49273
59.60000,-5.95985,-5.51262
59.80000,-5.97985,-5.53895
60.00000,-6.00025,-5.53511
60.20000,-6.02012,-5.56144
60.40000,-6.04012,-5.59047
60.60000,-6.06012,-5.60566
60.80000,-6.07999,-5.61458
61.00000,-6.09985,-5.63601
61.20000,-6.12012,-5.65348
61.40000,-6.14012,-5.65264
61.60000,-6.15985,-5.66507
61.80000,-6.18012,-5.67741
62.00000,-6.19998,-5.68226
62.20000,-6.21998,-5.70767
62.40000,-6.23985,-5.72971
62.60000,-6.25985,-5.74724
62.80000,-6.27998,-5.76511
63.00000,-6.30012,-5.78996
63.20000,-6.32025,-5.80708
63.40000,-6.33985,-5.81971
63.60000,-6.35985,-5.82396
63.80000,-6.38012,-5.83828
64.00000,-6.39998,-5.85244
64.20000,-6.42012,-5.86516
64.40000,-6.44012,-5.87380
64.60001,-6.45985,-5.88988
64.80000,-6.48012,-5.90513
65.00000,-6.50012,-5.91438
65.20000,-6.51985,-5.93329
65.40000,-6.53985,-5.93652
65.60001,-6.56012,-5.94449
65.80000,-6.57998,-5.95514
66.00000,-6.60012,-5.96570
66.20001,-6.62025,-5.97578
66.40000,-6.63972,-5.96362
66.60001,-6.65998,-5.98016
66.80000,-6.68025,-5.99748
67.00000,-6.70012,-6.00730
67.20001,-6.71985,-6.00214
67.40000,-6.73998,-6.01421
67.60001,-6.75998,-6.01082
67.80000,-6.77998,-6.02243
68.00000,-6.80025,-6.03389
68.20001,-6.81985,-6.03383
68.40000,-6.83998,-6.03832
68.60001,-6.86012,-6.03820
68.80000,-6.87998,-6.04218
69.00000,-6.89985,-6.05452
69.20001,-6.91998,-6.06215
69.40000,-6.93998,-6.07793
69.60001,-6.95998,-6.06765
69.80000,-6.98025,-6.08000
70.00000,-7.00012,-6.09646
70.20001,-7.01985,-6.10319
70.40000,-7.03998,-6.10630
70.60001,-7.06025,-6.11830
70.80000,-7.07998,-6.13214
71.00000,-7.09998,-6.13317
71.20001,-7.12012,-6.14416
71.40000,-7.13998,-6.15064
71.60001,-7.16012,-6.15757
71.80000,-7.18012,-6.16115
72.00000,-7.19972,-6.15655
72.20001,-7.22012,-6.15052
72.40000,-7.24012,-6.14999
72.60001,-7.25998,-6.14299
72.80000,-7.27998,-6.14505
73.00000,-7.29985,-6.14867
73.20001,-7.31985,-6.15194
73.40000,-7.34025,-6.14869
73.60001,-7.36025,-6.13105
73.80000,-7.37998,-6.13050
74.00000,-7.39998,-6.11327
74.20001,-7.41998,-6.11896
74.40000,-7.43998,-6.12072
74.60001,-7.45998,-6.11726
74.80000,-7.47998,-6.10955
75.00000,-7.50011,-6.10901
75.20001,-7.51998,-6.11254
75.40000,-7.54025,-6.11351
75.60001,-7.55985,-6.11174
75.80000,-7.57971,-6.10511
76.00000,-7.60011,-6.10784
76.20001,-7.62011,-6.09990
76.40000,-7.64011,-6.09498
76.60001,-7.66011,-6.08816
76.80000,-7.67998,-6.06626
77.00000,-7.69985,-6.06180
77.20001,-7.72025,-6.06144
77.40000,-7.74011,-6.05140
77.60001,-7.75985,-6.03839
77.80000,-7.78011,-6.03394
78.00000,-7.80011,-6.04776
78.20001,-7.81998,-6.04425
78.40000,-7.83998,-6.04799
78.60001,-7.85985,-6.04358
78.80000,-7.87985,-6.04718
79.00000,-7.90011,-6.05421
79.20001,-7.92025,-6.04489
79.40000,-7.93985,-6.04619
79.60001,-7.95985,-6.03673
79.80000,-7.98011,-6.03528
80.00000,-8.00011,-6.03690
80.20001,-8.02025,-6.04336
80.40000,-8.04011,-6.04557
80.60001,-8.05998,-6.04348
80.80000,-8.07998,-6.03408
81.00001,-8.10025,-6.02326
81.20001,-8.11998,-6.02127
81.40000,-8.13985,-6.02384
81.60001,-8.16011,-6.02222
81.80000,-8.18011,-6.01901
82.00001,-8.19998,-6.01691
82.20001,-8.22011,-6.00848
82.40000,-8.23971,-6.00715
82.60001,-8.25998,-6.00833
82.80000,-8.28025,-6.02145
83.00001,-8.30011,-6.01609
83.20001,-8.31985,-6.01971
83.40000,-8.34011,-6.02505
83.60001,-8.35998,-6.01822
83.80000,-8.37998,-6.02989
84.00001,-8.40011,-6.02201
84.20001,-8.41985,-6.02916
84.40000,-8.43998,-6.02643
84.60001,-8.46025,-6.00983
84.80000,-8.48011,-6.02879
85.00001,-8.49985,-6.02598
85.20001,-8.51998,-6.04106
85.40000,-8.54025,-6.04075
85.60001,-8.55998,-6.04284
85.80000,-8.58011,-6.05240
86.00001,-8.60025,-6.05800
86.20001,-8.61985,-6.06113
86.40000,-8.63998,-6.05823
86.60001,-8.66025,-6.05925
86.80000,-8.67998,-6.06269
87.00001,-8.69998,-6.05832
87.20001,-8.72025,-6.06050
87.40000,-8.74011,-6.04061
87.60001,-8.76011,-6.04697
87.80000,-8.78025,-6.04868
88.00001,-8.79971,-6.05875
88.20001,-8.82011,-6.06613
88.40000,-8.84038,-6.06889
88.60001,-8.86011,-6.05878
88.80000,-8.87998,-6.06826
89.00001,-8.89985,-6.07651
89.20001,-8.91985,-6.07943
89.40000,-8.94011,-6.08234
89.60001,-8.96025,-6.06843
89.80000,-8.97998,-6.06468
90.00001,-8.99998,-6.06664
90.20001,-9.02011,-6.07200
90.40000,-9.04011,-6.06653
90.60001,-9.05998,-6.05947
90.80000,-9.08011,-6.07210
91.00001,-9.10011,-6.06560
91.20001,-9.12011,-6.05879
91.40000,-9.14024,-6.04190
91.60001,-9.15984,-6.04453
91.80000,-9.17984,-6.04606
92.00001,-9.20011,-6.05117
92.20001,-9.22011,-6.04960
92.40000,-9.24011,-6.05639
92.60001,-9.26011,-6.05259
92.80000,-9.27998,-6.05793
93.00001,-9.29998,-6.07298
93.20001,-9.32011,-6.08040
93.40000,-9.34038,-6.07511
93.60001,-9.35984,-6.07531
93.80000,-9.38011,-6.07774
94.00001,-9.40011,-6.08631
94.20001,-9.41998,-6.08585
94.40000,-9.43998,-6.07707
94.60001,-9.45984,-6.07546
94.80000,-9.47998,-6.07961
95.00001,-9.50011,-6.08627
95.20001,-9.52024,-6.08813
95.40000,-9.53984,-6.08790
95.60001,-9.55984,-6.08762
95.80000,-9.58024,-6.10244
96.00001,-9.59998,-6.10955
96.20001,-9.62024,-6.12224
96.40000,-9.64024,-6.12068
96.60001,-9.65998,-6.11713
96.80000,-9.67998,-6.12441
97.00001,-9.70024,-6.13900
97.20001,-9.71998,-6.14202
97.40000,-9.73998,-6.15367
97.60001,-9.76024,-6.14455
97.80000,-9.78011,-6.13751
98.00001,-9.80011,-6.15115
98.20001,-9.82024,-6.16055
98.40000,-9.83971,-6.16177
98.60001,-9.85998,-6.16987
98.80000,-9.88024,-6.19254
99.00001,-9.89998,-6.20210
99.20001,-9.91998,-6.21387
99.40000,-9.94011,-6.22032
99.60001,-9.95998,-6.21862
99.80000,-9.97998,-6.23711
100.00001,-10.00011,-6.24254
100.20001,-10.01998,-6.25479
100.40000,-10.03998,-6.24629
100.60001,-10.06024,-6.25824
100.80000,-10.08011,-6.27280
101.00001,-10.09984,-6.27975
101.20001,-10.11998,-6.29619
101.40000,-10.14024,-6.29853
101.60001,-10.16011,-6.30827
101.80000,-10.18024,-6.32473
102.00001,-10.20011,-6.33715
102.20001,-10.21984,-6.35395
102.40000,-10.24011,-6.35775
102.60001,-10.26024,-6.35951
102.80000,-10.27997,-6.36432
103.00001,-10.30011,-6.38421
103.20001,-10.32024,-6.38668
103.40000,-10.33997,-6.39794
103.60001,-10.36011,-6.40022
103.80000,-10.38011,-6.41189
104.00001,-10.39971,-6.43063
104.20001,-10.42011,-6.44061
104.40000,-10.44024,-6.44789
104.60001,-10.46011,-6.44947
104.80000,-10.47997,-6.47608
105.00001,-10.49984,-6.48168
105.20001,-10.51997,-6.49816
105.40000,-10.54011,-6.49259
105.60001,-10.56011,-6.50385
105.80000,-10.57984,-6.50397
106.00001,-10.60011,-6.53206
106.20001,-10.62024,-6.53475
106.40000,-10.64011,-6.54687
106.60001,-10.65997,-6.54012
106.80000,-10.68011,-6.54408
107.00001,-10.70011,-6.56041
107.20001,-10.72011,-6.57315
107.40000,-10.74037,-6.57658
107.60001,-10.75997,-6.57298
107.80000,-10.77971,-6.58171
108.00001,-10.80024,-6.60065
108.20001,-10.82011,-6.61327
108.40000,-10.84011,-6.60485
108.60001,-10.86011,-6.61052
108.80000,-10.87997,-6.61809
109.00001,-10.89997,-6.62030
109.20001,-10.92011,-6.63394
109.40000,-10.94024,-6.64389
109.60001,-10.95984,-6.65397
109.80000,-10.98011,-6.65681
110.00001,-11.00011,-6.66306
110.20001,-11.01997,-6.66446
110.40000,-11.03997,-6.68029
110.60001,-11.05971,-6.68299
110.80000,-11.07997,-6.68972
111.00001,-11.10011,-6.71187
111.20001,-11.12024,-6.71883
111.40000,-11.13997,-6.72739
111.60001,-11.15997,-6.72489
111.80000,-11.18024,-6.73524
112.00001,-11.20011,-6.75285
112.20001,-11.22011,-6.75282
112.40000,-11.24011,-6.76715
112.60001,-11.26011,-6.76920
112.80000,-11.28011,-6.78867
113.00001,-11.30011,-6.79005
113.20001,-11.31997,-6.81407
113.40001,-11.33997,-6.81192
113.60001,-11.36024,-6.81658
113.80000,-11.38011,-6.83107
114.00001,-11.40011,-6.85295
114.20001,-11.42024,-6.86007
114.40001,-11.43971,-6.86840
114.60001,-11.45997,-6.87005
114.80000,-11.48024,-6.87520
115.00001,-11.50011,-6.89041
115.20001,-11.51997,-6.85876
115.40001,-11.53997,-6.87874
115.60001,-11.55997,-6.89186
115.80000,-11.57997,-6.88100
116.00001,-11.60024,-6.90834
116.20001,-11.61984,-6.92787
116.40001,-11.63997,-6.93303
116.60001,-11.66024,-6.92879
116.80000,-11.68010,-6.93697
117.00001,-11.69997,-6.95311
117.20001,-11.71997,-6.88058
117.40001,-11.74024,-6.88489
117.60001,-11.76010,-6.89542
117.80000,-11.78037,-6.89958
118.00001,-11.80010,-6.91778
118.20001,-11.81984,-6.92736
118.40001,-11.84010,-6.93421
118.60001,-11.86024,-6.93894
118.80000,-11.87997,-6.95485
119.00001,-11.90010,-6.95915
119.20001,-11.92024,-6.97046
119.40001,-11.93997,-6.97839
119.60001,-11.96024,-6.98604
119.80000,-11.98010,-7.00333
120.00001,-11.99970,-7.01781
120.20001,-12.02010,-7.02265
120.40001,-12.04024,-7.03026
120.60001,-12.06010,-7.03767
120.80000,-12.08010,-7.04552
121.00001,-12.09984,-7.05261
121.20001,-12.11997,-7.06672
121.40001,-12.14010,-7.07629
121.60001,-12.16024,-7.08490
121.80000,-12.17984,-7.11320
122.00001,-12.19997,-7.12042
122.20001,-12.22024,-7.13449
122.40001,-12.23997,-7.14555
122.60001,-12.25997,-7.14721
122.80000,-12.28010,-7.17251
123.00001,-12.30024,-7.19065
123.20001,-12.31997,-7.18165
123.40001,-12.34037,-7.20058
123.60001,-12.35997,-7.20141
123.80000,-12.37970,-7.22547
124.00001,-12.40024,-7.24336
124.20001,-12.42010,-7.25775
124.40001,-12.44010,-7.27413
124.60001,-12.46024,-7.28228
124.80000,-12.47984,-7.29578
125.00001,-12.49997,-7.31540
125.20001,-12.52024,-7.33718
125.40001,-12.54010,-7.34751
125.60001,-12.55970,-7.36236
125.80000,-12.58024,-7.37672
126.00001,-12.60010,-7.39528
126.20001,-12.62010,-7.41258
126.40001,-12.63997,-7.41815
126.60001,-12.65970,-7.41043
126.80000,-12.67997,-7.43493
127.00001,-12.70024,-7.46247
127.20001,-12.72024,-7.46948
127.40001,-12.73997,-7.49092
127.60001,-12.75997,-7.49950
127.80000,-12.77997,-7.52292
128.00000,-12.80010,-7.53037
128.20002,-12.82024,-7.54532
128.40001,-12.84010,-7.55160
128.60001,-12.85997,-7.57297
128.80000,-12.88010,-7.58260
129.00000,-12.90010,-7.59632
129.20002,-12.91997,-7.61729
129.40001,-12.93997,-7.62927
129.60001,-12.96023,-7.63837
129.80000,-12.98010,-7.65897
130.00000,-13.00023,-7.67448
130.20002,-13.02024,-7.67829
130.40001,-13.03983,-7.70221
130.60001,-13.05997,-7.69525
130.80000,-13.08010,-7.71805
131.00000,-13.10023,-7.73552
131.20002,-13.12010,-7.75018
131.40002,-13.13997,-7.75858
131.60000,-13.15997,-7.77172
131.80000,-13.18010,-7.80152
132.00000,-13.20010,-7.81536
132.20002,-13.21983,-7.83078
132.40002,-13.24010,-7.84078
132.60000,-13.26010,-7.84927
132.80000,-13.28023,-7.86204
133.00000,-13.29983,-7.88534
133.20002,-13.31997,-7.88908
133.40002,-13.34023,-7.90554
133.60000,-13.36010,-7.91004
133.80000,-13.38037,-7.92774
134.00000,-13.40010,-7.94594
134.20002,-13.41970,-7.96168
134.40002,-13.44010,-7.96490
134.60000,-13.46023,-7.82525
134.80000,-13.47997,-7.85817
135.00000,-13.49997,-7.87860
135.20002,-13.52023,-7.86010
135.40002,-13.54010,-7.88198
135.60000,-13.56010,-7.90831
135.80000,-13.58010,-7.92378
136.00000,-13.59983,-7.94742
136.20002,-13.62023,-7.95966
136.40002,-13.64023,-7.97392
136.60000,-13.66010,-7.98009
136.80000,-13.67997,-7.89926
137.00000,-13.69983,-7.93237
137.20002,-13.71997,-7.95150
137.40002,-13.74023,-7.96778
137.60000,-13.76023,-7.98206
137.80000,-13.77997,-7.98968
138.00000,-13.79997,-8.01547
138.20002,-13.82023,-8.03535
138.40002,-13.84010,-8.04837
138.60000,-13.86010,-8.05971
138.80000,-13.87997,-8.06638
139.00000,-13.90010,-8.06393
139.20002,-13.91997,-8.06200
139.40002,-13.94023,-7.96413
139.60000,-13.95997,-7.99499
139.80000,-13.97970,-8.00858
140.00000,-14.00023,-8.04677
140.20002,-14.02010,-8.05873
140.40002,-14.04010,-8.06588
140.60000,-14.06023,-8.07676
140.80000,-14.07997,-8.08506
141.00000,-14.09997,-8.10339
141.20002,-14.12023,-8.11132
141.40002,-14.14023,-8.12419
141.60000,-14.15997,-8.13981
141.80000,-14.18010,-8.16701
142.00000,-14.20010,-8.16036
142.20002,-14.21996,-8.18931
142.40002,-14.23983,-8.22170
142.60000,-14.25983,-8.24286
142.80000,-14.27997,-8.26276
143.00000,-14.30023,-8.29125
143.20002,-14.32023,-8.30781
143.40002,-14.33983,-8.34478
143.60000,-14.35983,-8.35594
143.80000,-14.38010,-8.37957
144.00000,-14.40010,-8.41209
144.20002,-14.42023,-8.42870
144.40002,-14.44023,-8.44506
144.60000,-14.45996,-8.44429
144.80000,-14.48010,-8.47867
145.00000,-14.50023,-8.51163
145.20002,-14.51996,-8.51190
145.40002,-14.53983,-8.53946
145.60000,-14.56023,-8.56129
145.80000,-14.58023,-8.60702
146.00000,-14.60023,-8.63332
146.20002,-14.62010,-8.65465
146.40002,-14.63970,-8.67121
146.60000,-14.65996,-8.68070
146.80000,-14.68023,-8.70945
147.00000,-14.70010,-8.73508
147.20002,-14.71983,-8.76434
147.40002,-14.73996,-8.78966
147.60000,-14.75996,-8.80898
147.80000,-14.77996,-8.84939
148.00000,-14.80010,-8.86922
148.20002,-14.81983,-8.90451
148.40002,-14.83996,-8.92048
148.60000,-14.86023,-8.94335
148.80000,-14.88010,-8.98117
149.00000,-14.89983,-8.99667
149.20002,-14.91996,-9.00814
149.40002,-14.94023,-9.03027
149.60000,-14.95996,-9.05469
149.80000,-14.98023,-9.08235
150.00000,-15.00010,-9.10744
150.20002,-15.01983,-9.12846
150.40002,-15.03996,-9.15150
150.60000,-15.06023,-9.16822
150.80000,-15.08010,-9.19582
151.00000,-15.10010,-9.22326
151.20002,-15.12023,-9.25720
151.40002,-15.13983,-9.26428
151.60000,-15.16010,-9.30072
151.80000,-15.18023,-9.34119
152.00000,-15.19970,-9.37316
152.20002,-15.22010,-9.39764
152.40002,-15.24023,-9.41988
152.60000,-15.26010,-9.44251
152.80000,-15.27996,-9.47570
153.00000,-15.29983,-9.50862
153.20002,-15.31996,-9.53919
153.40002,-15.34010,-9.57035
153.60000,-15.36036,-9.59152
153.80000,-15.37983,-9.63722
154.00000,-15.40010,-9.66410
154.20002,-15.42023,-9.69348
154.40002,-15.43996,-9.72005
154.60000,-15.45996,-9.72381
154.80000,-15.48010,-9.75498
155.00000,-15.50023,-9.79811
155.20002,-15.52010,-9.81445
155.40002,-15.54023,-9.86045
155.60000,-15.55996,-9.88352
155.80000,-15.57983,-9.92635
156.00000,-15.60023,-9.95107
156.20002,-15.62009,-9.95017
156.40002,-15.64009,-9.97376
156.60000,-15.66023,-10.00053
156.80000,-15.67996,-9.94364
157.00000,-15.69996,-9.99211
157.20002,-15.72023,-10.04033
157.40002,-15.74009,-10.07598
157.60000,-15.75996,-10.10259
157.80000,-15.78023,-10.13920
158.00000,-15.80009,-10.17047
158.20002,-15.81996,-10.21424
158.40002,-15.83996,-10.23961
158.60000,-15.85970,-10.26535
158.80000,-15.87996,-10.30299
159.00000,-15.90023,-10.33687
159.20002,-15.92023,-10.35605
159.40002,-15.93983,-10.39199
159.60000,-15.95983,-10.41672
159.80000,-15.98009,-10.45122
160.00000,-16.00009,-10.48945
160.01202,-16.00116,-10.49033