File: project1/data/Packing_Peanuts_Instron/Pink_1.is_comp_RawData/Specimen_RawData_3.csv
Time,Extension,Load
(sec),(mm),(N)
0.00000,-0.67880,-0.01824
0.10000,-0.68080,-0.02443
0.20000,-0.69133,-0.03008
0.30000,-0.70440,-0.02105
0.40000,-0.71666,-0.03311
0.50000,-0.72760,-0.03874
0.60000,-0.73800,-0.02402
0.70000,-0.74840,-0.04310
0.80000,-0.75826,-0.04009
0.90000,-0.76853,-0.04706
1.00000,-0.77853,-0.04309
1.10000,-0.78853,-0.03532
1.20000,-0.79853,-0.04361
1.30000,-0.80853,-0.04658
1.40000,-0.81893,-0.04230
1.50000,-0.82853,-0.04212
1.60000,-0.83880,-0.03828
1.70000,-0.84893,-0.05472
1.80000,-0.85853,-0.04974
1.90000,-0.86893,-0.04871
2.00000,-0.87880,-0.05811
2.10000,-0.88866,-0.05893
2.20000,-0.89880,-0.06126
2.30000,-0.90840,-0.05553
2.40000,-0.91853,-0.06666
2.50000,-0.92880,-0.06482
2.60000,-0.93866,-0.05716
2.70000,-0.94880,-0.07164
2.80000,-0.95880,-0.08352
2.90000,-0.96866,-0.06841
3.00000,-0.97866,-0.07822
3.10000,-0.98880,-0.07476
3.20000,-0.99880,-0.08263
3.30000,-1.00866,-0.08379
3.40000,-1.01906,-0.08380
3.50000,-1.02866,-0.09483
3.60000,-1.03853,-0.09487
3.70000,-1.04880,-0.09580
3.80000,-1.05853,-0.09318
3.90000,-1.06866,-0.13030
4.00000,-1.07893,-0.10231
4.10000,-1.08866,-0.07947
4.20000,-1.09880,-0.11602
4.30000,-1.10880,-0.12553
4.40000,-1.11866,-0.11746
4.50000,-1.12866,-0.13419
4.60000,-1.13880,-0.13534
4.70000,-1.14880,-0.14768
4.80000,-1.15866,-0.14365
4.90000,-1.16893,-0.16104
5.00000,-1.17853,-0.15630
5.10000,-1.18840,-0.16589
5.20000,-1.19893,-0.18379
5.30000,-1.20853,-0.18715
5.40000,-1.21880,-0.19985
5.50000,-1.22893,-0.20815
5.60000,-1.23853,-0.20384
5.70000,-1.24880,-0.22030
5.80000,-1.25880,-0.23352
5.90000,-1.26866,-0.23612
6.00000,-1.27866,-0.25027
6.10000,-1.28866,-0.26136
6.20000,-1.29866,-0.26332
6.30000,-1.30853,-0.28453
6.40000,-1.31853,-0.29363
6.50000,-1.32866,-0.30175
6.60000,-1.33853,-0.31187
6.70000,-1.34866,-0.32526
6.80000,-1.35853,-0.34056
6.90000,-1.36853,-0.36077
7.00000,-1.37893,-0.37377
7.10000,-1.38853,-0.37379
7.20000,-1.39880,-0.39476
7.30000,-1.40893,-0.41143
7.40000,-1.41840,-0.42224
7.50000,-1.42880,-0.43472
7.60000,-1.43866,-0.44597
7.70000,-1.44853,-0.46583
7.80000,-1.45866,-0.47624
7.90000,-1.46853,-0.49175
8.00000,-1.47866,-0.50301
8.10000,-1.48880,-0.52025
8.20000,-1.49893,-0.54159
8.30000,-1.50880,-0.55573
8.40000,-1.51866,-0.57109
8.50000,-1.52880,-0.58418
8.60000,-1.53866,-0.59675
8.70000,-1.54880,-0.61680
8.80000,-1.55866,-0.62837
8.90000,-1.56840,-0.63562
9.00000,-1.57880,-0.65061
9.10000,-1.58866,-0.66355
9.20000,-1.59866,-0.67934
9.30000,-1.60893,-0.63781
9.40000,-1.61866,-0.63285
9.50000,-1.62866,-0.62143
9.60000,-1.63893,-0.63227
9.70000,-1.64866,-0.64759
9.80000,-1.65880,-0.64605
9.90000,-1.66893,-0.62701
10.00000,-1.67880,-0.64277
10.10000,-1.68866,-0.66472
10.20000,-1.69880,-0.64993
10.30000,-1.70866,-0.68646
10.40000,-1.71853,-0.71561
10.50000,-1.72880,-0.75060
10.60000,-1.73866,-0.76508
10.70000,-1.74853,-0.79532
10.80000,-1.75906,-0.81983
10.90000,-1.76866,-0.85009
11.00000,-1.77866,-0.87887
11.10000,-1.78893,-0.90114
11.20000,-1.79853,-0.93527
11.30000,-1.80880,-0.96014
11.40000,-1.81893,-0.99366
11.50000,-1.82853,-1.01829
11.60000,-1.83866,-1.04548
11.70000,-1.84853,-1.07522
11.80000,-1.85853,-1.11134
11.90000,-1.86853,-1.14192
12.00000,-1.87880,-1.16922
12.10000,-1.88880,-1.19296
12.20000,-1.89853,-1.22231
12.30000,-1.90906,-1.25859
12.40000,-1.91880,-1.28866
12.50000,-1.92866,-1.31267
12.60000,-1.93906,-1.33614
12.70000,-1.94853,-1.37074
12.80000,-1.95866,-1.39947
12.90000,-1.96880,-1.43278
13.00000,-1.97840,-1.45541
13.10000,-1.98866,-1.48222
13.20000,-1.99880,-1.51502
13.30000,-2.00866,-1.54309
13.40000,-2.01866,-1.56485
13.50000,-2.02880,-1.60058
13.60000,-2.03893,-1.62659
13.70000,-2.04893,-1.66108
13.80000,-2.05879,-1.69342
13.90000,-2.06880,-1.72212
14.00000,-2.07853,-1.73206
14.10000,-2.08879,-1.74094
14.20000,-2.09853,-1.76723
14.30000,-2.10866,-1.79645
14.40000,-2.11879,-1.83542
14.50000,-2.12839,-1.86321
14.60000,-2.13893,-1.90021
14.70000,-2.14879,-1.94128
14.80000,-2.15866,-1.96618
14.90000,-2.16893,-2.01133
15.00000,-2.17879,-2.03884
15.10000,-2.18879,-2.07039
15.20000,-2.19866,-2.10670
15.30000,-2.20879,-2.14331
15.40000,-2.21853,-2.17853
15.50000,-2.22853,-2.22130
15.60000,-2.23893,-2.25020
15.70000,-2.24853,-2.29788
15.80000,-2.25879,-2.33593
15.90000,-2.26879,-2.37899
16.00000,-2.27853,-2.41165
16.10000,-2.28879,-2.45243
16.20000,-2.29879,-2.49671
16.30000,-2.30839,-2.53930
16.40000,-2.31879,-2.57859
16.50000,-2.32879,-2.62975
16.60000,-2.33866,-2.66150
16.70000,-2.34879,-2.71837
16.80000,-2.35866,-2.75048
16.90000,-2.36866,-2.79804
17.00000,-2.37866,-2.84509
17.10000,-2.38853,-2.88704
17.20000,-2.39839,-2.93903
17.30000,-2.40853,-2.98781
17.40000,-2.41893,-3.03772
17.50000,-2.42853,-3.08189
17.60000,-2.43879,-3.12590
17.70000,-2.44879,-3.18947
17.80000,-2.45839,-3.23348
17.90000,-2.46893,-3.28521
18.00000,-2.47866,-3.33923
18.10000,-2.48853,-3.38509
18.20000,-2.49879,-3.45112
18.30000,-2.50839,-3.50104
18.40000,-2.51853,-3.55769
18.50000,-2.52879,-3.61354
18.60000,-2.53866,-3.66604
18.70000,-2.54879,-3.73285
18.80000,-2.55879,-3.79372
18.90000,-2.56879,-3.84821
19.00000,-2.57879,-3.90391
19.10000,-2.58893,-3.95428
19.20000,-2.59879,-4.02595
19.30000,-2.60866,-4.08287
19.40000,-2.61893,-4.14242
19.50000,-2.62879,-4.20236
19.60000,-2.63853,-4.25970
19.70000,-2.64893,-4.34157
19.80000,-2.65853,-4.38721
19.90000,-2.66866,-4.46051
20.00000,-2.67893,-4.52822
20.10000,-2.68853,-4.58024
20.20000,-2.69879,-4.65067
20.30000,-2.70893,-4.73145
20.40000,-2.71879,-4.78575
20.50000,-2.72879,-4.86132
20.60000,-2.73879,-4.91912
20.70000,-2.74879,-4.99679
20.80000,-2.75866,-5.05235
20.90000,-2.76893,-5.12277
21.00000,-2.77853,-5.18206
21.10000,-2.78839,-5.24451
21.20000,-2.79893,-5.31774
21.30000,-2.80853,-5.37504
21.40000,-2.81879,-5.44493
21.50000,-2.82893,-5.51062
21.60000,-2.83853,-5.55703
21.70000,-2.84879,-5.63684
21.80000,-2.85893,-5.70337
21.90000,-2.86866,-5.76991
22.00000,-2.87879,-5.82265
22.10000,-2.88866,-5.88059
22.20000,-2.89866,-5.94686
22.30000,-2.90853,-6.01161
22.40000,-2.91853,-6.07024
22.50000,-2.92866,-6.13110
22.60000,-2.93853,-6.18690
22.70000,-2.94879,-6.26178
22.80000,-2.95866,-6.31691
22.90000,-2.96853,-6.38334
23.00000,-2.97893,-6.44077
23.10000,-2.98853,-6.49207
23.20000,-2.99879,-6.55641
23.30000,-3.00893,-6.62543
23.40000,-3.01839,-6.67798
23.50000,-3.02879,-6.73805
23.60000,-3.03879,-6.79221
23.70000,-3.04853,-6.85868
23.80000,-3.05866,-6.91130
23.90000,-3.06853,-6.97403
24.00000,-3.07866,-7.03611
24.10000,-3.08879,-7.08963
24.20000,-3.09879,-7.15170
24.30000,-3.10866,-7.20931
24.40000,-3.11866,-7.26159
24.50000,-3.12879,-7.32284
24.60000,-3.13866,-7.38567
24.70000,-3.14879,-7.44225
24.80000,-3.15879,-7.49906
24.90000,-3.16853,-7.55486
25.00000,-3.17893,-7.61406
25.10000,-3.18866,-7.66966
25.20000,-3.19853,-7.73045
25.30000,-3.20893,-7.79173
25.40000,-3.21866,-7.84228
25.50000,-3.22866,-7.89187
25.60000,-3.23893,-7.95911
25.70000,-3.24879,-8.01688
25.80000,-3.25879,-8.07733
25.90000,-3.26879,-8.13653
26.00000,-3.27866,-8.18589
26.10000,-3.28853,-8.24868
26.20000,-3.29866,-8.31145
26.30000,-3.30866,-8.37405
26.40000,-3.31853,-8.43732
26.50000,-3.32893,-8.48716
26.60000,-3.33866,-8.54816
26.70000,-3.34853,-8.61164
26.80000,-3.35906,-8.67454
26.90000,-3.36879,-8.73419
27.00000,-3.37866,-8.79307
27.10000,-3.38892,-8.85115
27.20000,-3.39853,-8.90798
27.30000,-3.40879,-8.97407
27.40000,-3.41879,-9.02980
27.50000,-3.42853,-9.10320
27.60000,-3.43852,-9.15913
27.70000,-3.44839,-9.23707
27.80000,-3.45852,-9.29676
27.90000,-3.46852,-9.37735
28.00000,-3.47879,-9.42947
28.10000,-3.48879,-9.50820
28.20000,-3.49866,-9.56690
28.30000,-3.50906,-9.64580
28.40000,-3.51879,-9.70856
28.50000,-3.52866,-9.77814
28.60000,-3.53906,-9.85094
28.70000,-3.54852,-9.92722
28.80000,-3.55866,-9.99789
28.90000,-3.56879,-10.07908
29.00000,-3.57852,-10.14434
29.10000,-3.58866,-10.21568
29.20000,-3.59879,-10.30214
29.30000,-3.60866,-10.38241
29.40000,-3.61866,-10.44512
29.50000,-3.62879,-10.51986
29.60000,-3.63879,-10.59762
29.70000,-3.64879,-10.68067
29.80000,-3.65892,-10.75526
29.90000,-3.66879,-10.84026
30.00000,-3.67852,-10.91270
30.10000,-3.68892,-10.99701
30.20000,-3.69852,-11.07850
30.30000,-3.70852,-11.15371
30.40000,-3.71879,-11.23627
30.50000,-3.72839,-11.31423
30.60000,-3.73879,-11.39158
30.70000,-3.74892,-11.48721
30.80000,-3.75866,-11.55866
30.90000,-3.76879,-11.65322
31.00000,-3.77866,-11.73241
31.10000,-3.78879,-11.81423
31.20000,-3.79892,-11.90185
31.30000,-3.80892,-11.97745
31.40000,-3.81866,-12.06080
31.50000,-3.82852,-12.14012
31.60000,-3.83892,-12.22540
31.70000,-3.84852,-12.31285
31.80000,-3.85866,-12.39532
31.90000,-3.86879,-12.49025
32.00000,-3.87852,-12.56645
32.10000,-3.88892,-12.64884
32.20000,-3.89892,-12.73711
32.30000,-3.90852,-12.82254
32.40000,-3.91892,-12.91384
32.50000,-3.92879,-12.99722
32.60000,-3.93866,-13.07662
32.70000,-3.94866,-13.17049
32.80000,-3.95866,-13.25506
32.90000,-3.96866,-13.34935
33.00000,-3.97852,-13.44049
33.10000,-3.98852,-13.51445
33.20000,-3.99852,-13.61461
33.30000,-4.00852,-13.70934
33.40000,-4.01892,-13.79507
33.50000,-4.02852,-13.87176
33.60000,-4.03892,-13.95839
33.70000,-4.04879,-14.05484
33.80000,-4.05852,-14.13069
33.90000,-4.06892,-14.22672
34.00000,-4.07866,-14.31627
34.10000,-4.08852,-14.38561
34.20000,-4.09879,-14.48573
34.30000,-4.10852,-14.56986
34.40000,-4.11852,-14.65966
34.50000,-4.12879,-14.73904
34.60000,-4.13866,-14.81975
34.70000,-4.14852,-14.91272
34.80000,-4.15866,-14.99742
34.90000,-4.16892,-15.08980
35.00000,-4.17879,-15.16829
35.10000,-4.18892,-15.24451
35.20000,-4.19879,-15.33664
35.30000,-4.20852,-15.41840
35.40000,-4.21879,-15.50436
35.50000,-4.22879,-15.58924
35.60000,-4.23852,-15.66162
35.70000,-4.24892,-15.76160
35.80000,-4.25852,-15.83413
35.90000,-4.26866,-15.92305
36.00000,-4.27892,-16.00776
36.10000,-4.28852,-16.07761
36.20000,-4.29879,-16.16949
36.30000,-4.30892,-16.26164
36.40000,-4.31879,-16.33195
36.50000,-4.32879,-16.41773
36.60000,-4.33879,-16.49443
36.70000,-4.34892,-16.58915
36.80000,-4.35866,-16.65653
36.90000,-4.36892,-16.73884
37.00000,-4.37866,-16.81203
37.10000,-4.38826,-16.88118
37.20000,-4.39892,-16.97546
37.30000,-4.40866,-17.04864
37.40000,-4.41879,-17.12075
37.50000,-4.42892,-17.20434
37.60000,-4.43852,-17.27264
37.70000,-4.44879,-17.35794
37.80000,-4.45892,-17.42760
37.90000,-4.46852,-17.49527
38.00000,-4.47879,-17.57463
38.10000,-4.48866,-17.64037
38.20000,-4.49866,-17.71955
38.30000,-4.50866,-17.79456
38.40000,-4.51852,-17.86156
38.50000,-4.52866,-17.93673
38.60000,-4.53852,-17.99124
38.70000,-4.54879,-18.08042
38.80000,-4.55866,-18.14985
38.90000,-4.56866,-18.22121
39.00000,-4.57892,-18.29840
39.10000,-4.58852,-18.36031
39.20000,-4.59866,-18.43192
39.30000,-4.60879,-18.50264
39.40000,-4.61839,-18.56040
39.50000,-4.62879,-18.62664
39.60000,-4.63879,-18.69393
39.70000,-4.64852,-18.76010
39.80000,-4.65866,-18.82109
39.90000,-4.66866,-18.88760
40.00000,-4.67866,-18.94421
40.10000,-4.68879,-19.00743
40.20000,-4.69879,-19.06653
40.30000,-4.70866,-19.13561
40.40000,-4.71879,-19.19209
40.50000,-4.72892,-19.26210
40.60000,-4.73865,-19.31023
40.70000,-4.74879,-19.38046
40.80000,-4.75879,-19.43857
40.90000,-4.76852,-19.49216
41.00000,-4.77879,-19.55302
41.10000,-4.78865,-19.61217
41.20000,-4.79852,-19.66936
41.30000,-4.80892,-19.74028
41.40000,-4.81879,-19.78791
41.50000,-4.82866,-19.83891
41.60000,-4.83892,-19.89935
41.70000,-4.84879,-19.95931
41.80000,-4.85865,-20.01310
41.90000,-4.86879,-20.06564
42.00000,-4.87879,-20.12530
42.10000,-4.88865,-20.17253
42.20000,-4.89865,-20.22848
42.30000,-4.90879,-20.29406
42.40000,-4.91852,-20.34036
42.50000,-4.92892,-20.40608
42.60000,-4.93865,-20.45526
42.70000,-4.94852,-20.51035
42.80000,-4.95892,-20.57008
42.90000,-4.96865,-20.61640
43.00000,-4.97865,-20.67070
43.10000,-4.98892,-20.72727
43.20000,-4.99852,-20.77045
43.30000,-5.00879,-20.82803
43.40000,-5.01879,-20.88091
43.50000,-5.02865,-20.93724
43.60000,-5.03865,-20.98575
43.70000,-5.04839,-21.03572
43.80000,-5.05865,-21.08624
43.90000,-5.06852,-21.15013
44.00000,-5.07865,-21.20208
44.10000,-5.08879,-21.24712
44.20000,-5.09839,-21.29241
44.30000,-5.10892,-21.35341
44.40000,-5.11879,-21.39623
44.50000,-5.12865,-21.44315
44.60000,-5.13892,-21.49096
44.70000,-5.14852,-21.53811
44.80000,-5.15865,-21.59116
44.90000,-5.16879,-21.64724
45.00000,-5.17852,-21.69111
45.10000,-5.18865,-21.74700
45.20000,-5.19879,-21.79029
45.30000,-5.20865,-21.83942
45.40000,-5.21865,-21.88843
45.50000,-5.22879,-21.93156
45.60000,-5.23879,-21.97630
45.70000,-5.24879,-22.03283
45.80000,-5.25892,-22.07430
45.90000,-5.26879,-22.12629
46.00000,-5.27852,-22.16190
46.10000,-5.28892,-22.21093
46.20000,-5.29852,-22.25715
46.30000,-5.30852,-22.31247
46.40000,-5.31865,-22.36444
46.50000,-5.32839,-22.40983
46.60000,-5.33892,-22.45102
46.70000,-5.34892,-22.50856
46.80000,-5.35865,-22.54215
46.90000,-5.36879,-22.59762
47.00000,-5.37879,-22.64369
47.10000,-5.38879,-22.68499
47.20000,-5.39879,-22.72983
47.30000,-5.40892,-22.78043
47.40000,-5.41865,-22.82231
47.50000,-5.42852,-22.86142
47.60000,-5.43892,-22.90836
47.70000,-5.44852,-22.95251
47.80000,-5.45865,-22.99331
47.90000,-5.46892,-23.05106
48.00000,-5.47865,-23.08685
48.10000,-5.48879,-23.12900
48.20000,-5.49879,-23.17341
48.30000,-5.50865,-23.22125
48.40000,-5.51892,-23.26802
48.50000,-5.52879,-23.30804
48.60000,-5.53879,-23.34572
48.70000,-5.54879,-23.39604
48.80000,-5.55852,-23.43183
48.90000,-5.56879,-23.48009
49.00000,-5.57865,-23.52070
49.10000,-5.58865,-23.56226
49.20000,-5.59865,-23.61136
49.30000,-5.60852,-23.65507
49.40000,-5.61865,-23.69716
49.50000,-5.62839,-23.74543
49.60000,-5.63879,-23.76986
49.70000,-5.64879,-23.83899
49.80000,-5.65865,-23.86104
49.90000,-5.66905,-23.91557
50.00000,-5.67865,-23.95281
50.10000,-5.68852,-23.98453
50.20000,-5.69879,-24.04041
50.30000,-5.70839,-24.08420
50.40000,-5.71865,-24.12296
50.50000,-5.72879,-24.16797
50.60000,-5.73865,-24.19553
50.70000,-5.74865,-24.25116
50.80000,-5.75865,-24.28530
50.90000,-5.76865,-24.33303
51.00000,-5.77879,-24.37601
51.10000,-5.78892,-24.41259
51.20000,-5.79879,-24.45687
51.30000,-5.80865,-24.50333
51.40000,-5.81892,-24.54906
51.50000,-5.82879,-24.58786
51.60000,-5.83852,-24.62243
51.70000,-5.84892,-24.68058
51.80000,-5.85852,-24.71335
51.90000,-5.86852,-24.75975
52.00000,-5.87892,-24.80335
52.10000,-5.88852,-24.83855
52.20000,-5.89879,-24.88339
52.30000,-5.90892,-24.93633
52.40000,-5.91865,-24.96796
52.50000,-5.92865,-25.00923
52.60000,-5.93879,-25.05495
52.70000,-5.94892,-25.10668
52.80000,-5.95865,-25.13181
52.90000,-5.96892,-25.17380
53.00000,-5.97852,-25.20812
53.10000,-5.98839,-25.25033
53.20000,-5.99892,-25.30987
53.30000,-6.00852,-25.34978
53.40000,-6.01879,-25.39271
53.50000,-6.02892,-25.44824
53.60000,-6.03852,-25.48192
53.70000,-6.04879,-25.52932
53.80000,-6.05892,-25.57471
53.90000,-6.06865,-25.61222
54.00000,-6.07879,-25.65746
54.10000,-6.08865,-25.70155
54.20000,-6.09852,-25.73575
54.30000,-6.10865,-25.79360
54.40000,-6.11852,-25.82783
54.50000,-6.12852,-25.87683
54.60000,-6.13852,-25.91916
54.70000,-6.14892,-25.97619
54.80000,-6.15878,-26.01279
54.90000,-6.16865,-26.05174
55.00000,-6.17905,-26.11322
55.10000,-6.18865,-26.14352
55.20000,-6.19878,-26.18992
55.30000,-6.20892,-26.24534
55.40000,-6.21852,-26.27699
55.50000,-6.22879,-26.32893
55.60000,-6.23865,-26.38118
55.70000,-6.24852,-26.42413
55.80000,-6.25865,-26.46901
55.90000,-6.26852,-26.51351
56.00000,-6.27865,-26.56339
56.10000,-6.28878,-26.61540
56.20000,-6.29878,-26.65459
56.30000,-6.30865,-26.71039
56.40000,-6.31865,-26.75708
56.50000,-6.32892,-26.80837
56.60000,-6.33865,-26.85110
56.70000,-6.34878,-26.89678
56.80000,-6.35878,-26.94334
56.90000,-6.36852,-26.98313
57.00000,-6.37892,-27.02851
57.10000,-6.38865,-27.08082
57.20000,-6.39852,-27.11862
57.30000,-6.40892,-27.17358
57.40000,-6.41865,-27.21801
57.50000,-6.42878,-27.26806
57.60000,-6.43892,-27.31084
57.70000,-6.44878,-27.36552
57.80000,-6.45878,-27.41144
57.90000,-6.46892,-27.45900
58.00000,-6.47878,-27.50053
58.10000,-6.48878,-27.54911
58.20000,-6.49892,-27.59537
58.30000,-6.50878,-27.64933
58.40000,-6.51852,-27.69102
58.50000,-6.52892,-27.75219
58.60000,-6.53878,-27.80043
58.70000,-6.54852,-27.83949
58.80000,-6.55905,-27.89747
58.90000,-6.56878,-27.94211
59.00000,-6.57878,-27.98952
59.10000,-6.58892,-28.04330
59.20000,-6.59838,-28.09021
59.30000,-6.60878,-28.14583
59.40000,-6.61892,-28.18926
59.50000,-6.62865,-28.23200
59.60000,-6.63865,-28.28692
59.70000,-6.64852,-28.33275
59.80000,-6.65865,-28.37546
59.90000,-6.66852,-28.43105
60.00000,-6.67878,-28.48714
60.10000,-6.68878,-28.54799
60.20000,-6.69852,-28.58176
60.30000,-6.70905,-28.63787
60.40000,-6.71865,-28.68017
60.50000,-6.72865,-28.72556
60.60000,-6.73905,-28.78105
60.70000,-6.74852,-28.82603
60.80000,-6.75865,-28.87997
60.90000,-6.76892,-28.93702
61.00000,-6.77838,-28.97979
61.10000,-6.78865,-29.04017
61.20000,-6.79892,-29.09213
61.30000,-6.80865,-29.14367
61.40000,-6.81878,-29.19636
61.50000,-6.82878,-29.24610
61.60000,-6.83878,-29.29506
61.70000,-6.84878,-29.35466
61.80000,-6.85892,-29.40495
61.90000,-6.86878,-29.45572
62.00000,-6.87865,-29.50148
62.10000,-6.88892,-29.56559
62.20000,-6.89852,-29.60819
62.30000,-6.90865,-29.66360
62.40000,-6.91878,-29.73109
62.50000,-6.92852,-29.77142
62.60000,-6.93892,-29.82914
62.70000,-6.94878,-29.89637
62.80000,-6.95878,-29.93091
62.90000,-6.96892,-29.99224
63.00000,-6.97865,-30.04597
63.10000,-6.98878,-30.09657
63.20000,-6.99892,-30.15234
63.30000,-7.00892,-30.20556
63.40000,-7.01865,-30.25002
63.50000,-7.02852,-30.30333
63.60000,-7.03878,-30.35980
63.70000,-7.04865,-30.41805
63.80000,-7.05865,-30.46512
63.90000,-7.06878,-30.53735
64.00000,-7.07852,-30.57355
64.10001,-7.08878,-30.63746
64.20000,-7.09892,-30.69216
64.30000,-7.10865,-30.74491
64.40000,-7.11892,-30.80958
64.50000,-7.12878,-30.86003
64.60001,-7.13865,-30.90625
64.70000,-7.14878,-30.97024
64.80000,-7.15852,-31.01909
64.90000,-7.16865,-31.07898
65.00000,-7.17865,-31.12466
65.10001,-7.18852,-31.18662
65.20000,-7.19852,-31.24128
65.30000,-7.20865,-31.30679
65.40000,-7.21892,-31.36260
65.50000,-7.22865,-31.41527
65.60001,-7.23892,-31.47484
65.70001,-7.24878,-31.54191
65.80000,-7.25838,-31.58976
65.90000,-7.26892,-31.65191
66.00000,-7.27865,-31.71262
66.10001,-7.28852,-31.75774
66.20001,-7.29892,-31.82434
66.30000,-7.30852,-31.87751
66.40000,-7.31865,-31.93758
66.50000,-7.32878,-31.99712
66.60001,-7.33865,-32.04835
66.70001,-7.34878,-32.11626
66.80000,-7.35878,-32.17254
66.90000,-7.36878,-32.22699
67.00000,-7.37878,-32.29236
67.10001,-7.38892,-32.34950
67.20001,-7.39878,-32.41675
67.30000,-7.40865,-32.46862
67.40000,-7.41892,-32.53276
67.50000,-7.42878,-32.59050
67.60001,-7.43852,-32.64532
67.70001,-7.44878,-32.71174
67.80000,-7.45851,-32.76720
67.90000,-7.46865,-32.83422
68.00000,-7.47905,-32.90131
68.10001,-7.48865,-32.95413
68.20001,-7.49878,-33.01160
68.30000,-7.50891,-33.07807
68.40000,-7.51878,-33.13267
68.50000,-7.52892,-33.19648
68.60001,-7.53878,-33.25828
68.70001,-7.54878,-33.31520
68.80000,-7.55865,-33.37311
68.90000,-7.56891,-33.44000
69.00000,-7.57865,-33.49249
69.10001,-7.58838,-33.55548
69.20001,-7.59891,-33.62549
69.30000,-7.60851,-33.68389
69.40000,-7.61878,-33.74819
69.50000,-7.62891,-33.82453
69.60001,-7.63851,-33.87607
69.70001,-7.64891,-33.94165
69.80000,-7.65891,-34.00714
69.90000,-7.66865,-34.06053
70.00000,-7.67878,-34.12708
70.10001,-7.68865,-34.19297
70.20001,-7.69865,-34.25098
70.30000,-7.70865,-34.31260
70.40000,-7.71865,-34.37799
70.50000,-7.72878,-34.45255
70.60001,-7.73851,-34.50588
70.70001,-7.74878,-34.58012
70.80000,-7.75865,-34.64151
70.90000,-7.76865,-34.70742
71.00000,-7.77891,-34.78215
71.10001,-7.78865,-34.83516
71.20001,-7.79878,-34.90693
71.30000,-7.80891,-34.97832
71.40000,-7.81851,-35.02335
71.50000,-7.82891,-35.09511
71.60001,-7.83878,-35.15710
71.70001,-7.84865,-35.22018
71.80000,-7.85865,-35.28972
71.90000,-7.86851,-35.36154
72.00000,-7.87865,-35.42477
72.10001,-7.88891,-35.49943
72.20001,-7.89891,-35.56371
72.30000,-7.90878,-35.63258
72.40000,-7.91865,-35.69476
72.50000,-7.92891,-35.76766
72.60001,-7.93878,-35.83076
72.70001,-7.94891,-35.89743
72.80000,-7.95878,-35.96873
72.90000,-7.96851,-36.02897
73.00000,-7.97891,-36.09676
73.10001,-7.98865,-36.17074
73.20001,-7.99851,-36.23355
73.30000,-8.00891,-36.31595
73.40000,-8.01865,-36.38463
73.50000,-8.02878,-36.45508
73.60001,-8.03891,-36.52682
73.70001,-8.04878,-36.59290
73.80000,-8.05878,-36.66882
73.90000,-8.06891,-36.73562
74.00000,-8.07878,-36.80112
74.10001,-8.08865,-36.87446
74.20001,-8.09878,-36.93957
74.30000,-8.10865,-37.01449
74.40000,-8.11851,-37.08810
74.50000,-8.12891,-37.15687
74.60001,-8.13865,-37.22014
74.70001,-8.14851,-37.29215
74.80000,-8.15905,-37.36969
74.90000,-8.16878,-37.43829
75.00000,-8.17878,-37.50100
75.10001,-8.18891,-37.58372
75.20001,-8.19851,-37.64769
75.30000,-8.20878,-37.72657
75.40000,-8.21891,-37.80333
75.50000,-8.22878,-37.86536
75.60001,-8.23865,-37.93843
75.70001,-8.24851,-38.00872
75.80000,-8.25865,-38.08209
75.90000,-8.26851,-38.15508
76.00000,-8.27878,-38.22995
76.10001,-8.28878,-38.31515
76.20001,-8.29851,-38.37635
76.30000,-8.30905,-38.46572
76.40000,-8.31878,-38.52983
76.50000,-8.32878,-38.60383
76.60001,-8.33905,-38.68578
76.70001,-8.34851,-38.76302
76.80000,-8.35865,-38.83087
76.90000,-8.36891,-38.91356
77.00000,-8.37851,-38.97714
77.10001,-8.38865,-39.06034
77.20001,-8.39878,-39.13339
77.30000,-8.40865,-39.21311
77.40000,-8.41878,-39.29404
77.50000,-8.42878,-39.36191
77.60001,-8.43878,-39.43995
77.70001,-8.44891,-39.52608
77.80000,-8.45905,-39.60596
77.90000,-8.46878,-39.67803
78.00000,-8.47865,-39.74780
78.10001,-8.48891,-39.83819
78.20001,-8.49865,-39.90758
78.30000,-8.50878,-39.98946
78.40000,-8.51878,-40.07438
78.50000,-8.52838,-40.13419
78.60001,-8.53878,-40.21914
78.70001,-8.54891,-40.30801
78.80000,-8.55865,-40.37740
78.90000,-8.56891,-40.46231
79.00000,-8.57878,-40.54014
79.10001,-8.58878,-40.62837
79.20001,-8.59891,-40.70324
79.30000,-8.60891,-40.78221
79.40000,-8.61865,-40.86497
79.50000,-8.62851,-40.93823
79.60001,-8.63891,-41.02420
79.70001,-8.64851,-41.10265
79.80000,-8.65865,-41.17598
79.90000,-8.66878,-41.27495
80.00000,-8.67851,-41.34938
80.10001,-8.68891,-41.44079
80.20001,-8.69891,-41.52619
80.30000,-8.70851,-41.60276
80.40000,-8.71891,-41.69559
80.50001,-8.72878,-41.78360
80.60001,-8.73878,-41.85579
80.70001,-8.74891,-41.94654
80.80000,-8.75865,-42.02368
80.90000,-8.76865,-42.11138
81.00001,-8.77865,-42.18758
81.10001,-8.78851,-42.27384
81.20001,-8.79851,-42.35773
81.30000,-8.80851,-42.43993
81.40000,-8.81891,-42.54051
81.50001,-8.82865,-42.61189
81.60001,-8.83891,-42.69447
81.70001,-8.84891,-42.80023
81.80000,-8.85851,-42.86763
81.90000,-8.86891,-42.96510
82.00001,-8.87865,-43.04663
82.10001,-8.88851,-43.12690
82.20001,-8.89878,-43.22223
82.30000,-8.90851,-43.30979
82.40000,-8.91864,-43.39946
82.50001,-8.92878,-43.48755
82.60001,-8.93865,-43.56614
82.70001,-8.94864,-43.66587
82.80000,-8.95878,-43.75471
82.90000,-8.96878,-43.84825
83.00001,-8.97891,-43.93209
83.10001,-8.98904,-44.02496
83.20001,-8.99878,-44.11172
83.30000,-9.00865,-44.19880
83.40000,-9.01891,-44.29840
83.50001,-9.02878,-44.38654
83.60001,-9.03851,-44.47128
83.70001,-9.04891,-44.57372
83.80000,-9.05851,-44.66389
83.90000,-9.06864,-44.75456
84.00001,-9.07891,-44.85125
84.10001,-9.08851,-44.93825
84.20001,-9.09878,-45.03610
84.30000,-9.10891,-45.13875
84.40000,-9.11878,-45.22311
84.50001,-9.12891,-45.31475
84.60001,-9.13878,-45.41378
84.70001,-9.14878,-45.50431
84.80000,-9.15864,-45.59429
84.90000,-9.16904,-45.69869
85.00001,-9.17864,-45.78935
85.10001,-9.18838,-45.87783
85.20001,-9.19891,-45.97947
85.30000,-9.20864,-46.07401
85.40000,-9.21878,-46.16446
85.50001,-9.22891,-46.27261
85.60001,-9.23851,-46.36163
85.70001,-9.24878,-46.46145
85.80000,-9.25891,-46.56317
85.90000,-9.26864,-46.64847
86.00001,-9.27878,-46.75026
86.10001,-9.28864,-46.85224
86.20001,-9.29864,-46.93868
86.30000,-9.30878,-47.03569
86.40000,-9.31864,-47.12895
86.50001,-9.32864,-47.24078
86.60001,-9.33851,-47.33064
86.70001,-9.34891,-47.43927
86.80000,-9.35878,-47.54130
86.90000,-9.36864,-47.63832
87.00001,-9.37891,-47.74982
87.10001,-9.38864,-47.84451
87.20001,-9.39864,-47.94373
87.30000,-9.40891,-48.06057
87.40000,-9.41851,-48.15127
87.50001,-9.42878,-48.26116
87.60001,-9.43878,-48.36324
87.70001,-9.44851,-48.46364
87.80000,-9.45864,-48.56448
87.90000,-9.46851,-48.67279
88.00001,-9.47864,-48.78016
88.10001,-9.48891,-48.89253
88.20001,-9.49891,-48.99206
88.30000,-9.50878,-49.10496
88.40000,-9.51864,-49.19932
88.50001,-9.52891,-49.31156
88.60001,-9.53864,-49.41365
88.70001,-9.54878,-49.51981
88.80000,-9.55878,-49.63547
88.90000,-9.56851,-49.74374
89.00001,-9.57878,-49.84935
89.10001,-9.58864,-49.95764
89.20001,-9.59851,-50.05872
89.30000,-9.60891,-50.17787
89.40000,-9.61878,-50.29160
89.50001,-9.62878,-50.39699
89.60001,-9.63904,-50.50757
89.70001,-9.64878,-50.61289
89.80000,-9.65878,-50.72733
89.90000,-9.66891,-50.83865
90.00001,-9.67891,-50.94283
90.10001,-9.68864,-51.05781
90.20001,-9.69878,-51.16017
90.30000,-9.70878,-51.29410
90.40000,-9.71851,-51.39546
90.50001,-9.72878,-51.50751
90.60001,-9.73864,-51.62418
90.70001,-9.74838,-51.73423
90.80000,-9.75891,-51.85360
90.90000,-9.76878,-51.96320
91.00001,-9.77864,-52.06567
91.10001,-9.78878,-52.18640
91.20001,-9.79864,-52.30675
91.30000,-9.80891,-52.42147
91.40000,-9.81891,-52.54070
91.50001,-9.82878,-52.64848
91.60001,-9.83851,-52.76497
91.70001,-9.84838,-52.87369
91.80000,-9.85864,-53.00106
91.90000,-9.86864,-53.12747
92.00001,-9.87878,-53.23853
92.10001,-9.88878,-53.37714
92.20001,-9.89851,-53.48295
92.30000,-9.90891,-53.60963
92.40000,-9.91891,-53.74074
92.50001,-9.92878,-53.84377
92.60001,-9.93904,-53.97575
92.70001,-9.94851,-54.09495
92.80000,-9.95864,-54.20830
92.90000,-9.96891,-54.33388
93.00001,-9.97851,-54.45368
93.10001,-9.98864,-54.58543
93.20001,-9.99878,-54.71037
93.30000,-10.00864,-54.83590
93.40000,-10.01878,-54.95982
93.42001,-10.02078,-54.98993