File: project1/data/Packing_Peanuts_Instron/Test1.is_comp_RawData/Specimen_RawData_3.csv
Time,Extension,Load
(sec),(mm),(N)
0.00000,0.00000,-0.00522
0.20000,-0.01227,-0.00610
0.40000,-0.03720,-0.00797
0.60000,-0.05920,-0.00910
0.80000,-0.07987,-0.01175
1.00000,-0.09987,-0.01189
1.20000,-0.11987,-0.01362
1.40000,-0.13973,-0.01432
1.60000,-0.16000,-0.01506
1.80000,-0.17987,-0.01640
2.00000,-0.20013,-0.01624
2.20000,-0.22000,-0.01643
2.40000,-0.23960,-0.01875
2.60000,-0.26000,-0.01886
2.80000,-0.28000,-0.01986
3.00000,-0.29973,-0.02114
3.20000,-0.31973,-0.02095
3.40000,-0.33973,-0.02356
3.60000,-0.36013,-0.02452
3.80000,-0.38000,-0.02602
4.00000,-0.40000,-0.02862
4.20000,-0.41973,-0.03287
4.40000,-0.43973,-0.03368
4.60000,-0.46000,-0.03523
4.80000,-0.48013,-0.03596
5.00000,-0.50000,-0.03731
5.20000,-0.52000,-0.03706
5.40000,-0.53973,-0.03885
5.60000,-0.55973,-0.04030
5.80000,-0.58027,-0.03888
6.00000,-0.60000,-0.03994
6.20000,-0.61973,-0.04128
6.40000,-0.64000,-0.04161
6.60000,-0.65987,-0.04187
6.80000,-0.67973,-0.04253
7.00000,-0.69973,-0.04310
7.20000,-0.71973,-0.04528
7.40000,-0.73986,-0.04791
7.60000,-0.76026,-0.04860
7.80000,-0.77986,-0.05251
8.00000,-0.79960,-0.05458
8.20000,-0.81986,-0.05607
8.40000,-0.83986,-0.05914
8.60000,-0.86000,-0.06222
8.80000,-0.88013,-0.06435
9.00000,-0.89986,-0.06745
9.20000,-0.91986,-0.07071
9.40000,-0.94000,-0.07181
9.60000,-0.95986,-0.07526
9.80000,-0.97973,-0.07651
10.00000,-0.99986,-0.08143
10.20000,-1.02013,-0.08529
10.40000,-1.04000,-0.08763
10.60000,-1.05986,-0.09063
10.80000,-1.07986,-0.09115
11.00000,-1.09960,-0.09475
11.20000,-1.11986,-0.09869
11.40000,-1.14026,-0.10357
11.60000,-1.15986,-0.10730
11.80000,-1.17973,-0.11202
12.00000,-1.20000,-0.11855
12.20000,-1.21973,-0.12429
12.40000,-1.23973,-0.12751
12.60000,-1.26000,-0.12977
12.80000,-1.27960,-0.13396
13.00000,-1.29986,-0.13741
13.20000,-1.32013,-0.14122
13.40000,-1.33973,-0.14268
13.60000,-1.35973,-0.14443
13.80000,-1.37986,-0.14753
14.00000,-1.39986,-0.15019
14.20000,-1.42000,-0.15288
14.40000,-1.44000,-0.15716
14.60000,-1.45960,-0.16033
14.80000,-1.47986,-0.16730
15.00000,-1.50000,-0.17348
15.20000,-1.52000,-0.17916
15.40000,-1.53986,-0.18679
15.60000,-1.55986,-0.19316
15.80000,-1.57986,-0.19785
16.00000,-1.59986,-0.20334
16.20000,-1.62013,-0.21106
16.40000,-1.63973,-0.21842
16.60000,-1.65973,-0.22483
16.80000,-1.68000,-0.23295
17.00000,-1.70000,-0.24325
17.20000,-1.71986,-0.25293
17.40000,-1.73973,-0.26363
17.60000,-1.75986,-0.27187
17.80000,-1.77973,-0.28221
18.00000,-1.80013,-0.29117
18.20000,-1.82000,-0.30220
18.40000,-1.83960,-0.31083
18.60000,-1.85973,-0.32495
18.80000,-1.87986,-0.33837
19.00000,-1.89973,-0.35405
19.20000,-1.91986,-0.36766
19.40000,-1.94000,-0.38397
19.60000,-1.96000,-0.39975
19.80000,-1.98000,-0.41174
20.00000,-2.00013,-0.42992
20.20000,-2.01960,-0.43719
20.40000,-2.03973,-0.44939
20.60000,-2.06013,-0.46234
20.80000,-2.07999,-0.47633
21.00000,-2.09999,-0.48973
21.20000,-2.11986,-0.50936
21.40000,-2.13986,-0.52453
21.60000,-2.15986,-0.54309
21.80000,-2.18013,-0.56456
22.00000,-2.19999,-0.58157
22.20000,-2.21973,-0.60397
22.40000,-2.23999,-0.62440
22.60000,-2.25986,-0.64584
22.80000,-2.27973,-0.67410
23.00000,-2.29986,-0.69581
23.20000,-2.31973,-0.72572
23.40000,-2.33999,-0.74563
23.60000,-2.36013,-0.76832
23.80000,-2.37986,-0.79160
24.00000,-2.39959,-0.81363
24.20000,-2.41999,-0.82326
24.40000,-2.43986,-0.85158
24.60000,-2.45999,-0.87910
24.80000,-2.48013,-0.92413
25.00000,-2.49986,-0.95415
25.20000,-2.51986,-0.97596
25.40000,-2.53986,-1.01867
25.60000,-2.55999,-1.05294
25.80000,-2.57973,-1.08403
26.00000,-2.59999,-1.12334
26.20000,-2.62013,-1.16490
26.40000,-2.63999,-1.20243
26.60000,-2.65999,-1.25009
26.80000,-2.67986,-1.28549
27.00000,-2.69959,-1.32298
27.20000,-2.71999,-1.35798
27.40000,-2.74013,-1.39917
27.60000,-2.75986,-1.43483
27.80000,-2.77973,-1.48569
28.00000,-2.79986,-1.53809
28.20000,-2.81973,-1.58792
28.40000,-2.83986,-1.63691
28.60000,-2.85999,-1.66558
28.80000,-2.87973,-1.69291
29.00000,-2.89986,-1.73092
29.20000,-2.92026,-1.76727
29.40000,-2.93973,-1.81761
29.60000,-2.95959,-1.85972
29.80000,-2.97999,-1.91048
30.00000,-2.99999,-1.96407
30.20000,-3.01999,-2.01433
30.40000,-3.04013,-2.06948
30.60000,-3.05973,-2.11452
30.80000,-3.07973,-2.17887
31.00000,-3.09986,-2.24080
31.20000,-3.11999,-2.28611
31.40000,-3.13986,-2.34081
31.60000,-3.15986,-2.39845
31.80000,-3.17999,-2.46307
32.00000,-3.19973,-2.50677
32.20000,-3.22013,-2.55891
32.40000,-3.23986,-2.59240
32.60000,-3.25973,-2.63737
32.80000,-3.27999,-2.69015
33.00000,-3.29999,-2.74353
33.20000,-3.31986,-2.78625
33.40000,-3.33973,-2.83459
33.60000,-3.35973,-2.90063
33.80000,-3.37973,-2.97213
34.00000,-3.40026,-3.02807
34.20000,-3.41999,-3.09440
34.40000,-3.43959,-3.16354
34.60000,-3.45986,-3.23943
34.80000,-3.47986,-3.29456
35.00000,-3.49972,-3.36084
35.20000,-3.51999,-3.43075
35.40000,-3.53986,-3.50770
35.60000,-3.55999,-3.57385
35.80000,-3.57999,-3.66065
36.00000,-3.59999,-3.74344
36.20000,-3.61972,-3.83455
36.40000,-3.63972,-3.92996
36.60000,-3.66012,-4.02750
36.80000,-3.67999,-4.12729
37.00000,-3.69999,-4.20549
37.20000,-3.71999,-4.29736
37.40000,-3.73972,-4.39157
37.60000,-3.75972,-4.45967
37.80000,-3.78026,-4.53213
38.00000,-3.79999,-4.57460
38.20000,-3.81972,-4.63973
38.40000,-3.83999,-4.70598
38.60000,-3.85972,-4.76232
38.80000,-3.87986,-4.82393
39.00000,-3.89986,-4.89740
39.20000,-3.91972,-4.99129
39.40000,-3.93986,-5.08627
39.60000,-3.96012,-5.16540
39.80000,-3.97986,-5.23869
40.00000,-3.99959,-5.31589
40.20000,-4.01999,-5.39023
40.40000,-4.03986,-5.44255
40.60000,-4.05999,-5.50413
40.80000,-4.08012,-5.55069
41.00000,-4.09986,-5.59549
41.20000,-4.11986,-5.63686
41.40000,-4.13999,-5.68929
41.60000,-4.15999,-5.73230
41.80000,-4.17972,-5.77151
42.00000,-4.19986,-5.81989
42.20000,-4.22012,-5.86185
42.40000,-4.23972,-5.89445
42.60000,-4.25999,-5.93092
42.80000,-4.27999,-5.95212
43.00000,-4.29959,-5.97544
43.20000,-4.31999,-6.03295
43.40000,-4.34026,-6.12205
43.60000,-4.35986,-6.17491
43.80000,-4.37972,-6.22678
44.00000,-4.39986,-6.27053
44.20000,-4.41972,-6.31114
44.40000,-4.43986,-6.35183
44.60000,-4.45986,-6.39260
44.80000,-4.47959,-6.40230
45.00000,-4.49999,-6.43746
45.20000,-4.51999,-6.47363
45.40000,-4.53972,-6.50853
45.60000,-4.55986,-6.51762
45.80000,-4.57999,-6.53700
46.00000,-4.59999,-6.56287
46.20000,-4.61999,-6.58479
46.40000,-4.64012,-6.58149
46.60000,-4.65959,-6.59315
46.80000,-4.67972,-6.61355
47.00000,-4.69986,-6.63675
47.20000,-4.71999,-6.66450
47.40000,-4.73999,-6.69170
47.60000,-4.75986,-6.72335
47.80000,-4.77986,-6.76402
48.00000,-4.79985,-6.79066
48.20000,-4.82012,-6.81547
48.40000,-4.83985,-6.82088
48.60000,-4.85972,-6.81653
48.80000,-4.87999,-6.83292
49.00000,-4.90012,-6.84877
49.20000,-4.91999,-6.85463
49.40000,-4.93985,-6.86960
49.60000,-4.95972,-6.88792
49.80000,-4.97972,-6.90777
50.00000,-4.99999,-6.93958
50.20000,-5.01999,-6.95351
50.40000,-5.03959,-6.97601
50.60000,-5.05985,-6.97168
50.80000,-5.07985,-6.95591
51.00000,-5.09972,-6.97431
51.20000,-5.11985,-7.01406
51.40000,-5.13999,-7.04006
51.60000,-5.15999,-7.07344
51.80000,-5.17999,-7.10461
52.00000,-5.19999,-7.13945
52.20000,-5.21972,-7.16257
52.40000,-5.23972,-7.18869
52.60000,-5.26012,-7.19200
52.80000,-5.27999,-7.20612
53.00000,-5.29985,-7.22136
53.20000,-5.31999,-7.23484
53.40000,-5.33985,-7.23158
53.60000,-5.35972,-7.24215
53.80000,-5.37999,-7.25506
54.00000,-5.39999,-7.26400
54.20000,-5.41972,-7.29181
54.40000,-5.43999,-7.31645
54.60000,-5.45985,-7.35874
54.80000,-5.47985,-7.39576
55.00000,-5.49972,-7.41249
55.20000,-5.51959,-7.41989
55.40000,-5.53985,-7.44413
55.60000,-5.56012,-7.46028
55.80000,-5.57999,-7.47567
56.00000,-5.59972,-7.48862
56.20000,-5.61985,-7.49700
56.40000,-5.63985,-7.52503
56.60000,-5.65999,-7.55332
56.80000,-5.68012,-7.57836
57.00000,-5.69985,-7.59380
57.20000,-5.71985,-7.61786
57.40000,-5.73985,-7.64337
57.60000,-5.75985,-7.65559
57.80000,-5.77972,-7.66636
58.00000,-5.79985,-7.68198
58.20000,-5.82025,-7.68972
58.40000,-5.83985,-7.69221
58.60000,-5.85985,-7.68638
58.80000,-5.87985,-7.69585
59.00000,-5.89972,-7.72699
59.20000,-5.91999,-7.74234
59.40000,-5.94025,-7.75846
59.60000,-5.95999,-7.76956
59.80000,-5.97972,-7.77639
60.00000,-5.99999,-7.78439
60.20000,-6.01972,-7.79988
60.40000,-6.03985,-7.81271
60.60000,-6.05999,-7.82591
60.80000,-6.07972,-7.83796
61.00000,-6.09985,-7.85277
61.20000,-6.11999,-7.87629
61.40000,-6.13972,-7.88209
61.60000,-6.15972,-7.90197
61.80000,-6.17999,-7.92542
62.00000,-6.19985,-7.93860
62.20000,-6.21998,-7.95189
62.40000,-6.24012,-7.95661
62.60000,-6.25972,-7.96693
62.80000,-6.27972,-7.99222
63.00000,-6.29985,-8.00799
63.20000,-6.32012,-8.02168
63.40000,-6.33985,-8.03518
63.60000,-6.35985,-8.05351
63.80000,-6.37998,-8.06479
64.00000,-6.39985,-8.07853
64.20000,-6.41998,-8.08997
64.40000,-6.43985,-8.09792
64.60001,-6.45972,-8.11317
64.80000,-6.47998,-8.12538
65.00000,-6.49998,-8.13721
65.20000,-6.51985,-8.15679
65.40000,-6.53972,-8.17460
65.60001,-6.55985,-8.19342
65.80000,-6.57972,-8.20991
66.00000,-6.60012,-8.22395
66.20001,-6.61998,-8.23742
66.40000,-6.63958,-8.24272
66.60001,-6.65985,-8.24817
66.80000,-6.67998,-8.25712
67.00000,-6.69972,-8.26252
67.20001,-6.71985,-8.27006
67.40000,-6.73998,-8.28794
67.60001,-6.75998,-8.30405
67.80000,-6.77998,-8.32949
68.00000,-6.79998,-8.34921
68.20001,-6.81972,-8.36298
68.40000,-6.83972,-8.39191
68.60001,-6.86012,-8.41923
68.80000,-6.87998,-8.44263
69.00000,-6.90012,-8.46903
69.20001,-6.91998,-8.49530
69.40000,-6.93972,-8.50924
69.60001,-6.95972,-8.52648
69.80000,-6.98012,-8.54343
70.00000,-6.99998,-8.54963
70.20001,-7.01972,-8.55937
70.40000,-7.03998,-8.57290
70.60001,-7.05972,-8.57611
70.80000,-7.07985,-8.58114
71.00000,-7.09972,-8.56685
71.20001,-7.11972,-8.54752
71.40000,-7.13985,-8.48233
71.60001,-7.16012,-8.40334
71.80000,-7.17985,-8.29371
72.00000,-7.19958,-8.14970
72.20001,-7.21998,-8.16139
72.40000,-7.23998,-8.17693
72.60001,-7.25998,-8.20525
72.80000,-7.27998,-8.22306
73.00000,-7.29985,-8.24129
73.20001,-7.31985,-8.24498
73.40000,-7.33985,-8.26980
73.60001,-7.35998,-8.29099
73.80000,-7.37972,-8.29812
74.00000,-7.39985,-8.31286
74.20001,-7.42012,-8.32069
74.40000,-7.43998,-8.32563
74.60001,-7.45998,-8.30707
74.80000,-7.47985,-8.31396
75.00000,-7.49958,-8.33171
75.20001,-7.51998,-8.37043
75.40000,-7.54011,-8.39641
75.60001,-7.55998,-8.41453
75.80000,-7.57971,-8.43273
76.00000,-7.59985,-8.46032
76.20001,-7.61971,-8.48277
76.40000,-7.63985,-8.51201
76.60001,-7.65998,-8.52101
76.80000,-7.67971,-8.54097
77.00000,-7.69985,-8.56773
77.20001,-7.72011,-8.58813
77.40000,-7.73985,-8.60289
77.60001,-7.75958,-8.62109
77.80000,-7.77998,-8.66614
78.00000,-7.79998,-8.69684
78.20001,-7.81998,-8.72431
78.40000,-7.84011,-8.74737
78.60001,-7.85971,-8.76571
78.80000,-7.87971,-8.79471
79.00000,-7.89998,-8.81271
79.20001,-7.92011,-8.82902
79.40000,-7.93985,-8.83281
79.60001,-7.95985,-8.86443
79.80000,-7.97998,-8.90533
80.00000,-7.99985,-8.93772
80.20001,-8.01998,-8.97681
80.40000,-8.03985,-9.00657
80.60001,-8.05971,-9.03526
80.80000,-8.07998,-9.06872
81.00001,-8.09998,-9.09844
81.20001,-8.11985,-9.11973
81.40000,-8.13971,-9.13632
81.60001,-8.15985,-9.16558
81.80000,-8.17971,-9.18382
82.00001,-8.20011,-9.21111
82.20001,-8.21998,-9.23351
82.40000,-8.23958,-9.24665
82.60001,-8.25985,-9.26976
82.80000,-8.27985,-9.28508
83.00001,-8.29971,-9.29449
83.20001,-8.31998,-9.29470
83.40000,-8.33998,-9.29285
83.60001,-8.35998,-9.27812
83.80000,-8.37998,-9.26073
84.00001,-8.39998,-9.23221
84.20001,-8.41958,-9.21441
84.40000,-8.43971,-9.21032
84.60001,-8.46011,-9.21807
84.80000,-8.47998,-9.21779
85.00001,-8.49998,-9.21870
85.20001,-8.51998,-9.21098
85.40000,-8.53971,-9.20439
85.60001,-8.55985,-9.21164
85.80000,-8.58011,-9.21442
86.00001,-8.59998,-9.20025
86.20001,-8.61971,-9.19804
86.40000,-8.63998,-9.20637
86.60001,-8.65985,-9.21099
86.80000,-8.67985,-9.20981
87.00001,-8.69971,-9.20065
87.20001,-8.71971,-9.21058
87.40000,-8.73985,-9.20846
87.60001,-8.76011,-9.21125
87.80000,-8.77998,-9.20362
88.00001,-8.79958,-9.18255
88.20001,-8.81998,-9.16717
88.40000,-8.83971,-9.13027
88.60001,-8.85984,-9.10533
88.80000,-8.87998,-9.07893
89.00001,-8.89971,-9.05728
89.20001,-8.91985,-9.04301
89.40000,-8.93998,-9.03964
89.60001,-8.95998,-9.03829
89.80000,-8.97971,-9.03575
90.00001,-8.99985,-9.04408
90.20001,-9.02011,-9.05091
90.40000,-9.03998,-9.05681
90.60001,-9.05998,-9.06646
90.80000,-9.07984,-9.06604
91.00001,-9.09958,-9.07869
91.20001,-9.11984,-9.09309
91.40000,-9.14011,-9.11072
91.60001,-9.15984,-9.11965
91.80000,-9.17971,-9.14073
92.00001,-9.19998,-9.16069
92.20001,-9.21984,-9.17844
92.40000,-9.23998,-9.18941
92.60001,-9.25998,-9.19521
92.80000,-9.27958,-9.20561
93.00001,-9.29998,-9.21897
93.20001,-9.32011,-9.22970
93.40000,-9.33971,-9.23971
93.60001,-9.35971,-9.25136
93.80000,-9.37998,-9.27281
94.00001,-9.39998,-9.29265
94.20001,-9.41998,-9.31646
94.40000,-9.44011,-9.33394
94.60001,-9.45971,-9.34511
94.80000,-9.47984,-9.36334
95.00001,-9.49984,-9.37776
95.20001,-9.51998,-9.39588
95.40000,-9.53984,-9.40775
95.60001,-9.55984,-9.41938
95.80000,-9.57998,-9.43348
96.00001,-9.59971,-9.44649
96.20001,-9.61998,-9.46761
96.40000,-9.63971,-9.47689
96.60001,-9.65971,-9.49593
96.80000,-9.68011,-9.51685
97.00001,-9.70011,-9.52657
97.20001,-9.71998,-9.52812
97.40000,-9.73971,-9.52119
97.60001,-9.75971,-9.52435
97.80000,-9.77971,-9.53641
98.00001,-9.80011,-9.55384
98.20001,-9.81998,-9.53397
98.40000,-9.83958,-9.54717
98.60001,-9.85998,-9.56482
98.80000,-9.87998,-9.57142
99.00001,-9.89971,-9.57571
99.20001,-9.91984,-9.59133
99.40000,-9.93998,-9.61419
99.60001,-9.95998,-9.62852
99.80000,-9.97984,-9.63121
100.00001,-9.99998,-9.64099
100.20001,-10.01971,-9.65233
100.40000,-10.03971,-9.67720
100.60001,-10.06011,-9.70425
100.80000,-10.07984,-9.72740
101.00001,-10.09998,-9.75953
101.20001,-10.11998,-9.78392
101.40000,-10.13971,-9.80849
101.60001,-10.15984,-9.84226
101.80000,-10.18011,-9.86323
102.00001,-10.19998,-9.87827
102.20001,-10.21971,-9.89831
102.40000,-10.24011,-9.91988
102.60001,-10.25984,-9.94092
102.80000,-10.27984,-9.94897
103.00001,-10.29971,-9.94428
103.20001,-10.31957,-9.95199
103.40000,-10.33997,-9.96974
103.60001,-10.36011,-9.98277
103.80000,-10.37984,-9.98290
104.00001,-10.39971,-9.97670
104.20001,-10.41984,-9.96448
104.40000,-10.43971,-9.90762
104.60001,-10.45997,-9.90200
104.80000,-10.48011,-9.90002
105.00001,-10.49984,-9.88548
105.20001,-10.51997,-9.85462
105.40000,-10.54011,-9.84673
105.60001,-10.55997,-9.84113
105.80000,-10.57984,-9.84486
106.00001,-10.59984,-9.85977
106.20001,-10.62011,-9.87248
106.40000,-10.63997,-9.88978
106.60001,-10.65997,-9.91885
106.80000,-10.67984,-9.93901
107.00001,-10.69971,-9.96661
107.20001,-10.71984,-9.97416
107.40000,-10.74011,-9.99319
107.60001,-10.75997,-10.01697
107.80000,-10.77984,-10.04943
108.00001,-10.79984,-10.06419
108.20001,-10.81971,-10.09780
108.40000,-10.83984,-10.13083
108.60001,-10.85997,-10.16003
108.80000,-10.87971,-10.19432
109.00001,-10.89997,-10.22891
109.20001,-10.92011,-10.24495
109.40000,-10.93984,-10.25529
109.60001,-10.95971,-10.27077
109.80000,-10.97984,-10.30223
110.00001,-10.99984,-10.32402
110.20001,-11.02011,-10.35550
110.40000,-11.03997,-10.37412
110.60001,-11.05971,-10.32362
110.80000,-11.07971,-10.32561
111.00001,-11.09984,-10.32235
111.20001,-11.11997,-10.33706
111.40000,-11.13997,-10.34489
111.60001,-11.15984,-10.35730
111.80000,-11.17997,-10.38056
112.00001,-11.19971,-10.39663
112.20001,-11.22011,-10.39659
112.40000,-11.23971,-10.37902
112.60001,-11.25971,-10.34869
112.80000,-11.28011,-10.30847
113.00001,-11.29997,-10.27167
113.20001,-11.31984,-10.23704
113.40001,-11.33971,-10.23275
113.60001,-11.35971,-10.25474
113.80000,-11.37971,-10.28307
114.00001,-11.39997,-10.31808
114.20001,-11.41997,-10.35325
114.40001,-11.43957,-10.38926
114.60001,-11.45984,-10.43911
114.80000,-11.47997,-10.47746
115.00001,-11.49971,-10.50782
115.20001,-11.51984,-10.54214
115.40001,-11.53997,-10.57317
115.60001,-11.55997,-10.56873
115.80000,-11.57997,-10.59785
116.00001,-11.60011,-10.63741
116.20001,-11.61970,-10.66453
116.40001,-11.63984,-10.70789
116.60001,-11.65997,-10.75121
116.80000,-11.67997,-10.76018
117.00001,-11.69997,-10.78496
117.20001,-11.71984,-10.77980
117.40001,-11.73970,-10.80508
117.60001,-11.75984,-10.83099
117.80000,-11.78010,-10.86086
118.00001,-11.79997,-10.87564
118.20001,-11.81957,-10.88233
118.40001,-11.83997,-10.90013
118.60001,-11.85997,-10.92416
118.80000,-11.87984,-10.95405
119.00001,-11.89970,-10.98630
119.20001,-11.91957,-11.02070
119.40001,-11.93997,-11.06595
119.60001,-11.96010,-11.09076
119.80000,-11.97997,-11.11207
120.00001,-11.99970,-11.12699
120.20001,-12.01997,-11.16539
120.40001,-12.03984,-11.18945
120.60001,-12.05984,-11.21713
120.80000,-12.07997,-11.24937
121.00001,-12.09984,-11.27951
121.20001,-12.11997,-11.29788
121.40001,-12.13997,-11.32470
121.60001,-12.15997,-11.34751
121.80000,-12.17970,-11.36884
122.00001,-12.19984,-11.39978
122.20001,-12.22010,-11.44447
122.40001,-12.23997,-11.45691
122.60001,-12.25997,-11.45212
122.80000,-12.27997,-11.45348
123.00001,-12.29970,-11.45264
123.20001,-12.31984,-11.46214
123.40001,-12.34024,-11.47227
123.60001,-12.35997,-11.48989
123.80000,-12.37970,-11.48934
124.00001,-12.39984,-11.48315
124.20001,-12.41970,-11.47244
124.40001,-12.43970,-11.48428
124.60001,-12.45984,-11.48147
124.80000,-12.47957,-11.45846
125.00001,-12.49997,-11.46337
125.20001,-12.52010,-11.45586
125.40001,-12.53970,-11.46313
125.60001,-12.55970,-11.47355
125.80000,-12.57997,-11.47962
126.00001,-12.59997,-11.47908
126.20001,-12.61997,-11.45063
126.40001,-12.64010,-11.45591
126.60001,-12.65957,-11.45786
126.80000,-12.67984,-11.46661
127.00001,-12.69997,-11.43874
127.20001,-12.71997,-11.44993
127.40001,-12.73984,-11.45678
127.60001,-12.75984,-11.46565
127.80000,-12.77997,-11.46273
128.00000,-12.79984,-11.45684
128.20002,-12.81997,-11.46434
128.40001,-12.83984,-11.44428
128.60001,-12.85970,-11.44340
128.80000,-12.88010,-11.46492
129.00000,-12.90010,-11.48224
129.20002,-12.91983,-11.49324
129.40001,-12.93970,-11.48981
129.60001,-12.95984,-11.47492
129.80000,-12.97970,-11.48035
130.00000,-13.00010,-11.46990
130.20002,-13.02010,-11.49783
130.40001,-13.03957,-11.49166
130.60001,-13.05983,-11.49758
130.80000,-13.07997,-11.48392
131.00000,-13.09970,-11.48097
131.20002,-13.11997,-11.49005
131.40002,-13.13997,-11.48525
131.60000,-13.15997,-11.49420
131.80000,-13.17997,-11.48799
132.00000,-13.20010,-11.50593
132.20002,-13.21970,-11.52265
132.40002,-13.23970,-11.54281
132.60000,-13.26010,-11.58418
132.80000,-13.27983,-11.60280
133.00000,-13.29983,-11.62836
133.20002,-13.31983,-11.64793
133.40002,-13.33983,-11.63004
133.60000,-13.35997,-11.67827
133.80000,-13.38010,-11.69899
134.00000,-13.39997,-11.73095
134.20002,-13.41970,-11.76658
134.40002,-13.44010,-11.81372
134.60000,-13.45983,-11.84459
134.80000,-13.47970,-11.85878
135.00000,-13.49970,-11.87769
135.20002,-13.51970,-11.89996
135.40002,-13.53983,-11.92489
135.60000,-13.56010,-11.90834
135.80000,-13.57997,-11.93217
136.00000,-13.59957,-11.95185
136.20002,-13.61997,-11.97987
136.40002,-13.63970,-11.99263
136.60000,-13.65997,-12.01872
136.80000,-13.68010,-12.01821
137.00000,-13.69983,-12.01483
137.20002,-13.71983,-12.04322
137.40002,-13.73997,-12.07837
137.60000,-13.75997,-11.58442
137.80000,-13.77970,-11.59477
138.00000,-13.79983,-11.65498
138.20002,-13.82010,-11.71348
138.40002,-13.83983,-11.76183
138.60000,-13.85997,-11.81774
138.80000,-13.87997,-11.85333
139.00000,-13.89970,-11.90351
139.20002,-13.91997,-11.95878
139.40002,-13.94023,-12.00883
139.60000,-13.95983,-12.04797
139.80000,-13.97983,-12.10090
140.00000,-13.99997,-12.15479
140.20002,-14.01970,-12.19855
140.40002,-14.03970,-12.25305
140.60000,-14.05983,-12.29918
140.80000,-14.07957,-12.36267
141.00000,-14.09983,-12.42818
141.20002,-14.12023,-12.49227
141.40002,-14.13983,-12.53211
141.60000,-14.15957,-12.57519
141.80000,-14.17983,-12.63928
142.00000,-14.19997,-12.69124
142.20002,-14.21996,-12.73880
142.40002,-14.24023,-12.77512
142.60000,-14.25970,-12.81072
142.80000,-14.27983,-12.85396
143.00000,-14.29997,-12.88648
143.20002,-14.31996,-12.89443
143.40002,-14.33983,-12.92647
143.60000,-14.35983,-12.96944
143.80000,-14.38010,-13.01372
144.00000,-14.39970,-13.05981
144.20002,-14.42010,-13.11450
144.40002,-14.43983,-13.14607
144.60000,-14.45956,-13.19938
144.80000,-14.47996,-13.25900
145.00000,-14.49996,-13.31685
145.20002,-14.51983,-13.37103
145.40002,-14.53970,-13.42454
145.60000,-14.55970,-13.48194
145.80000,-14.57970,-13.54655
146.00000,-14.60010,-13.61877
146.20002,-14.61996,-13.66754
146.40002,-14.63956,-13.72814
146.60000,-14.65996,-13.79244
146.80000,-14.67996,-13.84874
147.00000,-14.69970,-13.90808
147.20002,-14.71996,-13.96861
147.40002,-14.73996,-14.03237
147.60000,-14.75996,-14.09128
147.80000,-14.77996,-14.15234
148.00000,-14.80010,-14.18795
148.20002,-14.81956,-14.22107
148.40002,-14.83970,-14.27315
148.60000,-14.86010,-14.33765
148.80000,-14.87996,-14.38430
149.00000,-14.90010,-14.45120
149.20002,-14.91983,-14.50681
149.40002,-14.93970,-14.56423
149.60000,-14.95970,-14.63675
149.80000,-14.98010,-14.70548
150.00000,-14.99996,-14.76313
150.20002,-15.01970,-14.82367
150.33400,-15.03343,-14.86381