File: project1/data/Packing_Peanuts_Instron/Test1.is_comp_RawData/Specimen_RawData_1.csv
Time,Extension,Load
(sec),(mm),(N)
0.00000,0.00000,-0.00098
0.10000,-0.00213,-0.00048
0.20000,-0.01493,-0.00165
0.30000,-0.02747,-0.00277
0.40000,-0.03880,-0.00336
0.50000,-0.04907,-0.00437
0.60000,-0.05973,-0.00554
0.70000,-0.06973,-0.00614
0.80000,-0.07987,-0.00693
0.90000,-0.09013,-0.00789
1.00000,-0.09973,-0.00957
1.10000,-0.11000,-0.01133
1.20000,-0.12000,-0.01195
1.30000,-0.12973,-0.01227
1.40000,-0.13987,-0.01381
1.50000,-0.14987,-0.01457
1.60000,-0.16000,-0.01787
1.70000,-0.17013,-0.01935
1.80000,-0.18013,-0.02025
1.90000,-0.19000,-0.02193
2.00000,-0.20000,-0.02219
2.10000,-0.21013,-0.02385
2.20000,-0.22000,-0.02536
2.30000,-0.22987,-0.02714
2.40000,-0.24013,-0.02838
2.50000,-0.24987,-0.03061
2.60000,-0.25987,-0.03234
2.70000,-0.27000,-0.03418
2.80000,-0.27973,-0.03525
2.90000,-0.29013,-0.03599
3.00000,-0.30013,-0.03734
3.10000,-0.30987,-0.03844
3.20000,-0.32013,-0.04171
3.30000,-0.33000,-0.04273
3.40000,-0.34013,-0.04446
3.50000,-0.35000,-0.04576
3.60000,-0.36013,-0.04623
3.70000,-0.36987,-0.04722
3.80000,-0.37973,-0.04956
3.90000,-0.39013,-0.05013
4.00000,-0.39973,-0.05249
4.10000,-0.41000,-0.05392
4.20000,-0.42000,-0.05534
4.30000,-0.42973,-0.05749
4.40000,-0.44027,-0.05949
4.50000,-0.45000,-0.06220
4.60000,-0.45987,-0.06379
4.70000,-0.47000,-0.06686
4.80000,-0.47987,-0.06810
4.90000,-0.49000,-0.07090
5.00000,-0.50000,-0.07285
5.10000,-0.50973,-0.07448
5.20000,-0.51987,-0.07691
5.30000,-0.52987,-0.07932
5.40000,-0.53987,-0.08057
5.50000,-0.54987,-0.08204
5.60000,-0.55987,-0.08385
5.70000,-0.57013,-0.08562
5.80000,-0.57973,-0.08724
5.90000,-0.59013,-0.08884
6.00000,-0.60013,-0.08851
6.10000,-0.60973,-0.09094
6.20000,-0.62013,-0.09343
6.30000,-0.62987,-0.09382
6.40000,-0.63987,-0.09396
6.50000,-0.65000,-0.09620
6.60000,-0.65973,-0.09683
6.70000,-0.66987,-0.09916
6.80000,-0.68000,-0.10101
6.90000,-0.69000,-0.10316
7.00000,-0.70000,-0.10534
7.10000,-0.70986,-0.10712
7.20000,-0.72000,-0.10772
7.30000,-0.72986,-0.11055
7.40000,-0.74026,-0.11194
7.50000,-0.75000,-0.11413
7.60000,-0.75973,-0.11503
7.70000,-0.77013,-0.11769
7.80000,-0.77986,-0.11956
7.90000,-0.78973,-0.12114
8.00000,-0.80000,-0.12415
8.10000,-0.80973,-0.12521
8.20000,-0.82000,-0.12865
8.30000,-0.83026,-0.13096
8.40000,-0.83986,-0.13235
8.50000,-0.84986,-0.13525
8.60000,-0.86000,-0.13906
8.70000,-0.87013,-0.14162
8.80000,-0.88000,-0.14560
8.90000,-0.89000,-0.14734
9.00000,-0.90000,-0.15034
9.10000,-0.90986,-0.15218
9.20000,-0.92026,-0.15548
9.30000,-0.92986,-0.15972
9.40000,-0.93960,-0.16317
9.50000,-0.95026,-0.16703
9.60000,-0.95973,-0.17137
9.70000,-0.97000,-0.17614
9.80000,-0.98013,-0.17831
9.90000,-0.98973,-0.18250
10.00000,-1.00013,-0.18676
10.10000,-1.01000,-0.19235
10.20000,-1.02000,-0.19721
10.30000,-1.03000,-0.20143
10.40000,-1.03973,-0.20510
10.50000,-1.05000,-0.20947
10.60000,-1.06000,-0.21315
10.70000,-1.07000,-0.21752
10.80000,-1.08000,-0.22369
10.90000,-1.08986,-0.23041
11.00000,-1.10013,-0.23507
11.10000,-1.10986,-0.23882
11.20000,-1.12000,-0.24331
11.30000,-1.13013,-0.24711
11.40000,-1.13986,-0.25247
11.50000,-1.15013,-0.25780
11.60000,-1.16013,-0.26324
11.70000,-1.16986,-0.26938
11.80000,-1.18013,-0.27355
11.90000,-1.18986,-0.27716
12.00000,-1.19973,-0.28266
12.10000,-1.20986,-0.28905
12.20000,-1.21986,-0.29495
12.30000,-1.22986,-0.30096
12.40000,-1.24000,-0.30748
12.50000,-1.25013,-0.31459
12.60000,-1.26013,-0.31803
12.70000,-1.27013,-0.32460
12.80000,-1.28026,-0.32877
12.90000,-1.28986,-0.33837
13.00000,-1.30013,-0.34568
13.10000,-1.31000,-0.35481
13.20000,-1.31960,-0.36207
13.30000,-1.33000,-0.37034
13.40000,-1.33973,-0.37701
13.50000,-1.34973,-0.38535
13.60000,-1.36013,-0.39220
13.70000,-1.36986,-0.40238
13.80000,-1.38000,-0.41272
13.90000,-1.39013,-0.42367
14.00000,-1.40013,-0.43240
14.10000,-1.41000,-0.44283
14.20000,-1.42013,-0.45132
14.30000,-1.43013,-0.45879
14.40000,-1.43973,-0.46867
14.50000,-1.45000,-0.47938
14.60000,-1.46000,-0.49240
14.70000,-1.46973,-0.50384
14.80000,-1.48026,-0.51594
14.90000,-1.48986,-0.52769
15.00000,-1.49986,-0.53934
15.10000,-1.51026,-0.55308
15.20000,-1.52000,-0.56804
15.30000,-1.53000,-0.58593
15.40000,-1.54013,-0.60301
15.50000,-1.54986,-0.61847
15.60000,-1.56000,-0.63534
15.70000,-1.57000,-0.65185
15.80000,-1.57986,-0.66877
15.90000,-1.58973,-0.68866
16.00000,-1.59960,-0.71058
16.10000,-1.60986,-0.72995
16.20000,-1.61973,-0.74920
16.30000,-1.63013,-0.77274
16.40000,-1.64000,-0.79160
16.50000,-1.64973,-0.80934
16.60000,-1.66026,-0.83319
16.70000,-1.66986,-0.85315
16.80000,-1.68000,-0.87283
16.90000,-1.69026,-0.89843
17.00000,-1.69973,-0.91675
17.10000,-1.70986,-0.93758
17.20000,-1.72000,-0.96048
17.30000,-1.72986,-0.98027
17.40000,-1.73986,-1.00062
17.50000,-1.74986,-1.02475
17.60000,-1.76000,-1.04719
17.70000,-1.77000,-1.06960
17.80000,-1.78000,-1.09647
17.90000,-1.79000,-1.12022
18.00000,-1.80000,-1.14377
18.10000,-1.81013,-1.16979
18.20000,-1.82000,-1.19312
18.30000,-1.82986,-1.21860
18.40000,-1.84013,-1.24868
18.50000,-1.84986,-1.27477
18.60000,-1.85973,-1.29960
18.70000,-1.87000,-1.32907
18.80000,-1.87973,-1.35539
18.90000,-1.89013,-1.38538
19.00000,-1.90000,-1.41888
19.10000,-1.90986,-1.44737
19.20000,-1.92000,-1.47749
19.30000,-1.93000,-1.51171
19.40000,-1.94013,-1.54086
19.50000,-1.94986,-1.57112
19.60000,-1.96000,-1.60389
19.70000,-1.96973,-1.63555
19.80000,-1.97973,-1.66777
19.90000,-1.99013,-1.70542
20.00000,-1.99973,-1.73592
20.10000,-2.01013,-1.76722
20.20000,-2.02000,-1.80536
20.30000,-2.02973,-1.83686
20.40000,-2.04026,-1.87304
20.50000,-2.05000,-1.90909
20.60000,-2.05986,-1.94456
20.70000,-2.07013,-1.97992
20.80000,-2.07999,-2.01302
20.90000,-2.08999,-2.04964
21.00000,-2.09986,-2.08142
21.10000,-2.10973,-2.11843
21.20000,-2.11986,-2.15466
21.30000,-2.12986,-2.19189
21.40000,-2.13986,-2.22775
21.50000,-2.14973,-2.26279
21.60000,-2.15986,-2.29813
21.70000,-2.17013,-2.33731
21.80000,-2.17986,-2.37286
21.90000,-2.19013,-2.41052
22.00000,-2.19999,-2.44894
22.10000,-2.20973,-2.48483
22.20000,-2.22026,-2.52374
22.30000,-2.22986,-2.56150
22.40000,-2.23986,-2.59855
22.50000,-2.24999,-2.63642
22.60000,-2.25959,-2.67469
22.70000,-2.26973,-2.71067
22.80000,-2.27999,-2.74869
22.90000,-2.28999,-2.78687
23.00000,-2.29986,-2.82560
23.10000,-2.30999,-2.86189
23.20000,-2.32013,-2.89663
23.30000,-2.33013,-2.92764
23.40000,-2.34026,-2.95826
23.50000,-2.34999,-2.98779
23.60000,-2.35959,-3.02117
23.70000,-2.37013,-3.04815
23.80000,-2.37999,-3.07631
23.90000,-2.38986,-3.09879
24.00000,-2.39999,-3.12483
24.10000,-2.40986,-3.14689
24.20000,-2.41999,-3.17173
24.30000,-2.43013,-3.19430
24.40000,-2.43986,-3.21574
24.50000,-2.44999,-3.23854
24.60000,-2.45999,-3.26242
24.70000,-2.46999,-3.28432
24.80000,-2.47999,-3.30861
24.90000,-2.48999,-3.33063
25.00000,-2.49999,-3.35395
25.10000,-2.50973,-3.37703
25.20000,-2.52026,-3.40248
25.30000,-2.52986,-3.42775
25.40000,-2.53959,-3.44669
25.50000,-2.55026,-3.47217
25.60000,-2.55986,-3.49687
25.70000,-2.57013,-3.51968
25.80000,-2.58013,-3.54671
25.90000,-2.58973,-3.56948
26.00000,-2.60013,-3.59443
26.10000,-2.60999,-3.62144
26.20000,-2.61986,-3.64609
26.30000,-2.62986,-3.67889
26.40000,-2.63973,-3.70875
26.50000,-2.64986,-3.74040
26.60000,-2.65986,-3.77362
26.70000,-2.66986,-3.80844
26.80000,-2.67999,-3.84828
26.90000,-2.68973,-3.88137
27.00000,-2.70013,-3.91884
27.10000,-2.70973,-3.95517
27.20000,-2.71986,-3.99316
27.30000,-2.73013,-4.03423
27.40000,-2.73973,-4.07359
27.50000,-2.74999,-4.10879
27.60000,-2.76013,-4.14899
27.70000,-2.76973,-4.18705
27.80000,-2.77999,-4.22878
27.90000,-2.78986,-4.26976
28.00000,-2.79986,-4.30797
28.10000,-2.80986,-4.34669
28.20000,-2.81986,-4.38496
28.30000,-2.82999,-4.42436
28.40000,-2.84013,-4.46210
28.50000,-2.85013,-4.50136
28.60000,-2.85999,-4.53792
28.70000,-2.86999,-4.57405
28.80000,-2.88013,-4.61452
28.90000,-2.88986,-4.65206
29.00000,-2.90013,-4.68883
29.10000,-2.90999,-4.72462
29.20000,-2.91973,-4.75908
29.30000,-2.92999,-4.79622
29.40000,-2.93973,-4.83407
29.50000,-2.94986,-4.87003
29.60000,-2.96013,-4.90913
29.70000,-2.96986,-4.94488
29.80000,-2.98013,-4.97984
29.90000,-2.99026,-5.01707
30.00000,-3.00013,-5.05041
30.10000,-3.00999,-5.08480
30.20000,-3.01999,-5.11998
30.30000,-3.02999,-5.15395
30.40000,-3.03986,-5.18864
30.50000,-3.05013,-5.22488
30.60000,-3.05986,-5.26169
30.70000,-3.06973,-5.29684
30.80000,-3.08026,-5.33517
30.90000,-3.08986,-5.36958
31.00000,-3.09986,-5.40447
31.10000,-3.11026,-5.44237
31.20000,-3.11986,-5.47842
31.30000,-3.12986,-5.51378
31.40000,-3.14013,-5.54860
31.50000,-3.14986,-5.58139
31.60000,-3.15999,-5.61864
31.70000,-3.16999,-5.65115
31.80000,-3.17986,-5.68538
31.90000,-3.18986,-5.72149
32.00000,-3.19986,-5.75617
32.10000,-3.20986,-5.78982
32.20000,-3.21973,-5.81931
32.30000,-3.23013,-5.85282
32.40000,-3.23999,-5.88649
32.50000,-3.24973,-5.91671
32.60000,-3.26026,-5.95078
32.70000,-3.26986,-5.98433
32.80000,-3.27986,-6.01434
32.90000,-3.29013,-6.05043
33.00000,-3.29959,-6.08113
33.10000,-3.30999,-6.11318
33.20000,-3.32013,-6.14370
33.30000,-3.32986,-6.17078
33.40000,-3.33999,-6.20413
33.50000,-3.34986,-6.23469
33.60000,-3.35999,-6.26389
33.70000,-3.36999,-6.29599
33.80000,-3.38013,-6.32739
33.90000,-3.38999,-6.35708
34.00000,-3.39999,-6.38783
34.10000,-3.41026,-6.41670
34.20000,-3.41986,-6.44631
34.30000,-3.42973,-6.47561
34.40000,-3.43999,-6.50862
34.50000,-3.44972,-6.53725
34.60000,-3.45986,-6.56664
34.70000,-3.46999,-6.59772
34.80000,-3.47972,-6.62593
34.90000,-3.49012,-6.66087
35.00000,-3.50026,-6.69220
35.10000,-3.51012,-6.72303
35.20000,-3.52012,-6.75318
35.30000,-3.52986,-6.78457
35.40000,-3.54012,-6.81635
35.50000,-3.54999,-6.84715
35.60000,-3.56012,-6.87944
35.70000,-3.56972,-6.91128
35.80000,-3.57972,-6.94184
35.90000,-3.59012,-6.97807
36.00000,-3.59972,-7.01044
36.10000,-3.60999,-7.04324
36.20000,-3.61999,-7.07560
36.30000,-3.62959,-7.10452
36.40000,-3.64026,-7.13699
36.50000,-3.64999,-7.16740
36.60000,-3.65986,-7.19699
36.70000,-3.67012,-7.23306
36.80000,-3.67986,-7.27289
36.90000,-3.68986,-7.31231
37.00000,-3.69986,-7.34931
37.10000,-3.70986,-7.38263
37.20000,-3.71986,-7.41535
37.30000,-3.72972,-7.44711
37.40000,-3.73986,-7.47843
37.50000,-3.74986,-7.51226
37.60000,-3.75986,-7.54362
37.70000,-3.77012,-7.57693
37.80000,-3.77986,-7.60608
37.90000,-3.79012,-7.63746
38.00000,-3.80012,-7.66974
38.10000,-3.80972,-7.69788
38.20000,-3.82026,-7.72928
38.30000,-3.82986,-7.75918
38.40000,-3.83986,-7.78738
38.50000,-3.85012,-7.81883
38.60000,-3.85972,-7.84717
38.70000,-3.86986,-7.87514
38.80000,-3.87999,-7.90384
38.90000,-3.88999,-7.93112
39.00000,-3.89999,-7.95784
39.10000,-3.90999,-7.98520
39.20000,-3.92012,-8.01466
39.30000,-3.92999,-8.04250
39.40000,-3.94026,-8.06854
39.50000,-3.94999,-8.09358
39.60000,-3.95972,-8.11617
39.70000,-3.97012,-8.14065
39.80000,-3.97986,-8.16370
39.90000,-3.98972,-8.18558
40.00000,-3.99999,-8.21123
40.10000,-4.00972,-8.23479
40.20000,-4.01999,-8.25886
40.30000,-4.03012,-8.28230
40.40000,-4.03999,-8.30498
40.50000,-4.04999,-8.32956
40.60000,-4.06012,-8.35264
40.70000,-4.07012,-8.37622
40.80000,-4.07999,-8.39880
40.90000,-4.08999,-8.42114
41.00000,-4.09986,-8.44486
41.10000,-4.10972,-8.46555
41.20000,-4.12026,-8.49278
41.30000,-4.12999,-8.51681
41.40000,-4.13959,-8.53860
41.50000,-4.15026,-8.56517
41.60000,-4.15986,-8.58865
41.70000,-4.17012,-8.61281
41.80000,-4.18026,-8.63650
41.90000,-4.18972,-8.65978
42.00000,-4.20012,-8.68470
42.10000,-4.21012,-8.70795
42.20000,-4.21999,-8.73171
42.30000,-4.22986,-8.75696
42.40000,-4.23972,-8.78121
42.50000,-4.24986,-8.80737
42.60000,-4.25986,-8.83159
42.70000,-4.26986,-8.85630
42.80000,-4.27972,-8.88176
42.90000,-4.28959,-8.90624
43.00000,-4.30026,-8.93232
43.10000,-4.30999,-8.95945
43.20000,-4.31986,-8.98096
43.30000,-4.33026,-9.00784
43.40000,-4.33972,-9.03093
43.50000,-4.34986,-9.05423
43.60000,-4.35999,-9.08156
43.70000,-4.36972,-9.10410
43.80000,-4.37999,-9.12949
43.90000,-4.38999,-9.15454
44.00000,-4.39986,-9.17852
44.10000,-4.40986,-9.20274
44.20000,-4.41999,-9.22902
44.30000,-4.43012,-9.25547
44.40000,-4.44012,-9.27961
44.50000,-4.45026,-9.30544
44.60000,-4.45999,-9.32973
44.70000,-4.46999,-9.35537
44.80000,-4.48026,-9.38110
44.90000,-4.48986,-9.40574
45.00000,-4.49999,-9.42981
45.10000,-4.51012,-9.45624
45.20000,-4.51959,-9.48156
45.30000,-4.53012,-9.50708
45.40000,-4.53986,-9.53229
45.50000,-4.54972,-9.55613
45.60000,-4.56012,-9.58257
45.70000,-4.56986,-9.60874
45.80000,-4.57999,-9.63357
45.90000,-4.59012,-9.65893
46.00000,-4.60012,-9.68289
46.10000,-4.60999,-9.70861
46.20000,-4.61999,-9.73274
46.30000,-4.63012,-9.75771
46.40000,-4.63972,-9.77996
46.50000,-4.64999,-9.80540
46.60000,-4.65999,-9.83322
46.70000,-4.66972,-9.85730
46.80000,-4.68012,-9.88276
46.90000,-4.68986,-9.90816
47.00000,-4.69986,-9.93216
47.10000,-4.71026,-9.95985
47.20000,-4.71999,-9.98484
47.30000,-4.72999,-10.00974
47.40000,-4.74012,-10.03573
47.50000,-4.74986,-10.06069
47.60000,-4.75999,-10.08762
47.70000,-4.76986,-10.11206
47.80000,-4.77986,-10.13602
47.90000,-4.78985,-10.16264
48.00000,-4.79972,-10.18747
48.10000,-4.80986,-10.21394
48.20000,-4.81972,-10.23582
48.30000,-4.82999,-10.26125
48.40000,-4.83999,-10.28848
48.50000,-4.84972,-10.31151
48.60000,-4.86025,-10.33773
48.70000,-4.86986,-10.36290
48.80000,-4.87985,-10.38544
48.90000,-4.89012,-10.41148
49.00000,-4.89972,-10.43434
49.10000,-4.90985,-10.45926
49.20000,-4.91999,-10.48403
49.30000,-4.92985,-10.50735
49.40000,-4.93985,-10.53271
49.50000,-4.94985,-10.55802
49.60000,-4.95999,-10.58331
49.70000,-4.96999,-10.60956
49.80000,-4.98012,-10.63368
49.90000,-4.98999,-10.65956
50.00000,-4.99985,-10.68333
50.10000,-5.01012,-10.70866
50.20000,-5.01999,-10.73307
50.30000,-5.02972,-10.75576
50.40000,-5.04012,-10.78221
50.50000,-5.04972,-10.80549
50.60000,-5.05985,-10.82951
50.70000,-5.06999,-10.85614
50.80000,-5.07972,-10.87939
50.90000,-5.09025,-10.90766
51.00000,-5.10012,-10.93176
51.10000,-5.10999,-10.95674
51.20000,-5.12012,-10.98079
51.30000,-5.12999,-11.00381
51.40000,-5.14012,-11.02906
51.50000,-5.15012,-11.05519
51.60000,-5.16025,-11.07945
51.70000,-5.16985,-11.10345
51.80000,-5.17972,-11.12574
51.90000,-5.19012,-11.15283
52.00000,-5.19972,-11.17419
52.10000,-5.20999,-11.19649
52.20000,-5.21999,-11.22350
52.30000,-5.22972,-11.24590
52.40000,-5.24025,-11.27101
52.50000,-5.24999,-11.29334
52.60000,-5.25985,-11.31572
52.70000,-5.26999,-11.34244
52.80000,-5.27985,-11.36631
52.90000,-5.28999,-11.39167
53.00000,-5.29999,-11.41530
53.10000,-5.30985,-11.43745
53.20000,-5.31985,-11.46274
53.30000,-5.32972,-11.48556
53.40000,-5.33985,-11.51055
53.50000,-5.34985,-11.53475
53.60000,-5.35972,-11.55795
53.70000,-5.37012,-11.58395
53.80000,-5.37985,-11.60639
53.90000,-5.38999,-11.62998
54.00000,-5.40025,-11.65433
54.10000,-5.40972,-11.67674
54.20000,-5.42012,-11.70163
54.30000,-5.42985,-11.72567
54.40000,-5.43972,-11.74875
54.50000,-5.44985,-11.77358
54.60000,-5.45972,-11.79779
54.70000,-5.46985,-11.82251
54.80000,-5.47999,-11.84650
54.90000,-5.49012,-11.87037
55.00000,-5.49999,-11.89429
55.10000,-5.50999,-11.91675
55.20000,-5.52025,-11.94133
55.30000,-5.52999,-11.96469
55.40000,-5.54012,-11.98835
55.50000,-5.54999,-12.01350
55.60000,-5.55959,-12.03569
55.70000,-5.56999,-12.06037
55.80000,-5.57985,-12.08455
55.90000,-5.58972,-12.10801
56.00000,-5.59999,-12.13437
56.10000,-5.60972,-12.15715
56.20000,-5.61999,-12.18195
56.30000,-5.63025,-12.20745
56.40000,-5.63999,-12.23115
56.50000,-5.64999,-12.25562
56.60000,-5.66012,-12.28021
56.70000,-5.66999,-12.30574
56.80000,-5.67999,-12.32878
56.90000,-5.68999,-12.35114
57.00000,-5.69999,-12.37584
57.10000,-5.70972,-12.39802
57.20000,-5.72012,-12.42359
57.30000,-5.72985,-12.44702
57.40000,-5.73972,-12.46841
57.50000,-5.75025,-12.49542
57.60000,-5.75985,-12.51662
57.70000,-5.77012,-12.53998
57.80000,-5.78012,-12.56560
57.90000,-5.78985,-12.58993
58.00000,-5.80025,-12.61558
58.10000,-5.80999,-12.63895
58.20000,-5.81999,-12.66208
58.30000,-5.82985,-12.68686
58.40000,-5.83985,-12.71112
58.50000,-5.84999,-12.73549
58.60000,-5.85985,-12.75909
58.70000,-5.86985,-12.78292
58.80000,-5.87985,-12.80866
58.90000,-5.88972,-12.83130
59.00000,-5.89999,-12.85848
59.10000,-5.90985,-12.88353
59.20000,-5.91999,-12.90721
59.30000,-5.93012,-12.93425
59.40000,-5.93985,-12.95768
59.50000,-5.94999,-12.98027
59.60000,-5.95999,-13.00434
59.70000,-5.96959,-13.02622
59.80000,-5.97999,-13.05189
59.90000,-5.98985,-13.07651
60.00000,-5.99972,-13.10033
60.10000,-6.00985,-13.12543
60.20000,-6.01985,-13.15112
60.30000,-6.02999,-13.17648
60.40000,-6.04012,-13.19995
60.50000,-6.05012,-13.22334
60.60000,-6.05999,-13.24628
60.70000,-6.06999,-13.26894
60.80000,-6.08012,-13.29099
60.90000,-6.08972,-13.31239
61.00000,-6.09998,-13.33699
61.10000,-6.10999,-13.36238
61.20000,-6.11972,-13.38406
61.30000,-6.13025,-13.40969
61.40000,-6.13985,-13.43276
61.50000,-6.14985,-13.45642
61.60000,-6.16012,-13.48201
61.70000,-6.16985,-13.50413
61.80000,-6.17999,-13.52416
61.90000,-6.19012,-13.54418
62.00000,-6.19998,-13.56307
62.10000,-6.20998,-13.58596
62.20000,-6.21998,-13.60718
62.30000,-6.23012,-13.62869
62.40000,-6.23985,-13.64870
62.50000,-6.25012,-13.66912
62.60000,-6.25985,-13.69264
62.70000,-6.26958,-13.71311
62.80000,-6.27998,-13.73742
62.90000,-6.28985,-13.76054
63.00000,-6.29985,-13.78180
63.10000,-6.31025,-13.80582
63.20000,-6.31998,-13.82566
63.30000,-6.32998,-13.84699
63.40000,-6.34012,-13.86850
63.50000,-6.34985,-13.88966
63.60000,-6.35998,-13.91487
63.70000,-6.36998,-13.93682
63.80000,-6.37985,-13.96071
63.90000,-6.38985,-13.98571
64.00000,-6.39958,-14.00964
64.10001,-6.40985,-14.03676
64.20000,-6.41972,-14.06190
64.30000,-6.42998,-14.08769
64.40000,-6.43998,-14.11614
64.50000,-6.44972,-14.13754
64.60001,-6.46025,-14.16296
64.70000,-6.46985,-14.18528
64.80000,-6.47998,-14.20382
64.90000,-6.49012,-14.22927
65.00000,-6.49958,-14.25406
65.10001,-6.50998,-14.28180
65.20000,-6.52012,-14.30945
65.30000,-6.52985,-14.33191
65.40000,-6.53985,-14.35869
65.50000,-6.54985,-14.38325
65.60001,-6.55998,-14.40982
65.70001,-6.57012,-14.43425
65.80000,-6.58012,-14.45966
65.90000,-6.58998,-14.48825
66.00000,-6.59985,-14.51470
66.10001,-6.61012,-14.54222
66.20001,-6.62012,-14.57010
66.30000,-6.62985,-14.59498
66.40000,-6.64012,-14.62407
66.50000,-6.64972,-14.64948
66.60001,-6.65985,-14.67429
66.70001,-6.66998,-14.70381
66.80000,-6.67958,-14.73007
66.90000,-6.69012,-14.75961
67.00000,-6.70012,-14.78595
67.10001,-6.70998,-14.81219
67.20001,-6.72012,-14.83917
67.30000,-6.72998,-14.86575
67.40000,-6.74012,-14.89194
67.50000,-6.74998,-14.91760
67.60001,-6.75998,-14.94563
67.70001,-6.76972,-14.97108
67.80000,-6.77972,-14.99714
67.90000,-6.79012,-15.02773
68.00000,-6.79985,-15.05569
68.10001,-6.81012,-15.08396
68.20001,-6.81998,-15.11432
68.30000,-6.82972,-15.13831
68.40000,-6.84025,-15.16685
68.50000,-6.85012,-15.19255
68.60001,-6.85998,-15.21637
68.70001,-6.87012,-15.24416
68.80000,-6.87985,-15.26957
68.90000,-6.88985,-15.29743
69.00000,-6.89998,-15.32409
69.10001,-6.90985,-15.34983
69.20001,-6.91998,-15.38034
69.30000,-6.92985,-15.40855
69.40000,-6.93985,-15.43862
69.50000,-6.94972,-15.47060
69.60001,-6.95985,-15.49927
69.70001,-6.97012,-15.53548
69.80000,-6.97985,-15.56704
69.90000,-6.99012,-15.59895
70.00000,-6.99998,-15.63166
70.10001,-7.00958,-15.66165
70.20001,-7.02025,-15.69663
70.30000,-7.02985,-15.73067
70.40000,-7.03985,-15.76247
70.50000,-7.04998,-15.79691
70.60001,-7.05958,-15.82901
70.70001,-7.06985,-15.86233
70.80000,-7.07998,-15.89585
70.90000,-7.08998,-15.92770
71.00000,-7.09998,-15.96103
71.10001,-7.10998,-15.99392
71.20001,-7.12012,-16.02760
71.30000,-7.12998,-16.05961
71.40000,-7.14025,-16.09170
71.50000,-7.14998,-16.12487
71.60001,-7.15972,-16.15474
71.70001,-7.17012,-16.18773
71.80000,-7.17985,-16.22090
71.90000,-7.18972,-16.25425
72.00000,-7.20012,-16.29473
72.10001,-7.20985,-16.33339
72.20001,-7.22012,-16.37171
72.30000,-7.23025,-16.41228
72.40000,-7.23998,-16.44982
72.50000,-7.25012,-16.48906
72.60001,-7.26012,-16.52464
72.70001,-7.27012,-16.56379
72.80000,-7.28012,-16.59949
72.90000,-7.29012,-16.63442
73.00000,-7.29998,-16.67163
73.10001,-7.30972,-16.70506
73.20001,-7.32012,-16.74194
73.30000,-7.32985,-16.77543
73.40000,-7.33958,-16.80791
73.50000,-7.35012,-16.84510
73.60001,-7.35972,-16.87758
73.70001,-7.37012,-16.91189
73.80000,-7.38012,-16.94940
73.90000,-7.38972,-16.98319
74.00000,-7.40012,-17.01973
74.10001,-7.40998,-17.05696
74.20001,-7.41985,-17.09025
74.30000,-7.42985,-17.12885
74.40000,-7.43972,-17.16640
74.50000,-7.44985,-17.20447
74.60001,-7.45985,-17.24433
74.70001,-7.46985,-17.28481
74.80000,-7.47985,-17.32737
74.90000,-7.48972,-17.36679
75.00000,-7.50011,-17.41130
75.10001,-7.50985,-17.45342
75.20001,-7.51998,-17.49126
75.30000,-7.53025,-17.53383
75.40000,-7.53985,-17.57009
75.50000,-7.54998,-17.60828
75.60001,-7.56011,-17.64680
75.70001,-7.56971,-17.68162
75.80000,-7.57998,-17.72235
75.90000,-7.58998,-17.76228
76.00000,-7.59971,-17.79987
76.10001,-7.60985,-17.83852
76.20001,-7.61985,-17.87908
76.30000,-7.62998,-17.91959
76.40000,-7.64011,-17.96052
76.50000,-7.65011,-18.00171
76.60001,-7.65998,-18.04345
76.70001,-7.66998,-18.08421
76.80000,-7.68011,-18.12624
76.90000,-7.68985,-18.16731
77.00000,-7.70011,-18.20761
77.10001,-7.70998,-18.25268
77.20001,-7.71971,-18.29366
77.30000,-7.73011,-18.33578
77.40000,-7.73985,-18.37822
77.50000,-7.74985,-18.41706
77.60001,-7.76011,-18.46209
77.70001,-7.76985,-18.50470
77.80000,-7.77998,-18.54640
77.90000,-7.79011,-18.58963
78.00000,-7.80011,-18.63365
78.10001,-7.80998,-18.67918
78.20001,-7.82011,-18.72244
78.30000,-7.83011,-18.76837
78.40000,-7.83985,-18.81172
78.50000,-7.85011,-18.85552
78.60001,-7.85985,-18.90267
78.70001,-7.86958,-18.94461
78.80000,-7.88025,-18.99004
78.90000,-7.88998,-19.03847
79.00000,-7.89998,-19.08302
79.10001,-7.91011,-19.13647
79.20001,-7.91985,-19.17298
79.30000,-7.92998,-19.20793
79.40000,-7.94011,-19.24179
79.50000,-7.94985,-19.27327
79.60001,-7.95998,-19.30734
79.70001,-7.96985,-19.33956
79.80000,-7.97985,-19.37892
79.90000,-7.98971,-19.41063
80.00000,-7.99971,-19.43990
80.10001,-8.00985,-19.47091
80.20001,-8.01985,-19.50257
80.30000,-8.03011,-19.53498
80.40000,-8.03998,-19.57320
80.50001,-8.04971,-19.60370
80.60001,-8.06025,-19.63929
80.70001,-8.06985,-19.67473
80.80000,-8.07998,-19.70877
80.90000,-8.09011,-19.74761
81.00001,-8.09958,-19.78370
81.10001,-8.10998,-19.82226
81.20001,-8.12011,-19.86993
81.30000,-8.12971,-19.90707
81.40000,-8.13971,-19.94943
81.50001,-8.14985,-19.99385
81.60001,-8.15998,-20.03842
81.70001,-8.16998,-20.08156
81.80000,-8.17998,-20.12299
81.90000,-8.18998,-20.17115
82.00001,-8.19998,-20.21299
82.10001,-8.21025,-20.25649
82.20001,-8.21998,-20.29916
82.30000,-8.22985,-20.33936
82.40000,-8.24011,-20.38683
82.50001,-8.24985,-20.42932
82.60001,-8.25998,-20.47204
82.70001,-8.26985,-20.51493
82.80000,-8.27958,-20.55541
82.90000,-8.29011,-20.60158
83.00001,-8.29998,-20.64735
83.10001,-8.30998,-20.69300
83.20001,-8.32011,-20.73843
83.30000,-8.32998,-20.78224
83.40000,-8.34011,-20.82664
83.50001,-8.35011,-20.86873
83.60001,-8.36011,-20.91089
83.70001,-8.36985,-20.95171
83.80000,-8.37971,-20.99059
83.90000,-8.38998,-21.03472
84.00001,-8.39971,-21.07345
84.10001,-8.40998,-21.11318
84.20001,-8.41998,-21.15872
84.30000,-8.42971,-21.20213
84.40000,-8.44025,-21.24676
84.50001,-8.45011,-21.29091
84.60001,-8.45998,-21.33152
84.70001,-8.47011,-21.37734
84.80000,-8.47985,-21.42037
84.90000,-8.48985,-21.46305
85.00001,-8.49998,-21.50961
85.10001,-8.50985,-21.55304
85.20001,-8.51985,-21.59708
85.30000,-8.52985,-21.63966
85.40000,-8.53985,-21.68406
85.50001,-8.54971,-21.72982
85.60001,-8.55998,-21.77751
85.70001,-8.57011,-21.82879
85.80000,-8.57971,-21.87345
85.90000,-8.59011,-21.91867
86.00001,-8.60011,-21.96713
86.10001,-8.60971,-22.00841
86.20001,-8.62025,-22.05796
86.30000,-8.62998,-22.10214
86.40000,-8.63985,-22.14205
86.50001,-8.65011,-22.18508
86.60001,-8.65958,-22.22678
86.70001,-8.66985,-22.27042
86.80000,-8.68011,-22.31594
86.90000,-8.68998,-22.36078
87.00001,-8.69998,-22.40742
87.10001,-8.70998,-22.45148
87.20001,-8.72011,-22.49898
87.30000,-8.72998,-22.54367
87.40000,-8.74011,-22.58743
87.50001,-8.74998,-22.63336
87.60001,-8.75971,-22.67453
87.70001,-8.77011,-22.71977
87.80000,-8.77998,-22.76410
87.90000,-8.78971,-22.80560
88.00001,-8.80011,-22.85150
88.10001,-8.80984,-22.89453
88.20001,-8.81998,-22.93902
88.30000,-8.83025,-22.98432
88.40000,-8.83985,-23.02643
88.50001,-8.84998,-23.07243
88.60001,-8.86011,-23.11487
88.70001,-8.86998,-23.15979
88.80000,-8.87998,-23.20370
88.90000,-8.88998,-23.24632
89.00001,-8.89998,-23.29210
89.10001,-8.90984,-23.33518
89.20001,-8.92024,-23.37992
89.30000,-8.92984,-23.42487
89.40000,-8.93971,-23.46638
89.50001,-8.95011,-23.51377
89.60001,-8.95971,-23.55788
89.70001,-8.97011,-23.60197
89.80000,-8.98011,-23.64953
89.90000,-8.98971,-23.69342
90.00001,-9.00011,-23.74028
90.10001,-9.01011,-23.78320
90.20001,-9.01998,-23.82615
90.30000,-9.02998,-23.87180
90.40000,-9.03971,-23.91354
90.50001,-9.04984,-23.95515
90.60001,-9.05984,-23.99889
90.70001,-9.06985,-24.04272
90.80000,-9.07984,-24.09037
90.90000,-9.08971,-24.13396
91.00001,-9.10024,-24.18253
91.10001,-9.10998,-24.23173
91.20001,-9.11998,-24.27508
91.30000,-9.13024,-24.32688
91.40000,-9.13971,-24.37183
91.50001,-9.15011,-24.41858
91.60001,-9.16011,-24.46488
91.70001,-9.16971,-24.50753
91.80000,-9.17998,-24.55421
91.90000,-9.18998,-24.59918
92.00001,-9.19984,-24.64311
92.10001,-9.20998,-24.69261
92.20001,-9.21984,-24.73989
92.30000,-9.22984,-24.78963
92.40000,-9.23998,-24.83689
92.50001,-9.24998,-24.88540
92.60001,-9.25984,-24.93500
92.70001,-9.26984,-24.98270
92.80000,-9.27998,-25.03175
92.90000,-9.28984,-25.07949
93.00001,-9.30011,-25.12530
93.10001,-9.30998,-25.17880
93.20001,-9.31958,-25.22679
93.30000,-9.32998,-25.27506
93.40000,-9.33998,-25.32468
93.50001,-9.34984,-25.37203
93.60001,-9.36011,-25.42338
93.70001,-9.36984,-25.46891
93.80000,-9.37998,-25.51493
93.90000,-9.39011,-25.55976
94.00001,-9.39998,-25.60311
94.10001,-9.40984,-25.65010
94.20001,-9.41984,-25.69402
94.30000,-9.43011,-25.74005
94.40000,-9.43984,-25.78505
94.50001,-9.45011,-25.82750
94.60001,-9.45998,-25.87426
94.70001,-9.46971,-25.91612
94.80000,-9.48024,-25.96278
94.90000,-9.48998,-26.01041
95.00001,-9.49984,-26.05499
95.10001,-9.51024,-26.10627
95.20001,-9.51998,-26.15267
95.30000,-9.52998,-26.19835
95.40000,-9.54011,-26.24571
95.50001,-9.54971,-26.28946
95.60001,-9.55998,-26.33704
95.70001,-9.56998,-26.38315
95.80000,-9.57984,-26.42918
95.90000,-9.58984,-26.47651
96.00001,-9.59971,-26.52086
96.10001,-9.60998,-26.57067
96.20001,-9.61971,-26.61851
96.30000,-9.63011,-26.66702
96.40000,-9.63998,-26.71924
96.50001,-9.64971,-26.76408
96.60001,-9.66024,-26.81328
96.70001,-9.66984,-26.86050
96.80000,-9.67984,-26.90341
96.90000,-9.69011,-26.95240
97.00001,-9.69958,-26.99642
97.10001,-9.70984,-27.03983
97.20001,-9.72011,-27.08731
97.30000,-9.72984,-27.12990
97.40000,-9.73971,-27.17562
97.50001,-9.74984,-27.22282
97.60001,-9.75998,-27.27100
97.70001,-9.76998,-27.32671
97.80000,-9.78011,-27.37352
97.90000,-9.78998,-27.42027
98.00001,-9.79984,-27.46527
98.10001,-9.81011,-27.51186
98.20001,-9.81998,-27.55865
98.30000,-9.82971,-27.60196
98.40000,-9.84011,-27.65249
98.50001,-9.84984,-27.69957
98.60001,-9.85984,-27.74372
98.70001,-9.86998,-27.79456
98.80000,-9.87971,-27.83937
98.90000,-9.89011,-27.89316
99.00001,-9.90011,-27.94509
99.10001,-9.90984,-27.99246
99.20001,-9.91998,-28.04394
99.30000,-9.92998,-28.09617
99.40000,-9.94011,-28.14805
99.50001,-9.94998,-28.19735
99.60001,-9.96011,-28.24723
99.70001,-9.96984,-28.29597
99.80000,-9.97971,-28.34118
99.90000,-9.99024,-28.39366
100.00001,-9.99971,-28.44045
100.10001,-10.00984,-28.48710
100.20001,-10.02011,-28.54246
100.30000,-10.02971,-28.59093
100.40000,-10.04011,-28.64242
100.50001,-10.05011,-28.69329
100.60001,-10.05984,-28.73927
100.70001,-10.06998,-28.79107
100.80000,-10.07984,-28.83961
100.90000,-10.08998,-28.88815
101.00001,-10.09998,-28.93533
101.10001,-10.10998,-28.98353
101.20001,-10.11998,-29.03358
101.30000,-10.12971,-29.07855
101.40000,-10.13984,-29.12508
101.50001,-10.14984,-29.17497
101.60001,-10.15984,-29.22179
101.70001,-10.17011,-29.27619
101.80000,-10.17984,-29.32490
101.90000,-10.18998,-29.37295
102.00001,-10.20011,-29.42672
102.10001,-10.20971,-29.47320
102.20001,-10.22024,-29.52717
102.30000,-10.22997,-29.57792
102.40000,-10.23984,-29.62599
102.50001,-10.24998,-29.68036
102.60001,-10.25971,-29.73243
102.70001,-10.26984,-29.78496
102.80000,-10.27997,-29.83752
102.90000,-10.28998,-29.88812
103.00001,-10.29998,-29.93931
103.10001,-10.31011,-29.98972
103.20001,-10.32011,-30.04119
103.30000,-10.32997,-30.08938
103.40000,-10.34011,-30.13652
103.50001,-10.34997,-30.19035
103.60001,-10.35971,-30.23841
103.70001,-10.37024,-30.28981
103.80000,-10.37997,-30.34249
103.90000,-10.38971,-30.39142
104.00001,-10.39997,-30.44580
104.10001,-10.40971,-30.49648
104.20001,-10.41998,-30.54830
104.30000,-10.43024,-30.60364
104.40000,-10.43997,-30.65446
104.50001,-10.44997,-30.70703
104.60001,-10.46011,-30.75652
104.70001,-10.46997,-30.80679
104.80000,-10.48011,-30.85819
104.90000,-10.49011,-30.90610
105.00001,-10.49997,-30.95616
105.10001,-10.50971,-31.00313
105.20001,-10.52011,-31.05397
105.30000,-10.52984,-31.10468
105.40000,-10.53957,-31.15358
105.50001,-10.55011,-31.20930
105.60001,-10.55971,-31.26383
105.70001,-10.57011,-31.31776
105.80000,-10.58011,-31.37547
105.90000,-10.58971,-31.42754
106.00001,-10.60024,-31.48298
106.10001,-10.61011,-31.53720
106.20001,-10.61997,-31.58817
106.30000,-10.62997,-31.63889
106.40000,-10.63984,-31.68741
106.50001,-10.64984,-31.73737
106.60001,-10.65984,-31.78800
106.70001,-10.66984,-31.83630
106.80000,-10.67984,-31.89071
106.90000,-10.68971,-31.94085
107.00001,-10.70011,-31.99580
107.10001,-10.70984,-32.05231
107.20001,-10.71997,-32.10284
107.30000,-10.73024,-32.16242
107.40000,-10.73971,-32.21386
107.50001,-10.74997,-32.26812
107.60001,-10.76011,-32.32269
107.70001,-10.76957,-32.37127
107.80000,-10.77997,-32.42614
107.90000,-10.78984,-32.48041
108.00001,-10.79984,-32.53193
108.10001,-10.80997,-32.58740
108.20001,-10.81984,-32.64407
108.30000,-10.82997,-32.70124
108.40000,-10.84011,-32.75751
108.50001,-10.85011,-32.81288
108.60001,-10.85997,-32.86750
108.70001,-10.86997,-32.91911
108.80000,-10.88011,-32.97485
108.90000,-10.88971,-33.02687
109.00001,-10.90011,-33.08141
109.10001,-10.91011,-33.14196
109.20001,-10.91971,-33.19765
109.30000,-10.93011,-33.25355
109.40000,-10.93984,-33.30910
109.50001,-10.94984,-33.36303
109.60001,-10.96011,-33.42034
109.70001,-10.96984,-33.47516
109.80000,-10.97984,-33.52880
109.90000,-10.99011,-33.58451
110.00001,-11.00011,-33.63937
110.10001,-11.00997,-33.69714
110.20001,-11.01997,-33.75115
110.30000,-11.03011,-33.80861
110.40000,-11.03984,-33.86531
110.50001,-11.05011,-33.92263
110.60001,-11.05997,-33.98532
110.70001,-11.06957,-34.03861
110.80000,-11.08011,-34.09502
110.90000,-11.08997,-34.15375
111.00001,-11.09984,-34.20675
111.10001,-11.11011,-34.26490
111.20001,-11.11997,-34.32029
111.30000,-11.12997,-34.37353
111.40000,-11.14011,-34.43075
111.50001,-11.14984,-34.48755
111.60001,-11.15997,-34.54252
111.70001,-11.16997,-34.59698
111.80000,-11.17997,-34.65195
111.90000,-11.18984,-34.70880
112.00001,-11.19971,-34.76675
112.10001,-11.20984,-34.82679
112.20001,-11.21971,-34.88539
112.30000,-11.22997,-34.94204
112.40000,-11.23997,-35.00459
112.50001,-11.24971,-35.06086
112.60001,-11.26024,-35.11914
112.70001,-11.26984,-35.18201
112.80000,-11.27984,-35.23368
112.90001,-11.29011,-35.29454
113.00001,-11.29971,-35.35362
113.10001,-11.30984,-35.40654
113.20001,-11.31997,-35.46231
113.30000,-11.32984,-35.51793
113.40001,-11.33971,-35.57610
113.50001,-11.34997,-35.63713
113.60001,-11.35997,-35.69848
113.70001,-11.37011,-35.75776
113.80000,-11.38011,-35.81406
113.90001,-11.38997,-35.87656
114.00001,-11.39997,-35.93291
114.10001,-11.41011,-35.98869
114.20001,-11.42011,-36.05016
114.30000,-11.42984,-36.10620
114.40001,-11.44024,-36.16968
114.50001,-11.44997,-36.23211
114.60001,-11.45984,-36.28714
114.70001,-11.46997,-36.34953
114.80000,-11.47971,-36.40784
114.90001,-11.49011,-36.46916
115.00001,-11.50011,-36.53783
115.10001,-11.50997,-36.59744
115.20001,-11.52011,-36.65617
115.30000,-11.52997,-36.71544
115.40001,-11.54011,-36.77861
115.50001,-11.54997,-36.84048
115.60001,-11.56010,-36.90311
115.70001,-11.56984,-36.96665
115.80000,-11.57971,-37.02215
115.90001,-11.59011,-37.08511
116.00001,-11.59970,-37.14322
116.10001,-11.60997,-37.20111
116.20001,-11.61997,-37.26879
116.30000,-11.62971,-37.32783
116.40001,-11.64011,-37.38774
116.50001,-11.64997,-37.45100
116.60001,-11.65997,-37.51974
116.70001,-11.67011,-37.58321
116.80000,-11.67997,-37.64273
116.90001,-11.68997,-37.70033
117.00001,-11.69997,-37.76059
117.10001,-11.70984,-37.82011
117.20001,-11.71984,-37.89274
117.30000,-11.72984,-37.95646
117.40001,-11.73984,-38.01690
117.50001,-11.74984,-38.07965
117.60001,-11.75984,-38.14368
117.70001,-11.77024,-38.21250
117.80000,-11.77984,-38.27641
117.90001,-11.79010,-38.33756
118.00001,-11.79997,-38.40269
118.10001,-11.80970,-38.46150
118.20001,-11.82024,-38.53433
118.30000,-11.82984,-38.59844
118.40001,-11.83984,-38.65539
118.50001,-11.85010,-38.71811
118.60001,-11.85970,-38.78134
118.70001,-11.86984,-38.84672
118.80000,-11.87997,-38.91060
118.90001,-11.88984,-38.97251
119.00001,-11.89984,-39.04099
119.10001,-11.90997,-39.11033
119.20001,-11.92024,-39.17740
119.30000,-11.93010,-39.23901
119.40001,-11.94010,-39.29793
119.50001,-11.94997,-39.36372
119.60001,-11.95970,-39.42962
119.70001,-11.97010,-39.49699
119.80000,-11.97997,-39.56740
119.90001,-11.98970,-39.63066
120.00001,-11.99997,-39.69822
120.10001,-12.00970,-39.76270
120.20001,-12.01997,-39.82819
120.30000,-12.03010,-39.89713
120.40001,-12.03984,-39.96239
120.50001,-12.04997,-40.03252
120.60001,-12.06010,-40.09885
120.70001,-12.07010,-40.16463
120.80000,-12.07997,-40.23213
120.90001,-12.09010,-40.29723
121.00001,-12.09997,-40.36350
121.10001,-12.10984,-40.42638
121.20001,-12.12024,-40.49326
121.30000,-12.12984,-40.56033
121.40001,-12.13957,-40.62094
121.50001,-12.15010,-40.69302
121.60001,-12.15984,-40.75874
121.70001,-12.16997,-40.82319
121.80000,-12.17997,-40.89303
121.90001,-12.18970,-40.95842
122.00001,-12.20010,-41.02621
122.10001,-12.21010,-41.09767
122.20001,-12.21997,-41.16160
122.30000,-12.22984,-41.23034
122.40001,-12.23984,-41.29978
122.50001,-12.24984,-41.36794
122.60001,-12.25984,-41.43475
122.70001,-12.26984,-41.50405
122.80000,-12.27984,-41.57843
122.90001,-12.28970,-41.64785
123.00001,-12.30010,-41.71825
123.10001,-12.30984,-41.78809
123.20001,-12.31997,-41.85261
123.30000,-12.33024,-41.92540
123.40001,-12.33970,-41.99147
123.50001,-12.34997,-42.05699
123.60001,-12.36010,-42.12883
123.70001,-12.36970,-42.19616
123.80000,-12.37997,-42.27114
123.90001,-12.38997,-42.34912
124.00001,-12.39984,-42.41887
124.10001,-12.40984,-42.48900
124.20001,-12.41984,-42.55970
124.30000,-12.42997,-42.63217
124.40001,-12.44010,-42.70625
124.50001,-12.45010,-42.78202
124.60001,-12.45997,-42.85510
124.70001,-12.46997,-42.92549
124.80000,-12.48010,-42.99930
124.90001,-12.48984,-43.07232
125.00001,-12.50010,-43.14132
125.10001,-12.50997,-43.21999
125.20001,-12.51970,-43.29340
125.30000,-12.53010,-43.36658
125.40001,-12.53997,-43.44045
125.50001,-12.54984,-43.51171
125.60001,-12.56010,-43.59057
125.70001,-12.56984,-43.66693
125.80000,-12.57997,-43.74510
125.90001,-12.59024,-43.82570
126.00001,-12.59997,-43.89977
126.10001,-12.60997,-43.97622
126.20001,-12.62010,-44.04805
126.30000,-12.63010,-44.12353
126.40001,-12.63984,-44.19620
126.50001,-12.64997,-44.26546
126.60001,-12.65984,-44.34116
126.70001,-12.66970,-44.41322
126.80000,-12.68010,-44.48896
126.90001,-12.68997,-44.56832
127.00001,-12.69970,-44.64173
127.10001,-12.71010,-44.72178
127.20001,-12.71984,-44.79943
127.30000,-12.72984,-44.87287
127.40001,-12.74010,-44.95188
127.50001,-12.74984,-45.02943
127.60001,-12.75997,-45.10885
127.70001,-12.76997,-45.18595
127.80000,-12.77984,-45.25926
127.90001,-12.78984,-45.33955
128.00000,-12.79984,-45.41525
128.10001,-12.80984,-45.49724
128.20002,-12.81970,-45.57576
128.30000,-12.83010,-45.65278
128.40001,-12.83997,-45.73660
128.50000,-12.84984,-45.81431
128.60001,-12.86024,-45.89853
128.70002,-12.86983,-45.98193
128.80000,-12.87997,-46.05820
128.90001,-12.89010,-46.14561
129.00000,-12.89970,-46.23078
129.10001,-12.90997,-46.31052
129.20002,-12.92010,-46.39263
129.30000,-12.92984,-46.47266
129.40001,-12.93983,-46.55417
129.50000,-12.94984,-46.63577
129.60001,-12.95997,-46.71724
129.70002,-12.97010,-46.79921
129.80000,-12.97997,-46.88000
129.90001,-12.98997,-46.96305
130.00000,-12.99997,-47.04512
130.10001,-13.01023,-47.12665
130.20002,-13.01997,-47.20971
130.30000,-13.02984,-47.28353
130.40001,-13.04010,-47.37066
130.50000,-13.04983,-47.45468
130.60001,-13.05983,-47.53427
130.70002,-13.06997,-47.62268
130.80000,-13.07970,-47.70480
130.90001,-13.09010,-47.79400
131.00000,-13.09997,-47.88230
131.10000,-13.10997,-47.96348
131.20002,-13.12010,-48.04924
131.30000,-13.12997,-48.13404
131.40002,-13.14010,-48.22142
131.50000,-13.15010,-48.30782
131.60000,-13.16010,-48.38941
131.70002,-13.16983,-48.47553
131.80000,-13.17983,-48.56015
131.90002,-13.19010,-48.65527
132.00000,-13.19970,-48.74322
132.10000,-13.20997,-48.82797
132.20002,-13.21997,-48.92547
132.30000,-13.22970,-49.01023
132.40002,-13.24023,-49.10233
132.50000,-13.25010,-49.19499
132.60000,-13.25983,-49.27351
132.70002,-13.27010,-49.36426
132.80000,-13.27983,-49.45145
132.90002,-13.28997,-49.53666
133.00000,-13.29997,-49.62296
133.10000,-13.30983,-49.70738
133.20002,-13.31983,-49.79915
133.30000,-13.32970,-49.88442
133.40002,-13.33970,-49.97139
133.50000,-13.34970,-50.06148
133.60000,-13.35983,-50.14693
133.70002,-13.37010,-50.24473
133.80000,-13.37983,-50.33147
133.90002,-13.39010,-50.41872
134.00000,-13.40010,-50.51519
134.10000,-13.40970,-50.59994
134.20002,-13.42037,-50.69411
134.30000,-13.42997,-50.78822
134.40002,-13.43983,-50.87032
134.50000,-13.45010,-50.96524
134.60000,-13.45957,-51.05151
134.70002,-13.46983,-51.13896
134.80000,-13.47997,-51.23104
134.90002,-13.48997,-51.32792
135.00000,-13.49997,-51.42111
135.10000,-13.51010,-51.51269
135.20002,-13.52010,-51.60950
135.30000,-13.52997,-51.69972
135.40002,-13.54023,-51.79113
135.50000,-13.54997,-51.89369
135.60000,-13.55970,-51.98089
135.70002,-13.57010,-52.07269
135.80000,-13.57997,-52.17606
135.90002,-13.58983,-52.26573
136.00000,-13.59997,-52.36070
136.10000,-13.60970,-52.45202
136.15600,-13.61543,-52.50165