File: project1/data/Packing_Peanuts_Instron/Odd_Tests_raw.is_comp_RawData/Specimen_RawData_1.csv
Time,Extension,Load
(sec),(mm),(N)
0.00000,-0.00027,-0.02646
0.20000,-0.01253,-0.04205
0.40000,-0.03760,-0.05311
0.60000,-0.05973,-0.05593
0.80000,-0.07987,-0.07365
1.00000,-0.10013,-0.07617
1.20000,-0.12040,-0.08909
1.40000,-0.14000,-0.09849
1.60000,-0.16027,-0.10744
1.80000,-0.18040,-0.12592
2.00000,-0.20013,-0.13673
2.20000,-0.22013,-0.13904
2.40000,-0.24027,-0.14445
2.60000,-0.26027,-0.14595
2.80000,-0.28027,-0.15824
3.00000,-0.30040,-0.16963
3.20000,-0.32000,-0.17890
3.40000,-0.34013,-0.18507
3.60000,-0.36040,-0.19565
3.80000,-0.38040,-0.20725
4.00000,-0.40013,-0.22068
4.20000,-0.42000,-0.22864
4.40000,-0.44000,-0.24453
4.60000,-0.46000,-0.24641
4.80000,-0.48040,-0.27006
5.00000,-0.50013,-0.28288
5.20000,-0.52000,-0.29369
5.40000,-0.54040,-0.30953
5.60000,-0.56027,-0.31158
5.80000,-0.58000,-0.33024
6.00000,-0.60013,-0.33740
6.20000,-0.62040,-0.35205
6.40000,-0.64027,-0.36482
6.60000,-0.66040,-0.37163
6.80000,-0.68040,-0.38931
7.00000,-0.69986,-0.41897
7.20000,-0.72013,-0.43894
7.40000,-0.74040,-0.46400
7.60000,-0.76013,-0.47999
7.80000,-0.78040,-0.51534
8.00000,-0.80040,-0.54091
8.20000,-0.82013,-0.56602
8.40000,-0.84013,-0.58296
8.60000,-0.86040,-0.60923
8.80000,-0.88013,-0.64085
9.00000,-0.90026,-0.66027
9.20000,-0.92040,-0.69021
9.40000,-0.94026,-0.71740
9.60000,-0.96013,-0.74513
9.80000,-0.98000,-0.78080
10.00000,-1.00013,-0.81252
10.20000,-1.02026,-0.84547
10.40000,-1.04053,-0.87166
10.60000,-1.06013,-0.89890
10.80000,-1.08000,-0.93522
11.00000,-1.10026,-0.97016
11.20000,-1.12013,-0.99728
11.40000,-1.14013,-1.02326
11.60000,-1.16040,-1.05400
11.80000,-1.18026,-1.08938
12.00000,-1.20026,-1.12256
12.20000,-1.22026,-1.15267
12.40000,-1.24013,-1.17838
12.60000,-1.26000,-1.20730
12.80000,-1.28026,-1.24392
13.00000,-1.30040,-1.27485
13.20000,-1.32026,-1.30243
13.40000,-1.34040,-1.33136
13.60000,-1.36000,-1.35195
13.80000,-1.38000,-1.38985
14.00000,-1.40026,-1.42304
14.20000,-1.42040,-1.45084
14.40000,-1.44013,-1.48256
14.60000,-1.46026,-1.50293
14.80000,-1.48026,-1.53171
15.00000,-1.50026,-1.56618
15.20000,-1.52000,-1.59656
15.40000,-1.54013,-1.62382
15.60000,-1.56013,-1.64800
15.80000,-1.58040,-1.68638
16.00000,-1.60040,-1.70690
16.20000,-1.62013,-1.74092
16.40000,-1.63986,-1.76544
16.60000,-1.66026,-1.78630
16.80000,-1.68013,-1.81820
17.00000,-1.70040,-1.85286
17.20000,-1.72040,-1.87520
17.40000,-1.74000,-1.90253
17.60000,-1.76013,-1.92653
17.80000,-1.78026,-1.95988
18.00000,-1.80026,-1.98594
18.20000,-1.82026,-2.01390
18.40000,-1.84040,-2.04610
18.60000,-1.86026,-2.06384
18.80000,-1.88026,-2.09735
19.00000,-1.90040,-2.12316
19.20000,-1.92000,-2.15153
19.40000,-1.94000,-2.17406
19.60000,-1.96026,-2.19126
19.80000,-1.98040,-2.22130
20.00000,-2.00026,-2.25139
20.20000,-2.02000,-2.26986
20.40000,-2.04000,-2.29943
20.60000,-2.05999,-2.31644
20.80000,-2.08039,-2.34605
21.00000,-2.10026,-2.37725
21.20000,-2.12013,-2.39222
21.40000,-2.14039,-2.42226
21.60000,-2.16026,-2.44276
21.80000,-2.17999,-2.47102
22.00000,-2.19999,-2.49501
22.20000,-2.22039,-2.51974
22.40000,-2.24026,-2.53970
22.60000,-2.26039,-2.56148
22.80000,-2.28026,-2.59243
23.00000,-2.29986,-2.61422
23.20000,-2.32013,-2.63432
23.40000,-2.34026,-2.65547
23.60000,-2.36026,-2.66891
23.80000,-2.38039,-2.69527
24.00000,-2.40026,-2.72821
24.20000,-2.42026,-2.74166
24.40000,-2.44013,-2.76369
24.60000,-2.46039,-2.78367
24.80000,-2.48013,-2.81369
25.00000,-2.50026,-2.82812
25.20000,-2.52039,-2.85419
25.40000,-2.54039,-2.86720
25.60000,-2.56013,-2.88916
25.80000,-2.57999,-2.91435
26.00000,-2.59999,-2.93519
26.20000,-2.62026,-2.95138
26.40000,-2.64039,-2.97254
26.60000,-2.66026,-2.99077
26.80000,-2.67999,-3.01313
27.00000,-2.70039,-3.03017
27.20000,-2.72013,-3.04920
27.40000,-2.74013,-3.06252
27.60000,-2.76039,-3.07890
27.80000,-2.78039,-3.10611
28.00000,-2.80026,-3.12401
28.20000,-2.82039,-3.14630
28.40000,-2.84013,-3.16314
28.60000,-2.85986,-3.16551
28.80000,-2.88039,-3.19280
29.00000,-2.90039,-3.20961
29.20000,-2.92026,-3.23150
29.40000,-2.94039,-3.23808
29.60000,-2.96013,-3.25288
29.80000,-2.97999,-3.27148
30.00000,-3.00026,-3.29230
30.20000,-3.02039,-3.30347
30.40000,-3.04013,-3.32478
30.60000,-3.06013,-3.33142
30.80000,-3.08039,-3.35271
31.00000,-3.10013,-3.36611
31.20000,-3.12013,-3.38259
31.40000,-3.14013,-3.40336
31.60000,-3.16013,-3.41117
31.80000,-3.18026,-3.43045
32.00000,-3.20053,-3.44353
32.20000,-3.22013,-3.45375
32.40000,-3.23986,-3.47115
32.60000,-3.26026,-3.47813
32.80000,-3.28026,-3.49823
33.00000,-3.30026,-3.51954
33.20000,-3.32039,-3.52982
33.40000,-3.33999,-3.54425
33.60000,-3.36026,-3.54950
33.80000,-3.38026,-3.57241
34.00000,-3.40013,-3.58980
34.20000,-3.42012,-3.59826
34.40000,-3.44039,-3.61728
34.60000,-3.46039,-3.61841
34.80000,-3.48026,-3.63839
35.00000,-3.50039,-3.64749
35.20000,-3.51999,-3.66610
35.40000,-3.53999,-3.67695
35.60000,-3.56052,-3.68501
35.80000,-3.58039,-3.69929
36.00000,-3.60012,-3.71683
36.20000,-3.62012,-3.72820
36.40000,-3.64012,-3.74496
36.60000,-3.65999,-3.74686
36.80000,-3.68039,-3.76389
37.00000,-3.70026,-3.77316
37.20000,-3.72012,-3.78134
37.40000,-3.74039,-3.80230
37.60000,-3.76026,-3.80361
37.80000,-3.78012,-3.82728
38.00000,-3.79999,-3.83310
38.20000,-3.82039,-3.84742
38.40000,-3.84026,-3.85153
38.60000,-3.86039,-3.86180
38.80000,-3.88026,-3.88096
39.00000,-3.89986,-3.89407
39.20000,-3.92012,-3.89933
39.40000,-3.94039,-3.91121
39.60000,-3.96026,-3.91654
39.80000,-3.98026,-3.93427
40.00000,-4.00026,-3.94344
40.20000,-4.02012,-3.95349
40.40000,-4.04026,-3.97252
40.60000,-4.06026,-3.96948
40.80000,-4.08012,-3.99382
41.00000,-4.10026,-3.99715
41.20000,-4.12039,-4.00707
41.40000,-4.14039,-4.01874
41.60000,-4.15999,-4.02318
41.80000,-4.18012,-4.04105
42.00000,-4.20026,-4.04627
42.20000,-4.22026,-4.05424
42.40000,-4.24039,-4.07121
42.60000,-4.26012,-4.07395
42.80000,-4.27986,-4.08609
43.00000,-4.30039,-4.10089
43.20000,-4.32012,-4.10771
43.40000,-4.34026,-4.11467
43.60000,-4.36039,-4.12303
43.80000,-4.38026,-4.14164
44.00000,-4.40026,-4.14785
44.20000,-4.42039,-4.16326
44.40000,-4.43999,-4.17345
44.60000,-4.45986,-4.17021
44.80000,-4.48039,-4.19089
45.00000,-4.50026,-4.20064
45.20000,-4.52039,-4.21074
45.40000,-4.54026,-4.22228
45.60000,-4.55986,-4.22537
45.80000,-4.57999,-4.24304
46.00000,-4.60026,-4.25433
46.20000,-4.62039,-4.26531
46.40000,-4.64012,-4.27494
46.60000,-4.66026,-4.27276
46.80000,-4.68039,-4.29300
47.00000,-4.70026,-4.29887
47.20000,-4.71999,-4.30943
47.40000,-4.74012,-4.32550
47.60000,-4.76012,-4.32158
47.80000,-4.78039,-4.34329
48.00000,-4.80052,-4.35195
48.20000,-4.82012,-4.36030
48.40000,-4.83999,-4.37012
48.60000,-4.86025,-4.36956
48.80000,-4.88012,-4.38172
49.00000,-4.90025,-4.39973
49.20000,-4.92039,-4.40585
49.40000,-4.93999,-4.41640
49.60000,-4.96025,-4.41871
49.80000,-4.98025,-4.42930
50.00000,-5.00012,-4.43915
50.20000,-5.02012,-4.45361
50.40000,-5.04025,-4.46245
50.60000,-5.06025,-4.46425
50.80000,-5.08012,-4.47485
51.00000,-5.10039,-4.49344
51.20000,-5.11999,-4.49687
51.40000,-5.14025,-4.50342
51.60000,-5.16039,-4.51084
51.80000,-5.18039,-4.51733
52.00000,-5.20025,-4.52938
52.20000,-5.21999,-4.53572
52.40000,-5.24012,-4.54737
52.60000,-5.26012,-4.55180
52.80000,-5.28039,-4.56060
53.00000,-5.30025,-4.57745
53.20000,-5.31999,-4.58182
53.40000,-5.34025,-4.59267
53.60000,-5.36039,-4.59315
53.80000,-5.37999,-4.60950
54.00000,-5.40012,-4.61239
54.20000,-5.42052,-4.62758
54.40000,-5.44025,-4.63620
54.60000,-5.46039,-4.64307
54.80000,-5.48039,-4.65568
55.00000,-5.49999,-4.66230
55.20000,-5.52012,-4.66909
55.40000,-5.54039,-4.67764
55.60000,-5.56025,-4.68191
55.80000,-5.58039,-4.69469
56.00000,-5.60025,-4.70460
56.20000,-5.62012,-4.70695
56.40000,-5.64012,-4.71449
56.60000,-5.66039,-4.71953
56.80000,-5.67999,-4.74041
57.00000,-5.70025,-4.73901
57.20000,-5.72052,-4.75177
57.40000,-5.74025,-4.75776
57.60000,-5.75999,-4.76152
57.80000,-5.77999,-4.77824
58.00000,-5.79999,-4.78644
58.20000,-5.82025,-4.78703
58.40000,-5.84052,-4.80429
58.60000,-5.86025,-4.80240
58.80000,-5.87985,-4.81297
59.00000,-5.90025,-4.82214
59.20000,-5.92012,-4.83539
59.40000,-5.94025,-4.83712
59.60000,-5.96039,-4.84352
59.80000,-5.98025,-4.85505
60.00000,-6.00025,-4.86249
60.20000,-6.02039,-4.87825
60.40000,-6.04012,-4.88124
60.60000,-6.05985,-4.88334
60.80000,-6.08039,-4.90066
61.00000,-6.10038,-4.90120
61.20000,-6.12039,-4.91480
61.40000,-6.14038,-4.92097
61.60000,-6.15998,-4.92636
61.80000,-6.17999,-4.93541
62.00000,-6.20025,-4.94299
62.20000,-6.22038,-4.95170
62.40000,-6.24012,-4.96104
62.60000,-6.26012,-4.96536
62.80000,-6.28025,-4.97676
63.00000,-6.30012,-4.98224
63.20000,-6.31998,-4.99455
63.40000,-6.34012,-4.99772
63.60000,-6.36012,-4.99968
63.80000,-6.38038,-5.01532
64.00000,-6.40052,-5.02374
64.20000,-6.42012,-5.03225
64.40000,-6.43985,-5.03419
64.60001,-6.46025,-5.04000
64.80000,-6.48025,-5.05578
65.00000,-6.50025,-5.05646
65.20000,-6.52052,-5.06872
65.40000,-6.53998,-5.07001
65.60001,-6.56012,-5.07884
65.80000,-6.58038,-5.09099
66.00000,-6.60025,-5.10251
66.20001,-6.62012,-5.11165
66.40000,-6.64025,-5.10498
66.60001,-6.66025,-5.11999
66.80000,-6.68025,-5.13130
67.00000,-6.70038,-5.14073
67.20001,-6.71985,-5.15120
67.40000,-6.74012,-5.15286
67.60001,-6.76038,-5.15506
67.80000,-6.78038,-5.16217
68.00000,-6.80012,-5.17791
68.20001,-6.81998,-5.17988
68.40000,-6.84012,-5.18291
68.60001,-6.85998,-5.18909
68.80000,-6.88038,-5.19629
69.00000,-6.90025,-5.20405
69.20001,-6.92012,-5.16163
69.40000,-6.94038,-5.16676
69.60001,-6.96025,-5.17539
69.80000,-6.97998,-5.19343
70.00000,-6.99998,-5.20747
70.20001,-7.02038,-5.21239
70.40000,-7.04038,-5.22366
70.60001,-7.06038,-5.22373
70.80000,-7.08038,-5.23949
71.00000,-7.09998,-5.25106
71.20001,-7.12012,-5.25766
71.40000,-7.14038,-5.25751
71.60001,-7.16025,-5.26490
71.80000,-7.18025,-5.28095
72.00000,-7.20025,-5.29140
72.20001,-7.21998,-5.29459
72.40000,-7.24012,-5.29560
72.60001,-7.26038,-5.30516
72.80000,-7.28012,-5.31781
73.00000,-7.30025,-5.32527
73.20001,-7.32038,-5.33353
73.40000,-7.34025,-5.34458
73.60001,-7.35998,-5.34600
73.80000,-7.37998,-5.36117
74.00000,-7.40012,-5.36695
74.20001,-7.42025,-5.37391
74.40000,-7.44052,-5.37253
74.60001,-7.46012,-5.37812
74.80000,-7.47998,-5.39742
75.00000,-7.50051,-5.39269
75.20001,-7.52012,-5.41359
75.40000,-7.54025,-5.41056
75.60001,-7.56038,-5.41853
75.80000,-7.58025,-5.42521
76.00000,-7.60025,-5.43915
76.20001,-7.62038,-5.43712
76.40000,-7.63998,-5.45485
76.60001,-7.65985,-5.45005
76.80000,-7.68038,-5.46711
77.00000,-7.70038,-5.47334
77.20001,-7.72025,-5.47662
77.40000,-7.74025,-5.48591
77.60001,-7.75998,-5.49772
77.80000,-7.78011,-5.50903
78.00000,-7.80025,-5.50815
78.20001,-7.82038,-5.51088
78.40000,-7.84011,-5.51431
78.60001,-7.86025,-5.52171
78.80000,-7.88025,-5.53622
79.00000,-7.90011,-5.55141
79.20001,-7.92011,-5.55434
79.40000,-7.94011,-5.55391
79.60001,-7.96011,-5.55566
79.80000,-7.98038,-5.56260
80.00000,-8.00038,-5.57812
80.20001,-8.02011,-5.58299
80.40000,-8.03985,-5.58184
80.60001,-8.06025,-5.59511
80.80000,-8.08025,-5.60062
81.00001,-8.10051,-5.61040
81.20001,-8.12051,-5.61404
81.40000,-8.14011,-5.61452
81.60001,-8.16025,-5.62008
81.80000,-8.18025,-5.63518
82.00001,-8.20011,-5.64779
82.20001,-8.22011,-5.64509
82.40000,-8.24051,-5.65294
82.60001,-8.26038,-5.65568
82.80000,-8.28025,-5.67262
83.00001,-8.30038,-5.67567
83.20001,-8.31998,-5.68324
83.40000,-8.34011,-5.68712
83.60001,-8.36051,-5.69052
83.80000,-8.38025,-5.69730
84.00001,-8.40011,-5.70116
84.20001,-8.41998,-5.71300
84.40000,-8.44011,-5.71755
84.60001,-8.46011,-5.72074
84.80000,-8.48038,-5.74067
85.00001,-8.50025,-5.74341
85.20001,-8.51998,-5.74449
85.40000,-8.54038,-5.74170
85.60001,-8.56025,-5.75661
85.80000,-8.58011,-5.76406
86.00001,-8.60011,-5.76990
86.20001,-8.62025,-5.78130
86.40000,-8.64025,-5.78458
86.60001,-8.66051,-5.79038
86.80000,-8.68038,-5.80387
87.00001,-8.69985,-5.81070
87.20001,-8.72011,-5.81042
87.40000,-8.74038,-5.81704
87.60001,-8.76025,-5.81457
87.80000,-8.78038,-5.82670
88.00001,-8.80024,-5.83551
88.20001,-8.82011,-5.84478
88.40000,-8.84011,-5.85387
88.60001,-8.86038,-5.85199
88.80000,-8.88011,-5.87747
89.00001,-8.90011,-5.87884
89.20001,-8.92038,-5.88692
89.40000,-8.94025,-5.89370
89.60001,-8.96011,-5.89462
89.80000,-8.97998,-5.91638
90.00001,-8.99998,-5.91686
90.20001,-9.02024,-5.93367
90.40000,-9.04038,-5.93202
90.60001,-9.06025,-5.94268
90.80000,-9.07998,-5.95751
91.00001,-9.10038,-5.96007
91.20001,-9.11998,-5.97951
91.40000,-9.14024,-5.98475
91.60001,-9.16038,-5.98367
91.80000,-9.18011,-6.00216
92.00001,-9.20011,-6.01270
92.20001,-9.22038,-6.01997
92.40000,-9.24011,-6.03639
92.60001,-9.25998,-6.03584
92.80000,-9.28038,-6.05919
93.00001,-9.30024,-6.06686
93.20001,-9.32038,-6.07948
93.40000,-9.34051,-6.08909
93.60001,-9.35998,-6.08983
93.80000,-9.37998,-6.11071
94.00001,-9.40038,-6.11648
94.20001,-9.42051,-6.12730
94.40000,-9.44011,-6.14447
94.60001,-9.46024,-6.13836
94.80000,-9.48024,-6.15941
95.00001,-9.50024,-6.17540
95.20001,-9.52011,-6.18738
95.40000,-9.54011,-6.19081
95.60001,-9.56011,-6.19935
95.80000,-9.58038,-6.20952
96.00001,-9.60051,-6.22299
96.20001,-9.62011,-6.23820
96.40000,-9.63998,-6.24668
96.60001,-9.66038,-6.25252
96.80000,-9.68024,-6.27670
97.00001,-9.70024,-6.28193
97.20001,-9.72051,-6.28462
97.40000,-9.73998,-6.30450
97.60001,-9.76024,-6.30723
97.80000,-9.78024,-6.32667
98.00001,-9.80011,-6.34408
98.20001,-9.82011,-6.35178
98.40000,-9.84038,-6.36054
98.60001,-9.86024,-6.36602
98.80000,-9.88024,-6.38118
99.00001,-9.90038,-6.39605
99.20001,-9.91984,-6.40669
99.40000,-9.94011,-6.41648
99.60001,-9.96038,-6.42058
99.80000,-9.98038,-6.43919
100.00001,-10.00024,-6.45192
100.20001,-10.02011,-6.45608
100.40000,-10.04011,-6.46881
100.60001,-10.06011,-6.47569
100.80000,-10.08038,-6.49145
101.00001,-10.10024,-6.50405
101.20001,-10.11998,-6.51629
101.40000,-10.14038,-6.52124
101.60001,-10.16024,-6.52698
101.80000,-10.17998,-6.55737
102.00001,-10.19998,-6.56055
102.20001,-10.22037,-6.57076
102.40000,-10.24024,-6.59305
102.60001,-10.26038,-6.60396
102.80000,-10.28024,-6.62127
103.00001,-10.29984,-6.64650
103.20001,-10.32011,-6.65476
103.40000,-10.34037,-6.67367
103.60001,-10.36024,-6.69013
103.80000,-10.38024,-6.70334
104.00001,-10.40024,-6.71820
104.20001,-10.42011,-6.74453
104.40000,-10.44024,-6.75263
104.60001,-10.46037,-6.76323
104.80000,-10.48011,-6.80045
105.00001,-10.50024,-6.80727
105.20001,-10.52037,-6.82388
105.40000,-10.54024,-6.84543
105.60001,-10.55997,-6.85982
105.80000,-10.57997,-6.88901
106.00001,-10.60011,-6.90736
106.20001,-10.62024,-6.93460
106.40000,-10.64051,-6.95132
106.60001,-10.66024,-6.97477
106.80000,-10.67997,-7.00089
107.00001,-10.70024,-7.02201
107.20001,-10.72024,-7.05261
107.40000,-10.74037,-7.07422
107.60001,-10.76037,-7.09376
107.80000,-10.78024,-7.12228
108.00001,-10.80024,-7.14775
108.20001,-10.82037,-7.17683
108.40000,-10.84011,-7.20233
108.60001,-10.85997,-7.21781
108.80000,-10.88037,-7.25118
109.00001,-10.90037,-7.27670
109.20001,-10.92037,-7.30608
109.40000,-10.94024,-7.33359
109.60001,-10.95997,-7.35170
109.80000,-10.97997,-7.39197
110.00001,-11.00011,-7.41693
110.20001,-11.02051,-7.44673
110.40000,-11.04011,-7.47413
110.60001,-11.06024,-7.50352
110.80000,-11.08037,-7.53281
111.00001,-11.10011,-7.56576
111.20001,-11.12011,-7.60501
111.40000,-11.14011,-7.63903
111.60001,-11.16024,-7.65785
111.80000,-11.18024,-7.69776
112.00001,-11.20051,-7.73382
112.20001,-11.22011,-7.76896
112.40000,-11.23997,-7.79323
112.60001,-11.26024,-7.81934
112.80000,-11.28011,-7.86136
113.00001,-11.30037,-7.89323
113.20001,-11.32037,-7.92917
113.40001,-11.33997,-7.96357
113.60001,-11.36011,-7.99923
113.80000,-11.38024,-8.03102
114.00001,-11.40024,-8.06623
114.20001,-11.42011,-8.11416
114.40001,-11.44037,-8.14471
114.60001,-11.46037,-8.17386
114.80000,-11.48024,-8.21385
115.00001,-11.50037,-8.25125
115.20001,-11.51997,-8.29056
115.40001,-11.54011,-8.32876
115.60001,-11.56037,-8.35161
115.80000,-11.58037,-8.39271
116.00001,-11.60011,-8.43002
116.20001,-11.61997,-8.46213
116.40001,-11.64011,-8.50187
116.60001,-11.66010,-8.54017
116.80000,-11.68024,-8.56993
117.00001,-11.70024,-8.62099
117.20001,-11.71997,-8.65848
117.40001,-11.74024,-8.69323
117.60001,-11.76024,-8.72516
117.80000,-11.78010,-8.78212
118.00001,-11.80010,-8.80623
118.20001,-11.82050,-8.84744
118.40001,-11.84037,-8.87820
118.60001,-11.86037,-8.91176
118.80000,-11.88037,-8.94901
119.00001,-11.89997,-8.98116
119.20001,-11.92010,-9.01835
119.40001,-11.94037,-9.05776
119.60001,-11.96024,-9.09174
119.80000,-11.98024,-9.12942
120.00001,-12.00024,-9.16857
120.20001,-12.01997,-9.20695
120.40001,-12.04024,-9.23929
120.60001,-12.06050,-9.27462
120.80000,-12.08024,-9.31237
121.00001,-12.10024,-9.34201
121.20001,-12.12050,-9.39323
121.40001,-12.14024,-9.42286
121.60001,-12.16010,-9.45334
121.80000,-12.17997,-9.49497
122.00001,-12.19997,-9.53431
122.20001,-12.22024,-9.56937
122.40001,-12.24050,-9.59972
122.60001,-12.26024,-9.63720
122.80000,-12.27997,-9.67987
123.00001,-12.30024,-9.71666
123.20001,-12.32010,-9.75414
123.40001,-12.34010,-9.78234
123.60001,-12.36037,-9.81919
123.80000,-12.38037,-9.85868
124.00001,-12.40024,-9.89825
124.20001,-12.42024,-9.93374
124.40001,-12.44024,-9.97195
124.60001,-12.45997,-10.00144
124.80000,-12.48037,-10.03892
125.00001,-12.50037,-10.07142
125.20001,-12.52024,-10.11612
125.40001,-12.54024,-10.14938
125.60001,-12.56010,-10.17983
125.80000,-12.58010,-10.21645
126.00001,-12.60024,-10.25371
126.20001,-12.62037,-10.28707
126.40001,-12.64010,-10.32463
126.60001,-12.66010,-10.35404
126.80000,-12.68024,-10.38471
127.00001,-12.70010,-10.42708
127.20001,-12.72010,-10.45526
127.40001,-12.74024,-10.50014
127.60001,-12.76010,-10.52724
127.80000,-12.78024,-10.56828
128.00000,-12.80050,-10.60694
128.20002,-12.81997,-10.64734
128.40001,-12.83997,-10.66918
128.60001,-12.86024,-10.70249
128.80000,-12.88010,-10.73482
129.00000,-12.90024,-10.77122
129.20002,-12.92037,-10.80913
129.40001,-12.93997,-10.84191
129.60001,-12.96023,-10.87982
129.80000,-12.98037,-10.91410
130.00000,-13.00023,-10.94854
130.20002,-13.02010,-10.98110
130.40001,-13.04037,-11.01991
130.60001,-13.06037,-11.04386
130.80000,-13.08023,-11.08338
131.00000,-13.10037,-11.11919
131.20002,-13.11983,-11.16063
131.40002,-13.14010,-11.18284
131.60000,-13.16050,-11.21420
131.80000,-13.18037,-11.25077
132.00000,-13.20023,-11.29425
132.20002,-13.22010,-11.32690
132.40002,-13.24023,-11.35731
132.60000,-13.26010,-11.38093
132.80000,-13.28037,-11.42381
133.00000,-13.30023,-11.46705
133.20002,-13.31997,-11.49217
133.40002,-13.34023,-11.52324
133.60000,-13.36023,-11.55575
133.80000,-13.38010,-11.59120
134.00000,-13.40010,-11.62933
134.20002,-13.42023,-11.66043
134.40002,-13.44010,-11.69436
134.60000,-13.46037,-11.72682
134.80000,-13.48023,-11.75750
135.00000,-13.49983,-11.79348
135.20002,-13.52010,-11.83420
135.40002,-13.54037,-11.86472
135.60000,-13.56023,-11.89262
135.80000,-13.58037,-11.93034
136.00000,-13.60023,-11.96331
136.20002,-13.62010,-11.98969
136.40002,-13.64023,-12.02317
136.60000,-13.66037,-12.05826
136.80000,-13.68010,-12.09705
137.00000,-13.70023,-12.12607
137.20002,-13.72037,-12.15345
137.40002,-13.74023,-12.19113
137.60000,-13.76010,-12.21752
137.80000,-13.77997,-12.26669
138.00000,-13.79997,-12.30086
138.20002,-13.82023,-12.32499
138.40002,-13.84050,-12.36306
138.60000,-13.86023,-12.39395
138.80000,-13.87997,-12.42582
139.00000,-13.90037,-12.45850
139.20002,-13.91997,-12.49553
139.40002,-13.94010,-12.53103
139.60000,-13.96023,-12.56202
139.80000,-13.98037,-12.59696
140.00000,-14.00023,-12.63093
140.20002,-14.02037,-12.66716
140.40002,-14.04023,-12.70162
140.60000,-14.05997,-12.72750
140.80000,-14.08050,-12.76831
141.00000,-14.10037,-12.80586
141.20002,-14.12037,-12.83848
141.40002,-14.14037,-12.86932
141.60000,-14.15997,-12.89530
141.80000,-14.17997,-12.93721
142.00000,-14.20023,-12.98183
142.20002,-14.22037,-13.00832
142.40002,-14.24010,-13.04960
142.60000,-14.26023,-13.07536
142.80000,-14.28023,-13.11257
143.00000,-14.30010,-13.14965
143.20002,-14.31996,-13.18623
143.40002,-14.34010,-13.21677
143.60000,-14.36010,-13.24486
143.80000,-14.38036,-13.28439
144.00000,-14.40050,-13.31618
144.20002,-14.42010,-13.36499
144.40002,-14.43996,-13.38473
144.60000,-14.46036,-13.40790
144.80000,-14.48023,-13.45294
145.00000,-14.50036,-13.49012
145.20002,-14.52050,-13.52254
145.40002,-14.53996,-13.56088
145.60000,-14.56023,-13.59170
145.80000,-14.58023,-13.62789
146.00000,-14.60010,-13.66731
146.20002,-14.62010,-13.69865
146.40002,-14.64036,-13.73498
146.60000,-14.66023,-13.76958
146.80000,-14.68010,-13.80027
147.00000,-14.70036,-13.83832
147.20002,-14.71983,-13.87624
147.40002,-14.74010,-13.90513
147.60000,-14.76036,-13.93720
147.80000,-14.78036,-13.96911
148.00000,-14.80036,-14.00255
148.20002,-14.81996,-14.03884
148.40002,-14.84010,-14.07267
148.60000,-14.86010,-14.10797
148.80000,-14.88036,-14.13803
149.00000,-14.90023,-14.17931
149.20002,-14.92010,-14.21530
149.40002,-14.94036,-14.24732
149.60000,-14.96023,-14.27672
149.80000,-14.98010,-14.32507
150.00000,-15.00023,-14.35059
150.20002,-15.02050,-14.38951
150.40002,-15.04023,-14.42157
150.60000,-15.06050,-14.45993
150.80000,-15.08023,-14.49522
151.00000,-15.09996,-14.52703
151.20002,-15.12023,-14.56287
151.40002,-15.14023,-14.59823
151.60000,-15.16023,-14.63047
151.80000,-15.18050,-14.66681
152.00000,-15.20023,-14.70571
152.20002,-15.22010,-14.73429
152.40002,-15.24010,-14.77261
152.60000,-15.26036,-14.80396
152.80000,-15.28010,-14.84198
153.00000,-15.30010,-14.87448
153.20002,-15.32036,-14.90923
153.40002,-15.34023,-14.93720
153.60000,-15.36010,-14.95716
153.80000,-15.38010,-14.99152
154.00000,-15.40010,-15.01350
154.20002,-15.42023,-15.04020
154.40002,-15.44050,-15.06963
154.60000,-15.46023,-15.09222
154.80000,-15.47983,-15.12584
155.00000,-15.50036,-15.15968
155.20002,-15.52010,-15.19409
155.40002,-15.54023,-15.22918
155.60000,-15.56036,-15.26279
155.80000,-15.58036,-15.30400
156.00000,-15.60023,-15.34300
156.20002,-15.62036,-15.37888
156.40002,-15.64023,-15.41837
156.60000,-15.65996,-15.45117
156.80000,-15.68023,-15.49087
157.00000,-15.70049,-15.52365
157.20002,-15.72023,-15.56488
157.40002,-15.74023,-15.59514
157.60000,-15.75996,-15.62751
157.80000,-15.78010,-15.67137
158.00000,-15.80023,-15.71166
158.20002,-15.82036,-15.74486
158.40002,-15.84009,-15.78339
158.60000,-15.86023,-15.81521
158.80000,-15.88023,-15.85391
159.00000,-15.90009,-15.88879
159.20002,-15.92010,-15.93732
159.40002,-15.93996,-15.97330
159.60000,-15.96010,-16.00206
159.80000,-15.98036,-16.04345
160.00000,-16.00036,-16.07831
160.20002,-16.01996,-16.12567
160.40002,-16.04009,-16.16183
160.60000,-16.06036,-16.18922
160.80000,-16.08009,-16.22916
161.00002,-16.10023,-16.27277
161.20002,-16.12050,-16.31326
161.40002,-16.13996,-16.34420
161.60000,-16.16010,-16.38450
161.80000,-16.18036,-16.41952
162.00002,-16.20023,-16.46176
162.20002,-16.22023,-16.50254
162.40002,-16.24023,-16.53546
162.60000,-16.26036,-16.56860
162.80000,-16.28023,-16.60942
163.00002,-16.30023,-16.64977
163.20002,-16.31996,-16.69533
163.40002,-16.34009,-16.72431
163.60000,-16.36023,-16.75956
163.80000,-16.38036,-16.80157
164.00002,-16.40009,-16.84554
164.20002,-16.41996,-16.87072
164.40002,-16.44009,-16.90705
164.60000,-16.46009,-16.94271
164.80000,-16.48036,-16.98700
165.00002,-16.50023,-17.03002
165.20002,-16.51996,-17.06273
165.40002,-16.54023,-17.10460
165.60000,-16.56036,-17.14092
165.80000,-16.57996,-17.18500
166.00002,-16.60009,-17.22364
166.20002,-16.62036,-17.26469
166.40002,-16.64023,-17.29863
166.60000,-16.66023,-17.33993
166.80000,-16.68036,-17.37809
167.00002,-16.69996,-17.42282
167.20002,-16.72009,-17.45746
167.40002,-16.74036,-17.49238
167.60000,-16.76023,-17.53154
167.80000,-16.78023,-17.57774
168.00002,-16.80023,-17.62035
168.20002,-16.82009,-17.66047
168.40002,-16.84009,-17.69683
168.60000,-16.86036,-17.73641
168.80000,-16.87996,-17.78250
169.00002,-16.90023,-17.81870
169.20002,-16.92049,-17.85380
169.40002,-16.94022,-17.88414
169.60000,-16.96009,-17.91691
169.80000,-16.97996,-17.95438
170.00002,-17.00009,-17.99735
170.20002,-17.02023,-18.02131
170.40002,-17.04049,-18.06157
170.60000,-17.06023,-18.08279
170.80000,-17.07996,-18.13393
171.00002,-17.10036,-18.18047
171.20002,-17.12009,-18.21844
171.40002,-17.14022,-18.25955
171.60000,-17.16023,-18.29848
171.80000,-17.18022,-18.34622
172.00002,-17.20022,-18.38386
172.20002,-17.22036,-18.42530
172.40002,-17.24009,-18.46246
172.60000,-17.25996,-18.50381
172.80000,-17.28022,-18.54855
173.00002,-17.30049,-18.58902
173.20002,-17.32023,-18.63386
173.40002,-17.34022,-18.68003
173.60000,-17.36023,-18.71430
173.80000,-17.37996,-18.77023
174.00002,-17.40036,-18.81384
174.20002,-17.42063,-18.85726
174.40002,-17.44009,-18.90024
174.60000,-17.46009,-18.92767
174.80000,-17.48036,-18.97665
175.00002,-17.50022,-19.01783
175.20002,-17.51996,-19.06085
175.40002,-17.54022,-19.10758
175.60000,-17.56022,-19.12654
175.80000,-17.58022,-19.18480
176.00002,-17.60049,-19.22370
176.20002,-17.62009,-19.27167
176.40002,-17.63996,-19.31044
176.60000,-17.66036,-19.34849
176.80000,-17.68022,-19.39417
177.00002,-17.70036,-19.44565
177.20002,-17.72049,-19.47744
177.40002,-17.73996,-19.51846
177.60000,-17.76022,-19.55515
177.80000,-17.78036,-19.59385
178.00002,-17.80022,-19.65268
178.20002,-17.82009,-19.69329
178.40002,-17.84036,-19.74315
178.60000,-17.86036,-19.77555
178.80000,-17.88022,-19.82411
179.00002,-17.90036,-19.86260
179.20002,-17.91996,-19.91802
179.40002,-17.94009,-19.95461
179.60000,-17.96036,-19.99518
179.80000,-17.98036,-20.03150
180.00002,-18.00022,-20.10478
180.20002,-18.02009,-20.14050
180.40002,-18.04009,-20.18076
180.60000,-18.06009,-20.21873
180.80000,-18.08036,-20.26419
181.00002,-18.10022,-20.29902
181.20002,-18.11996,-20.34517
181.40002,-18.14036,-20.38582
181.60000,-18.16022,-20.42649
181.80000,-18.17996,-20.48821
182.00002,-18.20009,-20.52362
182.20002,-18.22049,-20.57146
182.40002,-18.24022,-20.61335
182.60000,-18.26049,-20.65824
182.80000,-18.28036,-20.71854
183.00002,-18.29996,-20.76232
183.20002,-18.32009,-20.80755
183.40002,-18.34035,-20.85411
183.60000,-18.36022,-20.89477
183.80000,-18.38022,-20.94046
184.00002,-18.40022,-20.98967
184.20002,-18.42009,-21.03529
184.40002,-18.44009,-21.08246
184.60000,-18.46036,-21.12942
184.80000,-18.48022,-21.18041
185.00002,-18.50022,-21.22881
185.20002,-18.52049,-21.26797
185.40002,-18.54022,-21.32333
185.60000,-18.56009,-21.35518
185.80000,-18.57995,-21.42880
186.00002,-18.59996,-21.46422
186.20002,-18.62022,-21.50938
186.40002,-18.64035,-21.55669
186.60000,-18.66022,-21.59344
186.80000,-18.67995,-21.65835
187.00002,-18.70022,-21.69696
187.20002,-18.71995,-21.75044
187.40002,-18.74022,-21.78713
187.60000,-18.76036,-21.83445
187.80000,-18.78035,-21.89172
188.00002,-18.80022,-21.93413
188.20002,-18.82035,-21.98913
188.40002,-18.84009,-22.02861
188.60000,-18.85995,-22.06943
188.80000,-18.88035,-22.12518
189.00002,-18.90035,-22.16868
189.20002,-18.92022,-22.21597
189.40002,-18.94022,-22.27104
189.60000,-18.95995,-22.29899
189.80000,-18.98009,-22.36011
190.00002,-18.99995,-22.40640
190.20002,-19.02035,-22.45343
190.40002,-19.04009,-22.50331
190.60000,-19.06022,-22.54531
190.80000,-19.08035,-22.59716
191.00002,-19.10022,-22.64122
191.20002,-19.12009,-22.69380
191.40002,-19.14009,-22.74760
191.60000,-19.16009,-22.78469
191.80000,-19.18035,-22.84040
192.00002,-19.20035,-22.88914
192.20002,-19.22009,-22.94926
192.40002,-19.24009,-22.99675
192.60000,-19.26022,-23.03145
192.80000,-19.28022,-23.09250
193.00002,-19.30035,-23.13857
193.20002,-19.32035,-23.19000
193.40002,-19.33995,-23.24213
193.60000,-19.36022,-23.29385
193.80000,-19.38022,-23.34789
194.00002,-19.40022,-23.40000
194.20002,-19.42022,-23.45018
194.40002,-19.44049,-23.49854
194.60000,-19.46022,-23.54394
194.80000,-19.48022,-23.59909
195.00002,-19.50035,-23.64925
195.20002,-19.51995,-23.69972
195.40002,-19.54009,-23.75111
195.60000,-19.56035,-23.80088
195.80000,-19.58035,-23.85421
196.00002,-19.60022,-23.90221
196.20002,-19.62009,-23.95803
196.40002,-19.64009,-24.00900
196.60000,-19.66009,-24.05351
196.80000,-19.68035,-24.11942
197.00002,-19.70022,-24.17012
197.20002,-19.72008,-24.21808
197.40002,-19.74035,-24.27293
197.60000,-19.76022,-24.32196
197.80000,-19.77995,-24.38199
198.00002,-19.80022,-24.43679
198.20002,-19.82035,-24.48808
198.40002,-19.84022,-24.54194
198.60000,-19.86035,-24.59145
198.80000,-19.88022,-24.65054
199.00002,-19.89982,-24.70545
199.20002,-19.92008,-24.75569
199.40002,-19.94035,-24.81072
199.60000,-19.96022,-24.86509
199.80000,-19.98022,-24.92635
200.00002,-20.00022,-24.97277
200.20002,-20.02008,-25.02585
200.40002,-20.04022,-25.08328
200.60000,-20.06049,-25.13361
200.80000,-20.08022,-25.18282
201.00002,-20.10022,-25.24190
201.20002,-20.12035,-25.29304
201.40002,-20.14022,-25.33445
201.60000,-20.16008,-25.38173
201.80000,-20.17995,-25.42351
202.00002,-20.19995,-25.47355
202.20002,-20.22022,-25.52004
202.40002,-20.24048,-25.57680
202.60000,-20.26022,-25.61489
202.80000,-20.27982,-25.66661
203.00002,-20.30035,-25.71870
203.20002,-20.32008,-25.76661
203.40002,-20.34022,-25.82058
203.60000,-20.36035,-25.87867
203.80000,-20.38022,-25.91999
204.00002,-20.40022,-25.97186
204.20002,-20.42035,-26.02613
204.40002,-20.44008,-26.07887
204.60000,-20.45995,-26.12889
204.80000,-20.48035,-26.19117
205.00002,-20.50022,-26.23418
205.20002,-20.52022,-26.29340
205.40002,-20.54035,-26.35402
205.60000,-20.56008,-26.40616
205.80000,-20.58008,-26.46439
206.00002,-20.60035,-26.51768
206.20002,-20.62035,-26.56846
206.40002,-20.64008,-26.63277
206.60000,-20.66022,-26.68677
206.80000,-20.68035,-26.74026
207.00002,-20.70022,-26.79468
207.20002,-20.72008,-26.84564
207.40002,-20.74008,-26.90746
207.60000,-20.76022,-26.96132
207.80000,-20.78035,-27.01722
208.00002,-20.80035,-27.07759
208.20002,-20.82008,-27.12793
208.40002,-20.83982,-27.18775
208.60000,-20.86035,-27.24561
208.80000,-20.88035,-27.31029
209.00002,-20.90022,-27.36882
209.20002,-20.92035,-27.43144
209.40002,-20.93995,-27.47712
209.60000,-20.96022,-27.54676
209.80000,-20.98022,-27.60081
210.00002,-21.00022,-27.65886
210.20002,-21.02008,-27.71597
210.40002,-21.04035,-27.78119
210.60000,-21.06035,-27.84560
210.80000,-21.08008,-27.89819
211.00002,-21.10048,-27.95932
211.20002,-21.11995,-28.02017
211.40002,-21.14008,-28.07994
211.60000,-21.16048,-28.13756
211.80000,-21.18035,-28.19746
212.00002,-21.20022,-28.25526
212.20002,-21.22008,-28.32201
212.40002,-21.24008,-28.38917
212.60000,-21.26008,-28.44126
212.80000,-21.28021,-28.51160
213.00002,-21.30008,-28.57135
213.20002,-21.31995,-28.63351
213.40002,-21.34048,-28.68995
213.60000,-21.36021,-28.75771
213.80000,-21.37995,-28.81781
214.00002,-21.40022,-28.87975
214.20002,-21.42048,-28.94925
214.40002,-21.44022,-29.01795
214.60000,-21.46048,-29.08163
214.80000,-21.48035,-29.13831
215.00002,-21.49995,-29.20090
215.20002,-21.52008,-29.26574
215.40002,-21.54035,-29.33675
215.60000,-21.56021,-29.39795
215.80000,-21.58021,-29.46114
216.00002,-21.60021,-29.53006
216.20002,-21.62008,-29.58889
216.40002,-21.64008,-29.65289
216.60000,-21.66035,-29.71987
216.80000,-21.67995,-29.77937
217.00002,-21.70021,-29.84704
217.20002,-21.72035,-29.91613
217.40002,-21.74021,-29.98227
217.60000,-21.76008,-30.04072
217.80000,-21.78008,-30.10887
218.00002,-21.79995,-30.18054
218.20002,-21.82021,-30.24948
218.40002,-21.84048,-30.31827
218.60000,-21.86021,-30.37762
218.80000,-21.87995,-30.45032
219.00002,-21.90021,-30.51148
219.20002,-21.92008,-30.58278
219.40002,-21.94021,-30.65388
219.60000,-21.96021,-30.71961
219.80000,-21.98021,-30.79191
220.00002,-22.00021,-30.85954
220.20002,-22.02035,-30.94243
220.40002,-22.04021,-31.00128
220.60000,-22.05981,-31.06757
220.80000,-22.08035,-31.14574
221.00002,-22.10035,-31.21467
221.20002,-22.12021,-31.28171
221.40002,-22.14035,-31.36029
221.60000,-22.16008,-31.41975
221.80000,-22.17995,-31.49886
222.00002,-22.20021,-31.56688
222.20002,-22.22048,-31.64009
222.40002,-22.24008,-31.71127
222.60000,-22.26021,-31.78375
222.80000,-22.28021,-31.85352
223.00002,-22.30008,-31.91882
223.20002,-22.32008,-31.98674
223.40002,-22.34008,-32.06794
223.60000,-22.36008,-32.14183
223.80000,-22.38035,-32.21915
224.00002,-22.40048,-32.28774
224.20002,-22.42008,-32.36607
224.40002,-22.43995,-32.43859
224.60000,-22.46021,-32.51845
224.80000,-22.48021,-32.58919
225.00002,-22.50021,-32.66412
225.20002,-22.52048,-32.74154
225.40002,-22.54008,-32.81103
225.60000,-22.56021,-32.89308
225.80002,-22.58021,-32.96783
226.00002,-22.60021,-33.04117
226.20002,-22.62008,-33.11368
226.40002,-22.64021,-33.19558
226.60000,-22.66034,-33.27705
226.80002,-22.68021,-33.35283
227.00002,-22.70035,-33.42180
227.20002,-22.71994,-33.49865
227.40002,-22.74008,-33.58579
227.60000,-22.76034,-33.65720
227.80002,-22.78034,-33.62269
228.00002,-22.80021,-33.68755
228.20002,-22.81994,-33.76910
228.40002,-22.84008,-33.84912
228.60000,-22.86008,-33.92124
228.80002,-22.88034,-34.00449
229.00002,-22.90021,-34.08358
229.20002,-22.92008,-34.16039
229.40002,-22.94034,-34.23521
229.60000,-22.96034,-34.32072
229.80002,-22.97994,-34.40411
230.00002,-23.00008,-34.48372
230.20002,-23.02034,-34.56331
230.40002,-23.04034,-34.64668
230.60000,-23.06034,-34.72671
230.80002,-23.08034,-34.81007
231.00002,-23.09994,-34.88567
231.20002,-23.12008,-34.96255
231.40002,-23.14034,-35.05509
231.60000,-23.16021,-35.12442
231.80002,-23.18034,-35.20749
232.00002,-23.20034,-35.28650
232.20002,-23.22008,-35.36335
232.40002,-23.24021,-35.45419
232.60000,-23.26048,-35.53474
232.80002,-23.28008,-35.60186
233.00002,-23.30008,-35.69315
233.20002,-23.32048,-35.77814
233.40002,-23.34034,-35.85620
233.60000,-23.36008,-35.92608
233.80002,-23.38008,-36.00409
234.00002,-23.40008,-36.08812
234.20002,-23.42021,-36.16942
234.40002,-23.44048,-36.26007
234.60000,-23.46021,-36.33117
234.80002,-23.47994,-36.42270
235.00002,-23.50034,-36.51537
235.20002,-23.52008,-36.59260
235.40002,-23.54021,-36.68378
235.60000,-23.56034,-36.77083
235.80002,-23.58021,-36.85196
236.00002,-23.60021,-36.93956
236.20002,-23.62048,-37.02832
236.40002,-23.64021,-37.10900
236.60000,-23.65994,-37.19408
236.80002,-23.68034,-37.29264
237.00002,-23.70034,-37.37425
237.20002,-23.72034,-37.46644
237.40002,-23.74034,-37.55568
237.60000,-23.76007,-37.63833
237.80002,-23.77994,-37.72785
238.00002,-23.80021,-37.81943
238.20002,-23.82034,-37.91008
238.40002,-23.84008,-37.99161
238.60000,-23.86021,-38.07689
238.80002,-23.88034,-38.16929
239.00002,-23.90007,-38.25111
239.20002,-23.92008,-38.34119
239.40002,-23.94008,-38.42657
239.60000,-23.96007,-38.51525
239.80002,-23.98021,-38.60564
240.00002,-24.00061,-38.70004
240.20002,-24.02007,-38.78742
240.40002,-24.03994,-38.87548
240.60000,-24.06021,-38.97001
240.80002,-24.08021,-39.06023
241.00002,-24.10021,-39.15685
241.20002,-24.12047,-39.25289
241.40002,-24.13994,-39.33606
241.60000,-24.16007,-39.44064
241.80002,-24.18034,-39.53082
242.00002,-24.20007,-39.62637
242.20002,-24.22021,-39.72365
242.40002,-24.24034,-39.82433
242.60000,-24.26034,-39.92109
242.80002,-24.28021,-40.01820
243.00002,-24.30034,-40.11171
243.20002,-24.31994,-40.20260
243.40002,-24.34007,-40.29978
243.60000,-24.36034,-40.40025
243.80002,-24.38034,-40.50594
244.00002,-24.40021,-40.59724
244.20002,-24.42007,-40.69356
244.40002,-24.43994,-40.79368
244.60000,-24.46007,-40.90916
244.80002,-24.48034,-40.99958
245.00002,-24.50021,-41.09256
245.20002,-24.52007,-41.19755
245.40002,-24.54034,-41.30056
245.60000,-24.56021,-41.40546
245.80002,-24.57994,-41.49344
246.00002,-24.60007,-41.60528
246.20002,-24.62034,-41.70506
246.40002,-24.64021,-41.82633
246.60000,-24.66034,-41.93054
246.80002,-24.68021,-42.02897
247.00002,-24.69981,-42.12001
247.20002,-24.72007,-42.22512
247.40002,-24.74034,-42.33586
247.60000,-24.76021,-42.43665
247.80002,-24.78034,-42.54668
248.00002,-24.80034,-42.65322
248.20002,-24.82007,-42.75618
248.40002,-24.84021,-42.85404
248.60000,-24.86034,-42.96378
248.80002,-24.88007,-43.01753
249.00002,-24.90021,-43.11923
249.20002,-24.92047,-43.22779
249.40002,-24.94021,-43.33132
249.60000,-24.96007,-43.43638
249.80002,-24.97994,-43.54252
250.00002,-25.00007,-43.64905
250.20002,-25.02021,-43.76157
250.40002,-25.04047,-43.87273
250.60000,-25.06007,-43.96757
250.80002,-25.07994,-44.08772
251.00002,-25.10034,-44.09301
251.20002,-25.11994,-43.99822
251.40002,-25.14034,-44.03064
251.60000,-25.16047,-44.10554
251.80002,-25.18034,-44.20507
252.00002,-25.20020,-44.31286
252.20002,-25.22034,-44.42640
252.40002,-25.24007,-44.53267
252.60000,-25.25994,-44.64759
252.80002,-25.28034,-44.78512
253.00002,-25.30034,-44.89537
253.20002,-25.32034,-45.01945
253.40002,-25.34047,-45.12883
253.60000,-25.36007,-45.24628
253.80002,-25.38007,-45.36267
254.00002,-25.40034,-45.07600
254.20002,-25.42034,-44.94760
254.40002,-25.44007,-44.93877
254.60000,-25.46020,-43.96588
254.80002,-25.48034,-44.03032
255.00002,-25.50034,-44.14812
255.20002,-25.52007,-44.27907
255.40002,-25.54007,-44.40486
255.60000,-25.56007,-44.56279
255.80002,-25.58034,-44.70816
256.00000,-25.60034,-44.85026
256.20002,-25.62007,-44.98773
256.40003,-25.63994,-45.14154
256.60000,-25.66034,-45.28654
256.80002,-25.68020,-45.42478
257.00000,-25.70034,-45.57234
257.20002,-25.72047,-45.72659
257.40003,-25.74007,-45.87245
257.60000,-25.76020,-46.01470
257.80002,-25.78020,-46.15837
258.00000,-25.80020,-46.30578
258.20002,-25.82007,-46.45383
258.40003,-25.84034,-46.60938
258.60000,-25.86047,-46.75050
258.80002,-25.88020,-46.88277
259.00000,-25.90034,-47.02562
259.20002,-25.92007,-47.17230
259.40003,-25.94007,-47.31556
259.60000,-25.96034,-47.45709
259.80002,-25.98034,-47.59574
260.00000,-26.00020,-47.73749
260.20002,-26.02007,-47.87726
260.40003,-26.04007,-48.02429
260.60000,-26.06007,-48.16630
260.80002,-26.08034,-48.30629
261.00000,-26.10020,-48.46075
261.20002,-26.12020,-48.59509
261.40003,-26.14034,-48.74132
261.60000,-26.16020,-48.88290
261.80002,-26.18007,-49.02033
262.00000,-26.20020,-49.15372
262.20000,-26.22034,-49.30303
262.40003,-26.24034,-49.44206
262.60000,-26.26047,-49.58756
262.80003,-26.28034,-49.72868
263.00000,-26.29994,-49.86376
263.20000,-26.32007,-50.00193
263.40003,-26.34034,-48.82139
263.60000,-26.36033,-48.94488
263.80003,-26.38034,-49.09923
264.00000,-26.40034,-49.24101
264.20000,-26.42020,-49.39925
264.40003,-26.44020,-49.55022
264.60000,-26.46033,-49.68978
264.80003,-26.48007,-49.84365
265.00000,-26.50033,-50.00010
265.20000,-26.52034,-50.15693
265.40003,-26.54034,-50.30379
265.60000,-26.56020,-50.46427
265.80003,-26.57994,-50.61411
266.00000,-26.60007,-50.76022
266.20000,-26.62007,-50.91795
266.40003,-26.64047,-51.07953
266.60000,-26.66020,-51.24031
266.80003,-26.67993,-51.39200
267.00000,-26.70047,-51.55713
267.20000,-26.72007,-51.70564
267.40003,-26.74020,-51.85007
267.60000,-26.76033,-52.01478
267.80003,-26.78034,-52.17141
268.00000,-26.80033,-52.32368
268.20000,-26.82033,-52.48736
268.40003,-26.84020,-52.64165
268.60000,-26.85994,-52.78755
268.80003,-26.88034,-52.95319
269.00000,-26.90047,-53.11197
269.20000,-26.92020,-53.28099
269.40003,-26.94047,-53.43462
269.60000,-26.96007,-53.59152
269.80003,-26.97993,-53.75822
270.00000,-27.00033,-53.91412
270.20000,-27.02047,-54.07126
270.40003,-27.04020,-54.21976
270.60000,-27.06020,-54.37892
270.80003,-27.08033,-54.53766
271.00000,-27.10020,-54.69502
271.20000,-27.12007,-54.86064
271.40003,-27.14007,-55.02395
271.60000,-27.16007,-55.18634
271.80003,-27.18033,-55.34219
272.00000,-27.20047,-55.51431
272.20000,-27.22007,-55.67139
272.40003,-27.24007,-55.83288
272.60000,-27.26033,-56.00009
272.80003,-27.28007,-56.15969
273.00000,-27.30033,-56.32189
273.20000,-27.32020,-56.47870
273.40003,-27.33993,-56.62961
273.60000,-27.36020,-56.75656
273.80003,-27.38033,-56.88551
274.00000,-27.40020,-57.01509
274.20000,-27.42007,-57.13977
274.40003,-27.44047,-57.27655
274.60000,-27.46047,-57.41689
274.80003,-27.48020,-57.57149
275.00000,-27.50047,-57.72636
275.20000,-27.51993,-57.89448
275.40003,-27.54007,-58.06735
275.60000,-27.56047,-58.24690
275.80003,-27.58047,-58.41519
276.00000,-27.60020,-58.59848
276.20000,-27.62007,-58.77985
276.40003,-27.64007,-58.95728
276.60000,-27.66007,-59.13506
276.80003,-27.68033,-59.30902
277.00000,-27.70020,-59.49381
277.20000,-27.72007,-59.66387
277.40003,-27.74033,-59.84720
277.60000,-27.76033,-60.02786
277.80003,-27.78007,-60.20976
278.00000,-27.80020,-60.39313
278.20000,-27.82047,-60.59378
278.40003,-27.84020,-60.77126
278.60000,-27.86046,-60.96850
278.80003,-27.88033,-61.14259
279.00000,-27.89993,-61.34506
279.20000,-27.92020,-61.53708
279.40003,-27.94033,-61.73186
279.60000,-27.96033,-61.92216
279.80003,-27.98033,-62.10762
280.00000,-28.00033,-62.30223
280.20000,-28.02020,-62.49606
280.40003,-28.04020,-62.69673
280.60000,-28.06033,-62.88682
280.80003,-28.07993,-63.06349
281.00000,-28.10020,-63.26374
281.20000,-28.12047,-63.46282
281.40003,-28.14033,-63.65784
281.60000,-28.16007,-63.70579
281.80003,-28.17993,-63.73572
282.00000,-28.20006,-63.93909
282.20000,-28.22020,-64.14615
282.40003,-28.24046,-64.27655
282.60000,-28.26020,-64.47298
282.80003,-28.27993,-64.68776
283.00000,-28.30033,-64.90567
283.20000,-28.32006,-65.11142
283.40003,-28.34020,-65.32683
283.60000,-28.36020,-65.53534
283.80003,-28.38020,-65.74643
284.00000,-28.40033,-65.96289
284.20000,-28.42033,-66.18947
284.40003,-28.44020,-66.39840
284.60000,-28.45993,-66.60721
284.80003,-28.48033,-66.84031
285.00000,-28.50046,-67.06072
285.20000,-28.52033,-67.25889
285.40003,-28.54033,-67.47700
285.60000,-28.56020,-67.70271
285.80003,-28.58006,-67.92676
286.00000,-28.60020,-68.15621
286.20000,-28.62046,-68.38769
286.40003,-28.64020,-68.60205
286.60000,-28.66020,-68.84436
286.80003,-28.68020,-69.06580
287.00000,-28.70006,-69.29462
287.20000,-28.72020,-69.53139
287.40003,-28.74020,-69.76140
287.60000,-28.76006,-70.00446
287.80003,-28.78033,-70.24052
288.00000,-28.80046,-70.47293
288.19803,-28.81993,-70.70772