File: project1/data/Packing_Peanuts_Instron/Odd_Tests.is_comp_RawData/Specimen_RawData_2.csv
Time,Extension,Load
(sec),(mm),(N)
0.00000,0.00000,-0.00570
0.10000,-0.00213,-0.01743
0.20000,-0.01187,-0.01701
0.30000,-0.02547,-0.01918
0.40000,-0.03720,-0.02091
0.50000,-0.04867,-0.02151
0.60000,-0.05920,-0.00741
0.70000,-0.06933,-0.01826
0.80000,-0.07987,-0.01894
0.90000,-0.08973,-0.01850
1.00000,-0.09973,-0.02489
1.10000,-0.10987,-0.00812
1.20000,-0.11973,-0.02280
1.30000,-0.12987,-0.01330
1.40000,-0.13987,-0.02028
1.50000,-0.14973,-0.02529
1.60000,-0.15973,-0.01724
1.70000,-0.16987,-0.02464
1.80000,-0.18013,-0.02566
1.90000,-0.18973,-0.02944
2.00000,-0.20000,-0.03135
2.10000,-0.21000,-0.02759
2.20000,-0.21960,-0.03328
2.30000,-0.23013,-0.03396
2.40000,-0.23987,-0.03880
2.50000,-0.24973,-0.04816
2.60000,-0.26000,-0.03934
2.70000,-0.26960,-0.05181
2.80000,-0.27987,-0.05612
2.90000,-0.29000,-0.06115
3.00000,-0.29987,-0.06585
3.10000,-0.30987,-0.06752
3.20000,-0.32000,-0.07799
3.30000,-0.33000,-0.08207
3.40000,-0.33987,-0.08920
3.50000,-0.35013,-0.09818
3.60000,-0.36000,-0.09872
3.70000,-0.36973,-0.10798
3.80000,-0.38000,-0.11399
3.90000,-0.38987,-0.11787
4.00000,-0.39973,-0.13089
4.10000,-0.41000,-0.13177
4.20000,-0.41973,-0.14156
4.30000,-0.42987,-0.15022
4.40000,-0.44013,-0.15712
4.50000,-0.44987,-0.16584
4.60000,-0.46000,-0.16597
4.70000,-0.47000,-0.18412
4.80000,-0.47987,-0.18980
4.90000,-0.48987,-0.19378
5.00000,-0.50000,-0.20145
5.10000,-0.51000,-0.20544
5.20000,-0.51973,-0.22188
5.30000,-0.53013,-0.22319
5.40000,-0.53973,-0.22927
5.50000,-0.54960,-0.24566
5.60000,-0.56013,-0.24266
5.70000,-0.56973,-0.25931
5.80000,-0.58000,-0.26779
5.90000,-0.59013,-0.27565
6.00000,-0.59973,-0.28429
6.10000,-0.61013,-0.28142
6.20000,-0.62013,-0.29941
6.30000,-0.63000,-0.29944
6.40000,-0.63987,-0.30839
6.50000,-0.64973,-0.32054
6.60000,-0.65973,-0.31968
6.70000,-0.66973,-0.34348
6.80000,-0.67973,-0.33723
6.90000,-0.68986,-0.34895
7.00000,-0.69960,-0.36077
7.10000,-0.71000,-0.36094
7.20000,-0.71986,-0.37705
7.30000,-0.72986,-0.38953
7.40000,-0.74013,-0.39028
7.50000,-0.74973,-0.39905
7.60000,-0.76000,-0.40071
7.70000,-0.77013,-0.41098
7.80000,-0.77973,-0.41894
7.90000,-0.78986,-0.41575
8.00000,-0.79986,-0.42746
8.10000,-0.80973,-0.42711
8.20000,-0.81986,-0.45002
8.30000,-0.82973,-0.44970
8.40000,-0.83986,-0.46462
8.50000,-0.85000,-0.48019
8.60000,-0.86013,-0.47992
8.70000,-0.87000,-0.43895
8.80000,-0.87986,-0.41607
8.90000,-0.89013,-0.42598
9.00000,-0.89986,-0.43187
9.10000,-0.91000,-0.43720
9.20000,-0.91986,-0.46812
9.30000,-0.92960,-0.48389
9.40000,-0.94000,-0.50264
9.50000,-0.94973,-0.50973
9.60000,-0.95986,-0.51839
9.70000,-0.97013,-0.52763
9.80000,-0.97986,-0.54149
9.90000,-0.99000,-0.56288
10.00000,-1.00013,-0.57824
10.10000,-1.01000,-0.58943
10.20000,-1.02000,-0.61057
10.30000,-1.03000,-0.62343
10.40000,-1.04000,-0.63887
10.50000,-1.04973,-0.65774
10.60000,-1.06000,-0.66555
10.70000,-1.06986,-0.69056
10.80000,-1.07973,-0.71082
10.90000,-1.09013,-0.72143
11.00000,-1.09986,-0.74247
11.10000,-1.10973,-0.74552
11.20000,-1.12013,-0.77733
11.30000,-1.13000,-0.79516
11.40000,-1.13986,-0.80649
11.50000,-1.15013,-0.82584
11.60000,-1.15986,-0.83433
11.70000,-1.17000,-0.86193
11.80000,-1.18000,-0.88066
11.90000,-1.18986,-0.89741
12.00000,-1.19973,-0.91374
12.10000,-1.20973,-0.93083
12.20000,-1.21986,-0.96122
12.30000,-1.22973,-0.98074
12.40000,-1.24000,-1.00143
12.50000,-1.25000,-1.02982
12.60000,-1.25960,-1.03589
12.70000,-1.27013,-1.06870
12.80000,-1.27986,-1.09138
12.90000,-1.28986,-1.10974
13.00000,-1.30013,-1.14202
13.10000,-1.30960,-1.15230
13.20000,-1.31973,-1.18473
13.30000,-1.33000,-1.20375
13.40000,-1.33973,-1.22924
13.50000,-1.34973,-1.25232
13.60000,-1.35986,-1.27605
13.70000,-1.36986,-1.30274
13.80000,-1.38000,-1.32750
13.90000,-1.39000,-1.34936
14.00000,-1.40000,-1.37859
14.10000,-1.41000,-1.39597
14.20000,-1.42013,-1.42610
14.30000,-1.43000,-1.45281
14.40000,-1.43986,-1.47056
14.50000,-1.45013,-1.49615
14.60000,-1.45973,-1.51111
14.70000,-1.46973,-1.53287
14.80000,-1.48000,-1.55704
14.90000,-1.48960,-1.57866
15.00000,-1.50000,-1.60515
15.10000,-1.51013,-1.61813
15.20000,-1.51986,-1.62889
15.30000,-1.53000,-1.65290
15.40000,-1.54000,-1.68194
15.50000,-1.55000,-1.70673
15.60000,-1.56000,-1.72392
15.70000,-1.57013,-1.75287
15.80000,-1.57986,-1.78492
15.90000,-1.58973,-1.80659
16.00000,-1.60013,-1.83465
16.10000,-1.60973,-1.84986
16.20000,-1.61986,-1.89044
16.30000,-1.63000,-1.91798
16.40000,-1.63973,-1.93888
16.50000,-1.65000,-1.96717
16.60000,-1.66000,-1.98900
16.70000,-1.66986,-2.01846
16.80000,-1.68000,-2.04201
16.90000,-1.69000,-2.08097
17.00000,-1.69986,-2.09754
17.10000,-1.70986,-2.12115
17.20000,-1.71973,-2.15553
17.30000,-1.72986,-2.18332
17.40000,-1.73973,-2.21170
17.50000,-1.74986,-2.24134
17.60000,-1.75973,-2.26370
17.70000,-1.76973,-2.30402
17.80000,-1.78013,-2.33621
17.90000,-1.78986,-2.36132
18.00000,-1.80000,-2.39171
18.10000,-1.81000,-2.42306
18.20000,-1.81960,-2.45619
18.30000,-1.83000,-2.48659
18.40000,-1.83986,-2.52312
18.50000,-1.84973,-2.55381
18.60000,-1.85986,-2.58052
18.70000,-1.86960,-2.61601
18.80000,-1.87986,-2.65529
18.90000,-1.89000,-2.67999
19.00000,-1.90000,-2.71541
19.10000,-1.90986,-2.74120
19.20000,-1.91986,-2.78239
19.30000,-1.93000,-2.81006
19.40000,-1.93986,-2.84607
19.50000,-1.95013,-2.87932
19.60000,-1.95986,-2.91091
19.70000,-1.96973,-2.95089
19.80000,-1.98013,-2.98707
19.90000,-1.98986,-3.01694
20.00000,-1.99973,-3.05312
20.10000,-2.01000,-3.07817
20.20000,-2.01973,-3.12580
20.30000,-2.02986,-3.16131
20.40000,-2.04013,-3.19970
20.50000,-2.05000,-3.22388
20.60000,-2.05999,-3.25663
20.70000,-2.07000,-3.29630
20.80000,-2.07986,-3.32408
20.90000,-2.08999,-3.35922
21.00000,-2.09999,-3.40008
21.10000,-2.10999,-3.44341
21.20000,-2.11986,-3.47421
21.30000,-2.13013,-3.51480
21.40000,-2.13986,-3.54973
21.50000,-2.14959,-3.58978
21.60000,-2.16013,-3.62232
21.70000,-2.16973,-3.65677
21.80000,-2.18013,-3.69463
21.90000,-2.19013,-3.73900
22.00000,-2.19973,-3.77099
22.10000,-2.20999,-3.80775
22.20000,-2.21999,-3.85666
22.30000,-2.22986,-3.89512
22.40000,-2.23986,-3.94008
22.50000,-2.24986,-3.98223
22.60000,-2.25986,-4.01308
22.70000,-2.26973,-4.05818
22.80000,-2.27973,-4.10653
22.90000,-2.28986,-4.14921
23.00000,-2.29973,-4.20052
23.10000,-2.31013,-4.22974
23.20000,-2.31986,-4.27541
23.30000,-2.32986,-4.32345
23.40000,-2.34013,-4.37400
23.50000,-2.34986,-4.41760
23.60000,-2.35999,-4.45174
23.70000,-2.36999,-4.50622
23.80000,-2.37959,-4.55319
23.90000,-2.38999,-4.59468
24.00000,-2.39999,-4.63800
24.10000,-2.40973,-4.67591
24.20000,-2.41986,-4.72662
24.30000,-2.42973,-4.78207
24.40000,-2.43986,-4.82696
24.50000,-2.44999,-4.87964
24.60000,-2.45999,-4.91815
24.70000,-2.46986,-4.97365
24.80000,-2.47973,-5.01978
24.90000,-2.49013,-5.07388
25.00000,-2.49986,-5.11571
25.10000,-2.50986,-5.16323
25.20000,-2.51999,-5.22175
25.30000,-2.52959,-5.26819
25.40000,-2.53999,-5.31893
25.50000,-2.54986,-5.36804
25.60000,-2.55973,-5.40659
25.70000,-2.56999,-5.45734
25.80000,-2.57986,-5.51656
25.90000,-2.58999,-5.55680
26.00000,-2.60013,-5.60712
26.10000,-2.61013,-5.64430
26.20000,-2.61986,-5.69876
26.30000,-2.62999,-5.74701
26.40000,-2.64013,-5.79558
26.50000,-2.64973,-5.84370
26.60000,-2.65986,-5.88553
26.70000,-2.66986,-5.94444
26.80000,-2.67959,-5.98435
26.90000,-2.68999,-6.03193
27.00000,-2.69986,-6.08778
27.10000,-2.70986,-6.12148
27.20000,-2.72013,-6.18184
27.30000,-2.72986,-6.23327
27.40000,-2.73986,-6.27383
27.50000,-2.74999,-6.33073
27.60000,-2.75986,-6.37080
27.70000,-2.76999,-6.42912
27.80000,-2.77999,-6.48565
27.90000,-2.78986,-6.53352
28.00000,-2.79986,-6.58879
28.10000,-2.80973,-6.62839
28.20000,-2.81986,-6.68701
28.30000,-2.82973,-6.73467
28.40000,-2.83999,-6.78449
28.50000,-2.84999,-6.83332
28.60000,-2.85986,-6.88340
28.70000,-2.87013,-6.93894
28.80000,-2.87999,-6.98726
28.90000,-2.88986,-7.03747
29.00000,-2.89999,-7.08736
29.10000,-2.90973,-7.13661
29.20000,-2.91986,-7.19398
29.30000,-2.92999,-7.24363
29.40000,-2.93973,-7.31388
29.50000,-2.94986,-7.35856
29.60000,-2.95986,-7.41205
29.70000,-2.96999,-7.46686
29.80000,-2.97999,-7.52002
29.90000,-2.98986,-7.56961
30.00000,-2.99999,-7.63786
30.10000,-3.00999,-7.67965
30.20000,-3.02013,-7.74030
30.30000,-3.02999,-7.79445
30.40000,-3.03973,-7.85586
30.50000,-3.05013,-7.90984
30.60000,-3.05973,-7.97261
30.70000,-3.06986,-8.02823
30.80000,-3.07986,-8.07656
30.90000,-3.08959,-8.13998
31.00000,-3.10013,-8.18923
31.10000,-3.10999,-8.23731
31.20000,-3.11986,-8.29910
31.30000,-3.13013,-8.36325
31.40000,-3.13986,-8.40641
31.50000,-3.14999,-8.45535
31.60000,-3.15999,-8.49949
31.70000,-3.16999,-8.56379
31.80000,-3.17973,-8.61773
31.90000,-3.18973,-8.67879
32.00000,-3.20013,-8.72702
32.10000,-3.20986,-8.75934
32.20000,-3.21986,-8.80247
32.30000,-3.22986,-8.85798
32.40000,-3.23959,-8.92161
32.50000,-3.25013,-8.96530
32.60000,-3.25999,-9.01256
32.70000,-3.26986,-9.07705
32.80000,-3.27999,-9.12690
32.90000,-3.28986,-9.17374
33.00000,-3.29986,-9.22513
33.10000,-3.30999,-9.27950
33.20000,-3.31973,-9.33736
33.30000,-3.32973,-9.39223
33.40000,-3.33986,-9.43798
33.50000,-3.34999,-9.48322
33.60000,-3.35999,-9.53639
33.70000,-3.36986,-9.59294
33.80000,-3.37999,-9.65291
33.90000,-3.38972,-9.69692
34.00000,-3.39999,-9.75214
34.10000,-3.40999,-9.79792
34.20000,-3.41972,-9.84422
34.30000,-3.43026,-9.89404
34.40000,-3.43999,-9.93597
34.50000,-3.44972,-9.98469
34.60000,-3.45999,-10.02821
34.70000,-3.46959,-10.08621
34.80000,-3.47986,-10.15046
34.90000,-3.48999,-10.18904
35.00000,-3.49986,-10.23465
35.10000,-3.50999,-10.29000
35.20000,-3.51999,-10.34807
35.30000,-3.53012,-10.40580
35.40000,-3.53999,-10.45122
35.50000,-3.55012,-10.49859
35.60000,-3.55999,-10.55660
35.70000,-3.56986,-10.60996
35.80000,-3.58012,-10.66155
35.90000,-3.58986,-10.70684
36.00000,-3.59959,-10.76483
36.10000,-3.60999,-10.79979
36.20000,-3.61972,-10.85383
36.30000,-3.62986,-10.91355
36.40000,-3.64012,-10.95544
36.50000,-3.64986,-11.00407
36.60000,-3.65999,-11.05024
36.70000,-3.67012,-11.10207
36.80000,-3.67999,-11.15367
36.90000,-3.68999,-11.19556
37.00000,-3.69999,-11.24188
37.10000,-3.70986,-11.29079
37.20000,-3.71972,-11.33685
37.30000,-3.72999,-11.38106
37.40000,-3.73972,-11.42267
37.50000,-3.74959,-11.47517
37.60000,-3.76012,-11.51247
37.70000,-3.76972,-11.56795
37.80000,-3.77999,-11.60786
37.90000,-3.79012,-11.65375
38.00000,-3.79972,-11.68426
38.10000,-3.80999,-11.72563
38.20000,-3.82012,-11.76869
38.30000,-3.82986,-11.80158
38.40000,-3.83986,-11.84388
38.50000,-3.84972,-11.87510
38.60000,-3.85986,-11.92097
38.70000,-3.86986,-11.96012
38.80000,-3.87986,-11.99623
38.90000,-3.88972,-12.04134
39.00000,-3.89959,-12.08532
39.10000,-3.90999,-12.12119
39.20000,-3.91999,-12.18314
39.30000,-3.92999,-12.21344
39.40000,-3.94012,-12.26371
39.50000,-3.94972,-12.30014
39.60000,-3.95986,-12.34179
39.70000,-3.97012,-12.39307
39.80000,-3.97972,-12.42397
39.90000,-3.98999,-12.46182
40.00000,-3.99986,-12.50315
40.10000,-4.00972,-12.53545
40.20000,-4.01986,-12.57250
40.30000,-4.02986,-12.61984
40.40000,-4.03999,-12.65146
40.50000,-4.05012,-12.69550
40.60000,-4.05986,-12.73470
40.70000,-4.06972,-12.77824
40.80000,-4.07986,-12.81099
40.90000,-4.09012,-12.85798
41.00000,-4.09999,-12.89615
41.10000,-4.11012,-12.93589
41.20000,-4.11999,-12.97171
41.30000,-4.12959,-13.01174
41.40000,-4.13999,-13.04439
41.50000,-4.14972,-13.08189
41.60000,-4.15972,-13.11912
41.70000,-4.17012,-13.15861
41.80000,-4.17986,-13.19778
41.90000,-4.18986,-13.23190
42.00000,-4.20012,-13.28233
42.10000,-4.20999,-13.31113
42.20000,-4.21986,-13.35068
42.30000,-4.22999,-13.39691
42.40000,-4.23999,-13.42566
42.50000,-4.24986,-13.45439
42.60000,-4.25999,-13.48384
42.70000,-4.26986,-13.53073
42.80000,-4.27959,-13.56515
42.90000,-4.28999,-13.59447
43.00000,-4.29986,-13.62645
43.10000,-4.30986,-13.66019
43.20000,-4.32012,-13.69262
43.30000,-4.32986,-13.73394
43.40000,-4.33999,-13.77317
43.50000,-4.35012,-13.81108
43.60000,-4.35986,-13.83844
43.70000,-4.36999,-13.88260
43.80000,-4.37999,-13.93008
43.90000,-4.38972,-13.96881
44.00000,-4.39972,-14.00623
44.10000,-4.40972,-14.04024
44.20000,-4.41986,-14.09055
44.30000,-4.42972,-14.13238
44.40000,-4.43999,-14.18390
44.50000,-4.44986,-14.21919
44.60000,-4.45972,-14.25230
44.70000,-4.47026,-14.31016
44.80000,-4.47986,-14.34481
44.90000,-4.48986,-14.39330
45.00000,-4.50012,-14.43110
45.10000,-4.50959,-14.47106
45.20000,-4.51986,-14.51231
45.30000,-4.52999,-14.55885
45.40000,-4.53972,-14.60409
45.50000,-4.54986,-14.63531
45.60000,-4.55986,-14.67474
45.70000,-4.56986,-14.71137
45.80000,-4.57999,-14.75684
45.90000,-4.58999,-14.79442
46.00000,-4.59999,-14.84098
46.10000,-4.60999,-14.88455
46.20000,-4.61999,-14.92305
46.30000,-4.62986,-14.96551
46.40000,-4.63972,-15.01617
46.50000,-4.65012,-15.05822
46.60000,-4.65986,-15.09909
46.70000,-4.66986,-15.15452
46.80000,-4.67999,-15.19035
46.90000,-4.68959,-15.24530
47.00000,-4.69999,-15.28163
47.10000,-4.70999,-15.33066
47.20000,-4.71972,-15.37163
47.30000,-4.72999,-15.41457
47.40000,-4.73985,-15.45396
47.50000,-4.74999,-15.49905
47.60000,-4.75999,-15.52813
47.70000,-4.77012,-15.57196
47.80000,-4.77972,-15.61556
47.90000,-4.78972,-15.65859
48.00000,-4.79999,-15.69622
48.10000,-4.80972,-15.73122
48.20000,-4.81986,-15.76974
48.30000,-4.82999,-15.81820
48.40000,-4.83985,-15.85971
48.50000,-4.85025,-15.89963
48.60000,-4.85999,-15.93889
48.70000,-4.86972,-15.98370
48.80000,-4.88012,-16.02548
48.90000,-4.88985,-16.06551
49.00000,-4.89985,-16.10394
49.10000,-4.90999,-16.14250
49.20000,-4.91972,-16.18134
49.30000,-4.92985,-16.22518
49.40000,-4.93985,-16.26102
49.50000,-4.94972,-16.30381
49.60000,-4.95972,-16.33195
49.70000,-4.96985,-16.38530
49.80000,-4.97999,-16.42346
49.90000,-4.98972,-16.45592
50.00000,-5.00012,-16.49457
50.10000,-5.00999,-16.53128
50.20000,-5.01972,-16.57165
50.30000,-5.03025,-16.61617
50.40000,-5.03985,-16.65215
50.50000,-5.04985,-16.69380
50.60000,-5.05999,-16.72070
50.70000,-5.06959,-16.77284
50.80000,-5.07972,-16.81206
50.90000,-5.08999,-16.84678
51.00000,-5.09985,-16.88164
51.10000,-5.10985,-16.92241
51.20000,-5.11999,-16.96727
51.30000,-5.13012,-17.00170
51.40000,-5.13999,-17.03961
51.50000,-5.15012,-17.07703
51.60000,-5.15999,-17.11147
51.70000,-5.16972,-17.14602
51.80000,-5.18012,-17.19571
51.90000,-5.18999,-17.23160
52.00000,-5.19972,-17.27508
52.10000,-5.20999,-17.29852
52.20000,-5.21972,-17.34463
52.30000,-5.22985,-17.39621
52.40000,-5.24012,-17.42940
52.50000,-5.24985,-17.46477
52.60000,-5.25999,-17.50269
52.70000,-5.27012,-17.54883
52.80000,-5.27999,-17.59109
52.90000,-5.28999,-17.61948
53.00000,-5.29999,-17.65688
53.10000,-5.30999,-17.69398
53.20000,-5.31985,-17.73453
53.30000,-5.33012,-17.78363
53.40000,-5.33985,-17.81921
53.50000,-5.34972,-17.85502
53.60000,-5.36012,-17.89239
53.70000,-5.36972,-17.92955
53.80000,-5.37999,-17.96833
53.90000,-5.38999,-18.01725
54.00000,-5.39959,-18.04379
54.10000,-5.40999,-18.08173
54.20000,-5.42012,-18.11909
54.30000,-5.42999,-18.15506
54.40000,-5.43999,-18.19393
54.50000,-5.44985,-18.23269
54.60000,-5.45985,-18.26414
54.70000,-5.46972,-18.30844
54.80000,-5.47972,-18.34737
54.90000,-5.48972,-18.38600
55.00000,-5.49972,-18.42754
55.10000,-5.50999,-18.44959
55.20000,-5.51985,-18.49432
55.30000,-5.52985,-18.53713
55.40000,-5.54012,-18.58038
55.50000,-5.54985,-18.62330
55.60000,-5.55999,-18.64923
55.70000,-5.57012,-18.69183
55.80000,-5.57959,-18.73277
55.90000,-5.58999,-18.76773
56.00000,-5.59999,-18.80215
56.10000,-5.60972,-18.83215
56.20000,-5.61985,-18.88272
56.30000,-5.62985,-18.91550
56.40000,-5.63999,-18.94879
56.50000,-5.65012,-18.98742
56.60000,-5.66012,-19.02462
56.70000,-5.66985,-19.07499
56.80000,-5.67985,-19.11086
56.90000,-5.68999,-19.15361
57.00000,-5.69985,-19.18765
57.10000,-5.70999,-19.20998
57.20000,-5.71999,-19.26350
57.30000,-5.72959,-19.29631
57.40000,-5.74012,-19.32319
57.50000,-5.74985,-19.35733
57.60000,-5.75985,-19.39963
57.70000,-5.77012,-19.45279
57.80000,-5.77985,-19.48025
57.90000,-5.78985,-19.51740
58.00000,-5.80012,-19.55772
58.10000,-5.80999,-19.59485
58.20000,-5.81999,-19.64257
58.30000,-5.82999,-19.69065
58.40000,-5.83999,-19.72475
58.50000,-5.84985,-19.74557
58.60000,-5.85999,-19.77429
58.70000,-5.86985,-19.82524
58.80000,-5.87959,-19.86268
58.90000,-5.88999,-19.89687
59.00000,-5.89985,-19.93259
59.10000,-5.90972,-19.96364
59.20000,-5.92025,-20.01278
59.30000,-5.92985,-20.04651
59.40000,-5.93985,-20.08957
59.50000,-5.95012,-20.12491
59.60000,-5.95985,-20.16097
59.70000,-5.96999,-20.19604
59.80000,-5.97999,-20.24571
59.90000,-5.98985,-20.28078
60.00000,-5.99972,-20.32263
60.10000,-6.00972,-20.35337
60.20000,-6.01985,-20.39794
60.30000,-6.02972,-20.43366
60.40000,-6.03999,-20.46542
60.50000,-6.04999,-20.50226
60.60000,-6.05959,-20.52914
60.70000,-6.06999,-20.57415
60.80000,-6.07999,-20.61584
60.90000,-6.08985,-20.66807
61.00000,-6.10025,-20.70450
61.10000,-6.10972,-20.73216
61.20000,-6.11985,-20.77703
61.30000,-6.13012,-20.82249
61.40000,-6.13972,-20.85318
61.50000,-6.14985,-20.89039
61.60000,-6.15998,-20.92184
61.70000,-6.16985,-20.95779
61.80000,-6.17999,-20.98503
61.90000,-6.18998,-21.02345
62.00000,-6.19998,-21.06683
62.10000,-6.20998,-21.10121
62.20000,-6.22012,-21.13886
62.30000,-6.22999,-21.17461
62.40000,-6.23985,-21.21084
62.50000,-6.25012,-21.24091
62.60000,-6.25985,-21.27008
62.70000,-6.26985,-21.31804
62.80000,-6.27998,-21.34999
62.90000,-6.28958,-21.39790
63.00000,-6.29998,-21.42460
63.10000,-6.31012,-21.45856
63.20000,-6.31998,-21.49730
63.30000,-6.33012,-21.53553
63.40000,-6.33998,-21.57543
63.50000,-6.35012,-21.61399
63.60000,-6.36012,-21.64649
63.70000,-6.37012,-21.68782
63.80000,-6.37985,-21.72023
63.90000,-6.38972,-21.76057
64.00000,-6.39998,-21.79431
64.10001,-6.40972,-21.82320
64.20000,-6.41985,-21.86497
64.30000,-6.42998,-21.90441
64.40000,-6.43972,-21.93713
64.50000,-6.45012,-21.96945
64.60001,-6.45998,-21.99396
64.70000,-6.46985,-22.03589
64.80000,-6.47998,-22.05255
64.90000,-6.48985,-22.08799
65.00000,-6.49985,-22.11669
65.10001,-6.50998,-22.14178
65.20000,-6.51985,-22.17399
65.30000,-6.52972,-22.20642
65.40000,-6.53985,-22.22888
65.50000,-6.54985,-22.26189
65.60001,-6.55972,-22.28445
65.70001,-6.56985,-22.33675
65.80000,-6.58012,-22.36151
65.90000,-6.58998,-22.38774
66.00000,-6.59998,-22.42162
66.10001,-6.60998,-22.44734
66.20001,-6.61972,-22.46831
66.30000,-6.63025,-22.48688
66.40000,-6.63985,-22.50801
66.50000,-6.64985,-22.53497
66.60001,-6.65998,-22.50096
66.70001,-6.66972,-22.52482
66.80000,-6.67985,-22.54305
66.90000,-6.69012,-22.55320
67.00000,-6.69998,-22.57857
67.10001,-6.70985,-22.59142
67.20001,-6.71998,-22.61498
67.30000,-6.72998,-22.63705
67.40000,-6.73998,-22.62439
67.50000,-6.75025,-22.64168
67.60001,-6.76012,-22.66858
67.70001,-6.76985,-22.68999
67.80000,-6.78012,-22.70481
67.90000,-6.78985,-22.71864
68.00000,-6.79972,-22.74240
68.10001,-6.80998,-22.75759
68.20001,-6.81972,-22.78022
68.30000,-6.82985,-22.79809
68.40000,-6.84025,-22.80432
68.50000,-6.84985,-22.82025
68.60001,-6.85998,-22.82219
68.70001,-6.87012,-22.83883
68.80000,-6.87998,-22.86144
68.90000,-6.89012,-22.88432
69.00000,-6.90012,-22.91353
69.10001,-6.90998,-22.92766
69.20001,-6.91972,-22.94125
69.30000,-6.93012,-22.96199
69.40000,-6.93985,-22.99197
69.50000,-6.94972,-23.02585
69.60001,-6.96012,-23.05651
69.70001,-6.96972,-23.07845
69.80000,-6.97998,-23.11249
69.90000,-6.99012,-23.14427
70.00000,-6.99972,-23.16560
70.10001,-7.00998,-23.19268
70.20001,-7.02012,-23.23076
70.30000,-7.02998,-23.25016
70.40000,-7.03985,-23.27797
70.50000,-7.04985,-23.30820
70.60001,-7.05985,-23.34170
70.70001,-7.06985,-23.37082
70.80000,-7.07985,-23.40670
70.90000,-7.08972,-23.44233
71.00000,-7.09972,-23.47376
71.10001,-7.11012,-23.48608
71.20001,-7.11985,-23.51615
71.30000,-7.12985,-23.54336
71.40000,-7.14025,-23.58401
71.50000,-7.14972,-23.61124
71.60001,-7.15985,-23.63625
71.70001,-7.17012,-23.67626
71.80000,-7.17972,-23.71209
71.90000,-7.18998,-23.74669
72.00000,-7.19998,-23.78251
72.10001,-7.20972,-23.80040
72.20001,-7.21985,-23.83107
72.30000,-7.22985,-23.84543
72.40000,-7.23998,-23.88277
72.50000,-7.25012,-23.90251
72.60001,-7.26012,-23.91684
72.70001,-7.26998,-23.95452
72.80000,-7.28012,-23.98023
72.90000,-7.29025,-24.00961
73.00000,-7.29985,-24.03023
73.10001,-7.30998,-24.04790
73.20001,-7.31998,-24.08398
73.30000,-7.32972,-24.11562
73.40000,-7.34012,-24.14070
73.50000,-7.34998,-24.17838
73.60001,-7.35985,-24.20077
73.70001,-7.36998,-24.22953
73.80000,-7.37985,-24.26833
73.90000,-7.38998,-24.30123
74.00000,-7.40012,-24.33925
74.10001,-7.40998,-24.34943
74.20001,-7.41985,-24.38491
74.30000,-7.42998,-24.41612
74.40000,-7.43998,-24.45783
74.50000,-7.44985,-24.48432
74.60001,-7.45998,-24.50766
74.70001,-7.46998,-24.55182
74.80000,-7.47972,-24.58152
74.90000,-7.49012,-24.62029
75.00000,-7.49998,-24.64970
75.10001,-7.50985,-24.66386
75.20001,-7.52012,-24.70772
75.30000,-7.52998,-24.73725
75.40000,-7.53998,-24.76392
75.50000,-7.55011,-24.79452
75.60001,-7.55985,-24.80485
75.70001,-7.56998,-24.84782
75.80000,-7.58011,-24.87163
75.90000,-7.58985,-24.90832
76.00000,-7.59971,-24.95159
76.10001,-7.60971,-24.96945
76.20001,-7.61985,-24.99761
76.30000,-7.62971,-25.02346
76.40000,-7.63998,-25.05074
76.50000,-7.64998,-25.08910
76.60001,-7.65971,-25.10631
76.70001,-7.67011,-25.14514
76.80000,-7.67998,-25.17710
76.90000,-7.68998,-25.20503
77.00000,-7.70011,-25.24464
77.10001,-7.70971,-25.26467
77.20001,-7.71998,-25.28443
77.30000,-7.73011,-25.32346
77.40000,-7.73971,-25.34477
77.50000,-7.74985,-25.37207
77.60001,-7.75998,-25.40646
77.70001,-7.76998,-25.43341
77.80000,-7.77998,-25.45852
77.90000,-7.79011,-25.48318
78.00000,-7.79998,-25.52259
78.10001,-7.81011,-25.54646
78.20001,-7.82025,-25.57155
78.30000,-7.82998,-25.58820
78.40000,-7.83985,-25.60813
78.50000,-7.85011,-25.63846
78.60001,-7.85985,-25.66320
78.70001,-7.86985,-25.68653
78.80000,-7.87985,-25.71676
78.90000,-7.88958,-25.74965
79.00000,-7.90011,-25.78291
79.10001,-7.91011,-25.80452
79.20001,-7.91985,-25.82582
79.30000,-7.93011,-25.84760
79.40000,-7.93985,-25.85818
79.50000,-7.94998,-25.87584
79.60001,-7.96011,-25.88992
79.70001,-7.96998,-25.90147
79.80000,-7.97985,-25.87412
79.90000,-7.98971,-25.88243
80.00000,-8.00011,-25.90240
80.10001,-8.00971,-25.90439
80.20001,-8.01998,-25.92458
80.30000,-8.02998,-25.94338
80.40000,-8.03971,-25.95065
80.50001,-8.04998,-25.97605
80.60001,-8.05998,-26.01334
80.70001,-8.06985,-26.02687
80.80000,-8.08011,-26.05776
80.90000,-8.08998,-26.09169
81.00001,-8.09985,-26.11985
81.10001,-8.10998,-26.14637
81.20001,-8.11985,-26.17414
81.30000,-8.12985,-26.20776
81.40000,-8.13985,-26.23733
81.50001,-8.14971,-26.27122
81.60001,-8.15971,-26.31110
81.70001,-8.16971,-26.35134
81.80000,-8.18011,-26.39859
81.90000,-8.18985,-26.42819
82.00001,-8.19998,-26.45990
82.10001,-8.21011,-26.50902
82.20001,-8.21971,-26.53664
82.30000,-8.23011,-26.56763
82.40000,-8.23998,-26.61500
82.50001,-8.24985,-26.64921
82.60001,-8.25985,-26.69500
82.70001,-8.26971,-26.73356
82.80000,-8.27985,-26.76576
82.90000,-8.28998,-26.80421
83.00001,-8.29998,-26.84002
83.10001,-8.30998,-26.88361
83.20001,-8.31998,-26.91914
83.30000,-8.33011,-26.96238
83.40000,-8.33998,-26.99278
83.50001,-8.35011,-27.03288
83.60001,-8.36011,-27.07878
83.70001,-8.36985,-27.11539
83.80000,-8.38011,-27.15435
83.90000,-8.38998,-27.19952
84.00001,-8.39971,-27.24152
84.10001,-8.40998,-27.27796
84.20001,-8.41971,-27.32103
84.30000,-8.42985,-27.36469
84.40000,-8.44025,-27.41904
84.50001,-8.44985,-27.45923
84.60001,-8.45998,-27.50181
84.70001,-8.47011,-27.55011
84.80000,-8.47998,-27.59611
84.90000,-8.49011,-27.63570
85.00001,-8.49998,-27.68714
85.10001,-8.50998,-27.73655
85.20001,-8.51985,-27.77451
85.30000,-8.53011,-27.82108
85.40000,-8.53985,-27.86256
85.50001,-8.54958,-27.90785
85.60001,-8.56011,-27.96453
85.70001,-8.56985,-28.00426
85.80000,-8.57998,-28.04785
85.90000,-8.59011,-28.10196
86.00001,-8.59985,-28.14685
86.10001,-8.61011,-28.19793
86.20001,-8.61998,-28.24226
86.30000,-8.62998,-28.28354
86.40000,-8.63998,-28.33316
86.50001,-8.64985,-28.37580
86.60001,-8.65985,-28.42818
86.70001,-8.66985,-28.47392
86.80000,-8.67985,-28.52159
86.90000,-8.68998,-28.58162
87.00001,-8.69971,-28.63314
87.10001,-8.70998,-28.67930
87.20001,-8.71971,-28.72082
87.30000,-8.72985,-28.76623
87.40000,-8.74011,-28.83901
87.50001,-8.74985,-28.88339
87.60001,-8.75998,-28.93776
87.70001,-8.77011,-28.99461
87.80000,-8.77971,-29.03738
87.90000,-8.79011,-29.07977
88.00001,-8.79998,-29.13372
88.10001,-8.80984,-29.17777
88.20001,-8.81985,-29.22802
88.30000,-8.82985,-29.27916
88.40000,-8.83998,-29.33582
88.50001,-8.84998,-29.37754
88.60001,-8.85998,-29.42440
88.70001,-8.86998,-29.48179
88.80000,-8.88011,-29.54470
88.90000,-8.89011,-29.60280
89.00001,-8.89985,-29.60304
89.10001,-8.91011,-29.65117
89.20001,-8.91998,-29.71746
89.30000,-8.92958,-29.75823
89.40000,-8.94011,-29.81386
89.50001,-8.94985,-29.86745
89.60001,-8.95971,-29.91724
89.70001,-8.97011,-29.97989
89.80000,-8.97984,-30.04137
89.90000,-8.98998,-30.08151
90.00001,-9.00011,-30.14529
90.10001,-9.00984,-30.18648
90.20001,-9.01985,-30.25276
90.30000,-9.03011,-30.31527
90.40000,-9.04011,-30.34542
90.50001,-9.04998,-30.38410
90.60001,-9.06011,-30.44537
90.70001,-9.06985,-30.51221
90.80000,-9.07958,-30.57495
90.90000,-9.09011,-30.63836
91.00001,-9.09984,-30.70082
91.10001,-9.10984,-30.75558
91.20001,-9.12011,-30.81956
91.30000,-9.12998,-30.86912
91.40000,-9.13984,-30.92823
91.50001,-9.14998,-30.98783
91.60001,-9.15971,-31.04896
91.70001,-9.16998,-31.11034
91.80000,-9.17998,-31.16821
91.90000,-9.18984,-31.22718
92.00001,-9.19984,-31.28912
92.10001,-9.20984,-31.35719
92.20001,-9.21998,-31.41858
92.30000,-9.22971,-31.48092
92.40000,-9.23998,-31.54365
92.50001,-9.24998,-31.60858
92.60001,-9.25971,-31.65985
92.70001,-9.27011,-31.72867
92.80000,-9.27984,-31.79123
92.90000,-9.28998,-31.84975
93.00001,-9.30011,-31.91685
93.10001,-9.30971,-31.97741
93.20001,-9.31984,-32.03420
93.30000,-9.33011,-32.09807
93.40000,-9.33984,-32.16169
93.50001,-9.34984,-32.23144
93.60001,-9.35984,-32.30405
93.70001,-9.36984,-32.37666
93.80000,-9.37998,-32.44000
93.90000,-9.38998,-32.50305
94.00001,-9.39998,-32.57367
94.10001,-9.40998,-32.64902
94.20001,-9.41998,-32.71403
94.30000,-9.42984,-32.77652
94.40000,-9.43971,-32.85040
94.50001,-9.45011,-32.92090
94.60001,-9.45984,-32.97912
94.70001,-9.46998,-33.03083
94.80000,-9.47998,-33.09174
94.90000,-9.48971,-33.14748
95.00001,-9.49998,-33.21531
95.10001,-9.50998,-33.29396
95.20001,-9.51984,-33.34971
95.30000,-9.53011,-33.41816
95.40000,-9.53984,-33.48404
95.50001,-9.54998,-33.53874
95.60001,-9.56011,-33.60855
95.70001,-9.57011,-33.67523
95.80000,-9.57984,-33.73995
95.90000,-9.58984,-33.81216
96.00001,-9.60011,-33.88616
96.10001,-9.60984,-33.93006
96.20001,-9.61984,-33.98284
96.30000,-9.62998,-34.05803
96.40000,-9.63984,-34.12348
96.50001,-9.65024,-34.19179
96.60001,-9.66011,-34.25703
96.70001,-9.66998,-34.32418
96.80000,-9.68011,-34.40238
96.90000,-9.68984,-34.46458
97.00001,-9.69984,-34.53956
97.10001,-9.70998,-34.62116
97.20001,-9.71971,-34.68823
97.30000,-9.72984,-34.75704
97.40000,-9.73984,-34.82595
97.50001,-9.74971,-34.89268
97.60001,-9.75971,-34.96147
97.70001,-9.76984,-35.03852
97.80000,-9.78011,-35.10899
97.90000,-9.78984,-35.17625
98.00001,-9.80011,-35.25419
98.10001,-9.80998,-35.34351
98.20001,-9.81971,-35.40873
98.30000,-9.83024,-35.49464
98.40000,-9.83984,-35.57404
98.50001,-9.84984,-35.64181
98.60001,-9.86011,-35.71867
98.70001,-9.86958,-35.78638
98.80000,-9.87971,-35.86153
98.90000,-9.88998,-35.93257
99.00001,-9.89984,-36.00845
99.10001,-9.90984,-36.09596
99.20001,-9.91998,-36.17406
99.30000,-9.93011,-36.25320
99.40000,-9.94011,-36.32639
99.50001,-9.95011,-36.40120
99.60001,-9.95998,-36.47185
99.70001,-9.96984,-36.54414
99.80000,-9.97998,-36.63065
99.90000,-9.98984,-36.70672
100.00001,-9.99984,-36.78760
100.10001,-10.01011,-36.87343
100.20001,-10.01971,-36.94065
100.30000,-10.02984,-37.01422
100.40000,-10.04011,-37.10898
100.50001,-10.04984,-37.17225
100.60001,-10.05998,-37.26627
100.70001,-10.07011,-37.34579
100.80000,-10.07998,-37.41346
100.90000,-10.09011,-37.49285
101.00001,-10.09998,-37.57315
101.10001,-10.10998,-37.66830
101.20001,-10.11984,-37.73711
101.30000,-10.13011,-37.81635
101.40000,-10.13984,-37.89652
101.50001,-10.14971,-37.97667
101.60001,-10.16011,-38.06375
101.70001,-10.16971,-38.13973
101.80000,-10.17998,-38.22411
101.90000,-10.19011,-38.32043
102.00001,-10.19971,-38.39720
102.10001,-10.21011,-38.48114
102.20001,-10.22011,-38.56745
102.30000,-10.22984,-38.64151
102.40000,-10.23998,-38.72376
102.50001,-10.24984,-38.80508
102.60001,-10.25971,-38.87724
102.70001,-10.26984,-38.95759
102.80000,-10.27984,-39.02796
102.90000,-10.28971,-39.11485
103.00001,-10.29971,-39.20083
103.10001,-10.31011,-39.29507
103.20001,-10.31984,-39.37862
103.30000,-10.32984,-39.46366
103.40000,-10.34011,-39.56000
103.50001,-10.34984,-39.64241
103.60001,-10.35997,-39.73282
103.70001,-10.37011,-39.81882
103.80000,-10.37971,-39.89341
103.90000,-10.38997,-39.98127
104.00001,-10.39997,-40.07148
104.10001,-10.40971,-40.14708
104.20001,-10.41984,-40.22913
104.30000,-10.42984,-40.31580
104.40000,-10.43997,-40.41125
104.50001,-10.45011,-40.50440
104.60001,-10.45997,-40.59282
104.70001,-10.46997,-40.68956
104.80000,-10.47997,-40.77711
104.90000,-10.49024,-40.87690
105.00001,-10.49997,-40.95842
105.10001,-10.51011,-41.04831
105.20001,-10.51997,-41.14462
105.30000,-10.52971,-41.22067
105.40000,-10.54011,-41.31123
105.50001,-10.54984,-41.39740
105.60001,-10.55971,-41.48265
105.70001,-10.57011,-41.58384
105.80000,-10.57984,-41.66385
105.90000,-10.58997,-41.75793
106.00001,-10.60024,-41.85831
106.10001,-10.60997,-41.93726
106.20001,-10.61997,-42.04593
106.30000,-10.62997,-42.13987
106.40000,-10.63997,-42.23147
106.50001,-10.64984,-42.32547
106.60001,-10.65997,-42.42134
106.70001,-10.66984,-42.52454
106.80000,-10.67957,-42.61705
106.90000,-10.69011,-42.72252
107.00001,-10.69984,-42.81739
107.10001,-10.70971,-42.91635
107.20001,-10.72024,-43.03270
107.30000,-10.72997,-43.12382
107.40000,-10.73984,-43.22984
107.50001,-10.75011,-43.34149
107.60001,-10.75971,-43.43496
107.70001,-10.76997,-43.54304
107.80000,-10.77997,-43.64633
107.90000,-10.78984,-43.74457
108.00001,-10.79984,-43.85754
108.10001,-10.80971,-43.96465
108.20001,-10.81984,-44.07688
108.30000,-10.82971,-44.19389
108.40000,-10.83997,-44.29958
108.50001,-10.84997,-44.42492
108.60001,-10.85971,-44.52970
108.70001,-10.87011,-44.65676
108.80000,-10.87984,-44.76599
108.90000,-10.88997,-44.87600
109.00001,-10.90011,-45.00839
109.10001,-10.90971,-45.12032
109.20001,-10.91997,-45.23667
109.30000,-10.93011,-45.37560
109.40000,-10.93971,-45.47126
109.50001,-10.94971,-45.60736
109.60001,-10.95997,-45.73400
109.70001,-10.96997,-45.82956
109.80000,-10.97997,-45.95325
109.90000,-10.99011,-46.07309
110.00001,-10.99997,-46.20032
110.10001,-11.01011,-46.32601
110.20001,-11.02024,-46.44702
110.30000,-11.02997,-46.55972
110.40000,-11.03984,-46.68260
110.50001,-11.04997,-46.80645
110.60001,-11.05984,-46.92409
110.70001,-11.06984,-47.04999
110.80000,-11.07984,-47.17957
110.90000,-11.08957,-47.29852
111.00001,-11.09997,-47.43375
111.10001,-11.10997,-47.57323
111.20001,-11.11984,-47.69601
111.30000,-11.13011,-47.83241
111.40000,-11.13984,-47.95820
111.50001,-11.15011,-48.08953
111.60001,-11.16011,-48.21996
111.70001,-11.17011,-48.35096
111.80000,-11.17984,-48.48103
111.90000,-11.18971,-48.61477
112.00001,-11.19997,-48.75925
112.10001,-11.20971,-48.88347
112.20001,-11.21984,-49.01424
112.30000,-11.23011,-49.16092
112.40000,-11.23971,-49.28795
112.50001,-11.25011,-49.37911
112.60001,-11.26011,-49.51517
112.70001,-11.26997,-49.64222
112.80000,-11.28011,-49.75084
112.90001,-11.28997,-49.88064
113.00001,-11.29984,-50.01523
113.10001,-11.30997,-50.16277
113.20001,-11.31984,-50.30472
113.30000,-11.32984,-50.45228
113.40001,-11.33984,-50.59862
113.50001,-11.34971,-50.74555
113.60001,-11.35971,-50.89756
113.70001,-11.36984,-51.04637
113.80000,-11.38011,-51.21825
113.90001,-11.38984,-51.36380
114.00001,-11.40011,-51.53195
114.10001,-11.41011,-51.69309
114.20001,-11.41971,-51.82897
114.30000,-11.43024,-52.00081
114.40001,-11.43997,-52.15507
114.50001,-11.44971,-52.30481
114.60001,-11.45997,-52.47983
114.70001,-11.46957,-52.62491
114.80000,-11.47984,-52.78531
114.90001,-11.48997,-52.95957
115.00001,-11.49997,-53.10792
115.10001,-11.50984,-53.28414
115.20001,-11.51997,-53.44133
115.30000,-11.53011,-53.60490
115.40001,-11.53997,-53.76525
115.50001,-11.55011,-53.92502
115.60001,-11.55997,-54.09757
115.70001,-11.56984,-54.24853
115.80000,-11.58010,-54.42327
115.90001,-11.58997,-54.58702
116.00001,-11.59970,-54.73951
116.10001,-11.60997,-54.92174
116.20001,-11.61970,-55.07270
116.30000,-11.62984,-55.23517
116.40001,-11.64024,-55.41551
116.50001,-11.64984,-55.56941
116.60001,-11.65997,-55.74156
116.70001,-11.67011,-55.90491
116.80000,-11.67997,-56.06481
116.90001,-11.68997,-56.22074
117.00001,-11.69997,-56.38742
117.10001,-11.70997,-56.56479
117.20001,-11.71984,-56.72328
117.30000,-11.73010,-56.90001
117.40001,-11.73984,-57.06115
117.50001,-11.74957,-57.22047
117.60001,-11.76010,-57.41311
117.70001,-11.76984,-57.56618
117.80000,-11.77997,-57.72880
117.90001,-11.79010,-57.90967
118.00001,-11.79957,-58.07302
118.10001,-11.81010,-58.25707
118.20001,-11.82024,-58.43792
118.30000,-11.83010,-58.59713
118.40001,-11.83997,-58.77640
118.50001,-11.84984,-58.94292
118.60001,-11.85984,-59.10520
118.70001,-11.86984,-59.28290
118.80000,-11.87984,-59.45307
118.90001,-11.88984,-59.64058
119.00001,-11.89970,-59.81273
119.10001,-11.91010,-59.98910
119.20001,-11.91997,-60.16282
119.30000,-11.92997,-60.33120
119.40001,-11.94010,-60.52298
119.50001,-11.94970,-60.67694
119.60001,-11.95997,-60.85486
119.70001,-11.97010,-61.03804
119.80000,-11.97970,-61.20304
119.90001,-11.99010,-61.39080
120.00001,-12.00010,-61.56922
120.10001,-12.00970,-61.73537
120.20001,-12.01984,-61.91642
120.30000,-12.02984,-62.09271
120.40001,-12.03997,-62.28206
120.50001,-12.05010,-62.46915
120.60001,-12.06010,-62.64593
120.70001,-12.06997,-62.82521
120.80000,-12.07997,-63.00385
120.90001,-12.09010,-63.19270
121.00001,-12.09984,-63.36582
121.10001,-12.10997,-63.54623
121.20001,-12.11997,-63.74071
121.30000,-12.12957,-63.91285
121.40001,-12.14010,-64.09457
121.50001,-12.14984,-64.28421
121.60001,-12.15970,-64.46289
121.70001,-12.17010,-64.66836
121.80000,-12.17984,-64.85239
121.90001,-12.18984,-65.03466
122.00001,-12.20010,-65.23906
122.10001,-12.20997,-65.41061
122.20001,-12.21997,-65.61175
122.30000,-12.22997,-65.80314
122.40001,-12.24010,-65.99448
122.50001,-12.24984,-66.17681
122.60001,-12.25997,-66.36430
122.70001,-12.26984,-66.57168
122.80000,-12.27970,-66.75593
122.90001,-12.29010,-66.95133
123.00001,-12.29984,-67.14654
123.10001,-12.30970,-67.32345
123.20001,-12.32024,-67.54699
123.30000,-12.32997,-67.73917
123.40001,-12.33997,-67.92260
123.50001,-12.35024,-68.12082
123.60001,-12.35984,-68.31530
123.70001,-12.36997,-68.50940
123.80000,-12.37997,-68.70025
123.90001,-12.38984,-68.89845
124.00001,-12.39984,-69.09963
124.10001,-12.40970,-69.28422
124.20001,-12.41984,-69.44402
124.30000,-12.42984,-69.32355
124.40001,-12.44010,-69.49688
124.50001,-12.44997,-69.69737
124.60001,-12.45970,-69.78764
124.70001,-12.47010,-69.99659
124.80000,-12.47984,-69.31998
124.90001,-12.48984,-69.42980
125.00001,-12.50010,-69.65242
125.10001,-12.50970,-69.84853
125.20001,-12.51984,-70.06319
125.30000,-12.53010,-70.29012
125.40001,-12.53984,-70.48313
125.50001,-12.54970,-70.70588
125.60001,-12.55984,-70.93446
125.70001,-12.56984,-71.14322
125.80000,-12.57997,-71.37065
125.90001,-12.59010,-71.59457
126.00001,-12.59997,-71.81003
126.10001,-12.60984,-72.03223
126.20001,-12.62010,-72.26318
126.30000,-12.62997,-72.47392
126.40001,-12.63984,-72.69126
126.50001,-12.65010,-72.93531
126.60001,-12.65984,-73.14388
126.70001,-12.66984,-73.35285
126.80000,-12.67997,-73.58571
126.90001,-12.68957,-73.80645
127.00001,-12.69997,-74.04553
127.10001,-12.71010,-74.27534
127.20001,-12.71997,-74.46069
127.30000,-12.73010,-74.69820
127.40001,-12.73984,-74.91824
127.50001,-12.74997,-75.14361
127.60001,-12.76010,-75.36928
127.70001,-12.77010,-75.59215
127.80000,-12.77984,-75.81966
127.90001,-12.78970,-76.03596
128.00000,-12.80024,-76.28421
128.10001,-12.80984,-76.50767
128.20002,-12.81983,-76.71011
128.30000,-12.82997,-76.95835
128.40001,-12.83957,-77.18033
128.50000,-12.85010,-77.41899
128.60001,-12.85997,-77.66376
128.70002,-12.86970,-77.86896
128.80000,-12.87997,-78.11934
128.90001,-12.88984,-78.35289
129.00000,-12.89984,-78.57355
129.10001,-12.90997,-78.81101
129.20002,-12.91983,-79.04060
129.30000,-12.92997,-79.28119
129.40001,-12.93970,-79.50701
129.50000,-12.94984,-79.73979
129.60001,-12.95984,-79.98750
129.70002,-12.96983,-80.21237
129.80000,-12.98023,-80.48090
129.90001,-12.98997,-80.70173
130.00000,-13.00010,-80.94217
130.10001,-13.01010,-81.19538
130.20002,-13.01970,-81.41413
130.30000,-13.03023,-81.68054
130.40001,-13.03983,-81.91614
130.50000,-13.04970,-82.14167
130.60001,-13.05997,-82.39692
130.70002,-13.06970,-82.63373
130.80000,-13.07984,-82.89192
130.90001,-13.08997,-83.13985
131.00000,-13.09997,-83.38196
131.10000,-13.10997,-83.64283
131.20002,-13.11997,-83.90035
131.30000,-13.12997,-84.14861
131.40002,-13.13997,-84.38223
131.50000,-13.15023,-84.63842
131.60000,-13.16010,-84.91009
131.70002,-13.16983,-85.14966
131.80000,-13.18023,-85.41168
131.90002,-13.18997,-85.65955
132.00000,-13.19970,-85.90008
132.10000,-13.20997,-86.17479
132.20002,-13.21970,-86.41893
132.30000,-13.22983,-86.68023
132.40002,-13.24023,-86.95548
132.50000,-13.24983,-87.19976
132.60000,-13.25983,-87.46231
132.70002,-13.27010,-87.73542
132.80000,-13.28010,-87.99791
132.90002,-13.29010,-88.25240
133.00000,-13.30010,-88.51495
133.10000,-13.30997,-88.79609
133.20002,-13.31983,-89.04239
133.30000,-13.33010,-89.31649
133.40002,-13.33970,-89.57448
133.50000,-13.34943,-89.83182
133.60000,-13.36010,-90.13547
133.70002,-13.36983,-90.39677
133.80000,-13.38010,-90.67421
133.90002,-13.39010,-90.96543
134.00000,-13.39970,-91.21935
134.10000,-13.41010,-91.51202
134.20002,-13.42010,-91.79082
134.30000,-13.42997,-92.04563
134.40002,-13.43997,-92.32851
134.50000,-13.44983,-92.60644
134.60000,-13.45983,-92.88430
134.70002,-13.46983,-93.16822
134.80000,-13.47970,-93.43187
134.90002,-13.48970,-93.71606
135.00000,-13.49970,-93.99256
135.10000,-13.50997,-94.27986
135.20002,-13.51983,-94.56606
135.30000,-13.52983,-94.82921
135.40002,-13.54010,-95.14499
135.50000,-13.54983,-95.41024
135.60000,-13.55997,-95.70937
135.70002,-13.57010,-96.01033
135.80000,-13.57970,-96.27789
135.90002,-13.59010,-96.58971
136.00000,-13.59997,-96.90179
136.10000,-13.60983,-97.17667
136.20002,-13.61997,-97.48560
136.30000,-13.62997,-97.78772
136.40002,-13.63997,-98.08707
136.50000,-13.65010,-98.39387
136.60000,-13.66010,-98.69569
136.70002,-13.66997,-98.99561
136.80000,-13.67997,-99.29750
136.90002,-13.69010,-99.62367
137.00000,-13.69983,-99.91488
137.10000,-13.71010,-100.21291
137.20002,-13.71997,-100.54477
137.30000,-13.72957,-100.83690
137.40002,-13.74010,-101.16038
137.50000,-13.74983,-101.48360
137.60000,-13.75970,-101.77589
137.70002,-13.76997,-102.12218
137.80000,-13.77983,-102.44538
137.90002,-13.78997,-102.75058
138.00000,-13.80010,-103.08211
138.10000,-13.81010,-103.39008
138.20002,-13.81997,-103.70807
138.30000,-13.83010,-104.02559
138.40002,-13.83997,-104.35354
138.50000,-13.84970,-104.65718
138.60000,-13.85983,-104.96064
138.70002,-13.86997,-105.32174
138.80000,-13.87970,-105.64138
138.90002,-13.88997,-105.97966
139.00000,-13.89997,-106.30944
139.10000,-13.90983,-106.61159
139.20002,-13.92010,-106.96266
139.30000,-13.92997,-107.28317
139.40002,-13.93983,-107.59778
139.50000,-13.95010,-107.94234
139.60000,-13.95983,-108.26849
139.70002,-13.96997,-108.60663
139.80000,-13.97997,-108.93890
139.90002,-13.98983,-109.21952
140.00000,-13.99983,-108.33151
140.10000,-14.00957,-108.66012
140.20002,-14.01983,-109.02315
140.30000,-14.02970,-109.37823
140.40002,-14.03997,-109.73719
140.50000,-14.05010,-110.13443
140.60000,-14.05970,-110.46140
140.70002,-14.07010,-110.83639
140.80000,-14.07997,-111.20991
140.90002,-14.08983,-111.54594
141.00000,-14.10010,-111.93909
141.10000,-14.10970,-112.29585
141.20002,-14.11983,-112.66410
141.30000,-14.13010,-113.04951
141.40002,-14.13983,-113.40181
141.50000,-14.14983,-113.78603
141.60000,-14.15983,-114.17075
141.70002,-14.16983,-114.54497
141.80000,-14.17997,-114.92474
141.90002,-14.18997,-115.30661
142.00000,-14.19997,-115.70933
142.10000,-14.21010,-116.09743
142.20002,-14.22023,-116.48490
142.30000,-14.22997,-116.86459
142.40002,-14.23997,-117.22556
142.50000,-14.25023,-117.63816
142.60000,-14.25983,-118.00490
142.70002,-14.26983,-118.37911
142.80000,-14.27983,-118.78806
142.90002,-14.28970,-119.16861
143.00000,-14.30010,-119.57763
143.10000,-14.30997,-119.99064
143.20002,-14.31996,-120.36765
143.30000,-14.33010,-120.78157
143.40002,-14.33996,-121.17126
143.50000,-14.35010,-121.59047
143.60000,-14.35996,-121.99374
143.70002,-14.36996,-122.37659
143.80000,-14.37983,-122.79613
143.90002,-14.38970,-123.19028
144.00000,-14.39996,-123.61807
144.10000,-14.40970,-124.01550
144.20002,-14.41996,-124.42222
144.30000,-14.42997,-124.88341
144.40002,-14.43983,-125.28479
144.50000,-14.45023,-125.72722
144.60000,-14.45996,-126.13963
144.70002,-14.46970,-126.52446
144.80000,-14.47996,-126.97722
144.90002,-14.48983,-127.39596
145.00000,-14.49996,-127.81435
145.10000,-14.51010,-128.26115
145.11802,-14.51183,-128.33813