File: project1/data/Packing_Peanuts_Instron/Odd_Tests_raw.is_comp.raw
"Test Type","Compression"
"Method Name",""
"Sample name","P:\+Courses\MatSci\Instron Data Default Location\Packing_Peanuts\Odd_Tests_raw.is_comp"
"User",""
"Sample note 1",""
"Sample note 2",""
"Sample note 3",""
"Geometry","Rectangular"
"Specimen",1
"Specimen label","Vertical1"
"Width",29.000000,"mm"
"Thickness",8.500000,"mm"
"Anvil height",36.000000,"mm"
"Diameter",18.000000,"mm"
"Inner diameter",8.000000,"mm"
"Outer diameter",10.000000,"mm"
"Wall thickness",1.000000,"mm"
"Area",2.465000,"cm^2"
"Linear density",100.000000,"tex"
"Sled weight",10.000000,"N"
"Loading span",10.000000,"mm"
"Support span",100.000000,"mm"
"Span ratio","2"
"Fixture type","4-point"
"Included"
"Final width",10.000000,"mm"
"Final thickness",1.000000,"mm"
"Final anvil height",100.000000,"mm"
"Final diameter",10.000000,"mm"
"Final Inner diameter",8.000000,"mm"
"Final outer diameter",10.000000,"mm"
"Final wall thickness",1.000000,"mm"
"Final area",0.100000,"cm^2"
"Final linear density",100.000000,"tex"
"Custom text input  1",""
"Custom text input  2",""
"Custom text input  3",""
"Custom text input  4",""
"Custom text input  5",""
"Custom text input  6",""
"Custom text input  7",""
"Custom text input  8",""
"Custom text input  9",""
"Custom text input 10",""
"Custom text input 11",""
"Custom text input 12",""
"Custom text input 13",""
"Custom text input 14",""
"Custom text input 15",""
"Custom text input 16",""
"Custom text input 17",""
"Custom text input 18",""
"Custom text input 19",""
"Custom text input 20",""
"Custom text input 21",""
"Custom text input 22",""
"Custom text input 23",""
"Custom text input 24",""
"Custom text input 25",""
"Custom text input 26",""
"Custom text input 27",""
"Custom text input 28",""
"Custom text input 29",""
"Custom text input 30",""
"Custom text input 31",""
"Custom text input 32",""
"Custom text input 33",""
"Custom text input 34",""
"Custom text input 35",""
"Custom text input 36",""
"Custom text input 37",""
"Custom text input 38",""
"Custom text input 39",""
"Custom text input 40",""
"Custom text input 41",""
"Custom text input 42",""
"Custom text input 43",""
"Custom text input 44",""
"Custom text input 45",""
"Custom text input 46",""
"Custom text input 47",""
"Custom text input 48",""
"Custom text input 49",""
"Custom text input 50",""
"Custom number input  1",0.000000,""
"Custom number input  2",0.000000,""
"Custom number input  3",0.000000,""
"Custom number input  4",0.000000,""
"Custom number input  5",0.000000,""
"Custom number input  6",0.000000,""
"Custom number input  7",0.000000,""
"Custom number input  8",0.000000,""
"Custom number input  9",0.000000,""
"Custom number input 10",0.000000,""
"Time sec","Extension mm","Load kgf","Compressive stress MPa","Cycle Count ","Total Cycle Count ","Repetitions Count ","Marked Data ","PIP Count ","Compressive extension mm","Compressive strain %","Compressive load kgf","Displacement (Strain 1) mm","True strain %","Corrected Position mm","True stress Pa"
0,-0.000266666,-0.002698676,0.000107363,0,0,0,0,0,0.000266666,0.0007407389,0.002698676,0,0.0007407417,-0.000266666,107.3622
0.6,-0.05973319,-0.005703746,0.0002269153,0,0,0,0,0,0.05973319,0.1659255,0.005703745,0,0.1660633,-0.05973319,226.5388
1.2,-0.1203997,-0.009084382,0.0003614092,0,0,0,0,0,0.1203997,0.3344436,0.009084382,0,0.3350041,-0.1203997,360.2004
1.8,-0.1803996,-0.01283991,0.0005108175,0,0,0,0,0,0.1803996,0.5011099,0.01283991,0,0.5023697,-0.1803996,508.2577
2.4,-0.2402661,-0.01472982,0.0005860048,0,0,0,0,0,0.2402661,0.6674058,0.01472982,0,0.6696429,-0.2402661,582.0938
3,-0.3003993,-0.01729741,0.0006881527,0,0,0,0,0,0.3003993,0.8344424,0.01729741,0,0.8379434,-0.3003993,682.4105
3.6,-0.3603991,-0.01995043,0.0007936993,0,0,0,0,0,0.3603992,1.001109,0.01995043,0,1.006154,-0.3603991,785.7536
4.2,-0.419999,-0.02331455,0.000927536,0,0,0,0,0,0.419999,1.166664,0.02331455,0,1.173523,-0.419999,916.7148
4.8,-0.4803988,-0.02753875,0.00109559,0,0,0,0,0,0.4803988,1.334441,0.02753875,0,1.343425,-0.4803988,1080.97
5.4,-0.5403987,-0.03156288,0.001255684,0,0,0,0,0,0.5403987,1.501107,0.03156288,0,1.512488,-0.5403987,1236.835
6,-0.6001319,-0.03440564,0.001368779,0,0,0,0,0,0.6001319,1.667033,0.03440564,0,1.681084,-0.6001319,1345.961
6.6,-0.6603984,-0.03789614,0.001507644,0,0,0,0,0,0.6603984,1.83444,0.03789614,0,1.851474,-0.6603984,1479.987
7.2,-0.7201316,-0.04475979,0.001780704,0,0,0,0,0,0.7201316,2.000365,0.04475979,0,2.020644,-0.7201316,1745.084
7.8,-0.7803981,-0.05254993,0.002090624,0,0,0,0,0,0.7803981,2.167773,0.05254992,0,2.191614,-0.7803981,2045.304
8.400001,-0.8401313,-0.0594454,0.00236495,0,0,0,0,0,0.8401313,2.333698,0.0594454,0,2.36136,-0.8401313,2309.76
9,-0.9002645,-0.06732928,0.002678599,0,0,0,0,0,0.9002644,2.500735,0.06732927,0,2.532534,-0.9002645,2611.614
9.6,-0.960131,-0.07598253,0.003022857,0,0,0,0,0,0.960131,2.667031,0.07598253,0,2.703241,-0.960131,2942.236
10.2,-1.020264,-0.08621359,0.003429884,0,0,0,0,0,1.020264,2.834067,0.08621359,0,2.875002,-1.020264,3332.679
10.8,-1.079997,-0.0953657,0.003793988,0,0,0,0,0,1.079997,2.999993,0.0953657,0,3.045913,-1.079997,3680.169
11.4,-1.140131,-0.1043438,0.00415117,0,0,0,0,0,1.140131,3.167029,0.1043438,0,3.218264,-1.140131,4019.701
12,-1.200264,-0.1144695,0.004554003,0,0,0,0,0,1.200264,3.334066,0.1144695,0,3.390913,-1.200264,4402.17
12.6,-1.259997,-0.1231104,0.004897771,0,0,0,0,0,1.259997,3.499991,0.1231104,0,3.562709,-1.259997,4726.35
13.2,-1.320263,-0.1328111,0.0052837,0,0,0,0,0,1.320264,3.667399,0.1328111,0,3.736338,-1.320263,5089.926
13.8,-1.379997,-0.141725,0.005638327,0,0,0,0,0,1.379997,3.833324,0.141725,0,3.908729,-1.379997,5422.191
14.4,-1.44013,-0.1511787,0.006014428,0,0,0,0,0,1.44013,4.00036,0.1511787,0,4.082575,-1.44013,5773.829
15,-1.500263,-0.1597061,0.006353678,0,0,0,0,0,1.500263,4.167397,0.1597061,0,4.256723,-1.500263,6088.895
15.6,-1.56013,-0.1680488,0.006685579,0,0,0,0,0,1.560129,4.333693,0.1680488,0,4.430402,-1.56013,6395.847
16.2,-1.620129,-0.1775248,0.00706257,0,0,0,0,0,1.620129,4.500359,0.1775248,0,4.60477,-1.620129,6744.729
16.8,-1.680129,-0.1854052,0.007376079,0,0,0,0,0,1.680129,4.667026,0.1854052,0,4.779443,-1.680129,7031.835
17.4,-1.739996,-0.1940042,0.007718181,0,0,0,0,0,1.739996,4.833322,0.1940042,0,4.954032,-1.739996,7345.136
18,-1.800262,-0.2025094,0.008056547,0,0,0,0,0,1.800262,5.000729,0.2025094,0,5.130096,-1.800262,7653.661
18.6,-1.860262,-0.2104535,0.008372591,0,0,0,0,0,1.860262,5.167395,0.2104535,0,5.30569,-1.860262,7939.946
19.2,-1.919995,-0.2193953,0.00872833,0,0,0,0,0,1.919995,5.33332,0.2193953,0,5.48081,-1.919995,8262.82
19.8,-1.980395,-0.2265099,0.009011374,0,0,0,0,0,1.980395,5.501098,0.2265099,0,5.658197,-1.980395,8515.65
20.4,-2.039995,-0.2344765,0.009328314,0,0,0,0,0,2.039995,5.666653,0.2344765,0,5.833543,-2.039995,8799.711
21,-2.100262,-0.2424119,0.009644013,0,0,0,0,0,2.100262,5.83406,0.2424119,0,6.011164,-2.100262,9081.375
21.6,-2.160261,-0.2490919,0.009909766,0,0,0,0,0,2.160261,6.000726,0.2490919,0,6.188313,-2.160261,9315.108
22.2,-2.220395,-0.2569424,0.01022209,0,0,0,0,0,2.220395,6.167763,0.2569424,0,6.366171,-2.220395,9591.612
22.8,-2.280261,-0.2643545,0.01051697,0,0,0,0,0,2.280261,6.334059,0.2643546,0,6.543555,-2.280261,9850.817
23.4,-2.340261,-0.2707821,0.01077268,0,0,0,0,0,2.340261,6.500725,0.2707821,0,6.72165,-2.340261,10072.38
24,-2.400261,-0.2781996,0.01106777,0,0,0,0,0,2.400261,6.667391,0.2781996,0,6.900064,-2.400261,10329.84
24.6,-2.460394,-0.2838549,0.01129276,0,0,0,0,0,2.460394,6.834428,0.2838549,0,7.079193,-2.460394,10520.96
25.2,-2.520394,-0.2910466,0.01157887,0,0,0,0,0,2.520394,7.001094,0.2910466,0,7.258246,-2.520394,10768.23
25.8,-2.579994,-0.2971806,0.01182291,0,0,0,0,0,2.579994,7.166649,0.2971806,0,7.436423,-2.579994,10975.6
26.4,-2.640394,-0.3031151,0.012059,0,0,0,0,0,2.640393,7.334426,0.303115,0,7.617316,-2.640394,11174.54
27,-2.700393,-0.3089909,0.01229276,0,0,0,0,0,2.700393,7.501092,0.3089909,0,7.797335,-2.700393,11370.67
27.6,-2.760393,-0.3139605,0.01249047,0,0,0,0,0,2.760393,7.667759,0.3139605,0,7.97768,-2.760393,11532.73
28.2,-2.820393,-0.3208332,0.01276389,0,0,0,0,0,2.820393,7.834425,0.3208331,0,8.15835,-2.820393,11763.91
28.8,-2.880393,-0.325575,0.01295254,0,0,0,0,0,2.880393,8.001092,0.325575,0,8.339348,-2.880393,11916.19
29.4,-2.940393,-0.3301919,0.01313621,0,0,0,0,0,2.940393,8.167758,0.3301919,0,8.520673,-2.940393,12063.28
30,-3.000259,-0.3357213,0.01335619,0,0,0,0,0,3.000259,8.334054,0.3357213,0,8.701924,-3.000259,12243.08
30.6,-3.060126,-0.3397098,0.01351487,0,0,0,0,0,3.060126,8.50035,0.3397098,0,8.883504,-3.060126,12366.06
31.2,-3.120126,-0.3449281,0.01372247,0,0,0,0,0,3.120126,8.667016,0.3449281,0,9.065819,-3.120126,12533.14
31.8,-3.180259,-0.3498085,0.01391663,0,0,0,0,0,3.180259,8.834052,0.3498085,0,9.248873,-3.180259,12687.23
32.4,-3.239859,-0.3539589,0.01408175,0,0,0,0,0,3.239859,8.999607,0.3539589,0,9.430637,-3.239859,12814.45
33,-3.300259,-0.3588928,0.01427804,0,0,0,0,0,3.300259,9.167385,0.3588928,0,9.615177,-3.300259,12969.11
33.6,-3.360258,-0.3619484,0.0143996,0,0,0,0,0,3.360258,9.334051,0.3619485,0,9.798833,-3.360258,13055.54
34.2,-3.420125,-0.3669201,0.01459739,0,0,0,0,0,3.420125,9.500347,0.3669201,0,9.982417,-3.420125,13210.59
34.8,-3.480258,-0.371013,0.01476022,0,0,0,0,0,3.480258,9.667384,0.371013,0,10.16716,-3.480258,13333.29
35.4,-3.539991,-0.3749449,0.01491665,0,0,0,0,0,3.539991,9.833309,0.3749449,0,10.35101,-3.539991,13449.85
36,-3.600125,-0.3790115,0.01507843,0,0,0,0,0,3.600125,10.00035,0.3790115,0,10.53644,-3.600125,13570.54
36.6,-3.659991,-0.3820729,0.01520022,0,0,0,0,0,3.659991,10.16664,0.3820729,0,10.72138,-3.659991,13654.87
37.2,-3.720124,-0.3855889,0.0153401,0,0,0,0,0,3.720124,10.33368,0.3855889,0,10.90749,-3.720124,13754.91
37.8,-3.780124,-0.3902735,0.01552647,0,0,0,0,0,3.780124,10.50034,0.3902735,0,11.09354,-3.780124,13896.14
38.4,-3.840257,-0.3927465,0.01562486,0,0,0,0,0,3.840257,10.66738,0.3927465,0,11.28035,-3.840257,13958.1
39,-3.899857,-0.3970841,0.01579743,0,0,0,0,0,3.899857,10.83294,0.3970841,0,11.46585,-3.899857,14086.1
39.6,-3.960257,-0.3993759,0.0158886,0,0,0,0,0,3.960257,11.00071,0.3993759,0,11.65418,-3.960257,14140.74
40.2,-4.020124,-0.4031442,0.01603852,0,0,0,0,0,4.020124,11.16701,0.4031442,0,11.84121,-4.020124,14247.49
40.8,-4.080123,-0.4072562,0.01620211,0,0,0,0,0,4.080123,11.33368,0.4072562,0,12.029,-4.080123,14365.81
41.4,-4.14039,-0.4097976,0.01630321,0,0,0,0,0,4.14039,11.50108,0.4097976,0,12.21799,-4.14039,14428.17
42,-4.200256,-0.4126047,0.01641489,0,0,0,0,0,4.200256,11.66738,0.4126047,0,12.40607,-4.200256,14499.7
42.6,-4.260123,-0.415427,0.01652717,0,0,0,0,0,4.260123,11.83368,0.415427,0,12.59451,-4.260123,14571.4
43.2,-4.320123,-0.4188696,0.01666413,0,0,0,0,0,4.320123,12.00034,0.4188696,0,12.78372,-4.320123,14664.37
43.8,-4.380256,-0.4223298,0.01680179,0,0,0,0,0,4.380256,12.16738,0.4223298,0,12.97372,-4.380256,14757.45
44.4,-4.439989,-0.425574,0.01693085,0,0,0,0,0,4.439989,12.3333,0.4255739,0,13.16281,-4.439989,14842.72
45,-4.500256,-0.4283466,0.01704116,0,0,0,0,0,4.500256,12.50071,0.4283466,0,13.35395,-4.500256,14910.89
45.6,-4.559855,-0.4308676,0.01714145,0,0,0,0,0,4.559855,12.66627,0.4308676,0,13.54334,-4.559855,14970.27
46.2,-4.620389,-0.4349402,0.01730347,0,0,0,0,0,4.620389,12.83441,0.4349402,0,13.73606,-4.620389,15082.67
46.8,-4.680389,-0.4377647,0.01741584,0,0,0,0,0,4.680388,13.00108,0.4377647,0,13.92745,-4.680389,15151.59
47.4,-4.740122,-0.4410785,0.01754768,0,0,0,0,0,4.740122,13.167,0.4410785,0,14.11835,-4.740122,15237.17
48,-4.800522,-0.4437755,0.01765497,0,0,0,0,0,4.800522,13.33478,0.4437755,0,14.31176,-4.800522,15300.72
48.6,-4.860255,-0.445571,0.0177264,0,0,0,0,0,4.860255,13.50071,0.445571,0,14.5034,-4.860255,15333.21
49.2,-4.920388,-0.4492714,0.01787362,0,0,0,0,0,4.920388,13.66774,0.4492714,0,14.69669,-4.920388,15430.7
49.8,-4.980254,-0.4516634,0.01796878,0,0,0,0,0,4.980255,13.83404,0.4516634,0,14.8895,-4.980254,15482.97
50.4,-5.040254,-0.4550434,0.01810325,0,0,0,0,0,5.040255,14.00071,0.4550434,0,15.08311,-5.040254,15568.67
51,-5.100388,-0.4582029,0.01822895,0,0,0,0,0,5.100388,14.16774,0.4582029,0,15.27753,-5.100388,15646.32
51.6,-5.160388,-0.4599777,0.01829955,0,0,0,0,0,5.160388,14.33441,0.4599777,0,15.4719,-5.160388,15676.42
52.2,-5.219987,-0.4625142,0.01840047,0,0,0,0,0,5.219987,14.49996,0.4625142,0,15.66534,-5.219987,15732.41
52.8,-5.280387,-0.465052,0.01850143,0,0,0,0,0,5.280387,14.66774,0.465052,0,15.86176,-5.280387,15787.69
53.4,-5.340253,-0.4683215,0.0186315,0,0,0,0,0,5.340253,14.83404,0.4683215,0,16.05683,-5.340253,15867.7
54,-5.40012,-0.4703327,0.01871151,0,0,0,0,0,5.40012,15.00033,0.4703327,0,16.25229,-5.40012,15904.73
54.6,-5.460387,-0.4734615,0.01883599,0,0,0,0,0,5.460387,15.16774,0.4734615,0,16.44943,-5.460387,15979
55.2,-5.52012,-0.4761144,0.01894153,0,0,0,0,0,5.52012,15.33367,0.4761144,0,16.64521,-5.52012,16037.1
55.8,-5.580387,-0.4787255,0.01904541,0,0,0,0,0,5.580387,15.50107,0.4787255,0,16.84314,-5.580387,16093.17
56.4,-5.64012,-0.4807442,0.01912572,0,0,0,0,0,5.64012,15.667,0.4807442,0,17.03969,-5.64012,16129.29
57,-5.700253,-0.4832448,0.0192252,0,0,0,0,0,5.700253,15.83404,0.4832448,0,17.23796,-5.700253,16181.08
57.6,-5.759986,-0.4855396,0.0193165,0,0,0,0,0,5.759986,15.99996,0.4855396,0,17.43529,-5.759986,16225.87
58.2,-5.820252,-0.4881413,0.01942,0,0,0,0,0,5.820252,16.16737,0.4881413,0,17.63479,-5.820252,16280.3
58.8,-5.879852,-0.4907861,0.01952522,0,0,0,0,0,5.879852,16.33292,0.4907861,0,17.83246,-5.879852,16336.18
59.4,-5.940252,-0.4932486,0.01962319,0,0,0,0,0,5.940252,16.5007,0.4932486,0,18.03319,-5.940252,16385.23
60,-6.000252,-0.4958359,0.01972612,0,0,0,0,0,6.000252,16.66737,0.4958359,0,18.233,-6.000252,16438.3
60.6,-6.059852,-0.497962,0.0198107,0,0,0,0,0,6.059852,16.83292,0.497962,0,18.43186,-6.059852,16475.98
61.2,-6.120385,-0.5011699,0.01993833,0,0,0,0,0,6.120385,17.00107,0.5011699,0,18.63425,-6.120385,16548.6
61.8,-6.179985,-0.5032713,0.02002193,0,0,0,0,0,6.179985,17.16663,0.5032713,0,18.83391,-6.179985,16584.84
62.4,-6.240118,-0.505885,0.02012591,0,0,0,0,0,6.240119,17.33366,0.5058851,0,19.03577,-6.240118,16637.36
63,-6.300118,-0.5080466,0.02021191,0,0,0,0,0,6.300118,17.50033,0.5080466,0,19.23759,-6.300118,16674.76
63.6,-6.360118,-0.5098251,0.02028266,0,0,0,0,0,6.360118,17.66699,0.5098251,0,19.43981,-6.360118,16699.33
64.2,-6.420118,-0.5131467,0.02041481,0,0,0,0,0,6.420118,17.83366,0.5131466,0,19.64245,-6.420118,16774.1
64.8,-6.480251,-0.5155461,0.02051026,0,0,0,0,0,6.480251,18.0007,0.5155461,0,19.84595,-6.480251,16818.27
65.4,-6.539984,-0.5169974,0.020568,0,0,0,0,0,6.539984,18.16662,0.5169973,0,20.0485,-6.539984,16831.49
66,-6.60025,-0.5203109,0.02069983,0,0,0,0,0,6.60025,18.33403,0.5203109,0,20.25328,-6.60025,16904.71
66.60001,-6.66025,-0.5220938,0.02077076,0,0,0,0,0,6.660251,18.5007,0.5220938,0,20.45757,-6.66025,16928.02
67.20001,-6.71985,-0.5252762,0.02089736,0,0,0,0,0,6.719851,18.66625,0.5252762,0,20.66092,-6.71985,16996.61
67.8,-6.780384,-0.5263948,0.02094186,0,0,0,0,0,6.780383,18.8344,0.5263948,0,20.86786,-6.780384,16997.59
68.4,-6.840117,-0.5285093,0.02102598,0,0,0,0,0,6.840117,19.00032,0.5285093,0,21.0725,-6.840117,17030.98
69,-6.90025,-0.5306652,0.02111176,0,0,0,0,0,6.900249,19.16736,0.5306652,0,21.27893,-6.90025,17065.19
69.60001,-6.96025,-0.5277425,0.02099548,0,0,0,0,0,6.960249,19.33403,0.5277424,0,21.48533,-6.96025,16936.21
70.20001,-7.020383,-0.5315157,0.02114559,0,0,0,0,0,7.020383,19.50106,0.5315157,0,21.69262,-7.020383,17021.98
70.8,-7.080383,-0.534279,0.02125552,0,0,0,0,0,7.080383,19.66773,0.5342789,0,21.89988,-7.080383,17075.04
71.4,-7.140383,-0.536117,0.02132865,0,0,0,0,0,7.140383,19.8344,0.536117,0,22.10756,-7.140383,17098.24
72,-7.200249,-0.5395725,0.02146612,0,0,0,0,0,7.20025,20.00069,0.5395725,0,22.31522,-7.200249,17172.75
72.60001,-7.260382,-0.5409757,0.02152194,0,0,0,0,0,7.260382,20.16773,0.5409757,0,22.52424,-7.260382,17181.46
73.20001,-7.320382,-0.5438684,0.02163703,0,0,0,0,0,7.320382,20.33439,0.5438684,0,22.73322,-7.320382,17237.27
73.8,-7.379982,-0.5466877,0.02174919,0,0,0,0,0,7.379982,20.49995,0.5466877,0,22.94125,-7.379982,17290.61
74.4,-7.440515,-0.5478454,0.02179524,0,0,0,0,0,7.440516,20.6681,0.5478454,0,23.15298,-7.440515,17290.58
75,-7.500515,-0.5499016,0.02187705,0,0,0,0,0,7.500515,20.83476,0.5499017,0,23.36329,-7.500515,17319.02
75.60001,-7.560382,-0.5525368,0.02198189,0,0,0,0,0,7.560382,21.00106,0.5525368,0,23.57358,-7.560382,17365.46
76.20001,-7.620381,-0.5544321,0.02205729,0,0,0,0,0,7.620381,21.16772,0.5544321,0,23.78477,-7.620381,17388.26
76.8,-7.680381,-0.5574901,0.02217894,0,0,0,0,0,7.680381,21.33439,0.5574901,0,23.99641,-7.680381,17447.2
77.4,-7.740248,-0.5594067,0.0222552,0,0,0,0,0,7.740247,21.50069,0.5594067,0,24.20803,-7.740248,17470.18
78,-7.800248,-0.561675,0.02234544,0,0,0,0,0,7.800248,21.66735,0.561675,0,24.42057,-7.800248,17503.77
78.60001,-7.860248,-0.5630576,0.02240044,0,0,0,0,0,7.860248,21.83402,0.5630576,0,24.63357,-7.860248,17509.52
79.20001,-7.920114,-0.5663848,0.02253281,0,0,0,0,0,7.920115,22.00032,0.5663848,0,24.84654,-7.920114,17575.52
79.8,-7.980381,-0.567227,0.02256631,0,0,0,0,0,7.980381,22.16772,0.567227,0,25.0614,-7.980381,17563.88
80.4,-8.039847,-0.5691893,0.02264438,0,0,0,0,0,8.039847,22.33291,0.5691893,0,25.27385,-8.039847,17587.23
81.00001,-8.100513,-0.572102,0.02276026,0,0,0,0,0,8.100513,22.50143,0.572102,0,25.49107,-8.100513,17638.88
81.60001,-8.160247,-0.573089,0.02279953,0,0,0,0,0,8.160247,22.66735,0.5730889,0,25.7054,-8.160247,17631.48
82.20001,-8.220114,-0.575639,0.02290097,0,0,0,0,0,8.220114,22.83365,0.575639,0,25.92067,-8.220114,17671.85
82.8,-8.280247,-0.578446,0.02301265,0,0,0,0,0,8.280247,23.00068,0.578446,0,26.13737,-8.280247,17719.58
83.4,-8.340113,-0.5799245,0.02307147,0,0,0,0,0,8.340113,23.16698,0.5799245,0,26.35357,-8.340113,17726.5
84.00001,-8.400113,-0.5813568,0.02312845,0,0,0,0,0,8.400113,23.33365,0.5813568,0,26.57073,-8.400113,17731.74
84.60001,-8.460113,-0.5833529,0.02320786,0,0,0,0,0,8.460113,23.50031,0.5833529,0,26.78835,-8.460113,17753.94
85.20001,-8.519979,-0.5857754,0.02330424,0,0,0,0,0,8.519979,23.66661,0.5857754,0,27.00597,-8.519979,17788.91
85.8,-8.580113,-0.5877709,0.02338363,0,0,0,0,0,8.580112,23.83365,0.5877709,0,27.22504,-8.580113,17810.46
86.4,-8.640246,-0.5898631,0.02346686,0,0,0,0,0,8.640245,24.00068,0.5898631,0,27.44458,-8.640246,17834.65
87.00001,-8.699846,-0.5925263,0.02357281,0,0,0,0,0,8.699845,24.16624,0.5925263,0,27.66266,-8.699846,17876.15
87.60001,-8.760246,-0.5929215,0.02358853,0,0,0,0,0,8.760245,24.33401,0.5929214,0,27.88415,-8.760246,17848.49
88.20001,-8.820112,-0.5960017,0.02371107,0,0,0,0,0,8.820112,24.50031,0.5960017,0,28.10416,-8.820112,17901.79
88.8,-8.880111,-0.5993349,0.02384368,0,0,0,0,0,8.880112,24.66698,0.5993349,0,28.32516,-8.880111,17962.17
89.4,-8.940245,-0.6009897,0.02390951,0,0,0,0,0,8.940245,24.83401,0.6009896,0,28.54714,-8.940245,17971.82
90.00001,-8.999978,-0.6033516,0.02400348,0,0,0,0,0,8.999978,24.99994,0.6033516,0,28.76813,-8.999978,18002.63
90.60001,-9.060245,-0.6059849,0.02410824,0,0,0,0,0,9.060245,25.16735,0.6059849,0,28.99159,-9.060245,18040.84
91.20001,-9.119978,-0.6097402,0.02425764,0,0,0,0,0,9.119978,25.33327,0.6097402,0,29.21356,-9.119978,18112.39
91.8,-9.180111,-0.6120496,0.02434952,0,0,0,0,0,9.180111,25.50031,0.6120496,0,29.43752,-9.180111,18140.32
92.4,-9.240111,-0.6155401,0.02448838,0,0,0,0,0,9.240111,25.66698,0.61554,0,29.66149,-9.240111,18202.95
93.00001,-9.300244,-0.6186477,0.02461202,0,0,0,0,0,9.300244,25.83401,0.6186477,0,29.88645,-9.300244,18253.74
93.60001,-9.359977,-0.6209898,0.02470519,0,0,0,0,0,9.359977,25.99994,0.6209898,0,30.11042,-9.359977,18281.86
94.20001,-9.42051,-0.6248103,0.02485719,0,0,0,0,0,9.42051,26.16809,0.6248103,0,30.33791,-9.42051,18352.54
94.8,-9.480244,-0.6280855,0.02498748,0,0,0,0,0,9.480244,26.33401,0.6280855,0,30.5629,-9.480244,18407.28
95.4,-9.54011,-0.6312872,0.02511486,0,0,0,0,0,9.54011,26.50031,0.6312872,0,30.78889,-9.54011,18459.34
96.00001,-9.60051,-0.6345688,0.02524541,0,0,0,0,0,9.60051,26.66808,0.6345688,0,31.01742,-9.60051,18512.94
96.60001,-9.660376,-0.6375799,0.02536521,0,0,0,0,0,9.660377,26.83438,0.6375799,0,31.24445,-9.660376,18558.61
97.20001,-9.72051,-0.6408534,0.02549544,0,0,0,0,0,9.72051,27.00142,0.6408534,0,31.47301,-9.72051,18611.31
97.8,-9.780243,-0.645141,0.02566601,0,0,0,0,0,9.780243,27.16734,0.6451409,0,31.70057,-9.780243,18693.24
98.4,-9.840376,-0.6485948,0.02580342,0,0,0,0,0,9.840376,27.33438,0.6485948,0,31.93018,-9.840376,18750.21
99.00001,-9.900376,-0.6522152,0.02594745,0,0,0,0,0,9.900376,27.50105,0.6522152,0,32.1598,-9.900376,18811.63
99.60001,-9.960376,-0.6547168,0.02604697,0,0,0,0,0,9.960376,27.66771,0.6547168,0,32.38996,-9.960376,18840.37
100.2,-10.02011,-0.6583367,0.02619098,0,0,0,0,0,10.02011,27.83364,0.6583368,0,32.61961,-10.02011,18901.08
100.8,-10.08038,-0.661944,0.0263345,0,0,0,0,0,10.08038,28.00104,0.661944,0,32.85186,-10.08038,18960.56
101.4,-10.14038,-0.6649814,0.02645533,0,0,0,0,0,10.14038,28.16771,0.6649814,0,33.08361,-10.14038,19003.47
102,-10.19998,-0.6689903,0.02661482,0,0,0,0,0,10.19998,28.33327,0.6689903,0,33.31435,-10.19998,19073.97
102.6,-10.26038,-0.6734167,0.02679092,0,0,0,0,0,10.26038,28.50104,0.6734167,0,33.54873,-10.26038,19155.23
103.2,-10.32011,-0.6785962,0.02699698,0,0,0,0,0,10.32011,28.66697,0.6785962,0,33.78107,-10.32011,19257.76
103.8,-10.38024,-0.6835507,0.02719408,0,0,0,0,0,10.38024,28.834,0.6835507,0,34.01551,-10.38024,19352.94
104.4,-10.44024,-0.6885762,0.02739402,0,0,0,0,0,10.44024,29.00067,0.6885762,0,34.24998,-10.44024,19449.57
105,-10.50024,-0.694148,0.02761569,0,0,0,0,0,10.50024,29.16734,0.694148,0,34.48499,-10.50024,19560.93
105.6,-10.55997,-0.6995071,0.02782889,0,0,0,0,0,10.55997,29.33326,0.6995071,0,34.71952,-10.55997,19665.77
106.2,-10.62024,-0.7071327,0.02813227,0,0,0,0,0,10.62024,29.50067,0.7071328,0,34.9567,-10.62024,19833.06
106.8,-10.67997,-0.7138917,0.02840116,0,0,0,0,0,10.67997,29.6666,0.7138917,0,35.19233,-10.67997,19975.5
107.4,-10.74037,-0.7213693,0.02869865,0,0,0,0,0,10.74037,29.83437,0.7213693,0,35.43116,-10.74037,20136.58
108,-10.80024,-0.7288675,0.02899695,0,0,0,0,0,10.80024,30.00067,0.7288675,0,35.66845,-10.80024,20297.67
108.6,-10.85997,-0.736012,0.02928119,0,0,0,0,0,10.85997,30.16659,0.736012,0,35.90577,-10.85997,20448.05
109.2,-10.92037,-0.7450132,0.02963929,0,0,0,0,0,10.92037,30.33437,0.7450132,0,36.14631,-10.92037,20648.39
109.8,-10.97997,-0.7537709,0.0299877,0,0,0,0,0,10.97997,30.49993,0.7537709,0,36.38424,-10.97997,20841.47
110.4,-11.04011,-0.7621492,0.03032102,0,0,0,0,0,11.04011,30.66696,0.7621492,0,36.62487,-11.04011,21022.48
111,-11.10011,-0.771493,0.03069275,0,0,0,0,0,11.10011,30.83363,0.771493,0,36.86554,-11.10011,21229.06
111.6,-11.16024,-0.7808831,0.03106632,0,0,0,0,0,11.16024,31.00067,0.7808831,0,37.10733,-11.16024,21435.55
112.2,-11.22011,-0.7922137,0.03151709,0,0,0,0,0,11.22011,31.16696,0.7922137,0,37.34863,-11.22011,21694.17
112.8,-11.28011,-0.8016353,0.03189192,0,0,0,0,0,11.28011,31.33363,0.8016353,0,37.59106,-11.28011,21899.02
113.4,-11.33997,-0.8120584,0.03230658,0,0,0,0,0,11.33997,31.49992,0.8120584,0,37.83353,-11.33997,22130.03
114,-11.40024,-0.8225268,0.03272305,0,0,0,0,0,11.40024,31.66733,0.8225268,0,38.07822,-11.40024,22360.54
114.6,-11.46037,-0.8335014,0.03315966,0,0,0,0,0,11.46037,31.83437,0.8335015,0,38.32297,-11.46037,22603.49
115.2,-11.51997,-0.8454017,0.0336331,0,0,0,0,0,11.51997,31.99992,0.8454018,0,38.56613,-11.51997,22870.53
115.8,-11.58037,-0.8558186,0.03404752,0,0,0,0,0,11.58037,32.1677,0.8558186,0,38.81317,-11.58037,23095.21
116.4,-11.64011,-0.8669494,0.03449034,0,0,0,0,0,11.64011,32.33363,0.8669494,0,39.05808,-11.64011,23338.36
117,-11.70024,-0.8790968,0.03497361,0,0,0,0,0,11.70024,32.50066,0.8790967,0,39.30523,-11.70024,23606.95
117.6,-11.76024,-0.889719,0.0353962,0,0,0,0,0,11.76024,32.66733,0.8897189,0,39.55246,-11.76024,23833.21
118.2,-11.8205,-0.902188,0.03589226,0,0,0,0,0,11.82051,32.83474,0.9021879,0,39.8014,-11.8205,24107.13
118.8,-11.88037,-0.9125455,0.03630432,0,0,0,0,0,11.88037,33.00103,0.9125455,0,40.04929,-11.88037,24323.52
119.4,-11.94037,-0.9236346,0.03674548,0,0,0,0,0,11.94037,33.1677,0.9236346,0,40.29837,-11.94037,24557.85
120,-12.00024,-0.9349343,0.03719502,0,0,0,0,0,12.00024,33.33399,0.9349343,0,40.5475,-12.00024,24796.44
120.6,-12.0605,-0.9457479,0.03762523,0,0,0,0,0,12.0605,33.5014,0.9457479,0,40.79893,-12.0605,25020.25
121.2,-12.1205,-0.957843,0.03810642,0,0,0,0,0,12.12051,33.66807,0.957843,0,41.04988,-12.1205,25276.72
121.8,-12.17997,-0.9682176,0.03851916,0,0,0,0,0,12.17997,33.83325,0.9682176,0,41.29921,-12.17997,25486.87
122.4,-12.2405,-0.9788986,0.03894408,0,0,0,0,0,12.2405,34.0014,0.9788985,0,41.55367,-12.2405,25702.55
123,-12.30024,-0.9908238,0.03941851,0,0,0,0,0,12.30024,34.16732,0.9908239,0,41.80539,-12.30024,25950.26
123.6,-12.36037,-1.001279,0.03983445,0,0,0,0,0,12.36037,34.33436,1.001279,0,42.05944,-12.36037,26157.55
124.2,-12.42024,-1.01296,0.04029915,0,0,0,0,0,12.42024,34.50066,1.01296,0,42.31301,-12.42024,26395.68
124.8,-12.48037,-1.023685,0.04072586,0,0,0,0,0,12.48037,34.66769,1.023685,0,42.56835,-12.48037,26607.14
125.4,-12.54024,-1.034948,0.04117395,0,0,0,0,0,12.54024,34.83399,1.034948,0,42.82322,-12.54024,26831.42
126,-12.60024,-1.045588,0.04159721,0,0,0,0,0,12.60024,35.00066,1.045588,0,43.0793,-12.60024,27037.92
126.6,-12.6601,-1.055818,0.04200422,0,0,0,0,0,12.6601,35.16695,1.055818,0,43.33548,-12.6601,27232.62
127.2,-12.7201,-1.066139,0.04241483,0,0,0,0,0,12.7201,35.33362,1.066139,0,43.59287,-12.7201,27428.14
127.8,-12.78024,-1.077665,0.04287335,0,0,0,0,0,12.78024,35.50065,1.077665,0,43.85151,-12.78024,27653.03
128.4,-12.83997,-1.087954,0.04328268,0,0,0,0,0,12.83997,35.66658,1.087954,0,44.1091,-12.83997,27845.23
129,-12.90024,-1.098359,0.04369663,0,0,0,0,0,12.90024,35.83399,1.098359,0,44.36965,-12.90024,28038.39
129.6,-12.96023,-1.109433,0.04413721,0,0,0,0,0,12.96023,36.00065,1.109433,0,44.62973,-12.96023,28247.53
130.2,-13.0201,-1.11976,0.04454805,0,0,0,0,0,13.0201,36.16695,1.11976,0,44.88991,-13.0201,28436.38
130.8,-13.08023,-1.13019,0.04496299,0,0,0,0,0,13.08023,36.33398,1.13019,0,45.15193,-13.08023,28626.15
131.4,-13.1401,-1.140333,0.0453665,0,0,0,0,0,13.1401,36.50028,1.140332,0,45.41347,-13.1401,28807.6
132,-13.20023,-1.151693,0.04581845,0,0,0,0,0,13.20024,36.66732,1.151693,0,45.67687,-13.20023,29018.05
132.6,-13.2601,-1.160532,0.0461701,0,0,0,0,0,13.2601,36.83361,1.160532,0,45.93979,-13.2601,29163.98
133.2,-13.31997,-1.171876,0.04662139,0,0,0,0,0,13.31997,36.99991,1.171875,0,46.2034,-13.31997,29371.52
133.8,-13.3801,-1.181973,0.04702312,0,0,0,0,0,13.3801,37.16695,1.181973,0,46.46889,-13.3801,29546.06
134.4,-13.4401,-1.192493,0.04744163,0,0,0,0,0,13.4401,37.33361,1.192493,0,46.73449,-13.4401,29729.96
135,-13.49983,-1.2026,0.04784374,0,0,0,0,0,13.49983,37.49954,1.2026,0,46.99962,-13.49983,29902.56
135.6,-13.56023,-1.21271,0.04824593,0,0,0,0,0,13.56023,37.66732,1.21271,0,47.26843,-13.56023,30072.98
136.2,-13.6201,-1.222608,0.04863972,0,0,0,0,0,13.6201,37.83361,1.222608,0,47.53557,-13.6201,30237.56
136.8,-13.6801,-1.233556,0.04907526,0,0,0,0,0,13.6801,38.00027,1.233556,0,47.80402,-13.6801,30426.53
137.4,-13.74023,-1.243149,0.04945691,0,0,0,0,0,13.74023,38.16731,1.243149,0,48.0738,-13.74023,30580.54
138,-13.79997,-1.254338,0.04990205,0,0,0,0,0,13.79997,38.33324,1.254338,0,48.34251,-13.79997,30772.98
138.6,-13.86023,-1.263831,0.05027971,0,0,0,0,0,13.86023,38.50065,1.263831,0,48.61435,-13.86023,30921.69
139.2,-13.91997,-1.27419,0.05069182,0,0,0,0,0,13.91997,38.66657,1.27419,0,48.88452,-13.91997,31091.03
139.8,-13.98037,-1.284533,0.0511033,0,0,0,0,0,13.98037,38.83435,1.284533,0,49.15844,-13.98037,31257.67
140.4,-14.04023,-1.295204,0.05152786,0,0,0,0,0,14.04023,39.00064,1.295204,0,49.43069,-14.04023,31431.66
141,-14.10037,-1.305834,0.05195076,0,0,0,0,0,14.10037,39.16768,1.305834,0,49.7049,-14.10037,31602.85
141.6,-14.15997,-1.314955,0.05231359,0,0,0,0,0,14.15997,39.33324,1.314955,0,49.97742,-14.15997,31736.96
142.2,-14.22037,-1.32648,0.0527721,0,0,0,0,0,14.22037,39.50101,1.32648,0,50.25436,-14.22037,31926.59
142.8,-14.28023,-1.33711,0.05319501,0,0,0,0,0,14.28023,39.66731,1.33711,0,50.52961,-14.28023,32093.98
143.4,-14.3401,-1.347735,0.05361772,0,0,0,0,0,14.3401,39.83361,1.347735,0,50.80562,-14.3401,32259.85
144,-14.4005,-1.357872,0.05402101,0,0,0,0,0,14.4005,40.00138,1.357872,0,51.08487,-14.4005,32411.86
144.6,-14.46036,-1.367226,0.05439311,0,0,0,0,0,14.46036,40.16768,1.367226,0,51.36242,-14.46036,32544.66
145.2,-14.5205,-1.378916,0.05485818,0,0,0,0,0,14.5205,40.33472,1.378916,0,51.64199,-14.5205,32731.29
145.8,-14.58023,-1.389658,0.05528558,0,0,0,0,0,14.58023,40.50064,1.389658,0,51.92047,-14.58023,32894.56
146.4,-14.64036,-1.400578,0.05572001,0,0,0,0,0,14.64036,40.66768,1.400578,0,52.2016,-14.64036,33059.97
147,-14.70036,-1.411116,0.05613925,0,0,0,0,0,14.70037,40.83435,1.411116,0,52.4829,-14.70036,33215.15
147.6,-14.76036,-1.421199,0.05654036,0,0,0,0,0,14.76036,41.00101,1.421199,0,52.76499,-14.76036,33358.24
148.2,-14.81996,-1.431563,0.05695269,0,0,0,0,0,14.81996,41.16656,1.431563,0,53.04599,-14.81996,33507.22
148.8,-14.88036,-1.441677,0.05735507,0,0,0,0,0,14.88036,41.33434,1.441677,0,53.33157,-14.88036,33647.73
149.4,-14.94036,-1.452822,0.05779845,0,0,0,0,0,14.94036,41.50101,1.452822,0,53.61607,-14.94036,33811.51
150,-15.00023,-1.463353,0.0582174,0,0,0,0,0,15.00023,41.6673,1.463353,0,53.90074,-15.00023,33959.78
150.6,-15.0605,-1.474503,0.05866099,0,0,0,0,0,15.0605,41.83471,1.474503,0,54.18814,-15.0605,34120.33
151.2,-15.12023,-1.485,0.05907859,0,0,0,0,0,15.12023,42.00064,1.485,0,54.47382,-15.12023,34265.21
151.8,-15.1805,-1.495599,0.05950026,0,0,0,0,0,15.1805,42.16805,1.495599,0,54.76287,-15.1805,34410.16
152.4,-15.2401,-1.506387,0.05992945,0,0,0,0,0,15.2401,42.3336,1.506387,0,55.04956,-15.2401,34559.15
153,-15.3001,-1.516775,0.06034272,0,0,0,0,0,15.3001,42.50027,1.516775,0,55.33899,-15.3001,34696.9
153.6,-15.3601,-1.525205,0.06067812,0,0,0,0,0,15.3601,42.66693,1.525205,0,55.62926,-15.3601,34788.63
154.2,-15.42023,-1.533674,0.06101501,0,0,0,0,0,15.42023,42.83397,1.533674,0,55.92103,-15.42023,34879.86
154.8,-15.47983,-1.542406,0.06136243,0,0,0,0,0,15.47983,42.99953,1.542406,0,56.21106,-15.47983,34976.88
155.4,-15.54023,-1.552944,0.06178167,0,0,0,0,0,15.54023,43.1673,1.552944,0,56.50583,-15.54023,35112.19
156,-15.60023,-1.56455,0.0622434,0,0,0,0,0,15.60023,43.33397,1.56455,0,56.79952,-15.60023,35270.87
156.6,-15.65996,-1.575581,0.06268223,0,0,0,0,0,15.65996,43.49989,1.575581,0,57.09277,-15.65996,35415.52
157.2,-15.72023,-1.587176,0.06314353,0,0,0,0,0,15.72023,43.6673,1.587176,0,57.38951,-15.72023,35570.45
157.8,-15.7801,-1.598035,0.06357552,0,0,0,0,0,15.7801,43.8336,1.598035,0,57.68514,-15.7801,35708.09
158.4,-15.84009,-1.609457,0.06402996,0,0,0,0,0,15.84009,44.00026,1.609457,0,57.98232,-15.84009,35856.61
159,-15.90009,-1.620205,0.06445756,0,0,0,0,0,15.90009,44.16693,1.620205,0,58.28038,-15.90009,35988.63
159.6,-15.9601,-1.631756,0.0649171,0,0,0,0,0,15.9601,44.3336,1.631756,0,58.57934,-15.9601,36137.01
160.2,-16.01996,-1.644361,0.06541856,0,0,0,0,0,16.01996,44.49989,1.644361,0,58.87852,-16.01996,36307.37
160.8,-16.08009,-1.654914,0.06583837,0,0,0,0,0,16.0801,44.66693,1.654914,0,59.17994,-16.08009,36430.4
161.4,-16.13996,-1.666644,0.06630506,0,0,0,0,0,16.13996,44.83323,1.666644,0,59.48094,-16.13996,36578.36
162,-16.20023,-1.678633,0.066782,0,0,0,0,0,16.20023,45.00063,1.678632,0,59.78485,-16.20023,36729.67
162.6,-16.26036,-1.689527,0.0672154,0,0,0,0,0,16.26036,45.16767,1.689527,0,60.08902,-16.26036,36855.77
163.2,-16.31996,-1.70245,0.06772954,0,0,0,0,0,16.31996,45.33322,1.70245,0,60.3914,-16.31996,37025.56
163.8,-16.38036,-1.713283,0.06816051,0,0,0,0,0,16.38036,45.501,1.713283,0,60.69879,-16.38036,37146.8
164.4,-16.44009,-1.724039,0.06858844,0,0,0,0,0,16.44009,45.66693,1.724039,0,61.00371,-16.44009,37266.21
165,-16.50023,-1.736579,0.0690873,0,0,0,0,0,16.50023,45.83397,1.736579,0,61.31161,-16.50023,37421.85
165.6,-16.56036,-1.747888,0.06953721,0,0,0,0,0,16.56036,46.001,1.747887,0,61.62047,-16.56036,37549.39
166.2,-16.62036,-1.760508,0.0700393,0,0,0,0,0,16.62036,46.16767,1.760508,0,61.92959,-16.62036,37703.79
166.8,-16.68036,-1.772072,0.07049935,0,0,0,0,0,16.68036,46.33433,1.772072,0,62.23967,-16.68036,37833.94
167.4,-16.74036,-1.783726,0.07096299,0,0,0,0,0,16.74036,46.501,1.783726,0,62.55072,-16.74036,37964.49
168,-16.80023,-1.796775,0.07148213,0,0,0,0,0,16.80023,46.6673,1.796775,0,62.86205,-16.80023,38123.35
168.6,-16.86036,-1.80861,0.07195296,0,0,0,0,0,16.86036,46.83433,1.80861,0,63.17573,-16.86036,38254.28
169.2,-16.92049,-1.820581,0.07242922,0,0,0,0,0,16.92049,47.00137,1.820581,0,63.49041,-16.92049,38386.5
169.8,-16.97996,-1.830837,0.07283725,0,0,0,0,0,16.97996,47.16655,1.830837,0,63.80257,-16.97996,38482.43
170.4,-17.04049,-1.841767,0.07327207,0,0,0,0,0,17.04049,47.3347,1.841767,0,64.12134,-17.04049,38588.95
171,-17.10036,-1.853892,0.07375443,0,0,0,0,0,17.10036,47.501,1.853892,0,64.4376,-17.10036,38720.34
171.6,-17.16023,-1.865926,0.0742332,0,0,0,0,0,17.16022,47.66729,1.865926,0,64.75486,-17.16023,38848.24
172.2,-17.22036,-1.878857,0.07474764,0,0,0,0,0,17.22036,47.83433,1.878857,0,65.07455,-17.22036,38992.61
172.8,-17.28022,-1.891426,0.07524767,0,0,0,0,0,17.28022,48.00063,1.891426,0,65.39385,-17.28022,39128.32
173.4,-17.34022,-1.904833,0.07578104,0,0,0,0,0,17.34022,48.16729,1.904833,0,65.71488,-17.34022,39279.37
174,-17.40036,-1.918477,0.07632387,0,0,0,0,0,17.40036,48.33433,1.918477,0,66.03766,-17.40036,39433.24
174.6,-17.46009,-1.930085,0.07678568,0,0,0,0,0,17.46009,48.50025,1.930085,0,66.35933,-17.46009,39544.43
175.2,-17.51996,-1.943666,0.07732598,0,0,0,0,0,17.51996,48.66655,1.943666,0,66.68276,-17.51996,39694.09
175.8,-17.58022,-1.956305,0.07782879,0,0,0,0,0,17.58022,48.83396,1.956305,0,67.00941,-17.58022,39821.91
176.4,-17.63996,-1.969117,0.07833849,0,0,0,0,0,17.63996,48.99988,1.969117,0,67.33422,-17.63996,39952.72
177,-17.70036,-1.982904,0.07888702,0,0,0,0,0,17.70036,49.16766,1.982904,0,67.66374,-17.70036,40100.12
177.6,-17.76022,-1.99407,0.07933123,0,0,0,0,0,17.76022,49.33395,1.99407,0,67.99142,-17.76022,40194
178.2,-17.82009,-2.008157,0.07989166,0,0,0,0,0,17.82009,49.50025,2.008157,0,68.32018,-17.82009,40345.09
178.8,-17.88022,-2.021497,0.08042237,0,0,0,0,0,17.88022,49.66729,2.021497,0,68.6515,-17.88022,40478.76
179.4,-17.94009,-2.034804,0.08095175,0,0,0,0,0,17.94009,49.83358,2.034804,0,68.98243,-17.94009,40610.6
180,-18.00022,-2.050117,0.08156099,0,0,0,0,0,18.00022,50.00062,2.050117,0,69.31596,-18.00022,40779.99
180.6,-18.06009,-2.061736,0.08202325,0,0,0,0,0,18.06009,50.16692,2.061737,0,69.64911,-18.06009,40874.71
181.2,-18.11996,-2.07463,0.08253618,0,0,0,0,0,18.11996,50.33321,2.07463,0,69.98337,-18.11996,40993.07
181.8,-18.17996,-2.089216,0.08311649,0,0,0,0,0,18.17996,50.49988,2.089216,0,70.31951,-18.17996,41142.76
182.4,-18.24022,-2.101976,0.08362412,0,0,0,0,0,18.24022,50.66729,2.101976,0,70.65827,-18.24022,41254.05
183,-18.29996,-2.117167,0.08422848,0,0,0,0,0,18.29996,50.83321,2.117167,0,70.99518,-18.29996,41412.44
183.6,-18.36022,-2.130673,0.08476578,0,0,0,0,0,18.36022,51.00061,2.130673,0,71.33625,-18.36022,41534.71
184.2,-18.42009,-2.145003,0.08533587,0,0,0,0,0,18.42009,51.16692,2.145003,0,71.67621,-18.42009,41672.14
184.8,-18.48022,-2.159801,0.08592459,0,0,0,0,0,18.48022,51.33395,2.159801,0,72.01886,-18.48022,41816.1
185.4,-18.54022,-2.174374,0.08650438,0,0,0,0,0,18.54022,51.50062,2.174374,0,72.36191,-18.54022,41954.09
186,-18.59996,-2.188741,0.08707595,0,0,0,0,0,18.59995,51.66654,2.188741,0,72.70462,-18.59996,42086.82
186.6,-18.66022,-2.201918,0.08760016,0,0,0,0,0,18.66022,51.83395,2.201918,0,73.05157,-18.66022,42193.54
187.2,-18.71995,-2.217927,0.08823706,0,0,0,0,0,18.71995,51.99987,2.217927,0,73.39665,-18.71995,42353.9
187.8,-18.78035,-2.232334,0.08881021,0,0,0,0,0,18.78035,52.16765,2.232334,0,73.7468,-18.78035,42480.01
188.4,-18.84009,-2.246293,0.08936557,0,0,0,0,0,18.84009,52.33358,2.246294,0,74.09429,-18.84009,42597.37
189,-18.90035,-2.260576,0.08993379,0,0,0,0,0,18.90035,52.50098,2.260576,0,74.44611,-18.90035,42717.67
189.6,-18.95995,-2.273865,0.09046245,0,0,0,0,0,18.95996,52.66654,2.273865,0,74.79527,-18.95995,42819.01
190.2,-19.02035,-2.289612,0.09108896,0,0,0,0,0,19.02036,52.83432,2.289612,0,75.15036,-19.02035,42962.73
190.8,-19.08035,-2.304269,0.09167206,0,0,0,0,0,19.08035,53.00098,2.304269,0,75.50435,-19.08035,43084.97
191.4,-19.14009,-2.31961,0.09228236,0,0,0,0,0,19.14009,53.16691,2.31961,0,75.85802,-19.14009,43218.68
192,-19.20035,-2.334043,0.09285655,0,0,0,0,0,19.20035,53.33431,2.334043,0,76.21611,-19.20035,43332.15
192.6,-19.26022,-2.348554,0.09343388,0,0,0,0,0,19.26022,53.50061,2.348554,0,76.5731,-19.26022,43446.18
193.2,-19.32035,-2.364722,0.09407709,0,0,0,0,0,19.32035,53.66765,2.364722,0,76.93298,-19.32035,43588.13
193.8,-19.38022,-2.380822,0.09471761,0,0,0,0,0,19.38022,53.83394,2.380822,0,77.29253,-19.38022,43727.38
194.4,-19.44049,-2.396184,0.09532876,0,0,0,0,0,19.44049,54.00135,2.396184,0,77.65582,-19.44049,43849.94
195,-19.50035,-2.411552,0.09594015,0,0,0,0,0,19.50035,54.16764,2.411552,0,78.01799,-19.50035,43971.63
195.6,-19.56035,-2.427014,0.09655529,0,0,0,0,0,19.56035,54.33431,2.427014,0,78.3823,-19.56035,44092.64
196.2,-19.62009,-2.44304,0.09719284,0,0,0,0,0,19.62008,54.50024,2.44304,0,78.74631,-19.62009,44222.51
196.8,-19.68035,-2.459496,0.09784753,0,0,0,0,0,19.68035,54.66765,2.459496,0,79.11492,-19.68035,44356.59
197.4,-19.74035,-2.47515,0.09847029,0,0,0,0,0,19.74035,54.83431,2.47515,0,79.48325,-19.74035,44474.78
198,-19.80022,-2.49186,0.09913507,0,0,0,0,0,19.80022,55.00061,2.491859,0,79.85211,-19.80022,44610.18
198.6,-19.86035,-2.50763,0.09976245,0,0,0,0,0,19.86035,55.16764,2.50763,0,80.22401,-19.86035,44725.86
199.2,-19.92008,-2.524378,0.1004288,0,0,0,0,0,19.92008,55.33357,2.524378,0,80.59479,-19.92008,44857.95
199.8,-19.98022,-2.54178,0.1011211,0,0,0,0,0,19.98022,55.50061,2.54178,0,80.96946,-19.98022,44998.28
200.4,-20.04022,-2.557783,0.1017577,0,0,0,0,0,20.04022,55.66727,2.557783,0,81.3447,-20.04022,45111.98
201,-20.10022,-2.573958,0.1024012,0,0,0,0,0,20.10022,55.83394,2.573958,0,81.72135,-20.10022,45226.59
201.6,-20.16008,-2.588216,0.1029685,0,0,0,0,0,20.16008,56.00024,2.588216,0,82.09859,-20.16008,45305.88
202.2,-20.22022,-2.602319,0.1035296,0,0,0,0,0,20.22022,56.16727,2.602319,0,82.47895,-20.22022,45379.83
202.8,-20.27982,-2.617266,0.1041242,0,0,0,0,0,20.27982,56.33282,2.617266,0,82.85735,-20.27982,45468.09
203.4,-20.34022,-2.632966,0.1047488,0,0,0,0,0,20.34022,56.5006,2.632966,0,83.24231,-20.34022,45565.09
204,-20.40022,-2.648392,0.1053625,0,0,0,0,0,20.40022,56.66727,2.648392,0,83.62619,-20.40022,45656.45
204.6,-20.45995,-2.664406,0.1059996,0,0,0,0,0,20.45995,56.83319,2.664406,0,84.00984,-20.45995,45756.63
205.2,-20.52022,-2.68118,0.1066669,0,0,0,0,0,20.52022,57.00061,2.68118,0,84.39841,-20.52022,45866.13
205.8,-20.58008,-2.698617,0.1073606,0,0,0,0,0,20.58008,57.1669,2.698617,0,84.7859,-20.58008,45985.88
206.4,-20.64008,-2.715787,0.1080437,0,0,0,0,0,20.64008,57.33356,2.715787,0,85.17576,-20.64008,46098.4
207,-20.70022,-2.732297,0.1087005,0,0,0,0,0,20.70022,57.5006,2.732297,0,85.56802,-20.70022,46197.07
207.6,-20.76022,-2.749289,0.1093765,0,0,0,0,0,20.76022,57.66727,2.749289,0,85.96095,-20.76022,46302.08
208.2,-20.82008,-2.766279,0.1100525,0,0,0,0,0,20.82008,57.83356,2.766279,0,86.35456,-20.82008,46405.2
208.8,-20.88035,-2.784875,0.1107923,0,0,0,0,0,20.88035,58.00097,2.784875,0,86.75236,-20.88035,46531.68
209.4,-20.93995,-2.801887,0.1114691,0,0,0,0,0,20.93995,58.16653,2.801887,0,87.14734,-20.93995,46631.38
210,-21.00022,-2.820419,0.1122063,0,0,0,0,0,21.00022,58.33393,2.820419,0,87.54831,-21.00022,46751.96
210.6,-21.06035,-2.839461,0.1129639,0,0,0,0,0,21.06035,58.50097,2.839461,0,87.95001,-21.06035,46878.92
211.2,-21.11995,-2.857262,0.1136721,0,0,0,0,0,21.11995,58.66652,2.857262,0,88.34974,-21.11995,46984.62
211.8,-21.18035,-2.875341,0.1143913,0,0,0,0,0,21.18035,58.8343,2.875341,0,88.75648,-21.18035,47089.99
212.4,-21.24008,-2.89489,0.1151691,0,0,0,0,0,21.24008,59.00023,2.89489,0,89.16037,-21.24008,47219.06
213,-21.30008,-2.913467,0.1159081,0,0,0,0,0,21.30008,59.16689,2.913467,0,89.5677,-21.30008,47328.88
[...]
86.70001,-8.669846,-2.903532,0.1155128,0,0,0,0,0,8.669846,47.8997,2.903532,0,65.19995,-8.669846,60182.54
87.00001,-8.699712,-2.919768,0.1161588,0,0,0,0,0,8.699713,48.06471,2.919768,0,65.51716,-8.699712,60327.41
87.3,-8.729845,-2.933339,0.1166987,0,0,0,0,0,8.729845,48.23119,2.933339,0,65.83823,-8.729845,60413.53
87.60001,-8.759979,-2.95083,0.1173946,0,0,0,0,0,8.759979,48.39767,2.95083,0,66.16035,-8.759979,60578.32
87.9,-8.790112,-2.965311,0.1179707,0,0,0,0,0,8.790112,48.56416,2.965311,0,66.48349,-8.790112,60679.21
88.20001,-8.819846,-2.980428,0.1185721,0,0,0,0,0,8.819845,48.72843,2.980428,0,66.80337,-8.819846,60793.77
88.50001,-8.849978,-2.995676,0.1191787,0,0,0,0,0,8.849978,48.89491,2.995676,0,67.12861,-8.849978,60906.37
88.8,-8.880111,-3.012721,0.1198568,0,0,0,0,0,8.880112,49.06139,3.012721,0,67.4549,-8.880111,61053.39
89.10001,-8.910112,-3.023578,0.1202887,0,0,0,0,0,8.910112,49.22714,3.023578,0,67.78082,-8.910112,61074.02
89.4,-8.940112,-3.040167,0.1209487,0,0,0,0,0,8.940112,49.39288,3.040167,0,68.1078,-8.940112,61208.66
89.70001,-8.970112,-3.057098,0.1216223,0,0,0,0,0,8.970112,49.55863,3.057098,0,68.43585,-8.970112,61347.94
90.00001,-9.000111,-3.073964,0.1222933,0,0,0,0,0,9.000112,49.72437,3.073964,0,68.76498,-9.000111,61483.71
90.3,-9.030111,-3.091297,0.1229828,0,0,0,0,0,9.030111,49.89012,3.091297,0,69.09519,-9.030111,61626.55
90.60001,-9.060112,-3.104564,0.1235106,0,0,0,0,0,9.060112,50.05587,3.104564,0,69.42651,-9.060112,61686.31
90.9,-9.090112,-3.124244,0.1242936,0,0,0,0,0,9.090112,50.22161,3.124243,0,69.75893,-9.090112,61871.33
91.20001,-9.120111,-3.142721,0.1250286,0,0,0,0,0,9.120111,50.38736,3.142721,0,70.09245,-9.120111,62030.02
91.50001,-9.149978,-3.159879,0.1257113,0,0,0,0,0,9.149978,50.55236,3.159879,0,70.42559,-9.149978,62161.25
91.8,-9.179978,-3.178273,0.126443,0,0,0,0,0,9.179977,50.71811,3.178273,0,70.76135,-9.179978,62313.53
92.10001,-9.209844,-3.197544,0.1272097,0,0,0,0,0,9.209845,50.88312,3.197544,0,71.09674,-9.209844,62481.44
92.4,-9.239977,-3.216557,0.1279661,0,0,0,0,0,9.239977,51.0496,3.216557,0,71.43626,-9.239977,62639.93
92.70001,-9.270111,-3.235424,0.1287167,0,0,0,0,0,9.270111,51.21608,3.235424,0,71.77695,-9.270111,62793.05
93.00001,-9.300111,-3.254613,0.1294801,0,0,0,0,0,9.300111,51.38183,3.254613,0,72.11728,-9.300111,62950.87
93.3,-9.330111,-3.273092,0.1302153,0,0,0,0,0,9.330111,51.54757,3.273092,0,72.45877,-9.330111,63092.47
93.60001,-9.359844,-3.294096,0.1310509,0,0,0,0,0,9.359844,51.71185,3.294096,0,72.79839,-9.359844,63282.06
93.9,-9.389977,-3.314389,0.1318582,0,0,0,0,0,9.389977,51.87833,3.314389,0,73.14375,-9.389977,63452.39
94.20001,-9.419977,-3.335903,0.1327141,0,0,0,0,0,9.419977,52.04407,3.335903,0,73.48877,-9.419977,63644.29
94.50001,-9.450111,-3.356998,0.1335534,0,0,0,0,0,9.45011,52.21056,3.356998,0,73.83654,-9.450111,63824.41
94.8,-9.479977,-3.374419,0.1342464,0,0,0,0,0,9.479978,52.37556,3.374419,0,74.18242,-9.479977,63934.1
95.10001,-9.509977,-3.395039,0.1350667,0,0,0,0,0,9.509977,52.54131,3.395039,0,74.53105,-9.509977,64100.91
95.4,-9.539844,-3.414422,0.1358379,0,0,0,0,0,9.539844,52.70632,3.414422,0,74.87935,-9.539844,64242.74
95.70001,-9.57011,-3.433918,0.1366135,0,0,0,0,0,9.570109,52.87354,3.433918,0,75.23354,-9.57011,64381.12
96.00001,-9.60011,-3.455427,0.1374692,0,0,0,0,0,9.60011,53.03928,3.455427,0,75.58588,-9.60011,64556.53
96.3,-9.629977,-3.472953,0.1381665,0,0,0,0,0,9.629977,53.20429,3.472953,0,75.93787,-9.629977,64655.98
96.60001,-9.66011,-3.493245,0.1389737,0,0,0,0,0,9.66011,53.37077,3.493245,0,76.29426,-9.66011,64802.38
96.9,-9.689843,-3.514409,0.1398157,0,0,0,0,0,9.689843,53.53505,3.514409,0,76.64718,-9.689843,64965.32
97.20001,-9.71971,-3.537215,0.1407231,0,0,0,0,0,9.719709,53.70005,3.537215,0,77.00294,-9.71971,65154.7
97.50001,-9.74971,-3.558063,0.1415524,0,0,0,0,0,9.74971,53.8658,3.558063,0,77.36156,-9.74971,65304.09
97.8,-9.78011,-3.580121,0.14243,0,0,0,0,0,9.780109,54.03376,3.580121,0,77.72629,-9.78011,65469.71
98.10001,-9.809976,-3.604035,0.1433814,0,0,0,0,0,9.809977,54.19876,3.604035,0,78.08591,-9.809976,65670.44
98.4,-9.839843,-3.627542,0.1443166,0,0,0,0,0,9.839843,54.36377,3.627542,0,78.44683,-9.839843,65860.64
98.70001,-9.869576,-3.649195,0.145178,0,0,0,0,0,9.869576,54.52805,3.649195,0,78.80745,-9.869576,66015.28
99.00001,-9.899843,-3.67184,0.1460789,0,0,0,0,0,9.899842,54.69526,3.67184,0,79.17586,-9.899843,66180.67
99.3,-9.93011,-3.696797,0.1470718,0,0,0,0,0,9.93011,54.86248,3.696797,0,79.54564,-9.93011,66384.55
99.60001,-9.959976,-3.719093,0.1479588,0,0,0,0,0,9.959976,55.02749,3.719093,0,79.91188,-9.959976,66540.79
99.9,-9.989843,-3.743044,0.1489116,0,0,0,0,0,9.989842,55.1925,3.743044,0,80.27947,-9.989843,66723.58
100.2,-10.01971,-3.766898,0.1498607,0,0,0,0,0,10.01971,55.35751,3.766898,0,80.64841,-10.01971,66901.52
100.5,-10.04984,-3.790514,0.1508002,0,0,0,0,0,10.04984,55.52399,3.790514,0,81.02203,-10.04984,67069.91
100.8,-10.07998,-3.815111,0.1517787,0,0,0,0,0,10.07998,55.69047,3.815111,0,81.39704,-10.07998,67252.44
101.1,-10.10998,-3.841098,0.1528126,0,0,0,0,0,10.10997,55.85622,3.841098,0,81.7718,-10.10998,67457.26
101.4,-10.13984,-3.86437,0.1537384,0,0,0,0,0,10.13984,56.02122,3.86437,0,82.1463,-10.13984,67612.28
101.7,-10.16971,-3.88917,0.1547251,0,0,0,0,0,10.16971,56.18623,3.88917,0,82.52221,-10.16971,67790.88
102,-10.19971,-3.915425,0.1557696,0,0,0,0,0,10.19971,56.35198,3.915425,0,82.90123,-10.19971,67990.34
102.3,-10.22984,-3.940338,0.1567607,0,0,0,0,0,10.22984,56.51846,3.940338,0,83.28338,-10.22984,68161.96
102.6,-10.25971,-3.964375,0.157717,0,0,0,0,0,10.25971,56.68347,3.964375,0,83.66359,-10.25971,68317.52
102.9,-10.28971,-3.988604,0.1586809,0,0,0,0,0,10.28971,56.84922,3.988605,0,84.04696,-10.28971,68472.06
103.2,-10.31984,-4.015502,0.159751,0,0,0,0,0,10.31984,57.0157,4.015502,0,84.43353,-10.31984,68667.84
103.5,-10.34984,-4.042401,0.1608211,0,0,0,0,0,10.34984,57.18145,4.042401,0,84.81987,-10.34984,68861.28
103.8,-10.37971,-4.067996,0.1618394,0,0,0,0,0,10.37971,57.34645,4.067996,0,85.20598,-10.37971,69030.25
104.1,-10.40971,-4.093863,0.1628685,0,0,0,0,0,10.40971,57.5122,4.093863,0,85.59532,-10.40971,69199.24
104.4,-10.43997,-4.120801,0.1639402,0,0,0,0,0,10.43997,57.67942,4.1208,0,85.98966,-10.43997,69380.43
104.7,-10.46997,-4.14918,0.1650692,0,0,0,0,0,10.46997,57.84517,4.14918,0,86.38208,-10.46997,69584.65
105,-10.49997,-4.176596,0.1661599,0,0,0,0,0,10.49997,58.01091,4.176596,0,86.77604,-10.49997,69769.03
105.3,-10.52971,-4.203338,0.1672238,0,0,0,0,0,10.52971,58.17518,4.203339,0,87.16803,-10.52971,69941.06
105.6,-10.55971,-4.230053,0.1682866,0,0,0,0,0,10.55971,58.34093,4.230053,0,87.5651,-10.55971,70106.65
105.9,-10.58997,-4.258124,0.1694034,0,0,0,0,0,10.58997,58.50814,4.258124,0,87.9673,-10.58997,70288.61
106.2,-10.61997,-4.287492,0.1705717,0,0,0,0,0,10.61997,58.67389,4.287492,0,88.36756,-10.61997,70490.67
106.5,-10.64984,-4.315997,0.1717058,0,0,0,0,0,10.64984,58.8389,4.315997,0,88.76765,-10.64984,70675.99
106.8,-10.67957,-4.345729,0.1728886,0,0,0,0,0,10.67957,59.00317,4.345729,0,89.16754,-10.67957,70878.85
107.1,-10.70971,-4.37625,0.1741029,0,0,0,0,0,10.70971,59.16965,4.37625,0,89.57446,-10.70971,71086.8
107.4,-10.73984,-4.408217,0.1753746,0,0,0,0,0,10.73984,59.33614,4.408216,0,89.98303,-10.73984,71314.09
107.7,-10.76997,-4.440154,0.1766452,0,0,0,0,0,10.76997,59.50262,4.440154,0,90.39328,-10.76997,71536.68
108,-10.79984,-4.472224,0.177921,0,0,0,0,0,10.79984,59.66763,4.472224,0,90.80157,-10.79984,71759.78
108.3,-10.82971,-4.506523,0.1792856,0,0,0,0,0,10.82971,59.83263,4.506523,0,91.21153,-10.82971,72014.29
108.6,-10.85971,-4.540765,0.1806479,0,0,0,0,0,10.85971,59.99838,4.540765,0,91.62503,-10.85971,72262.06
108.9,-10.88997,-4.576079,0.1820528,0,0,0,0,0,10.88997,60.1656,4.576079,0,92.04393,-10.88997,72519.63
109.2,-10.91997,-4.612857,0.1835159,0,0,0,0,0,10.91997,60.33134,4.612857,0,92.46088,-10.91997,72798.3
109.5,-10.94971,-4.650656,0.1850197,0,0,0,0,0,10.94971,60.49562,4.650656,0,92.87586,-10.94971,73090.89
109.8,-10.97997,-4.685928,0.1864229,0,0,0,0,0,10.97997,60.66284,4.685927,0,93.30005,-10.97997,73333.49
110.1,-11.01011,-4.723938,0.1879351,0,0,0,0,0,11.01011,60.82932,4.723938,0,93.72416,-11.01011,73615.47
110.4,-11.03984,-4.7603,0.1893818,0,0,0,0,0,11.03984,60.99359,4.760301,0,94.14442,-11.03984,73871.02
110.7,-11.06984,-4.797764,0.1908722,0,0,0,0,0,11.06984,61.15934,4.797764,0,94.57024,-11.06984,74136.02
111,-11.09997,-4.836897,0.192429,0,0,0,0,0,11.09997,61.32582,4.836896,0,94.99979,-11.09997,74420.35
111.3,-11.13011,-4.877549,0.1940463,0,0,0,0,0,11.13011,61.4923,4.877549,0,95.4312,-11.13011,74722.77
111.6,-11.16011,-4.917068,0.1956185,0,0,0,0,0,11.16011,61.65805,4.917068,0,95.86255,-11.16011,75003.95
111.9,-11.18971,-4.957327,0.1972201,0,0,0,0,0,11.18971,61.82158,4.957326,0,96.28997,-11.18971,75295.54
112.2,-11.21984,-4.998062,0.1988407,0,0,0,0,0,11.21984,61.98806,4.998062,0,96.727,-11.21984,75583.21
112.5,-11.25011,-5.035268,0.2003209,0,0,0,0,0,11.25011,62.15528,5.035268,0,97.16787,-11.25011,75810.9
112.8,-11.28011,-5.073174,0.201829,0,0,0,0,0,11.28011,62.32103,5.073174,0,97.60679,-11.28011,76047.09
113.1,-11.30997,-5.115179,0.2035001,0,0,0,0,0,11.30997,62.48603,5.115179,0,98.04569,-11.30997,76340.95
113.4,-11.33984,-5.159623,0.2052682,0,0,0,0,0,11.33984,62.65104,5.159623,0,98.48652,-11.33984,76665.54
113.7,-11.36984,-5.205281,0.2070847,0,0,0,0,0,11.36984,62.81679,5.205281,0,98.93129,-11.36984,77000.72
114,-11.40011,-5.254796,0.2090546,0,0,0,0,0,11.40011,62.98401,5.254797,0,99.38201,-11.40011,77383.62
114.3,-11.43024,-5.302607,0.2109566,0,0,0,0,0,11.43024,63.15049,5.302607,0,99.8328,-11.43024,77736.48
114.6,-11.45997,-5.351453,0.2128999,0,0,0,0,0,11.45997,63.31476,5.351453,0,100.2796,-11.45997,78102.84
114.9,-11.48997,-5.400373,0.2148461,0,0,0,0,0,11.48997,63.48051,5.400373,0,100.7324,-11.48997,78460.71
115.2,-11.51997,-5.4495,0.2168005,0,0,0,0,0,11.51997,63.64626,5.4495,0,101.1873,-11.51997,78815.12
115.5,-11.55011,-5.498821,0.2187627,0,0,0,0,0,11.55011,63.81274,5.498821,0,101.6463,-11.55011,79164.25
115.8,-11.5801,-5.549629,0.220784,0,0,0,0,0,11.5801,63.97848,5.549629,0,102.1054,-11.5801,79529.77
116.1,-11.60997,-5.600458,0.2228062,0,0,0,0,0,11.60997,64.14349,5.600458,0,102.5645,-11.60997,79890.55
116.4,-11.64024,-5.65081,0.2248094,0,0,0,0,0,11.64024,64.31071,5.650809,0,103.0319,-11.64024,80232.88
116.7,-11.67011,-5.700714,0.2267947,0,0,0,0,0,11.6701,64.47572,5.700714,0,103.4954,-11.67011,80567.22
117,-11.69997,-5.749916,0.2287522,0,0,0,0,0,11.69997,64.64072,5.749917,0,103.9609,-11.69997,80885.13
117.3,-11.7301,-5.802187,0.2308317,0,0,0,0,0,11.7301,64.80721,5.802186,0,104.4329,-11.7301,81236.13
117.6,-11.7601,-5.854508,0.2329132,0,0,0,0,0,11.7601,64.97295,5.854508,0,104.905,-11.7601,81582.62
117.9,-11.7901,-5.905143,0.2349277,0,0,0,0,0,11.7901,65.13869,5.905143,0,105.3793,-11.7901,81898.84
118.2,-11.82024,-5.95901,0.2370707,0,0,0,0,0,11.82024,65.30518,5.95901,0,105.858,-11.82024,82251.24
118.5,-11.84984,-6.010505,0.2391194,0,0,0,0,0,11.84984,65.46871,6.010505,0,106.3304,-11.84984,82571
118.8,-11.87984,-6.062526,0.2411889,0,0,0,0,0,11.87984,65.63447,6.062526,0,106.8116,-11.87984,82885.85
119.1,-11.9101,-6.117186,0.2433635,0,0,0,0,0,11.9101,65.80168,6.117186,0,107.2994,-11.9101,83226.23
119.4,-11.9401,-6.171627,0.2455294,0,0,0,0,0,11.9401,65.96742,6.171627,0,107.7852,-11.9401,83559.97
119.7,-11.9701,-6.224147,0.2476188,0,0,0,0,0,11.9701,66.13317,6.224147,0,108.2734,-11.9701,83860.64
120,-12.0001,-6.278313,0.2497737,0,0,0,0,0,12.0001,66.29892,6.278313,0,108.764,-12.0001,84176.44
120.3,-12.02984,-6.331694,0.2518974,0,0,0,0,0,12.02984,66.4632,6.331694,0,109.2527,-12.02984,84478.33
120.6,-12.0601,-6.388107,0.2541417,0,0,0,0,0,12.0601,66.63041,6.388107,0,109.7525,-12.0601,84806.04
120.9,-12.0901,-6.443862,0.2563598,0,0,0,0,0,12.0901,66.79615,6.443861,0,110.2504,-12.0901,85121.34
121.2,-12.11997,-6.499743,0.258583,0,0,0,0,0,12.11997,66.96116,6.499743,0,110.7486,-12.11997,85432.83
121.5,-12.14984,-6.555165,0.2607879,0,0,0,0,0,12.14984,67.12617,6.555165,0,111.2493,-12.14984,85730.98
121.8,-12.17984,-6.613104,0.2630929,0,0,0,0,0,12.17984,67.29192,6.613104,0,111.7548,-12.17984,86052.64
122.1,-12.20997,-6.670026,0.2653575,0,0,0,0,0,12.20997,67.4584,6.670026,0,112.2651,-12.20997,86351.58
122.4,-12.2401,-6.729564,0.2677261,0,0,0,0,0,12.2401,67.62488,6.729564,0,112.778,-12.2401,86676.65
122.7,-12.26984,-6.788422,0.2700677,0,0,0,0,0,12.26984,67.78915,6.788423,0,113.2867,-12.26984,86991.08
123,-12.29984,-6.847042,0.2723998,0,0,0,0,0,12.29984,67.9549,6.847042,0,113.8026,-12.29984,87290.79
123.3,-12.32997,-6.907473,0.2748039,0,0,0,0,0,12.32997,68.12138,6.907473,0,114.3234,-12.32997,87603.72
123.6,-12.35984,-6.966222,0.2771412,0,0,0,0,0,12.35984,68.28638,6.966222,0,114.8424,-12.35984,87891.5
123.9,-12.38984,-7.025686,0.2795069,0,0,0,0,0,12.38984,68.45214,7.025686,0,115.3665,-12.38984,88178.43
124.2,-12.41984,-7.08132,0.2817202,0,0,0,0,0,12.41984,68.61788,7.08132,0,115.8932,-12.41984,88409.76
124.5,-12.44997,-7.107154,0.282748,0,0,0,0,0,12.44997,68.78436,7.107154,0,116.4251,-12.44997,88261.58
124.8,-12.47984,-7.068671,0.2812169,0,0,0,0,0,12.47984,68.94937,7.068671,0,116.9551,-12.47984,87319.63
125.1,-12.5097,-7.122568,0.2833612,0,0,0,0,0,12.5097,69.11438,7.122568,0,117.4879,-12.5097,87517.86
125.4,-12.53984,-7.187279,0.2859356,0,0,0,0,0,12.53984,69.28086,7.187279,0,118.0284,-12.53984,87836.97
125.7,-12.56984,-7.25459,0.2886135,0,0,0,0,0,12.56984,69.44661,7.25459,0,118.5695,-12.56984,88181.21
126,-12.59997,-7.322585,0.2913186,0,0,0,0,0,12.59997,69.61309,7.322585,0,119.1158,-12.59997,88522.71
126.3,-12.62997,-7.390283,0.2940119,0,0,0,0,0,12.62997,69.77883,7.390283,0,119.6627,-12.62997,88853.82
126.6,-12.65984,-7.4586,0.2967297,0,0,0,0,0,12.65983,69.94384,7.458601,0,120.2102,-12.65984,89185.58
126.9,-12.68957,-7.526163,0.2994176,0,0,0,0,0,12.68957,70.10812,7.526164,0,120.7583,-12.68957,89501.57
127.2,-12.71997,-7.592877,0.3020718,0,0,0,0,0,12.71997,70.27607,7.592877,0,121.3218,-12.71997,89787.6
127.5,-12.74997,-7.662515,0.3048422,0,0,0,0,0,12.74997,70.44182,7.662515,0,121.881,-12.74997,90105.82
127.8,-12.77984,-7.731453,0.3075848,0,0,0,0,0,12.77984,70.60683,7.731453,0,122.4408,-12.77984,90408.94
128.1,-12.80984,-7.801611,0.3103759,0,0,0,0,0,12.80983,70.77257,7.80161,0,123.0062,-12.80984,90714.92
128.4,-12.83957,-7.870203,0.3131048,0,0,0,0,0,12.83957,70.93684,7.870203,0,123.5699,-12.83957,90998.13
128.7,-12.8697,-7.940424,0.3158984,0,0,0,0,0,12.8697,71.10332,7.940424,0,124.1444,-12.8697,91284.14
129,-12.89984,-8.012273,0.3187568,0,0,0,0,0,12.89984,71.26981,8.012273,0,124.7222,-12.89984,91579.42
129.3,-12.92997,-8.084431,0.3216275,0,0,0,0,0,12.92997,71.43629,8.084432,0,125.3033,-12.92997,91868.77
129.6,-12.95984,-8.156455,0.3244929,0,0,0,0,0,12.95983,71.6013,8.156455,0,125.8827,-12.95984,92151.78
129.9,-12.98997,-8.229286,0.3273904,0,0,0,0,0,12.98997,71.76778,8.229286,0,126.4706,-12.98997,92429.59
130.2,-13.0197,-8.301931,0.3302805,0,0,0,0,0,13.0197,71.93205,8.301931,0,127.0542,-13.0197,92702.95
130.5,-13.0497,-8.376119,0.3332319,0,0,0,0,0,13.0497,72.09779,8.376119,0,127.6464,-13.0497,92979.06
130.8,-13.07984,-8.452623,0.3362755,0,0,0,0,0,13.07983,72.26428,8.452623,0,128.2449,-13.07984,93268.43
131.1,-13.10997,-8.529195,0.3393218,0,0,0,0,0,13.10997,72.43076,8.529195,0,128.847,-13.10997,93548.43
131.4,-13.13997,-8.604593,0.3423214,0,0,0,0,0,13.13997,72.5965,8.604592,0,129.45,-13.13997,93808.04
131.7,-13.16983,-8.682849,0.3454347,0,0,0,0,0,13.16983,72.76151,8.682849,0,130.0539,-13.16983,94091.2
132,-13.1997,-8.75937,0.348479,0,0,0,0,0,13.1997,72.92652,8.75937,0,130.6616,-13.1997,94345.4
132.3,-13.22983,-8.838923,0.3516439,0,0,0,0,0,13.22983,73.09301,8.838923,0,131.2784,-13.22983,94616.79
132.6,-13.25983,-8.918674,0.3548166,0,0,0,0,0,13.25984,73.25876,8.918674,0,131.8963,-13.25983,94882.37
132.9,-13.2901,-8.999241,0.3580219,0,0,0,0,0,13.2901,73.42597,8.999241,0,132.5236,-13.2901,95140.85
133.2,-13.31983,-9.079797,0.3612267,0,0,0,0,0,13.31983,73.59024,9.079797,0,133.1436,-13.31983,95399.12
133.5,-13.34943,-9.160296,0.3644293,0,0,0,0,0,13.34943,73.75378,9.160296,0,133.7648,-13.34943,95648.89
133.8,-13.3801,-9.246196,0.3678467,0,0,0,0,0,13.3801,73.92321,9.246196,0,134.4125,-13.3801,95922.61
134.1,-13.4101,-9.331629,0.3712455,0,0,0,0,0,13.4101,74.08895,9.331629,0,135.0501,-13.4101,96193.61
134.4,-13.43997,-9.414888,0.3745579,0,0,0,0,0,13.43997,74.25396,9.414888,0,135.6889,-13.43997,96433.83
134.7,-13.46983,-9.500515,0.3779644,0,0,0,0,0,13.46983,74.41897,9.500515,0,136.3319,-13.46983,96687.2
135,-13.4997,-9.584574,0.3813086,0,0,0,0,0,13.4997,74.58398,9.584574,0,136.979,-13.4997,96913.48
135.3,-13.52983,-9.669888,0.3847027,0,0,0,0,0,13.52983,74.75046,9.669888,0,137.6362,-13.52983,97135.67
135.6,-13.55997,-9.759639,0.3882733,0,0,0,0,0,13.55997,74.91695,9.75964,0,138.2978,-13.55997,97390.8
135.9,-13.5901,-9.849409,0.3918447,0,0,0,0,0,13.5901,75.08343,9.849409,0,138.9637,-13.5901,97634.26
136.2,-13.61997,-9.940765,0.3954791,0,0,0,0,0,13.61997,75.24844,9.940764,0,139.6281,-13.61997,97887.26
136.5,-13.6501,-10.03338,0.3991638,0,0,0,0,0,13.6501,75.41492,10.03338,0,140.303,-13.6501,98134.75
136.8,-13.67997,-10.12553,0.4028296,0,0,0,0,0,13.67997,75.57993,10.12553,0,140.9765,-13.67997,98371.3
137.1,-13.7101,-10.21887,0.4065433,0,0,0,0,0,13.7101,75.74641,10.21887,0,141.6605,-13.7101,98601.35
137.4,-13.7401,-10.31549,0.4103869,0,0,0,0,0,13.7401,75.91216,10.31549,0,142.3463,-13.7401,98853.37
137.7,-13.76997,-10.41356,0.4142888,0,0,0,0,0,13.76997,76.07716,10.41356,0,143.0337,-13.76997,99109.63
138,-13.8001,-10.51145,0.418183,0,0,0,0,0,13.8001,76.24364,10.51145,0,143.732,-13.8001,99345.05
138.3,-13.8301,-10.60766,0.4220105,0,0,0,0,0,13.8301,76.40939,10.60766,0,144.4321,-13.8301,99554.86
138.6,-13.85983,-10.70301,0.4258038,0,0,0,0,0,13.85983,76.57366,10.70301,0,145.1309,-13.85983,99750.24
138.9,-13.88997,-10.80692,0.4299377,0,0,0,0,0,13.88997,76.74014,10.80692,0,145.8441,-13.88997,100002.9
139.2,-13.9201,-10.90716,0.4339256,0,0,0,0,0,13.9201,76.90662,10.90716,0,146.5624,-13.9201,100208.1
139.5,-13.9501,-11.00705,0.4378999,0,0,0,0,0,13.9501,77.07237,11.00706,0,147.2828,-13.9501,100400.1
139.8,-13.97997,-11.10868,0.4419428,0,0,0,0,0,13.97997,77.23738,11.10868,0,148.005,-13.97997,100597.8
140.1,-14.00957,-11.08025,0.4408119,0,0,0,0,0,14.00957,77.40092,11.08025,0,148.7261,-14.00957,99619.44
140.4,-14.03997,-11.19008,0.4451813,0,0,0,0,0,14.03997,77.56887,11.19008,0,149.472,-14.03997,99859.2
140.7,-14.0701,-11.30217,0.4496405,0,0,0,0,0,14.0701,77.73535,11.30217,0,150.217,-14.0701,100110.9
141,-14.1001,-11.41461,0.4541139,0,0,0,0,0,14.1001,77.9011,11.41461,0,150.9642,-14.1001,100354.2
141.3,-14.1301,-11.52784,0.4586187,0,0,0,0,0,14.1301,78.06684,11.52784,0,151.717,-14.1301,100589.6
141.6,-14.15983,-11.64218,0.4631673,0,0,0,0,0,14.15983,78.23112,11.64218,0,152.4689,-14.15983,100826.4
141.9,-14.18997,-11.758,0.4677753,0,0,0,0,0,14.18997,78.3976,11.758,0,153.2366,-14.18997,101050.7
142.2,-14.22023,-11.87815,0.4725554,0,0,0,0,0,14.22023,78.56482,11.87815,0,154.0137,-14.22023,101293.1
142.5,-14.25023,-11.99575,0.4772339,0,0,0,0,0,14.25023,78.73056,11.99575,0,154.7899,-14.25023,101505
142.8,-14.27983,-12.11301,0.4818988,0,0,0,0,0,14.27983,78.8941,12.11301,0,155.5617,-14.27983,101709.1
143.1,-14.30997,-12.23564,0.4867774,0,0,0,0,0,14.30996,79.06058,12.23564,0,156.3536,-14.30997,101928.4
143.4,-14.33996,-12.35603,0.491567,0,0,0,0,0,14.33996,79.22633,12.35603,0,157.1484,-14.33996,102116.5
143.7,-14.36996,-12.47894,0.4964568,0,0,0,0,0,14.36996,79.39207,12.47894,0,157.9494,-14.36996,102309.5
144,-14.39996,-12.60554,0.5014932,0,0,0,0,0,14.39996,79.55782,12.60554,0,158.7569,-14.39996,102516.2
144.3,-14.42997,-12.73456,0.5066264,0,0,0,0,0,14.42997,79.72356,12.73456,0,159.5711,-14.42997,102725.8
144.6,-14.45996,-12.86266,0.5117226,0,0,0,0,0,14.45996,79.88931,12.86266,0,160.3918,-14.45996,102911
144.9,-14.48983,-12.99077,0.5168193,0,0,0,0,0,14.48983,80.05431,12.99077,0,161.2157,-14.48983,103083.2
145.118,-14.51183,-13.08685,0.5206415,0,0,0,0,0,14.51183,80.17587,13.08685,0,161.827,-14.51183,103212.7