File: project1/data/Packing_Peanuts_Instron/Pink_1.is_comp.raw
"Test Type","Compression"
"Method Name",""
"Sample name","P:\+Courses\MatSci\Instron Data Default Location\Packing_Peanuts\Pink_1.is_comp"
"User",""
"Sample note 1",""
"Sample note 2",""
"Sample note 3",""
"Geometry","Irregular"
"Specimen",1
"Specimen label","Pink1"
"Width",10.000000,"mm"
"Thickness",1.000000,"mm"
"Anvil height",13.800000,"mm"
"Diameter",18.000000,"mm"
"Inner diameter",8.000000,"mm"
"Outer diameter",10.000000,"mm"
"Wall thickness",1.000000,"mm"
"Area",415.000000,"mm^2"
"Linear density",100.000000,"tex"
"Sled weight",10.000000,"N"
"Loading span",10.000000,"mm"
"Support span",100.000000,"mm"
"Span ratio","2"
"Fixture type","4-point"
"Included"
"Final width",10.000000,"mm"
"Final thickness",1.000000,"mm"
"Final anvil height",100.000000,"mm"
"Final diameter",10.000000,"mm"
"Final Inner diameter",8.000000,"mm"
"Final outer diameter",10.000000,"mm"
"Final wall thickness",1.000000,"mm"
"Final area",415.000000,"mm^2"
"Final linear density",100.000000,"tex"
"Custom text input  1",""
"Custom text input  2",""
"Custom text input  3",""
"Custom text input  4",""
"Custom text input  5",""
"Custom text input  6",""
"Custom text input  7",""
"Custom text input  8",""
"Custom text input  9",""
"Custom text input 10",""
"Custom text input 11",""
"Custom text input 12",""
"Custom text input 13",""
"Custom text input 14",""
"Custom text input 15",""
"Custom text input 16",""
"Custom text input 17",""
"Custom text input 18",""
"Custom text input 19",""
"Custom text input 20",""
"Custom text input 21",""
"Custom text input 22",""
"Custom text input 23",""
"Custom text input 24",""
"Custom text input 25",""
"Custom text input 26",""
"Custom text input 27",""
"Custom text input 28",""
"Custom text input 29",""
"Custom text input 30",""
"Custom text input 31",""
"Custom text input 32",""
"Custom text input 33",""
"Custom text input 34",""
"Custom text input 35",""
"Custom text input 36",""
"Custom text input 37",""
"Custom text input 38",""
"Custom text input 39",""
"Custom text input 40",""
"Custom text input 41",""
"Custom text input 42",""
"Custom text input 43",""
"Custom text input 44",""
"Custom text input 45",""
"Custom text input 46",""
"Custom text input 47",""
"Custom text input 48",""
"Custom text input 49",""
"Custom text input 50",""
"Custom number input  1",0.000000,""
"Custom number input  2",0.000000,""
"Custom number input  3",0.000000,""
"Custom number input  4",0.000000,""
"Custom number input  5",0.000000,""
"Custom number input  6",0.000000,""
"Custom number input  7",0.000000,""
"Custom number input  8",0.000000,""
"Custom number input  9",0.000000,""
"Custom number input 10",0.000000,""
"Time sec","Extension mm","Load kgf","Compressive stress MPa","Cycle Count ","Total Cycle Count ","Repetitions Count ","Marked Data ","PIP Count ","Compressive extension mm","Compressive strain %","Compressive load kgf","Displacement (Strain 1) mm","True strain %","Corrected Position mm","True stress Pa"
0,-0.000266666,-0.0009856362,2.329106e-005,0,0,0,0,0,0.000266666,0.001932362,0.0009856363,0,0.001932381,-0.000266666,23.29061
0.3,-0.02613327,-0.002057575,4.862148e-005,0,0,0,0,0,0.02613327,0.1893715,0.002057575,0,0.1895511,-0.02613327,48.52941
0.6,-0.05946652,-0.001354781,3.201412e-005,0,0,0,0,0,0.05946652,0.4309168,0.001354781,0,0.4318479,-0.05946652,31.87617
0.9000001,-0.08986645,-0.002632298,6.220248e-005,0,0,0,0,0,0.08986646,0.6512062,0.002632299,0,0.6533358,-0.08986645,61.79742
1.2,-0.1199997,-0.0030903,7.302528e-005,0,0,0,0,0,0.1199997,0.8695631,0.0030903,0,0.8733658,-0.1199997,72.39028
1.5,-0.1502663,-0.002993958,7.074866e-005,0,0,0,0,0,0.1502663,1.088886,0.002993958,0,1.094858,-0.1502663,69.97829
1.8,-0.1802662,-0.002733181,6.458638e-005,0,0,0,0,0,0.1802662,1.306277,0.002733181,0,1.314884,-0.1802662,63.7427
2.1,-0.2101328,-0.002355633,5.566475e-005,0,0,0,0,0,0.2101328,1.522702,0.002355633,0,1.534414,-0.2101328,54.81714
2.4,-0.2398661,-0.003368462,7.959839e-005,0,0,0,0,0,0.2398661,1.73816,0.003368462,0,1.753443,-0.2398661,78.21484
2.7,-0.2701327,-0.004391384,0.0001037705,0,0,0,0,0,0.2701327,1.957483,0.004391384,0,1.976896,-0.2701327,101.7392
3,-0.3002659,-0.003975928,9.39531e-005,0,0,0,0,0,0.3002659,2.17584,0.003975928,0,2.199861,-0.3002659,91.90883
3.3,-0.3302659,-0.005092875,0.0001203471,0,0,0,0,0,0.3302659,2.393231,0.005092875,0,2.422334,-0.3302659,117.4669
3.6,-0.3601325,-0.005861587,0.0001385121,0,0,0,0,0,0.3601325,2.609655,0.005861587,0,2.644311,-0.3601325,134.8974
3.9,-0.389999,-0.006594516,0.0001558316,0,0,0,0,0,0.389999,2.82608,0.006594516,0,2.866782,-0.389999,151.4277
4.2,-0.4202656,-0.008495725,0.0002007581,0,0,0,0,0,0.4202656,3.045403,0.008495726,0,3.092739,-0.4202656,194.6442
4.5,-0.4502656,-0.008335878,0.0001969808,0,0,0,0,0,0.4502656,3.262794,0.008335878,0,3.31721,-0.4502656,190.5537
4.8,-0.4802655,-0.009910634,0.0002341931,0,0,0,0,0,0.4802655,3.480185,0.009910634,0,3.542186,-0.4802655,226.0427
5.1,-0.5101321,-0.01068239,0.00025243,0,0,0,0,0,0.5101321,3.696609,0.01068239,0,3.766666,-0.5101321,243.0987
5.4,-0.5401321,-0.01244804,0.0002941533,0,0,0,0,0,0.540132,3.914,0.01244804,0,3.992657,-0.5401321,282.6401
5.7,-0.5699986,-0.01373087,0.0003244671,0,0,0,0,0,0.5699986,4.130425,0.01373087,0,4.218151,-0.5699986,311.0653
6,-0.6002652,-0.01558311,0.0003682365,0,0,0,0,0,0.6002652,4.349748,0.01558311,0,4.447186,-0.6002652,352.2191
6.3,-0.6301318,-0.01708365,0.0004036948,0,0,0,0,0,0.6301318,4.566173,0.01708364,0,4.673708,-0.6301318,385.2613
6.6,-0.6601317,-0.01813859,0.0004286235,0,0,0,0,0,0.6601317,4.783563,0.01813859,0,4.90176,-0.6601317,408.12
6.9,-0.690265,-0.02030081,0.000479718,0,0,0,0,0,0.690265,5.00192,0.02030081,0,5.131351,-0.690265,455.7229
7.2,-0.7203983,-0.02252017,0.0005321625,0,0,0,0,0,0.7203982,5.220277,0.02252017,0,5.36147,-0.7203983,504.3821
7.5,-0.7501315,-0.0254515,0.0006014311,0,0,0,0,0,0.7501315,5.435736,0.0254515,0,5.589054,-0.7501315,568.7389
7.8,-0.7801314,-0.02869373,0.0006780467,0,0,0,0,0,0.7801315,5.653126,0.02869373,0,5.819205,-0.7801314,639.7158
8.1,-0.810398,-0.03035792,0.0007173723,0,0,0,0,0,0.810398,5.872449,0.03035792,0,6.05194,-0.810398,675.245
8.400001,-0.8405313,-0.03428175,0.0008100942,0,0,0,0,0,0.8405312,6.090806,0.03428175,0,6.284189,-0.8405313,760.7529
8.700001,-0.8702645,-0.03758507,0.0008881533,0,0,0,0,0,0.8702645,6.306265,0.03758507,0,6.513886,-0.8702645,832.144
9,-0.9001311,-0.0420954,0.0009947346,0,0,0,0,0,0.9001311,6.522689,0.0420954,0,6.745145,-0.9001311,929.8512
9.3,-0.9303977,-0.04653614,0.001099671,0,0,0,0,0,0.9303977,6.742013,0.04653614,0,6.980047,-0.9303977,1025.531
9.6,-0.9603977,-0.05017741,0.001185716,0,0,0,0,0,0.9603976,6.959403,0.05017741,0,7.213426,-0.9603977,1103.198
9.900001,-0.9902642,-0.05603949,0.00132424,0,0,0,0,0,0.9902642,7.175828,0.05603949,0,7.44631,-0.9902642,1229.215
10.2,-1.020398,-0.06293535,0.001487193,0,0,0,0,0,1.020398,7.394185,0.06293535,0,7.681825,-1.020398,1377.227
10.5,-1.050131,-0.06926504,0.001636766,0,0,0,0,0,1.050131,7.609643,0.06926504,0,7.914758,-1.050131,1512.214
10.8,-1.080264,-0.07615409,0.001799558,0,0,0,0,0,1.080264,7.828001,0.07615409,0,8.15138,-1.080264,1658.688
11.1,-1.110397,-0.08198622,0.001937374,0,0,0,0,0,1.110397,8.046357,0.08198623,0,8.388562,-1.110397,1781.486
11.4,-1.140531,-0.09055202,0.002139788,0,0,0,0,0,1.140531,8.264714,0.09055202,0,8.626309,-1.140531,1962.941
11.7,-1.170397,-0.09856826,0.002329215,0,0,0,0,0,1.170397,8.481139,0.09856826,0,8.86251,-1.170397,2131.671
12,-1.200264,-0.1071044,0.002530928,0,0,0,0,0,1.200264,8.697563,0.1071044,0,9.099271,-1.200264,2310.799
12.3,-1.230264,-0.1161867,0.002745549,0,0,0,0,0,1.230264,8.914954,0.1161867,0,9.337655,-1.230264,2500.784
12.6,-1.26053,-0.1248477,0.002950211,0,0,0,0,0,1.26053,9.134277,0.1248477,0,9.578735,-1.26053,2680.73
12.9,-1.29053,-0.1360893,0.003215856,0,0,0,0,0,1.29053,9.351668,0.1360893,0,9.818265,-1.29053,2915.12
13.2,-1.320263,-0.1468071,0.003469122,0,0,0,0,0,1.320263,9.567126,0.1468071,0,10.05623,-1.320263,3137.227
13.5,-1.350397,-0.1575206,0.003722288,0,0,0,0,0,1.350397,9.785483,0.1575206,0,10.29798,-1.350397,3358.044
13.8,-1.380397,-0.1698667,0.004014033,0,0,0,0,0,1.380397,10.00287,0.1698667,0,10.53925,-1.380397,3612.514
14.1,-1.410397,-0.1805815,0.004267227,0,0,0,0,0,1.410397,10.22026,0.1805815,0,10.78109,-1.410397,3831.106
14.4,-1.440397,-0.1933489,0.004568927,0,0,0,0,0,1.440397,10.43766,0.1933489,0,11.02352,-1.440397,4092.039
14.7,-1.470396,-0.2067221,0.004884943,0,0,0,0,0,1.470396,10.65505,0.2067221,0,11.26654,-1.470396,4364.45
15,-1.500396,-0.2203716,0.005207486,0,0,0,0,0,1.500396,10.87244,0.2203716,0,11.51015,-1.500396,4641.306
15.3,-1.530396,-0.2336222,0.005520606,0,0,0,0,0,1.530396,11.08983,0.2336222,0,11.75436,-1.530396,4908.38
15.6,-1.559996,-0.2459921,0.005812912,0,0,0,0,0,1.559996,11.30432,0.2459921,0,11.9959,-1.559996,5155.801
15.9,-1.590129,-0.2598625,0.006140676,0,0,0,0,0,1.590129,11.52268,0.2598625,0,12.24239,-1.590129,5433.106
16.2,-1.620396,-0.2725765,0.006441115,0,0,0,0,0,1.620396,11.742,0.2725765,0,12.49058,-1.620396,5684.799
16.5,-1.650263,-0.2856179,0.00674929,0,0,0,0,0,1.650263,11.95842,0.2856179,0,12.7361,-1.650263,5942.181
16.8,-1.680396,-0.2995379,0.007078226,0,0,0,0,0,1.680396,12.17678,0.299538,0,12.98443,-1.680396,6216.326
17.1,-1.710129,-0.3125377,0.007385415,0,0,0,0,0,1.710129,12.39224,0.3125377,0,13.23006,-1.710129,6470.197
17.4,-1.740129,-0.3265334,0.007716141,0,0,0,0,0,1.740129,12.60963,0.3265334,0,13.47851,-1.740129,6743.164
17.7,-1.770262,-0.3405911,0.008048332,0,0,0,0,0,1.770262,12.82799,0.3405911,0,13.72869,-1.770262,7015.893
18,-1.800396,-0.3555277,0.008401291,0,0,0,0,0,1.800395,13.04634,0.3555277,0,13.97949,-1.800396,7305.23
18.3,-1.830262,-0.3694114,0.00872937,0,0,0,0,0,1.830262,13.26277,0.3694114,0,14.2287,-1.830262,7571.614
18.6,-1.860129,-0.384794,0.009092869,0,0,0,0,0,1.860129,13.47919,0.3847941,0,14.47853,-1.860129,7867.224
18.9,-1.890129,-0.3994943,0.009440243,0,0,0,0,0,1.890129,13.69658,0.3994943,0,14.7301,-1.890129,8147.253
19.2,-1.920395,-0.4160363,0.009831139,0,0,0,0,0,1.920395,13.91591,0.4160363,0,14.98456,-1.920395,8463.047
19.5,-1.950129,-0.4325195,0.01022064,0,0,0,0,0,1.950129,14.13137,0.4325195,0,15.23516,-1.950129,8776.328
19.8,-1.980128,-0.4492069,0.01061498,0,0,0,0,0,1.980128,14.34876,0.4492069,0,15.48864,-1.980128,9091.859
20.1,-2.010128,-0.4667517,0.01102957,0,0,0,0,0,2.010128,14.56615,0.4667517,0,15.74278,-2.010128,9422.985
20.4,-2.040128,-0.4850697,0.01146243,0,0,0,0,0,2.040128,14.78354,0.4850697,0,15.99756,-2.040128,9767.877
20.7,-2.070128,-0.5029156,0.01188414,0,0,0,0,0,2.070128,15.00093,0.5029156,0,16.25299,-2.070128,10101.41
21,-2.099995,-0.5207829,0.01230635,0,0,0,0,0,2.099995,15.21735,0.5207829,0,16.50793,-2.099995,10433.65
21.3,-2.130128,-0.5395968,0.01275093,0,0,0,0,0,2.130128,15.43571,0.5395968,0,16.76581,-2.130128,10782.74
21.6,-2.160261,-0.5560663,0.01314012,0,0,0,0,0,2.160261,15.65407,0.5560663,0,17.02436,-2.160261,11083.15
21.9,-2.189995,-0.5746304,0.01357879,0,0,0,0,0,2.189995,15.86953,0.5746304,0,17.28013,-2.189995,11423.9
22.2,-2.219861,-0.59271,0.01400602,0,0,0,0,0,2.219861,16.08595,0.59271,0,17.53771,-2.219861,11753.02
22.5,-2.250128,-0.6109335,0.01443665,0,0,0,0,0,2.250128,16.30527,0.6109335,0,17.79942,-2.250128,12082.72
22.8,-2.280261,-0.6293171,0.01487107,0,0,0,0,0,2.280261,16.52363,0.6293171,0,18.06066,-2.280261,12413.83
23.1,-2.310128,-0.6477285,0.01530614,0,0,0,0,0,2.310127,16.74006,0.6477285,0,18.32026,-2.310128,12743.88
23.4,-2.340261,-0.6677823,0.01578002,0,0,0,0,0,2.340261,16.95841,0.6677822,0,18.58286,-2.340261,13103.98
23.7,-2.370127,-0.6863945,0.01621983,0,0,0,0,0,2.370127,17.17484,0.6863945,0,18.84383,-2.370127,13434.1
24,-2.399994,-0.7054799,0.01667083,0,0,0,0,0,2.399994,17.39126,0.7054799,0,19.10547,-2.399994,13771.56
24.3,-2.430261,-0.7237317,0.01710213,0,0,0,0,0,2.430261,17.61059,0.7237316,0,19.37132,-2.430261,14090.34
24.6,-2.460261,-0.7435568,0.01757061,0,0,0,0,0,2.460261,17.82798,0.7435568,0,19.63553,-2.460261,14438.12
24.9,-2.490127,-0.7625427,0.01801925,0,0,0,0,0,2.490127,18.0444,0.7625427,0,19.89925,-2.490127,14767.79
25.2,-2.519994,-0.7827645,0.0184971,0,0,0,0,0,2.519994,18.26082,0.7827646,0,20.16368,-2.519994,15119.38
25.5,-2.549994,-0.8027859,0.01897022,0,0,0,0,0,2.549994,18.47822,0.8027859,0,20.42999,-2.549994,15464.86
25.8,-2.580127,-0.8223888,0.01943344,0,0,0,0,0,2.580127,18.69657,0.8223888,0,20.6982,-2.580127,15800.06
26.1,-2.61026,-0.8413645,0.01988185,0,0,0,0,0,2.61026,18.91493,0.8413646,0,20.96713,-2.61026,16121.21
26.4,-2.640127,-0.8620326,0.02037025,0,0,0,0,0,2.640127,19.13136,0.8620327,0,21.2344,-2.640127,16473.14
26.7,-2.670127,-0.8815799,0.02083216,0,0,0,0,0,2.670127,19.34875,0.8815799,0,21.50358,-2.670127,16801.4
27,-2.700127,-0.9013355,0.02129899,0,0,0,0,0,2.700127,19.56614,0.9013355,0,21.77349,-2.700127,17131.6
27.3,-2.729993,-0.9207464,0.02175768,0,0,0,0,0,2.729993,19.78256,0.9207464,0,22.04292,-2.729993,17453.45
27.6,-2.759993,-0.9397926,0.02220775,0,0,0,0,0,2.759993,19.99995,0.9397926,0,22.31429,-2.759993,17766.21
27.9,-2.790126,-0.960669,0.02270107,0,0,0,0,0,2.790127,20.21831,0.960669,0,22.58761,-2.790126,18111.3
28.2,-2.82026,-0.9811062,0.02318401,0,0,0,0,0,2.82026,20.43667,0.9811062,0,22.86168,-2.82026,18445.97
28.5,-2.850393,-1.000347,0.02363867,0,0,0,0,0,2.850393,20.65502,1.000347,0,23.1365,-2.850393,18756.1
28.8,-2.879993,-1.020582,0.02411684,0,0,0,0,0,2.879993,20.86951,1.020582,0,23.4072,-2.879993,19083.77
29.1,-2.909993,-1.03887,0.02454899,0,0,0,0,0,2.909993,21.0869,1.03887,0,23.6823,-2.909993,19372.37
29.4,-2.940259,-1.058767,0.02501917,0,0,0,0,0,2.940259,21.30623,1.058767,0,23.96061,-2.940259,19688.53
29.7,-2.970126,-1.077651,0.02546542,0,0,0,0,0,2.970126,21.52265,1.077651,0,24.23602,-2.970126,19984.59
30,-3.000259,-1.095825,0.02589487,0,0,0,0,0,3.000259,21.74101,1.095825,0,24.51465,-3.000259,20265.06
30.3,-3.030259,-1.115022,0.0263485,0,0,0,0,0,3.030259,21.9584,1.115022,0,24.79282,-3.030259,20562.79
30.6,-3.059993,-1.133383,0.02678237,0,0,0,0,0,3.059993,22.17386,1.133383,0,25.06928,-3.059993,20843.69
30.9,-3.090393,-1.152639,0.02723742,0,0,0,0,0,3.090393,22.39415,1.152639,0,25.35274,-3.090393,21137.83
31.2,-3.120526,-1.171076,0.02767308,0,0,0,0,0,3.120526,22.6125,1.171076,0,25.6345,-3.120526,21415.5
31.5,-3.150392,-1.188848,0.02809306,0,0,0,0,0,3.150392,22.82893,1.188848,0,25.91455,-3.150392,21679.71
31.8,-3.180125,-1.207099,0.02852433,0,0,0,0,0,3.180125,23.04439,1.207099,0,26.19414,-3.180125,21951.07
32.1,-3.209992,-1.224632,0.02893865,0,0,0,0,0,3.209992,23.26081,1.224632,0,26.47577,-3.209992,22207.29
32.4,-3.240259,-1.242846,0.02936905,0,0,0,0,0,3.240259,23.48013,1.242846,0,26.76198,-3.240259,22473.16
32.7,-3.270259,-1.260525,0.0297868,0,0,0,0,0,3.270259,23.69753,1.260525,0,27.04648,-3.270259,22728.07
33,-3.300259,-1.277831,0.03019576,0,0,0,0,0,3.300259,23.91492,1.277831,0,27.3318,-3.300259,22974.47
33.3,-3.330259,-1.294158,0.03058158,0,0,0,0,0,3.330259,24.13231,1.294158,0,27.61793,-3.330259,23201.54
33.6,-3.360258,-1.310518,0.03096817,0,0,0,0,0,3.360258,24.3497,1.310518,0,27.90488,-3.360258,23427.52
33.9,-3.390258,-1.327517,0.03136986,0,0,0,0,0,3.390258,24.56709,1.327517,0,28.19265,-3.390258,23663.2
34.2,-3.420258,-1.342975,0.03173514,0,0,0,0,0,3.420259,24.78448,1.342975,0,28.48126,-3.420258,23869.75
34.5,-3.450392,-1.358281,0.03209684,0,0,0,0,0,3.450392,25.00284,1.358281,0,28.77199,-3.450392,24071.72
34.8,-3.480392,-1.374148,0.03247178,0,0,0,0,0,3.480392,25.22023,1.374148,0,29.06228,-3.480392,24282.33
35.1,-3.510525,-1.388323,0.03280674,0,0,0,0,0,3.510525,25.43859,1.388323,0,29.3547,-3.510525,24461.17
35.4,-3.540258,-1.403338,0.03316155,0,0,0,0,0,3.540258,25.65404,1.403338,0,29.64409,-3.540258,24654.28
35.7,-3.570391,-1.417463,0.03349534,0,0,0,0,0,3.570391,25.8724,1.417463,0,29.93823,-3.570391,24829.29
36,-3.600525,-1.432367,0.03384751,0,0,0,0,0,3.600524,26.09076,1.432367,0,30.23323,-3.600525,25016.44
36.3,-3.630391,-1.445813,0.03416526,0,0,0,0,0,3.630391,26.30718,1.445813,0,30.52648,-3.630391,25177.34
36.6,-3.660391,-1.458758,0.03447115,0,0,0,0,0,3.660391,26.52457,1.458758,0,30.82192,-3.660391,25327.83
36.9,-3.690258,-1.472317,0.03479155,0,0,0,0,0,3.690258,26.741,1.472317,0,31.1169,-3.690258,25487.94
37.2,-3.719991,-1.485999,0.03511488,0,0,0,0,0,3.719991,26.95646,1.485999,0,31.41144,-3.719991,25649.15
37.5,-3.750257,-1.497817,0.03539414,0,0,0,0,0,3.750258,27.17578,1.497817,0,31.71216,-3.750257,25775.51
37.8,-3.780524,-1.510481,0.0356934,0,0,0,0,0,3.780524,27.3951,1.510481,0,32.01378,-3.780524,25915.16
38.1,-3.810391,-1.522903,0.03598693,0,0,0,0,0,3.810391,27.61153,1.522903,0,32.31231,-3.810391,26050.39
38.4,-3.840257,-1.535632,0.03628773,0,0,0,0,0,3.840257,27.82795,1.535632,0,32.61174,-3.840257,26189.6
38.7,-3.870124,-1.548025,0.03658057,0,0,0,0,0,3.870124,28.04437,1.548025,0,32.91206,-3.870124,26321.78
39,-3.90039,-1.56105,0.03688836,0,0,0,0,0,3.90039,28.2637,1.56105,0,33.21733,-3.90039,26462.34
39.3,-3.93039,-1.574201,0.03719912,0,0,0,0,0,3.93039,28.48109,1.574201,0,33.52083,-3.93039,26604.41
39.6,-3.960391,-1.586272,0.03748436,0,0,0,0,0,3.960391,28.69848,1.586272,0,33.82526,-3.960391,26726.92
39.9,-3.990257,-1.598491,0.0377731,0,0,0,0,0,3.990257,28.91491,1.59849,0,34.12925,-3.990257,26851.04
40.2,-4.02039,-1.611011,0.03806897,0,0,0,0,0,4.02039,29.13326,1.611011,0,34.4369,-4.02039,26978.23
40.5,-4.050257,-1.622472,0.03833979,0,0,0,0,0,4.050257,29.34969,1.622472,0,34.74276,-4.050257,27087.18
40.8,-4.08039,-1.634685,0.03862841,0,0,0,0,0,4.08039,29.56804,1.634686,0,35.05231,-4.08039,27206.74
41.1,-4.11039,-1.646943,0.03891805,0,0,0,0,0,4.11039,29.78543,1.646943,0,35.36144,-4.11039,27326.14
41.4,-4.140256,-1.659745,0.03922057,0,0,0,0,0,4.140256,30.00186,1.659745,0,35.67015,-4.140256,27453.67
41.7,-4.17039,-1.671846,0.03950653,0,0,0,0,0,4.17039,30.22022,1.671846,0,35.98258,-4.17039,27567.57
42,-4.200123,-1.684187,0.03979815,0,0,0,0,0,4.200123,30.43568,1.684187,0,36.29183,-4.200123,27685.31
42.3,-4.230257,-1.696938,0.04009945,0,0,0,0,0,4.230257,30.65403,1.696938,0,36.60622,-4.230257,27807.35
42.6,-4.260123,-1.70919,0.04038899,0,0,0,0,0,4.260123,30.87046,1.70919,0,36.9188,-4.260123,27920.72
42.9,-4.290256,-1.721835,0.04068779,0,0,0,0,0,4.290256,31.08881,1.721835,0,37.23517,-4.290256,28038.44
43.2,-4.32039,-1.735945,0.04102121,0,0,0,0,0,4.32039,31.30717,1.735945,0,37.55254,-4.32039,28178.63
43.5,-4.350123,-1.746902,0.04128014,0,0,0,0,0,4.350123,31.52263,1.746902,0,37.86669,-4.350123,28267.55
43.8,-4.37999,-1.758918,0.04156407,0,0,0,0,0,4.37999,31.73906,1.758918,0,38.18324,-4.37999,28372.03
44.1,-4.410123,-1.771397,0.04185897,0,0,0,0,0,4.410122,31.95741,1.771397,0,38.50363,-4.410123,28481.93
44.4,-4.440389,-1.785327,0.04218814,0,0,0,0,0,4.440389,32.17673,1.785327,0,38.82649,-4.440389,28613.38
44.7,-4.470256,-1.797761,0.04248197,0,0,0,0,0,4.470256,32.39316,1.797761,0,39.1461,-4.470256,28720.72
45,-4.500256,-1.80961,0.04276196,0,0,0,0,0,4.500256,32.61055,1.80961,0,39.46817,-4.500256,28817.05
45.3,-4.529989,-1.822662,0.04307038,0,0,0,0,0,4.529989,32.82601,1.822662,0,39.7884,-4.529989,28932.1
45.6,-4.560122,-1.834845,0.04335826,0,0,0,0,0,4.560122,33.04436,1.834845,0,40.11399,-4.560122,29030.8
45.9,-4.590122,-1.846879,0.04364264,0,0,0,0,0,4.590122,33.26175,1.846879,0,40.4392,-4.590122,29126.33
46.2,-4.620255,-1.86,0.04395271,0,0,0,0,0,4.620255,33.48011,1.86,0,40.76692,-4.620255,29237.29
46.5,-4.649989,-1.872037,0.04423714,0,0,0,0,0,4.649989,33.69557,1.872037,0,41.09135,-4.649989,29331.18
46.8,-4.680122,-1.88457,0.0445333,0,0,0,0,0,4.680122,33.91393,1.88457,0,41.42121,-4.680122,29430.31
47.1,-4.709988,-1.895979,0.0448029,0,0,0,0,0,4.709989,34.13035,1.895979,0,41.74924,-4.709988,29511.51
47.4,-4.740255,-1.909996,0.04513413,0,0,0,0,0,4.740255,34.34967,1.909996,0,42.08276,-4.740255,29630.7
47.7,-4.770255,-1.921666,0.0454099,0,0,0,0,0,4.770255,34.56707,1.921666,0,42.41445,-4.770255,29713.03
48,-4.800122,-1.93357,0.04569119,0,0,0,0,0,4.800121,34.78349,1.93357,0,42.74575,-4.800122,29798.2
48.3,-4.830255,-1.947077,0.04601037,0,0,0,0,0,4.830255,35.00185,1.947077,0,43.08114,-4.830255,29905.89
48.6,-4.859988,-1.95822,0.04627369,0,0,0,0,0,4.859988,35.2173,1.95822,0,43.41317,-4.859988,29977.34
48.9,-4.889988,-1.971905,0.04659706,0,0,0,0,0,4.889989,35.4347,1.971905,0,43.74931,-4.889988,30085.53
49.2,-4.920121,-1.985464,0.04691747,0,0,0,0,0,4.920121,35.65305,1.985464,0,44.08807,-4.920121,30189.96
49.5,-4.950255,-1.997968,0.04721295,0,0,0,0,0,4.950255,35.87141,1.997968,0,44.42799,-4.950255,30277
49.8,-4.980254,-2.010306,0.0475045,0,0,0,0,0,4.980254,36.0888,2.010306,0,44.76755,-4.980254,30360.7
50.1,-5.010121,-2.022857,0.04780109,0,0,0,0,0,5.010121,36.30523,2.022857,0,45.10677,-5.010121,30446.8
50.4,-5.039988,-2.035786,0.0481066,0,0,0,0,0,5.039988,36.52165,2.035786,0,45.44713,-5.039988,30537.27
50.7,-5.070121,-2.049124,0.0484218,0,0,0,0,0,5.070121,36.74001,2.049124,0,45.79171,-5.070121,30631.62
51,-5.100121,-2.06053,0.04869132,0,0,0,0,0,5.100121,36.9574,2.06053,0,46.13595,-5.100121,30696.28
51.3,-5.130254,-2.073903,0.04900733,0,0,0,0,0,5.130254,37.17575,2.073903,0,46.48291,-5.130254,30788.49
51.6,-5.160121,-2.08569,0.04928586,0,0,0,0,0,5.160121,37.39218,2.08569,0,46.828,-5.160121,30856.8
51.9,-5.189987,-2.098341,0.04958481,0,0,0,0,0,5.189987,37.6086,2.098341,0,47.17428,-5.189987,30936.66
52.2,-5.220121,-2.110761,0.04987831,0,0,0,0,0,5.220121,37.82696,2.110761,0,47.52488,-5.220121,31010.86
52.5,-5.250387,-2.122744,0.05016147,0,0,0,0,0,5.250387,38.04628,2.122744,0,47.87826,-5.250387,31076.89
52.8,-5.280254,-2.136654,0.05049016,0,0,0,0,0,5.280254,38.26271,2.136654,0,48.22821,-5.280254,31171.26
53.1,-5.310254,-2.149745,0.0507995,0,0,0,0,0,5.310254,38.4801,2.149745,0,48.58095,-5.310254,31251.8
53.4,-5.339987,-2.164547,0.05114929,0,0,0,0,0,5.339987,38.69556,2.164547,0,48.93179,-5.339987,31356.78
53.7,-5.369987,-2.178047,0.05146831,0,0,0,0,0,5.369987,38.91295,2.178047,0,49.28703,-5.369987,31440.47
54,-5.400253,-2.193108,0.0518242,0,0,0,0,0,5.400253,39.13227,2.193108,0,49.64671,-5.400253,31544.21
54.3,-5.430254,-2.207539,0.05216522,0,0,0,0,0,5.430254,39.34966,2.207539,0,50.0045,-5.430254,31638.38
54.6,-5.46012,-2.22096,0.05248236,0,0,0,0,0,5.46012,39.56609,2.22096,0,50.36198,-5.46012,31717.14
54.9,-5.490253,-2.236114,0.05284045,0,0,0,0,0,5.490253,39.78444,2.236114,0,50.72395,-5.490253,31818.17
55.2,-5.520253,-2.25143,0.05320237,0,0,0,0,0,5.520254,40.00183,2.25143,0,51.08562,-5.520253,31920.44
55.5,-5.550253,-2.264624,0.05351414,0,0,0,0,0,5.550253,40.21923,2.264623,0,51.44861,-5.550253,31991.17
55.8,-5.58012,-2.280309,0.05388479,0,0,0,0,0,5.58012,40.43565,2.280308,0,51.8113,-5.58012,32096.12
56.1,-5.610386,-2.294415,0.05421813,0,0,0,0,0,5.610386,40.65497,2.294415,0,52.18019,-5.610386,32175.76
56.4,-5.64052,-2.309618,0.05457738,0,0,0,0,0,5.64052,40.87333,2.309618,0,52.54881,-5.64052,32269.79
56.7,-5.670386,-2.32493,0.05493923,0,0,0,0,0,5.670386,41.08976,2.32493,0,52.91552,-5.670386,32364.83
57,-5.700119,-2.339939,0.05529389,0,0,0,0,0,5.700119,41.30521,2.339939,0,53.28193,-5.700119,32454.63
57.3,-5.730253,-2.353979,0.05562567,0,0,0,0,0,5.730253,41.52357,2.353979,0,53.65464,-5.730253,32527.9
57.6,-5.760386,-2.369226,0.05598595,0,0,0,0,0,5.760386,41.74193,2.369226,0,54.02875,-5.760386,32616.33
57.9,-5.790386,-2.384881,0.05635588,0,0,0,0,0,5.790385,41.95932,2.384881,0,54.40259,-5.790386,32709.34
58.2,-5.820386,-2.398927,0.05668779,0,0,0,0,0,5.820385,42.17671,2.398926,0,54.77785,-5.820386,32778.75
58.5,-5.850119,-2.413924,0.05704218,0,0,0,0,0,5.850119,42.39217,2.413924,0,55.15116,-5.850119,32860.76
58.8,-5.880119,-2.429758,0.05741634,0,0,0,0,0,5.880119,42.60956,2.429758,0,55.52924,-5.880119,32951.49
59.1,-5.910385,-2.444378,0.05776183,0,0,0,0,0,5.910386,42.82888,2.444378,0,55.91213,-5.910385,33023.09
59.4,-5.940519,-2.461129,0.05815766,0,0,0,0,0,5.940519,43.04724,2.461129,0,56.2948,-5.940519,33122.39
59.7,-5.970385,-2.476976,0.05853213,0,0,0,0,0,5.970385,43.26366,2.476976,0,56.67552,-5.970385,33208.99
60,-6.000252,-2.491341,0.0588716,0,0,0,0,0,6.000252,43.48009,2.491341,0,57.05772,-6.000252,33274.18
60.3,-6.030119,-2.507809,0.05926075,0,0,0,0,0,6.030118,43.69651,2.507809,0,57.44137,-6.030119,33365.87
60.6,-6.060519,-2.523085,0.05962171,0,0,0,0,0,6.060519,43.9168,2.523085,0,57.83339,-6.060519,33437.76
60.9,-6.090385,-2.540116,0.06002416,0,0,0,0,0,6.090385,44.13323,2.540116,0,58.22004,-6.090385,33533.56
61.2,-6.120252,-2.554873,0.06037288,0,0,0,0,0,6.120252,44.34965,2.554873,0,58.60819,-6.120252,33597.72
61.5,-6.150385,-2.570907,0.06075177,0,0,0,0,0,6.150385,44.56801,2.570907,0,59.00133,-6.150385,33675.92
61.8,-6.180251,-2.587694,0.06114847,0,0,0,0,0,6.180252,44.78443,2.587694,0,59.39252,-6.180251,33763.47
62.1,-6.210252,-2.603841,0.06153002,0,0,0,0,0,6.210252,45.00182,2.603841,0,59.78702,-6.210252,33840.39
62.4,-6.240385,-2.621148,0.06193898,0,0,0,0,0,6.240385,45.22018,2.621148,0,60.18483,-6.240385,33930.06
62.7,-6.270385,-2.638027,0.06233786,0,0,0,0,0,6.270385,45.43757,2.638027,0,60.58247,-6.270385,34013.05
63,-6.300251,-2.654087,0.06271736,0,0,0,0,0,6.300251,45.654,2.654087,0,60.97991,-6.300251,34084.38
63.3,-6.330251,-2.671297,0.06312403,0,0,0,0,0,6.330252,45.87139,2.671297,0,61.38073,-6.330251,34168.16
63.6,-6.359985,-2.68768,0.06351119,0,0,0,0,0,6.359984,46.08685,2.68768,0,61.77957,-6.359985,34240.88
63.9,-6.390118,-2.704056,0.06389815,0,0,0,0,0,6.390118,46.3052,2.704056,0,62.1854,-6.390118,34309.98
64.2,-6.420384,-2.721679,0.06431459,0,0,0,0,0,6.420384,46.52452,2.721679,0,62.59471,-6.420384,34392.53
64.5,-6.450384,-2.739176,0.06472805,0,0,0,0,0,6.450385,46.74192,2.739176,0,63.00206,-6.450384,34472.92
64.8,-6.480384,-2.756188,0.06513005,0,0,0,0,0,6.480384,46.9593,2.756188,0,63.41107,-6.480384,34545.43
65.10001,-6.510118,-2.774082,0.06555288,0,0,0,0,0,6.510118,47.17477,2.774081,0,63.81812,-6.510118,34628.46
65.4,-6.54025,-2.791436,0.06596298,0,0,0,0,0,6.54025,47.39312,2.791436,0,64.23233,-6.54025,34701.06
65.70001,-6.570384,-2.809434,0.06638828,0,0,0,0,0,6.570384,47.61148,2.809434,0,64.64827,-6.570384,34779.84
66,-6.600384,-2.828587,0.06684087,0,0,0,0,0,6.600384,47.82887,2.828587,0,65.06409,-6.600384,34871.64
66.3,-6.630117,-2.845181,0.067233,0,0,0,0,0,6.630117,48.04433,2.845181,0,65.47793,-6.630117,34931.36
66.60001,-6.659984,-2.86336,0.06766257,0,0,0,0,0,6.659984,48.26075,2.86336,0,65.89535,-6.659984,35008.1
66.9,-6.690117,-2.88183,0.06809902,0,0,0,0,0,6.690117,48.47911,2.88183,0,66.31828,-6.690117,35085.22
67.20001,-6.72025,-2.900209,0.06853332,0,0,0,0,0,6.720251,48.69747,2.900208,0,66.74301,-6.72025,35159.33
67.5,-6.750383,-2.919048,0.06897852,0,0,0,0,0,6.750383,48.91582,2.919048,0,67.16954,-6.750383,35237.11
67.8,-6.780117,-2.936363,0.06938768,0,0,0,0,0,6.780117,49.13128,2.936363,0,67.5922,-6.780117,35296.62
68.10001,-6.810117,-2.955972,0.06985105,0,0,0,0,0,6.810117,49.34867,2.955972,0,68.02047,-6.810117,35380.49
68.4,-6.84025,-2.974172,0.07028111,0,0,0,0,0,6.84025,49.56703,2.974172,0,68.4525,-6.84025,35444.85
68.70001,-6.869983,-2.991887,0.07069974,0,0,0,0,0,6.869983,49.78249,2.991887,0,68.88064,-6.869983,35503.65
69,-6.900116,-3.01218,0.07117926,0,0,0,0,0,6.900116,50.00084,3.01218,0,69.3164,-6.900116,35589.03
69.3,-6.930117,-3.030847,0.07162037,0,0,0,0,0,6.930117,50.21824,3.030847,0,69.75215,-6.930117,35653.89
69.60001,-6.96025,-3.051043,0.07209761,0,0,0,0,0,6.960249,50.43659,3.051043,0,70.19173,-6.96025,35734.03
69.9,-6.99025,-3.070521,0.07255789,0,0,0,0,0,6.99025,50.65398,3.070521,0,70.63131,-6.99025,35804.43
70.20001,-7.019983,-3.088985,0.0729942,0,0,0,0,0,7.019983,50.86944,3.088985,0,71.06889,-7.019983,35862.46
70.5,-7.050116,-3.109139,0.07347047,0,0,0,0,0,7.050116,51.0878,3.109139,0,71.51433,-7.050116,35936.02
70.8,-7.080249,-3.129535,0.07395242,0,0,0,0,0,7.080249,51.30616,3.129535,0,71.96176,-7.080249,36010.28
71.10001,-7.110249,-3.150709,0.07445277,0,0,0,0,0,7.110249,51.52354,3.150709,0,72.4092,-7.110249,36092.06
71.4,-7.140249,-3.170359,0.07491711,0,0,0,0,0,7.140249,51.74094,3.170359,0,72.85865,-7.140249,36154.3
71.70001,-7.170116,-3.191192,0.07540941,0,0,0,0,0,7.170115,51.95736,3.191192,0,73.30812,-7.170116,36228.67
72,-7.199982,-3.21155,0.07589047,0,0,0,0,0,7.199982,52.17378,3.21155,0,73.75962,-7.199982,36295.54
72.3,-7.230116,-3.232703,0.07639032,0,0,0,0,0,7.230115,52.39214,3.232702,0,74.21724,-7.230116,36367.79
72.60001,-7.260249,-3.254534,0.0769062,0,0,0,0,0,7.260249,52.6105,3.254534,0,74.67695,-7.260249,36445.47
72.9,-7.290116,-3.274984,0.07738944,0,0,0,0,0,7.290115,52.82692,3.274984,0,75.13469,-7.290116,36506.98
73.20001,-7.319982,-3.296165,0.07788996,0,0,0,0,0,7.319982,53.04335,3.296165,0,75.59453,-7.319982,36574.52
73.5,-7.349982,-3.317727,0.07839948,0,0,0,0,0,7.349982,53.26074,3.317727,0,76.05857,-7.349982,36643.34
73.8,-7.380249,-3.338899,0.0788998,0,0,0,0,0,7.380249,53.48006,3.338899,0,76.52892,-7.380249,36704.14
74.10001,-7.410249,-3.361468,0.0794331,0,0,0,0,0,7.410249,53.69746,3.361468,0,76.99733,-7.410249,36779.54
74.4,-7.440115,-3.38331,0.07994925,0,0,0,0,0,7.440115,53.91388,3.38331,0,77.46583,-7.440115,36845.51
74.70001,-7.470115,-3.404736,0.08045555,0,0,0,0,0,7.470115,54.13127,3.404736,0,77.93865,-7.470115,36903.94
75,-7.500115,-3.425767,0.08095253,0,0,0,0,0,7.500115,54.34866,3.425767,0,78.41372,-7.500115,36955.92
75.3,-7.530115,-3.446238,0.08143625,0,0,0,0,0,7.530115,54.56605,3.446238,0,78.89106,-7.530115,36999.71
75.60001,-7.560115,-3.46843,0.08196068,0,0,0,0,0,7.560115,54.78344,3.46843,0,79.37068,-7.560115,37059.8
75.9,-7.590115,-3.492003,0.08251771,0,0,0,0,0,7.590115,55.00083,3.492002,0,79.85262,-7.590115,37132.28
76.20001,-7.620115,-3.515593,0.08307515,0,0,0,0,0,7.620115,55.21822,3.515593,0,80.33689,-7.620115,37202.53
76.5,-7.650381,-3.539078,0.08363013,0,0,0,0,0,7.650382,55.43755,3.539078,0,80.82785,-7.650381,37267.64
76.8,-7.679981,-3.562539,0.08418452,0,0,0,0,0,7.679981,55.65204,3.562539,0,81.31034,-7.679981,37334.12
77.10001,-7.710115,-3.585736,0.08473268,0,0,0,0,0,7.710114,55.8704,3.585737,0,81.80393,-7.710115,37392.2
77.4,-7.740248,-3.610338,0.08531403,0,0,0,0,0,7.740248,56.08875,3.610338,0,82.29996,-7.740248,37462.46
77.70001,-7.770248,-3.63428,0.08587979,0,0,0,0,0,7.770248,56.30614,3.63428,0,82.79627,-7.770248,37524.19
78,-7.800248,-3.658496,0.08645203,0,0,0,0,0,7.800248,56.52353,3.658496,0,83.29504,-7.800248,37586.29
78.3,-7.830248,-3.683111,0.08703369,0,0,0,0,0,7.830248,56.74093,3.683111,0,83.79632,-7.830248,37649.96
78.60001,-7.859981,-3.706858,0.08759484,0,0,0,0,0,7.859981,56.95638,3.706858,0,84.29562,-7.859981,37703.99
78.9,-7.890248,-3.73257,0.08820243,0,0,0,0,0,7.890248,57.17571,3.73257,0,84.80647,-7.890248,37772.07
79.20001,-7.920381,-3.758137,0.08880658,0,0,0,0,0,7.920381,57.39406,3.758137,0,85.31766,-7.920381,37836.88
79.5,-7.950247,-3.782832,0.08939014,0,0,0,0,0,7.950247,57.61049,3.782832,0,85.82692,-7.950247,37892.05
79.8,-7.980114,-3.808947,0.09000725,0,0,0,0,0,7.980114,57.82691,3.808947,0,86.33879,-7.980114,37958.84
80.10001,-8.00998,-3.834572,0.09061279,0,0,0,0,0,8.00998,58.04333,3.834572,0,86.85329,-8.00998,38018.11
80.4,-8.040247,-3.860857,0.0912339,0,0,0,0,0,8.040248,58.26266,3.860857,0,87.37741,-8.040247,38078.6
80.70001,-8.070247,-3.887894,0.09187281,0,0,0,0,0,8.070248,58.48005,3.887894,0,87.89962,-8.070247,38145.54
81.00001,-8.100247,-3.914199,0.09249441,0,0,0,0,0,8.100247,58.69744,3.914199,0,88.42458,-8.100247,38202.56
81.3,-8.130114,-3.941639,0.09314282,0,0,0,0,0,8.130114,58.91387,3.941639,0,88.94995,-8.130114,38268.78
81.60001,-8.160381,-3.969988,0.09381274,0,0,0,0,0,8.16038,59.13319,3.969988,0,89.4852,-8.160381,38338.27
81.9,-8.190247,-3.995476,0.09441502,0,0,0,0,0,8.190248,59.34962,3.995476,0,90.01619,-8.190247,38380.06
82.20001,-8.220247,-4.023127,0.09506842,0,0,0,0,0,8.220247,59.56701,4.023127,0,90.55241,-8.220247,38439.01
82.50001,-8.25038,-4.050959,0.0957261,0,0,0,0,0,8.25038,59.78536,4.050959,0,91.09391,-8.25038,38495.91
82.8,-8.28038,-4.080014,0.0964127,0,0,0,0,0,8.280379,60.00275,4.080014,0,91.63595,-8.28038,38562.42
83.10001,-8.310514,-4.10931,0.09710497,0,0,0,0,0,8.310513,60.22111,4.10931,0,92.18339,-8.310514,38627.28
83.4,-8.340246,-4.13698,0.09775882,0,0,0,0,0,8.340246,60.43657,4.13698,0,92.72649,-8.340246,38676.75
83.70001,-8.37038,-4.165109,0.09842353,0,0,0,0,0,8.370379,60.65493,4.165109,0,93.27994,-8.37038,38724.81
84.00001,-8.400513,-4.194784,0.09912477,0,0,0,0,0,8.400513,60.87328,4.194784,0,93.83646,-8.400513,38784.27
84.3,-8.430379,-4.224879,0.09983593,0,0,0,0,0,8.43038,61.08971,4.224879,0,94.39113,-8.430379,38846.45
84.60001,-8.460379,-4.25443,0.1005342,0,0,0,0,0,8.46038,61.30709,4.254429,0,94.9514,-8.460379,38899.61
84.9,-8.49038,-4.28393,0.1012313,0,0,0,0,0,8.49038,61.52449,4.28393,0,95.51483,-8.49038,38949.27
85.20001,-8.519846,-4.312703,0.1019112,0,0,0,0,0,8.519846,61.73801,4.312703,0,96.07133,-8.519846,38993.27
85.50001,-8.550379,-4.34381,0.1026463,0,0,0,0,0,8.55038,61.95927,4.34381,0,96.65128,-8.550379,39047.41
85.8,-8.580512,-4.37704,0.1034316,0,0,0,0,0,8.580512,62.17763,4.37704,0,97.22693,-8.580512,39120.27
86.10001,-8.610512,-4.408245,0.104169,0,0,0,0,0,8.610512,62.39502,4.408245,0,97.80336,-8.610512,39172.72
86.4,-8.640379,-4.439455,0.1049065,0,0,0,0,0,8.640379,62.61144,4.439455,0,98.38054,-8.640379,39223.02
86.70001,-8.670112,-4.470985,0.1056515,0,0,0,0,0,8.670112,62.8269,4.470984,0,98.95848,-8.670112,39273.95
87.00001,-8.700379,-4.503254,0.1064141,0,0,0,0,0,8.700379,63.04623,4.503254,0,99.55024,-8.700379,39324.01
87.3,-8.730379,-4.537053,0.1072128,0,0,0,0,0,8.730379,63.26361,4.537053,0,100.1403,-8.730379,39386.09
87.60001,-8.760379,-4.571016,0.1080153,0,0,0,0,0,8.760379,63.48101,4.571016,0,100.7338,-8.760379,39446.11
87.9,-8.790245,-4.603864,0.1087915,0,0,0,0,0,8.790245,63.69743,4.603864,0,101.3282,-8.790245,39494.12
88.20001,-8.820245,-4.638601,0.1096124,0,0,0,0,0,8.820245,63.91482,4.638601,0,101.9288,-8.820245,39553.83
88.50001,-8.850245,-4.672568,0.110415,0,0,0,0,0,8.850245,64.13221,4.672568,0,102.533,-8.850245,39603.43
88.8,-8.880379,-4.707662,0.1112443,0,0,0,0,0,8.880379,64.35057,4.707662,0,103.1437,-8.880379,39657.96
89.10001,-8.910378,-4.742179,0.11206,0,0,0,0,0,8.910378,64.56796,4.742179,0,103.7554,-8.910378,39705.14
89.4,-8.940245,-4.777775,0.1129011,0,0,0,0,0,8.940245,64.78439,4.777775,0,104.3681,-8.940245,39758.83
89.70001,-8.970378,-4.814751,0.1137749,0,0,0,0,0,8.970378,65.00274,4.814751,0,104.99,-8.970378,39818.1
90.00001,-9.000111,-4.8492,0.1145889,0,0,0,0,0,9.000112,65.2182,4.8492,0,105.6076,-9.000111,39856.1
90.3,-9.030111,-4.884691,0.1154276,0,0,0,0,0,9.030111,65.43559,4.884691,0,106.2346,-9.030111,39896.87
90.60001,-9.060112,-4.923021,0.1163334,0,0,0,0,0,9.060112,65.65298,4.923021,0,106.8655,-9.060112,39957.04
90.9,-9.090378,-4.960867,0.1172277,0,0,0,0,0,9.090378,65.87231,4.960866,0,107.5061,-9.090378,40007.1
91.20001,-9.120378,-4.999194,0.1181334,0,0,0,0,0,9.120378,66.08969,4.999194,0,108.1451,-9.120378,40059.39
91.50001,-9.150244,-5.036995,0.1190266,0,0,0,0,0,9.150246,66.30612,5.036995,0,108.7854,-9.150244,40104.68
91.8,-9.179978,-5.075585,0.1199385,0,0,0,0,0,9.179977,66.52158,5.075585,0,109.4269,-9.179978,40153.53
92.10001,-9.210111,-5.114709,0.120863,0,0,0,0,0,9.210111,66.73993,5.114709,0,110.0813,-9.210111,40199.13
92.4,-9.240378,-5.155689,0.1218314,0,0,0,0,0,9.240377,66.95926,5.155689,0,110.7429,-9.240378,40254
92.70001,-9.270244,-5.195587,0.1227742,0,0,0,0,0,9.270245,67.17568,5.195587,0,111.4001,-9.270244,40299.8
93.00001,-9.300111,-5.236443,0.1237397,0,0,0,0,0,9.300111,67.39211,5.236444,0,112.0616,-9.300111,40348.9
93.3,-9.329977,-5.277539,0.1247108,0,0,0,0,0,9.329978,67.60854,5.277539,0,112.7275,-9.329977,40395.65
93.60001,-9.360244,-5.319465,0.1257015,0,0,0,0,0,9.360244,67.82785,5.319465,0,113.4069,-9.360244,40440.88
93.9,-9.390244,-5.362475,0.1267179,0,0,0,0,0,9.390244,68.04525,5.362475,0,114.0849,-9.390244,40492.38
94.20001,-9.420244,-5.405818,0.1277421,0,0,0,0,0,9.420243,68.26263,5.405818,0,114.7675,-9.420244,40541.98
94.50001,-9.449977,-5.447553,0.1287283,0,0,0,0,0,9.449978,68.4781,5.447554,0,115.4488,-9.449977,40577.62
94.8,-9.480244,-5.492179,0.1297828,0,0,0,0,0,9.480244,68.69742,5.492179,0,116.147,-9.480244,40625.38
95.10001,-9.509977,-5.536751,0.1308361,0,0,0,0,0,9.509978,68.91288,5.536751,0,116.8377,-9.509977,40673.17
95.4,-9.540243,-5.5822,0.1319101,0,0,0,0,0,9.540243,69.13219,5.5822,0,117.5456,-9.540243,40717.74
95.70001,-9.570244,-5.626654,0.1329606,0,0,0,0,0,9.570244,69.34959,5.626655,0,118.2524,-9.570244,40752.95
96.00001,-9.60011,-5.671847,0.1340285,0,0,0,0,0,9.60011,69.56602,5.671846,0,118.961,-9.60011,40790.2
96.3,-9.630243,-5.719476,0.135154,0,0,0,0,0,9.630243,69.78437,5.719476,0,119.6811,-9.630243,40837.62
96.60001,-9.66011,-5.766363,0.1362619,0,0,0,0,0,9.66011,70.00079,5.766363,0,120.3999,-9.66011,40877.49
96.9,-9.69011,-5.812314,0.1373478,0,0,0,0,0,9.690109,70.21819,5.812314,0,121.1272,-9.69011,40904.66
97.20001,-9.720109,-5.862316,0.1385293,0,0,0,0,0,9.720109,70.43558,5.862316,0,121.8598,-9.720109,40955.4
97.50001,-9.750243,-5.911041,0.1396807,0,0,0,0,0,9.750243,70.65394,5.911041,0,122.6012,-9.750243,40990.8
97.8,-9.780243,-5.960098,0.14084,0,0,0,0,0,9.780242,70.87132,5.960097,0,123.3447,-9.780243,41024.82
98.10001,-9.810243,-6.01085,0.1420393,0,0,0,0,0,9.810243,71.08871,6.01085,0,124.0938,-9.810243,41065.38
98.4,-9.839976,-6.060417,0.1432106,0,0,0,0,0,9.839976,71.30418,6.060417,0,124.8419,-9.839976,41095.46
98.70001,-9.870109,-6.112541,0.1444423,0,0,0,0,0,9.87011,71.52253,6.112541,0,125.6057,-9.870109,41133.51
99.00001,-9.900376,-6.165469,0.145693,0,0,0,0,0,9.900376,71.74186,6.165469,0,126.3789,-9.900376,41170.14
99.3,-9.930243,-6.218411,0.146944,0,0,0,0,0,9.930243,71.95828,6.218411,0,127.1477,-9.930243,41205.64
99.60001,-9.960109,-6.270548,0.1481761,0,0,0,0,0,9.96011,72.17471,6.270547,0,127.9225,-9.960109,41230.43
99.9,-9.989843,-6.325192,0.1494673,0,0,0,0,0,9.989842,72.39017,6.325192,0,128.6998,-9.989843,41267.69
100.028,-10.00318,-6.350251,0.1500595,0,0,0,0,0,10.00318,72.48678,6.350251,0,129.0504,-10.00318,41286.2
"Specimen",2
"Specimen label","Pink2"
"Width",10.000000,"mm"
"Thickness",1.000000,"mm"
"Anvil height",15.600000,"mm"
"Diameter",18.000000,"mm"
"Inner diameter",8.000000,"mm"
"Outer diameter",10.000000,"mm"
"Wall thickness",1.000000,"mm"
"Area",415.000000,"mm^2"
"Linear density",100.000000,"tex"
"Sled weight",10.000000,"N"
"Loading span",10.000000,"mm"
"Support span",100.000000,"mm"
"Span ratio","2"
"Fixture type","4-point"
"Included"
"Final width",10.000000,"mm"
"Final thickness",1.000000,"mm"
"Final anvil height",100.000000,"mm"
"Final diameter",10.000000,"mm"
"Final Inner diameter",8.000000,"mm"
"Final outer diameter",10.000000,"mm"
"Final wall thickness",1.000000,"mm"
"Final area",415.000000,"mm^2"
"Final linear density",100.000000,"tex"
"Custom text input  1",""
"Custom text input  2",""
"Custom text input  3",""
"Custom text input  4",""
"Custom text input  5",""
"Custom text input  6",""
"Custom text input  7",""
"Custom text input  8",""
"Custom text input  9",""
"Custom text input 10",""
"Custom text input 11",""
"Custom text input 12",""
"Custom text input 13",""
"Custom text input 14",""
"Custom text input 15",""
"Custom text input 16",""
"Custom text input 17",""
"Custom text input 18",""
"Custom text input 19",""
"Custom text input 20",""
"Custom text input 21",""
"Custom text input 22",""
"Custom text input 23",""
"Custom text input 24",""
"Custom text input 25",""
"Custom text input 26",""
"Custom text input 27",""
"Custom text input 28",""
"Custom text input 29",""
"Custom text input 30",""
"Custom text input 31",""
"Custom text input 32",""
"Custom text input 33",""
"Custom text input 34",""
"Custom text input 35",""
"Custom text input 36",""
"Custom text input 37",""
"Custom text input 38",""
"Custom text input 39",""
"Custom text input 40",""
"Custom text input 41",""
"Custom text input 42",""
"Custom text input 43",""
"Custom text input 44",""
"Custom text input 45",""
"Custom text input 46",""
"Custom text input 47",""
"Custom text input 48",""
"Custom text input 49",""
"Custom text input 50",""
"Custom number input  1",0.000000,""
"Custom number input  2",0.000000,""
"Custom number input  3",0.000000,""
"Custom number input  4",0.000000,""
[...]
42.6,-4.25999,-1.501252,0.03547532,0,0,0,0,0,4.25999,27.4838,1.501252,0,32.13603,-4.25999,25725.35
42.9,-4.28999,-1.514172,0.03578062,0,0,0,0,0,4.28999,27.67735,1.514172,0,32.40329,-4.28999,25877.49
43.2,-4.320256,-1.525474,0.0360477,0,0,0,0,0,4.320256,27.87262,1.525474,0,32.67365,-4.320256,26000.26
43.5,-4.350256,-1.537045,0.0363211,0,0,0,0,0,4.350256,28.06617,1.537045,0,32.94235,-4.350256,26127.16
43.8,-4.380123,-1.548941,0.03660222,0,0,0,0,0,4.380123,28.25886,1.548941,0,33.21058,-4.380123,26258.85
44.1,-4.409989,-1.560608,0.03687792,0,0,0,0,0,4.409989,28.45154,1.560608,0,33.47953,-4.409989,26385.58
44.4,-4.440123,-1.57375,0.03718848,0,0,0,0,0,4.440123,28.64595,1.57375,0,33.75161,-4.440123,26535.48
44.7,-4.470123,-1.585099,0.03745665,0,0,0,0,0,4.470122,28.8395,1.585099,0,34.02323,-4.470123,26654.34
45,-4.500256,-1.596674,0.03773016,0,0,0,0,0,4.500256,29.03391,1.596674,0,34.2968,-4.500256,26775.62
45.3,-4.530123,-1.609114,0.03802414,0,0,0,0,0,4.530122,29.2266,1.609114,0,34.56869,-4.530123,26910.98
45.6,-4.559989,-1.620299,0.03828845,0,0,0,0,0,4.559989,29.41928,1.620299,0,34.84132,-4.559989,27024.26
45.9,-4.589989,-1.632531,0.03857749,0,0,0,0,0,4.589989,29.61283,1.632531,0,35.11592,-4.589989,27153.6
46.2,-4.620122,-1.644161,0.03885231,0,0,0,0,0,4.620122,29.80724,1.644161,0,35.3925,-4.620122,27271.51
46.5,-4.650389,-1.656342,0.03914016,0,0,0,0,0,4.650389,30.00251,1.656342,0,35.67108,-4.650389,27397.13
46.8,-4.680122,-1.668746,0.03943327,0,0,0,0,0,4.680122,30.19433,1.668746,0,35.9455,-4.680122,27526.65
47.1,-4.709988,-1.680162,0.03970303,0,0,0,0,0,4.709989,30.38702,1.680162,0,36.22192,-4.709988,27638.46
47.4,-4.739855,-1.693482,0.04001779,0,0,0,0,0,4.739855,30.57971,1.693482,0,36.4991,-4.739855,27780.47
47.7,-4.770255,-1.705536,0.04030264,0,0,0,0,0,4.770255,30.77584,1.705536,0,36.78202,-4.770255,27899.16
48,-4.800122,-1.717863,0.04059393,0,0,0,0,0,4.800122,30.96853,1.717863,0,37.06077,-4.800122,28022.59
48.3,-4.830122,-1.729471,0.04086823,0,0,0,0,0,4.830122,31.16208,1.729471,0,37.34153,-4.830122,28132.84
48.6,-4.860255,-1.741963,0.04116343,0,0,0,0,0,4.860255,31.35648,1.741963,0,37.62435,-4.860255,28256.03
48.9,-4.890255,-1.754024,0.04144844,0,0,0,0,0,4.890254,31.55003,1.754024,0,37.90671,-4.890255,28371.44
49.2,-4.920121,-1.76725,0.04176098,0,0,0,0,0,4.920121,31.74272,1.76725,0,38.18861,-4.920121,28504.91
49.5,-4.950122,-1.779159,0.04204239,0,0,0,0,0,4.950121,31.93627,1.779159,0,38.47257,-4.950122,28615.62
49.8,-4.980254,-1.79208,0.04234772,0,0,0,0,0,4.980255,32.13067,1.79208,0,38.7586,-4.980254,28741.11
50.1,-5.010388,-1.804674,0.04264532,0,0,0,0,0,5.010388,32.32508,1.804674,0,39.04546,-5.010388,28860.18
50.4,-5.040254,-1.81725,0.04294249,0,0,0,0,0,5.040254,32.51777,1.81725,0,39.33058,-5.040254,28978.55
50.7,-5.069988,-1.829736,0.04323754,0,0,0,0,0,5.069988,32.7096,1.829736,0,39.61526,-5.069988,29094.72
51,-5.100254,-1.842511,0.04353941,0,0,0,0,0,5.100255,32.90487,1.84251,0,39.90587,-5.100254,29212.82
51.3,-5.130521,-1.854736,0.0438283,0,0,0,0,0,5.130521,33.10014,1.854736,0,40.19732,-5.130521,29321.07
51.6,-5.160388,-1.86697,0.04411739,0,0,0,0,0,5.160388,33.29282,1.86697,0,40.48576,-5.160388,29429.47
51.9,-5.190254,-1.880349,0.04443355,0,0,0,0,0,5.190254,33.48551,1.880349,0,40.77504,-5.190254,29554.75
52.2,-5.220121,-1.893262,0.04473868,0,0,0,0,0,5.220121,33.6782,1.893262,0,41.06515,-5.220121,29671.5
52.5,-5.249987,-1.905895,0.04503721,0,0,0,0,0,5.249988,33.87089,1.905895,0,41.35611,-5.249987,29782.71
52.8,-5.280254,-1.920031,0.04537125,0,0,0,0,0,5.280254,34.06615,1.920031,0,41.65183,-5.280254,29915.01
53.1,-5.310521,-1.931676,0.04564644,0,0,0,0,0,5.31052,34.26142,1.931676,0,41.94842,-5.310521,30007.32
53.4,-5.340253,-1.94623,0.04599036,0,0,0,0,0,5.340253,34.45325,1.94623,0,42.24065,-5.340253,30145.18
53.7,-5.370387,-1.958913,0.04629005,0,0,0,0,0,5.370387,34.64766,1.958913,0,42.53769,-5.370387,30251.64
54,-5.400253,-1.972078,0.04660116,0,0,0,0,0,5.400253,34.84034,1.972078,0,42.83297,-5.400253,30365.16
54.3,-5.43052,-1.985497,0.04691824,0,0,0,0,0,5.43052,35.03561,1.985497,0,43.1331,-5.43052,30480.15
54.6,-5.460387,-1.999002,0.04723739,0,0,0,0,0,5.460387,35.2283,1.999002,0,43.43014,-5.460387,30596.46
54.9,-5.490253,-2.01278,0.04756296,0,0,0,0,0,5.490253,35.42099,2.01278,0,43.72808,-5.490253,30715.69
55.2,-5.520387,-2.027258,0.04790508,0,0,0,0,0,5.520387,35.6154,2.027258,0,44.02957,-5.520387,30843.5
55.5,-5.550386,-2.039919,0.04820427,0,0,0,0,0,5.550386,35.80894,2.039919,0,44.33063,-5.550386,30942.83
55.8,-5.58052,-2.053972,0.04853635,0,0,0,0,0,5.58052,36.00335,2.053972,0,44.63395,-5.58052,31061.64
56.1,-5.610253,-2.066696,0.04883702,0,0,0,0,0,5.610253,36.19518,2.066696,0,44.93415,-5.610253,31160.37
56.4,-5.640386,-2.081408,0.04918468,0,0,0,0,0,5.640386,36.38959,2.081408,0,45.2393,-5.640386,31286.57
56.7,-5.670386,-2.095405,0.04951544,0,0,0,0,0,5.670386,36.58314,2.095406,0,45.54404,-5.670386,31401.14
57,-5.700386,-2.109848,0.04985671,0,0,0,0,0,5.700386,36.77668,2.109848,0,45.8497,-5.700386,31521.07
57.3,-5.729986,-2.123536,0.05018019,0,0,0,0,0,5.729986,36.96765,2.123536,0,46.15221,-5.729986,31629.75
57.6,-5.760119,-2.137027,0.05049898,0,0,0,0,0,5.760119,37.16206,2.137027,0,46.46112,-5.760119,31732.52
57.9,-5.790386,-2.152091,0.05085494,0,0,0,0,0,5.790385,37.35733,2.152091,0,46.77234,-5.790386,31856.9
58.2,-5.820386,-2.16682,0.05120302,0,0,0,0,0,5.820385,37.55088,2.166821,0,47.0818,-5.820386,31975.84
58.5,-5.850386,-2.180742,0.05153199,0,0,0,0,0,5.850386,37.74443,2.180742,0,47.39221,-5.850386,32081.53
58.8,-5.880252,-2.195476,0.05188016,0,0,0,0,0,5.880252,37.93711,2.195476,0,47.7022,-5.880252,32198.33
59.1,-5.909985,-2.209727,0.05221692,0,0,0,0,0,5.909986,38.12894,2.209727,0,48.01176,-5.909985,32307.16
59.4,-5.940119,-2.224771,0.05257242,0,0,0,0,0,5.940119,38.32335,2.224771,0,48.32648,-5.940119,32424.91
59.7,-5.970252,-2.239884,0.05292954,0,0,0,0,0,5.970252,38.51776,2.239884,0,48.64218,-5.970252,32542.27
60,-6.000252,-2.254747,0.05328076,0,0,0,0,0,6.000252,38.7113,2.254747,0,48.95747,-6.000252,32655.08
60.3,-6.030119,-2.269083,0.05361952,0,0,0,0,0,6.030118,38.90399,2.269083,0,49.27236,-6.030119,32759.39
60.6,-6.060119,-2.283224,0.05395368,0,0,0,0,0,6.060119,39.09754,2.283224,0,49.58966,-6.060119,32859.12
60.9,-6.090385,-2.298185,0.05430721,0,0,0,0,0,6.090385,39.29281,2.298185,0,49.9108,-6.090385,32968.38
61.2,-6.120385,-2.3137,0.05467384,0,0,0,0,0,6.120385,39.48635,2.3137,0,50.23013,-6.120385,33085.13
61.5,-6.150252,-2.328674,0.05502768,0,0,0,0,0,6.150252,39.67904,2.328674,0,50.54906,-6.150252,33193.22
61.8,-6.180118,-2.344069,0.05539147,0,0,0,0,0,6.180118,39.87173,2.344069,0,50.86901,-6.180118,33305.93
62.1,-6.210252,-2.35833,0.05572848,0,0,0,0,0,6.210252,40.06614,2.35833,0,51.19286,-6.210252,33400.23
62.4,-6.239851,-2.374332,0.05610662,0,0,0,0,0,6.239851,40.25711,2.374332,0,51.51199,-6.239851,33519.72
62.7,-6.270118,-2.389648,0.05646853,0,0,0,0,0,6.270118,40.45237,2.389648,0,51.83938,-6.270118,33625.67
63,-6.300118,-2.405301,0.05683842,0,0,0,0,0,6.300117,40.64592,2.405301,0,52.16493,-6.300118,33735.92
63.3,-6.330251,-2.420605,0.05720007,0,0,0,0,0,6.330252,40.84033,2.420605,0,52.49302,-6.330251,33839.37
63.6,-6.360251,-2.435463,0.05755116,0,0,0,0,0,6.360251,41.03388,2.435463,0,52.82071,-6.360251,33935.69
63.9,-6.389984,-2.451177,0.05792248,0,0,0,0,0,6.389984,41.2257,2.451177,0,53.14655,-6.389984,34043.53
64.2,-6.419984,-2.468401,0.05832952,0,0,0,0,0,6.419985,41.41925,2.468401,0,53.47641,-6.419984,34169.86
64.5,-6.450251,-2.483238,0.05868011,0,0,0,0,0,6.450251,41.61452,2.483238,0,53.8103,-6.450251,34260.66
64.8,-6.480384,-2.501027,0.05910046,0,0,0,0,0,6.480384,41.80893,2.501027,0,54.14383,-6.480384,34391.19
65.10001,-6.510251,-2.516154,0.05945792,0,0,0,0,0,6.510251,42.00162,2.516154,0,54.47551,-6.510251,34484.63
65.4,-6.540117,-2.532513,0.05984449,0,0,0,0,0,6.540117,42.19431,2.532513,0,54.80829,-6.540117,34593.53
65.70001,-6.569984,-2.549562,0.06024739,0,0,0,0,0,6.569984,42.38699,2.549562,0,55.14218,-6.569984,34710.33
66,-6.60025,-2.564661,0.06060416,0,0,0,0,0,6.600251,42.58226,2.564661,0,55.48169,-6.60025,34797.54
66.3,-6.630384,-2.581711,0.06100708,0,0,0,0,0,6.630383,42.77667,2.581711,0,55.82085,-6.630384,34910.28
66.60001,-6.660117,-2.598305,0.06139921,0,0,0,0,0,6.660117,42.9685,2.598305,0,56.15664,-6.660117,35016.89
66.9,-6.689984,-2.614073,0.0617718,0,0,0,0,0,6.689984,43.16119,2.614073,0,56.49508,-6.689984,35110.36
67.20001,-6.719984,-2.631614,0.06218632,0,0,0,0,0,6.719984,43.35473,2.631614,0,56.83618,-6.719984,35225.6
67.5,-6.750117,-2.647338,0.06255785,0,0,0,0,0,6.750117,43.54914,2.647337,0,57.17997,-6.750117,35314.45
67.8,-6.780117,-2.664393,0.0629609,0,0,0,0,0,6.780118,43.74269,2.664393,0,57.52342,-6.780117,35420.11
68.10001,-6.810117,-2.68187,0.06337388,0,0,0,0,0,6.810117,43.93624,2.68187,0,57.86805,-6.810117,35529.78
68.4,-6.840117,-2.699464,0.06378964,0,0,0,0,0,6.840117,44.12979,2.699464,0,58.21388,-6.840117,35639.4
68.70001,-6.870117,-2.716463,0.06419134,0,0,0,0,0,6.870117,44.32333,2.716463,0,58.5609,-6.870117,35739.6
69,-6.899983,-2.73334,0.06459013,0,0,0,0,0,6.899983,44.51602,2.73334,0,58.90759,-6.899983,35837.17
69.3,-6.930117,-2.751023,0.06500801,0,0,0,0,0,6.930117,44.71043,2.751023,0,59.25859,-6.930117,35942.65
69.60001,-6.960116,-2.768523,0.06542154,0,0,0,0,0,6.960116,44.90398,2.768523,0,59.60926,-6.960116,36044.66
69.9,-6.99025,-2.786042,0.06583551,0,0,0,0,0,6.99025,45.09838,2.786042,0,59.96274,-6.99025,36144.76
70.20001,-7.020249,-2.804655,0.06627535,0,0,0,0,0,7.020249,45.29193,2.804655,0,60.3159,-7.020249,36257.96
70.5,-7.050116,-2.822125,0.06668818,0,0,0,0,0,7.050116,45.48462,2.822125,0,60.66873,-7.050116,36355.31
70.8,-7.079983,-2.840498,0.06712234,0,0,0,0,0,7.079983,45.67731,2.840498,0,61.02281,-7.079983,36462.66
71.10001,-7.110116,-2.858927,0.06755781,0,0,0,0,0,7.110116,45.87172,2.858927,0,61.38133,-7.110116,36567.88
71.4,-7.140249,-2.8772,0.06798963,0,0,0,0,0,7.140249,46.06612,2.8772,0,61.74114,-7.140249,36669.44
71.70001,-7.170382,-2.895354,0.06841862,0,0,0,0,0,7.170382,46.26053,2.895354,0,62.10225,-7.170382,36767.8
72,-7.200116,-2.913246,0.06884141,0,0,0,0,0,7.200116,46.45236,2.913246,0,62.45985,-7.200116,36862.95
72.3,-7.229982,-2.931309,0.06926825,0,0,0,0,0,7.229982,46.64505,2.931309,0,62.82033,-7.229982,36958.04
72.60001,-7.260249,-2.951065,0.06973509,0,0,0,0,0,7.260249,46.84032,2.951065,0,63.18699,-7.260249,37070.95
72.9,-7.290382,-2.970281,0.07018919,0,0,0,0,0,7.290382,47.03473,2.970281,0,63.55337,-7.290382,37175.89
73.20001,-7.320249,-2.988745,0.07062548,0,0,0,0,0,7.320249,47.22741,2.988745,0,63.91783,-7.320249,37270.89
73.5,-7.350116,-3.007077,0.07105869,0,0,0,0,0,7.350116,47.4201,3.007077,0,64.28363,-7.350116,37362.59
73.8,-7.379982,-3.026738,0.07152327,0,0,0,0,0,7.379982,47.61279,3.026738,0,64.65077,-7.379982,37469.05
74.10001,-7.410115,-3.045074,0.07195657,0,0,0,0,0,7.410115,47.80719,3.045074,0,65.02255,-7.410115,37556.16
74.4,-7.440382,-3.064961,0.07242651,0,0,0,0,0,7.440382,48.00246,3.064961,0,65.39739,-7.440382,37660
74.70001,-7.470248,-3.084504,0.07288832,0,0,0,0,0,7.470248,48.19515,3.084504,0,65.76864,-7.470248,37759.69
75,-7.500248,-3.104767,0.07336715,0,0,0,0,0,7.500248,48.3887,3.104767,0,66.14295,-7.500248,37865.74
75.3,-7.530381,-3.124743,0.0738392,0,0,0,0,0,7.530381,48.58311,3.124743,0,66.52034,-7.530381,37965.82
75.60001,-7.560382,-3.145236,0.07432343,0,0,0,0,0,7.560382,48.77666,3.145236,0,66.89748,-7.560382,38070.95
75.9,-7.590248,-3.164416,0.07477669,0,0,0,0,0,7.590249,48.96935,3.164416,0,67.27437,-7.590248,38159.03
76.20001,-7.620381,-3.184993,0.07526293,0,0,0,0,0,7.620381,49.16375,3.184993,0,67.65605,-7.620381,38260.85
76.5,-7.650248,-3.206226,0.07576466,0,0,0,0,0,7.650248,49.35644,3.206226,0,68.03581,-7.650248,38369.93
76.8,-7.680514,-3.226866,0.07625239,0,0,0,0,0,7.680514,49.5517,3.226866,0,68.42212,-7.680514,38468.03
77.10001,-7.710381,-3.246637,0.07671959,0,0,0,0,0,7.710381,49.74439,3.246637,0,68.80481,-7.710381,38555.89
77.4,-7.740248,-3.267523,0.07721314,0,0,0,0,0,7.740248,49.93708,3.267523,0,69.18896,-7.740248,38655.15
77.70001,-7.770381,-3.28904,0.07772161,0,0,0,0,0,7.770381,50.13149,3.289041,0,69.57804,-7.770381,38758.61
78,-7.800514,-3.311276,0.07824706,0,0,0,0,0,7.800514,50.3259,3.311276,0,69.96864,-7.800514,38868.52
78.3,-7.830381,-3.331611,0.07872757,0,0,0,0,0,7.830381,50.51859,3.331611,0,70.35731,-7.830381,38955.51
78.60001,-7.860381,-3.353537,0.0792457,0,0,0,0,0,7.860381,50.71214,3.353537,0,70.74923,-7.860381,39058.51
78.9,-7.889981,-3.374088,0.07973133,0,0,0,0,0,7.889981,50.90311,3.374088,0,71.13744,-7.889981,39145.61
79.20001,-7.920381,-3.395976,0.08024856,0,0,0,0,0,7.920381,51.09923,3.395977,0,71.5377,-7.920381,39242.16
79.5,-7.950648,-3.418395,0.08077833,0,0,0,0,0,7.950648,51.2945,3.418396,0,71.93783,-7.950648,39343.49
79.8,-7.980381,-3.441303,0.08131964,0,0,0,0,0,7.980381,51.48633,3.441303,0,72.33246,-7.980381,39451.14
80.10001,-8.010381,-3.462536,0.0818214,0,0,0,0,0,8.010381,51.67988,3.462537,0,72.73221,-8.010381,39536.2
80.4,-8.040247,-3.485717,0.08236916,0,0,0,0,0,8.040248,51.87257,3.485717,0,73.13178,-8.040247,39642.17
80.70001,-8.070247,-3.507169,0.0828761,0,0,0,0,0,8.070248,52.06611,3.507169,0,73.53474,-8.070247,39725.74
81.00001,-8.10038,-3.532097,0.08346517,0,0,0,0,0,8.10038,52.26052,3.532097,0,73.94114,-8.10038,39845.84
81.3,-8.13038,-3.554739,0.08400021,0,0,0,0,0,8.13038,52.45406,3.554739,0,74.34739,-8.13038,39938.68
81.60001,-8.160247,-3.577517,0.08453846,0,0,0,0,0,8.160247,52.64675,3.577518,0,74.75348,-8.160247,40031.71
81.9,-8.19038,-3.601646,0.08510862,0,0,0,0,0,8.19038,52.84116,3.601645,0,75.16488,-8.19038,40136.23
82.20001,-8.220114,-3.62256,0.08560284,0,0,0,0,0,8.220114,53.03299,3.62256,0,75.57248,-8.220114,40205.09
82.50001,-8.25038,-3.639787,0.08600991,0,0,0,0,0,8.25038,53.22826,3.639787,0,75.9891,-8.25038,40228.34
82.8,-8.28038,-3.657574,0.08643024,0,0,0,0,0,8.280379,53.42181,3.657574,0,76.40377,-8.28038,40257.64
83.10001,-8.310246,-3.676449,0.08687626,0,0,0,0,0,8.310246,53.61449,3.676449,0,76.81831,-8.310246,40297.99
83.4,-8.340246,-3.697197,0.08736654,0,0,0,0,0,8.340246,53.80804,3.697197,0,77.23644,-8.340246,40356.32
83.70001,-8.370247,-3.720316,0.08791286,0,0,0,0,0,8.370247,54.00159,3.720316,0,77.65634,-8.370247,40438.52
84.00001,-8.400113,-3.741878,0.08842238,0,0,0,0,0,8.400113,54.19428,3.741878,0,78.07612,-8.400113,40502.51
84.3,-8.430113,-3.766418,0.08900227,0,0,0,0,0,8.430113,54.38783,3.766418,0,78.49955,-8.430113,40595.87
84.60001,-8.460379,-3.792088,0.08960887,0,0,0,0,0,8.46038,54.58309,3.792088,0,78.92857,-8.460379,40697.58
84.9,-8.490246,-3.816806,0.09019297,0,0,0,0,0,8.490246,54.77578,3.816807,0,79.35374,-8.490246,40789.07
85.20001,-8.520112,-3.842407,0.09079792,0,0,0,0,0,8.520112,54.96847,3.842407,0,79.78072,-8.520112,40887.69
85.50001,-8.549979,-3.867572,0.09139259,0,0,0,0,0,8.549979,55.16116,3.867572,0,80.20953,-8.549979,40979.38
85.8,-8.580113,-3.893515,0.09200563,0,0,0,0,0,8.580112,55.35557,3.893515,0,80.64406,-8.580113,41075.39
86.10001,-8.610246,-3.920781,0.09264995,0,0,0,0,0,8.610246,55.54997,3.920781,0,81.08046,-8.610246,41182.93
86.4,-8.640246,-3.947218,0.09327467,0,0,0,0,0,8.640245,55.74352,3.947218,0,81.51684,-8.640246,41280.09
86.70001,-8.670245,-3.973942,0.09390617,0,0,0,0,0,8.670245,55.93707,3.973943,0,81.95513,-8.670245,41377.82
87.00001,-8.699979,-4.000323,0.09452955,0,0,0,0,0,8.699979,56.12889,4.000323,0,82.39143,-8.699979,41471.16
87.3,-8.729978,-4.027357,0.09516837,0,0,0,0,0,8.729979,56.32244,4.027357,0,82.83358,-8.729978,41567.22
87.60001,-8.760246,-4.055689,0.0958379,0,0,0,0,0,8.760245,56.51771,4.055689,0,83.28165,-8.760246,41672.51
87.9,-8.790245,-4.082187,0.09646404,0,0,0,0,0,8.790245,56.71126,4.082187,0,83.72776,-8.790245,41758.07
88.20001,-8.820112,-4.109466,0.09710865,0,0,0,0,0,8.820112,56.90395,4.109466,0,84.17388,-8.820112,41849.99
88.50001,-8.849978,-4.136703,0.09775228,0,0,0,0,0,8.849978,57.09663,4.136703,0,84.62199,-8.849978,41939.02
88.8,-8.880111,-4.164595,0.09841138,0,0,0,0,0,8.880112,57.29104,4.164595,0,85.07615,-8.880111,42030.48
89.10001,-8.910245,-4.191969,0.09905826,0,0,0,0,0,8.910245,57.48545,4.191969,0,85.53239,-8.910245,42114.17
89.4,-8.940112,-4.220918,0.09974233,0,0,0,0,0,8.940112,57.67814,4.220918,0,85.98665,-8.940112,42212.81
89.70001,-8.970112,-4.248991,0.1004057,0,0,0,0,0,8.970112,57.87169,4.248991,0,86.44502,-8.970112,42299.23
90.00001,-9.000111,-4.278373,0.1011,0,0,0,0,0,9.000112,58.06524,4.278373,0,86.9055,-9.000111,42396.06
90.3,-9.029978,-4.308119,0.1018029,0,0,0,0,0,9.029978,58.25792,4.308119,0,87.36605,-9.029978,42494.65
90.60001,-9.059845,-4.336601,0.102476,0,0,0,0,0,9.059845,58.45061,4.336601,0,87.82873,-9.059845,42578.14
90.9,-9.089978,-4.367404,0.1032039,0,0,0,0,0,9.089978,58.64502,4.367404,0,88.29774,-9.089978,42679.93
91.20001,-9.120111,-4.396447,0.1038902,0,0,0,0,0,9.120111,58.83943,4.396447,0,88.76894,-9.120111,42761.78
91.50001,-9.150244,-4.427005,0.1046123,0,0,0,0,0,9.150245,59.03383,4.427005,0,89.24237,-9.150244,42855.63
91.8,-9.180111,-4.457681,0.1053371,0,0,0,0,0,9.180111,59.22652,4.457681,0,89.71384,-9.180111,42949.62
92.10001,-9.209977,-4.48755,0.106043,0,0,0,0,0,9.209977,59.41921,4.48755,0,90.18754,-9.209977,43033.08
92.4,-9.239977,-4.518781,0.106781,0,0,0,0,0,9.239977,59.61275,4.518781,0,90.66562,-9.239977,43125.89
92.70001,-9.270244,-4.550896,0.1075399,0,0,0,0,0,9.270245,59.80803,4.550896,0,91.15029,-9.270244,43222.39
93.00001,-9.300244,-4.582506,0.1082868,0,0,0,0,0,9.300244,60.00158,4.582506,0,91.63301,-9.300244,43313.02
93.3,-9.330111,-4.614746,0.1090487,0,0,0,0,0,9.330111,60.19426,4.614746,0,92.11591,-9.330111,43407.63
93.60001,-9.359977,-4.646499,0.109799,0,0,0,0,0,9.359977,60.38695,4.646499,0,92.60116,-9.359977,43494.74
93.9,-9.389844,-4.678653,0.1105588,0,0,0,0,0,9.389844,60.57964,4.678653,0,93.08877,-9.389844,43582.69
94.20001,-9.420111,-4.711045,0.1113243,0,0,0,0,0,9.420111,60.77491,4.711045,0,93.58536,-9.420111,43667.04
94.50001,-9.450244,-4.744416,0.1121128,0,0,0,0,0,9.450244,60.96931,4.744416,0,94.0822,-9.450244,43758.4
94.8,-9.480244,-4.777342,0.1128909,0,0,0,0,0,9.480244,61.16286,4.777342,0,94.57932,-9.480244,43843.59
95.10001,-9.51011,-4.810288,0.1136694,0,0,0,0,0,9.51011,61.35555,4.810288,0,95.0767,-9.51011,43926.92
95.4,-9.539977,-4.8441,0.1144684,0,0,0,0,0,9.539977,61.54824,4.8441,0,95.57656,-9.539977,44015.12
95.70001,-9.570244,-4.877699,0.1152624,0,0,0,0,0,9.570244,61.74351,4.877699,0,96.08569,-9.570244,44095.34
96.00001,-9.60011,-4.912319,0.1160805,0,0,0,0,0,9.60011,61.9362,4.912319,0,96.59064,-9.60011,44184.64
96.3,-9.63011,-4.948199,0.1169283,0,0,0,0,0,9.63011,62.12974,4.948199,0,97.10041,-9.63011,44281.06
96.60001,-9.660243,-4.984237,0.1177799,0,0,0,0,0,9.660243,62.32415,4.984237,0,97.61508,-9.660243,44374.59
96.9,-9.690243,-5.020258,0.1186311,0,0,0,0,0,9.690243,62.5177,5.020258,0,98.13012,-9.690243,44465.68
97.20001,-9.719843,-5.055246,0.1194579,0,0,0,0,0,9.719843,62.70866,5.055246,0,98.64092,-9.719843,44547.44
97.50001,-9.75011,-5.091732,0.1203201,0,0,0,0,0,9.75011,62.90393,5.091733,0,99.16593,-9.75011,44634.02
97.8,-9.780509,-5.129004,0.1212008,0,0,0,0,0,9.780509,63.10006,5.129004,0,99.69603,-9.780509,44723.04
98.10001,-9.810509,-5.165418,0.1220613,0,0,0,0,0,9.810509,63.29361,5.165419,0,100.2219,-9.810509,44804.31
98.4,-9.840243,-5.202462,0.1229367,0,0,0,0,0,9.840242,63.48544,5.202462,0,100.7459,-9.840243,44889.79
98.70001,-9.870109,-5.239805,0.1238191,0,0,0,0,0,9.87011,63.67812,5.239805,0,101.275,-9.870109,44973.42
99.00001,-9.900109,-5.276867,0.1246949,0,0,0,0,0,9.900109,63.87167,5.276866,0,101.8093,-9.900109,45050.18
99.3,-9.930376,-5.30244,0.1252992,0,0,0,0,0,9.930376,64.06694,5.302441,0,102.3512,-9.930376,45023.84
99.60001,-9.960376,-5.339413,0.1261729,0,0,0,0,0,9.960376,64.26049,5.339413,0,102.8913,-9.960376,45093.58
99.9,-9.990375,-5.379343,0.1271165,0,0,0,0,0,9.990376,64.45403,5.379343,0,103.4344,-9.990375,45184.77
100.03,-10.00318,-5.395967,0.1275093,0,0,0,0,0,10.00317,64.53661,5.395967,0,103.6669,-10.00318,45219.12