File: project1/data/Packing_Peanuts_Instron/Starch_1_raw.is_comp.raw
"Test Type","Compression"
"Method Name",""
"Sample name","P:\+Courses\MatSci\Instron Data Default Location\Packing_Peanuts\Starch_1_raw.is_comp"
"User",""
"Sample note 1",""
"Sample note 2",""
"Sample note 3",""
"Geometry","Circular"
"Specimen",1
"Specimen label","Starch1"
"Width",10.000000,"mm"
"Thickness",1.000000,"mm"
"Anvil height",21.300000,"mm"
"Diameter",17.900000,"mm"
"Inner diameter",8.000000,"mm"
"Outer diameter",10.000000,"mm"
"Wall thickness",1.000000,"mm"
"Area",2.516494,"cm^2"
"Linear density",100.000000,"tex"
"Sled weight",10.000000,"N"
"Loading span",10.000000,"mm"
"Support span",100.000000,"mm"
"Span ratio","2"
"Fixture type","4-point"
"Included"
"Final width",10.000000,"mm"
"Final thickness",1.000000,"mm"
"Final anvil height",100.000000,"mm"
"Final diameter",10.000000,"mm"
"Final Inner diameter",8.000000,"mm"
"Final outer diameter",10.000000,"mm"
"Final wall thickness",1.000000,"mm"
"Final area",0.785398,"cm^2"
"Final linear density",100.000000,"tex"
"Custom text input  1",""
"Custom text input  2",""
"Custom text input  3",""
"Custom text input  4",""
"Custom text input  5",""
"Custom text input  6",""
"Custom text input  7",""
"Custom text input  8",""
"Custom text input  9",""
"Custom text input 10",""
"Custom text input 11",""
"Custom text input 12",""
"Custom text input 13",""
"Custom text input 14",""
"Custom text input 15",""
"Custom text input 16",""
"Custom text input 17",""
"Custom text input 18",""
"Custom text input 19",""
"Custom text input 20",""
"Custom text input 21",""
"Custom text input 22",""
"Custom text input 23",""
"Custom text input 24",""
"Custom text input 25",""
"Custom text input 26",""
"Custom text input 27",""
"Custom text input 28",""
"Custom text input 29",""
"Custom text input 30",""
"Custom text input 31",""
"Custom text input 32",""
"Custom text input 33",""
"Custom text input 34",""
"Custom text input 35",""
"Custom text input 36",""
"Custom text input 37",""
"Custom text input 38",""
"Custom text input 39",""
"Custom text input 40",""
"Custom text input 41",""
"Custom text input 42",""
"Custom text input 43",""
"Custom text input 44",""
"Custom text input 45",""
"Custom text input 46",""
"Custom text input 47",""
"Custom text input 48",""
"Custom text input 49",""
"Custom text input 50",""
"Custom number input  1",0.000000,""
"Custom number input  2",0.000000,""
"Custom number input  3",0.000000,""
"Custom number input  4",0.000000,""
"Custom number input  5",0.000000,""
"Custom number input  6",0.000000,""
"Custom number input  7",0.000000,""
"Custom number input  8",0.000000,""
"Custom number input  9",0.000000,""
"Custom number input 10",0.000000,""
"Time sec","Extension mm","Load kgf","Compressive stress MPa","Cycle Count ","Total Cycle Count ","Repetitions Count ","Marked Data ","PIP Count ","Compressive extension mm","Compressive strain %","Compressive load kgf","Displacement (Strain 1) mm","True strain %","Corrected Position mm","True stress Pa"
0,-0.000266666,-0.0006676167,2.601668e-005,0,0,0,0,0,0.000266666,0.001251953,0.0006676167,0,0.001251961,-0.000266666,26.01636
0.4,-0.03826657,-0.002466447,9.611619e-005,0,0,0,0,0,0.03826657,0.1796553,0.002466447,0,0.1798169,-0.03826657,95.94351
0.8,-0.08013314,-0.00316475,0.0001233287,0,0,0,0,0,0.08013314,0.3762119,0.00316475,0,0.3769214,-0.08013314,122.8647
1.2,-0.1202664,-0.002680236,0.0001044474,0,0,0,0,0,0.1202664,0.5646309,0.002680236,0,0.5662309,-0.1202664,103.8577
1.6,-0.1605329,-0.0025328,9.870194e-005,0,0,0,0,0,0.160533,0.7536758,0.0025328,0,0.7565303,-0.1605329,97.95805
2,-0.2003995,-0.003241969,0.0001263379,0,0,0,0,0,0.2003995,0.9408428,0.003241969,0,0.9452967,-0.2003995,125.1492
2.4,-0.2402661,-0.00445608,0.0001736511,0,0,0,0,0,0.2402661,1.12801,0.00445608,0,1.13442,-0.2402661,171.6924
2.8,-0.280666,-0.003879569,0.0001511848,0,0,0,0,0,0.280666,1.317681,0.003879569,0,1.326439,-0.280666,149.1927
3.2,-0.3203992,-0.004323131,0.0001684702,0,0,0,0,0,0.3203992,1.504222,0.004323131,0,1.51565,-0.3203992,165.9361
3.6,-0.3601325,-0.003505354,0.0001366019,0,0,0,0,0,0.3601325,1.690763,0.003505354,0,1.705219,-0.3601325,134.2922
4,-0.4006657,-0.005352525,0.0002085852,0,0,0,0,0,0.4006657,1.88106,0.005352525,0,1.898977,-0.4006657,204.6615
4.4,-0.4402656,-0.005094983,0.0001985489,0,0,0,0,0,0.4402656,2.066975,0.005094983,0,2.088636,-0.4402656,194.445
4.8,-0.4802655,-0.005707374,0.0002224135,0,0,0,0,0,0.4802655,2.254768,0.005707374,0,2.280576,-0.4802655,217.3986
5.2,-0.5203987,-0.006431417,0.0002506291,0,0,0,0,0,0.5203987,2.443187,0.006431417,0,2.473528,-0.5203987,244.5057
5.6,-0.5602653,-0.006187929,0.0002411404,0,0,0,0,0,0.5602653,2.630354,0.006187929,0,2.665566,-0.5602653,234.7976
6,-0.6002652,-0.007318494,0.000285198,0,0,0,0,0,0.6002652,2.818146,0.007318494,0,2.858619,-0.6002652,277.1607
6.4,-0.6403984,-0.008230682,0.0003207455,0,0,0,0,0,0.6403984,3.006565,0.008230682,0,3.052689,-0.6403984,311.1021
6.8,-0.6805317,-0.008273276,0.0003224053,0,0,0,0,0,0.6805317,3.194984,0.008273276,0,3.247138,-0.6805317,312.1045
7.2,-0.7202649,-0.007998977,0.0003117161,0,0,0,0,0,0.7202649,3.381526,0.007998977,0,3.440021,-0.7202649,301.1753
7.6,-0.7603982,-0.007667597,0.0002988024,0,0,0,0,0,0.7603981,3.569944,0.007667597,0,3.635225,-0.7603982,288.1353
8,-0.8003981,-0.008876685,0.0003459199,0,0,0,0,0,0.8003981,3.757737,0.008876685,0,3.83016,-0.8003981,332.9212
8.400001,-0.840398,-0.009509021,0.0003705617,0,0,0,0,0,0.840398,3.94553,0.009509021,0,4.025476,-0.840398,355.9411
8.8,-0.8803979,-0.01037248,0.0004042104,0,0,0,0,0,0.8803979,4.133323,0.01037248,0,4.221174,-0.8803979,387.5031
9.200001,-0.9201311,-0.01104915,0.0004305798,0,0,0,0,0,0.9201311,4.319864,0.01104915,0,4.415948,-0.9201311,411.9793
9.6,-0.960531,-0.01086612,0.0004234473,0,0,0,0,0,0.960531,4.509535,0.01086612,0,4.614379,-0.960531,404.3518
10,-1.000131,-0.0126975,0.0004948152,0,0,0,0,0,1.000131,4.69545,0.0126975,0,4.809263,-1.000131,471.5814
10.4,-1.040264,-0.0129337,0.0005040197,0,0,0,0,0,1.040264,4.883869,0.0129337,0,5.007161,-1.040264,479.404
10.8,-1.080531,-0.01347901,0.0005252703,0,0,0,0,0,1.080531,5.072914,0.01347901,0,5.206111,-1.080531,498.6238
11.2,-1.120397,-0.01408044,0.0005487077,0,0,0,0,0,1.120397,5.260081,0.01408044,0,5.403474,-1.120397,519.8452
11.6,-1.160264,-0.0146781,0.0005719983,0,0,0,0,0,1.160264,5.447248,0.0146781,0,5.601229,-1.160264,540.8401
12,-1.200264,-0.01538481,0.0005995383,0,0,0,0,0,1.200264,5.635041,0.01538481,0,5.800038,-1.200264,565.754
12.4,-1.240397,-0.0168202,0.0006554745,0,0,0,0,0,1.240397,5.82346,0.0168202,0,5.999908,-1.240397,617.3032
12.8,-1.28013,-0.01770409,0.0006899192,0,0,0,0,0,1.28013,6.010001,0.01770408,0,6.19818,-1.28013,648.455
13.2,-1.32053,-0.01895287,0.0007385836,0,0,0,0,0,1.32053,6.199672,0.01895287,0,6.400183,-1.32053,692.7939
13.6,-1.36053,-0.0187089,0.0007290762,0,0,0,0,0,1.36053,6.387465,0.0187089,0,6.600589,-1.36053,682.5067
14,-1.400263,-0.01949606,0.0007597514,0,0,0,0,0,1.400263,6.574006,0.01949606,0,6.800057,-1.400263,709.8053
14.4,-1.440663,-0.02018871,0.0007867438,0,0,0,0,0,1.440663,6.763677,0.02018871,0,7.00328,-1.440663,733.531
14.8,-1.48013,-0.02132275,0.0008309368,0,0,0,0,0,1.48013,6.948966,0.02132275,0,7.202209,-1.48013,773.1953
15.2,-1.520263,-0.02186005,0.000851875,0,0,0,0,0,1.520263,7.137384,0.02186005,0,7.404904,-1.520263,791.0734
15.6,-1.56013,-0.02244834,0.0008748005,0,0,0,0,0,1.56013,7.324552,0.02244834,0,7.60666,-1.56013,810.7253
16,-1.600396,-0.02414093,0.0009407598,0,0,0,0,0,1.600396,7.513597,0.02414093,0,7.810854,-1.600396,870.075
16.4,-1.640396,-0.02486082,0.0009688135,0,0,0,0,0,1.640396,7.701389,0.02486082,0,8.01411,-1.640396,894.2014
16.8,-1.680263,-0.02613182,0.001018344,0,0,0,0,0,1.680263,7.888557,0.02613182,0,8.2171,-1.680263,938.0111
17.2,-1.720396,-0.02668636,0.001039954,0,0,0,0,0,1.720396,8.076976,0.02668636,0,8.421865,-1.720396,955.957
17.6,-1.760396,-0.02757696,0.00107466,0,0,0,0,0,1.760396,8.264769,0.02757696,0,8.626368,-1.760396,985.8419
18,-1.800529,-0.02914471,0.001135755,0,0,0,0,0,1.800529,8.453188,0.02914471,0,8.831974,-1.800529,1039.747
18.4,-1.840396,-0.03110266,0.001212055,0,0,0,0,0,1.840395,8.640354,0.03110266,0,9.036631,-1.840396,1107.329
18.8,-1.880395,-0.03212322,0.001251825,0,0,0,0,0,1.880395,8.828148,0.03212322,0,9.242397,-1.880395,1141.313
19.2,-1.920395,-0.03433128,0.001337872,0,0,0,0,0,1.920395,9.015941,0.03433128,0,9.448587,-1.920395,1217.251
19.6,-1.960129,-0.03576821,0.001393869,0,0,0,0,0,1.960129,9.202481,0.03576821,0,9.653823,-1.960129,1265.598
20,-2.000662,-0.03893713,0.00151736,0,0,0,0,0,2.000662,9.392778,0.03893713,0,9.863627,-2.000662,1374.838
20.4,-2.040128,-0.04049035,0.001577888,0,0,0,0,0,2.040128,9.578068,0.04049035,0,10.06833,-2.040128,1426.757
20.8,-2.080128,-0.04323295,0.001684766,0,0,0,0,0,2.080128,9.765861,0.04323295,0,10.27623,-2.080128,1520.234
21.2,-2.120528,-0.04585347,0.001786886,0,0,0,0,0,2.120528,9.955531,0.04585347,0,10.48665,-2.120528,1608.992
21.6,-2.160395,-0.04999287,0.001948197,0,0,0,0,0,2.160395,10.1427,0.04999287,0,10.69473,-2.160395,1750.597
22,-2.200261,-0.05506242,0.002145755,0,0,0,0,0,2.200261,10.32986,0.05506242,0,10.90324,-2.200261,1924.101
22.4,-2.240261,-0.05715859,0.002227441,0,0,0,0,0,2.240261,10.51766,0.05715859,0,11.11289,-2.240261,1993.167
22.8,-2.280395,-0.0608637,0.002371828,0,0,0,0,0,2.280395,10.70608,0.0608637,0,11.32368,-2.280395,2117.898
23.2,-2.320261,-0.06314821,0.002460853,0,0,0,0,0,2.320261,10.89324,0.06314821,0,11.5335,-2.320261,2192.787
23.6,-2.360394,-0.06705175,0.002612973,0,0,0,0,0,2.360394,11.08166,0.06705175,0,11.74518,-2.360394,2323.412
24,-2.400394,-0.07113701,0.002772173,0,0,0,0,0,2.400394,11.26946,0.07113701,0,11.9566,-2.400394,2459.764
24.4,-2.440527,-0.07676651,0.002991552,0,0,0,0,0,2.440527,11.45787,0.07676651,0,12.16918,-2.440527,2648.784
24.8,-2.480527,-0.08535221,0.003326132,0,0,0,0,0,2.480527,11.64567,0.08535221,0,12.3815,-2.480527,2938.782
25.2,-2.520127,-0.09108805,0.003549655,0,0,0,0,0,2.520127,11.83158,0.09108805,0,12.59214,-2.520127,3129.675
25.6,-2.560527,-0.09646411,0.003759157,0,0,0,0,0,2.560527,12.02125,0.09646411,0,12.80749,-2.560527,3307.26
26,-2.60026,-0.1047937,0.004083758,0,0,0,0,0,2.60026,12.2078,0.1047937,0,13.01975,-2.60026,3585.221
26.4,-2.640127,-0.1136433,0.004428623,0,0,0,0,0,2.640127,12.39496,0.1136433,0,13.23317,-2.640127,3879.697
26.8,-2.680527,-0.1213109,0.004727422,0,0,0,0,0,2.680527,12.58463,0.1213109,0,13.44991,-2.680527,4132.493
27.2,-2.72026,-0.1321546,0.00515,0,0,0,0,0,2.72026,12.77117,0.1321546,0,13.66353,-2.72026,4492.284
27.6,-2.76026,-0.1439054,0.005607922,0,0,0,0,0,2.76026,12.95897,0.1439054,0,13.87905,-2.76026,4881.193
28,-2.800527,-0.1587927,0.00618807,0,0,0,0,0,2.800527,13.14801,0.1587927,0,14.09648,-2.800527,5374.462
28.4,-2.840393,-0.1706047,0.006648377,0,0,0,0,0,2.840393,13.33518,0.1706047,0,14.31221,-2.840393,5761.804
28.8,-2.880126,-0.1854617,0.007227347,0,0,0,0,0,2.880126,13.52172,0.1854617,0,14.52769,-2.880126,6250.086
29.2,-2.920659,-0.1977323,0.007705527,0,0,0,0,0,2.92066,13.71202,0.1977323,0,14.74798,-2.920659,6648.944
29.6,-2.960393,-0.2088669,0.008139437,0,0,0,0,0,2.960393,13.89856,0.2088669,0,14.9644,-2.960393,7008.172
30,-3.000259,-0.1765903,0.006881635,0,0,0,0,0,3.000259,14.08572,0.1765903,0,15.18202,-3.000259,5912.307
30.4,-3.040659,-0.1934,0.007536699,0,0,0,0,0,3.040659,14.2754,0.1934,0,15.40303,-3.040659,6460.805
30.8,-3.080126,-0.2195948,0.008557497,0,0,0,0,0,3.080126,14.46068,0.2195948,0,15.61941,-3.080126,7320.024
31.2,-3.120392,-0.2407318,0.009381197,0,0,0,0,0,3.120392,14.64973,0.2407318,0,15.84066,-3.120392,8006.877
31.6,-3.160259,-0.2512788,0.009792208,0,0,0,0,0,3.160259,14.8369,0.2512788,0,16.06019,-3.160259,8339.348
32,-3.200259,-0.2611263,0.01017596,0,0,0,0,0,3.200259,15.02469,0.2611263,0,16.28094,-3.200259,8647.052
32.4,-3.240392,-0.278616,0.01085753,0,0,0,0,0,3.240392,15.21311,0.278616,0,16.50292,-3.240392,9205.758
32.8,-3.280392,-0.2921669,0.01138559,0,0,0,0,0,3.280392,15.4009,0.2921669,0,16.72466,-3.280392,9632.11
33.2,-3.320392,-0.307197,0.01197131,0,0,0,0,0,3.320392,15.58869,0.307197,0,16.94688,-3.320392,10105.14
33.6,-3.360392,-0.32633,0.01271691,0,0,0,0,0,3.360392,15.77649,0.3263299,0,17.16961,-3.360392,10710.63
34,-3.400392,-0.3162443,0.01232388,0,0,0,0,0,3.400392,15.96428,0.3162443,0,17.39282,-3.400392,10356.46
34.4,-3.440258,-0.3225613,0.01257005,0,0,0,0,0,3.440258,16.15145,0.3225614,0,17.6158,-3.440258,10539.81
34.8,-3.480658,-0.3395025,0.01323024,0,0,0,0,0,3.480658,16.34112,0.3395025,0,17.84226,-3.480658,11068.27
35.2,-3.520525,-0.3578386,0.01394479,0,0,0,0,0,3.520525,16.52829,0.3578386,0,18.06624,-3.520525,11639.95
35.6,-3.560125,-0.3779417,0.0147282,0,0,0,0,0,3.560125,16.7142,0.3779417,0,18.28921,-3.560125,12266.5
36,-3.600658,-0.3987445,0.01553887,0,0,0,0,0,3.600658,16.9045,0.3987445,0,18.51796,-3.600658,12912.1
36.4,-3.640124,-0.4199568,0.0163655,0,0,0,0,0,3.640125,17.08979,0.4199568,0,18.74119,-3.640124,13568.67
36.8,-3.680258,-0.4394461,0.01712499,0,0,0,0,0,3.680257,17.2782,0.4394461,0,18.96871,-3.680258,14166.1
37.2,-3.720391,-0.4602109,0.01793418,0,0,0,0,0,3.720391,17.46662,0.4602109,0,19.19674,-3.720391,14801.69
37.6,-3.760258,-0.4804667,0.01872354,0,0,0,0,0,3.760257,17.65379,0.4804667,0,19.42378,-3.760258,15418.13
38,-3.800391,-0.4993652,0.01946001,0,0,0,0,0,3.800391,17.84221,0.4993652,0,19.65285,-3.800391,15987.91
38.4,-3.840391,-0.5116703,0.01993953,0,0,0,0,0,3.840391,18.03,0.5116704,0,19.88169,-3.840391,16344.43
38.8,-3.88039,-0.5245742,0.02044239,0,0,0,0,0,3.880391,18.2178,0.5245742,0,20.11105,-3.88039,16718.24
39.2,-3.920124,-0.536372,0.02090214,0,0,0,0,0,3.920124,18.40434,0.5363719,0,20.33941,-3.920124,17055.24
39.6,-3.960524,-0.5598625,0.02181755,0,0,0,0,0,3.960524,18.59401,0.5598624,0,20.57213,-3.960524,17760.8
40,-4.00039,-0.5789723,0.02256226,0,0,0,0,0,4.000391,18.78118,0.5789723,0,20.80231,-4.00039,18324.8
40.4,-4.040523,-0.5979188,0.02330059,0,0,0,0,0,4.040524,18.96959,0.5979187,0,21.03457,-4.040523,18880.56
40.8,-4.080523,-0.6216168,0.02422409,0,0,0,0,0,4.080523,19.15739,0.6216168,0,21.2666,-4.080523,19583.39
41.2,-4.120257,-0.6407127,0.02496825,0,0,0,0,0,4.120257,19.34393,0.6407127,0,21.49761,-4.120257,20138.41
41.6,-4.160523,-0.6591525,0.02568684,0,0,0,0,0,4.160523,19.53297,0.6591524,0,21.73227,-4.160523,20669.43
42,-4.200256,-0.6713809,0.02616337,0,0,0,0,0,4.200256,19.71951,0.6713809,0,21.96436,-4.200256,21004.08
42.4,-4.240256,-0.6885784,0.02683355,0,0,0,0,0,4.240256,19.90731,0.6885784,0,22.19856,-4.240256,21491.71
42.8,-4.280523,-0.6989383,0.02723727,0,0,0,0,0,4.280523,20.09635,0.6989383,0,22.43487,-4.280523,21763.57
43.2,-4.320256,-0.7070389,0.02755295,0,0,0,0,0,4.320256,20.28289,0.7070389,0,22.6686,-4.320256,21964.41
43.6,-4.360256,-0.7131882,0.02779258,0,0,0,0,0,4.360256,20.47069,0.7131882,0,22.90445,-4.360256,22103.25
44,-4.400389,-0.7287025,0.02839717,0,0,0,0,0,4.400389,20.65911,0.7287025,0,23.14165,-4.400389,22530.57
44.4,-4.440389,-0.6504856,0.02534909,0,0,0,0,0,4.440389,20.8469,0.6504856,0,23.37862,-4.440389,20064.59
44.8,-4.480123,-0.6952852,0.02709491,0,0,0,0,0,4.480123,21.03344,0.6952852,0,23.61457,-4.480123,21395.92
45.2,-4.520656,-0.7268228,0.02832391,0,0,0,0,0,4.520656,21.22374,0.7268228,0,23.85584,-4.520656,22312.52
45.6,-4.560389,-0.7440188,0.02899403,0,0,0,0,0,4.560389,21.41028,0.7440188,0,24.09293,-4.560389,22786.33
46,-4.600255,-0.7582245,0.02954762,0,0,0,0,0,4.600255,21.59744,0.7582245,0,24.33136,-4.600255,23166.09
46.4,-4.640656,-0.7684717,0.02994695,0,0,0,0,0,4.640656,21.78712,0.7684717,0,24.57358,-4.640656,23422.37
46.8,-4.680122,-0.770567,0.03002861,0,0,0,0,0,4.680122,21.9724,0.770567,0,24.81076,-4.680122,23430.6
47.2,-4.720255,-0.7200645,0.02806055,0,0,0,0,0,4.720255,22.16082,0.7200645,0,25.05253,-4.720255,21842.1
47.6,-4.760255,-0.7326072,0.02854933,0,0,0,0,0,4.760255,22.34862,0.7326072,0,25.29408,-4.760255,22168.95
48,-4.800388,-0.7460208,0.02907205,0,0,0,0,0,4.800388,22.53703,0.7460208,0,25.53702,-4.800388,22520.07
48.4,-4.840388,-0.7638345,0.02976624,0,0,0,0,0,4.840388,22.72483,0.7638345,0,25.77975,-4.840388,23001.92
48.8,-4.880388,-0.7745787,0.03018494,0,0,0,0,0,4.880388,22.91262,0.7745788,0,26.02306,-4.880388,23268.78
49.2,-4.920388,-0.7801492,0.03040202,0,0,0,0,0,4.920388,23.10041,0.7801492,0,26.26697,-4.920388,23379.03
49.6,-4.960255,-0.7863569,0.03064393,0,0,0,0,0,4.960255,23.28758,0.7863569,0,26.51066,-4.960255,23507.7
50,-5.000521,-0.7887853,0.03073856,0,0,0,0,0,5.000521,23.47662,0.7887853,0,26.75739,-5.000521,23522.19
50.4,-5.040254,-0.7910812,0.03082803,0,0,0,0,0,5.040255,23.66317,0.7910811,0,27.00146,-5.040254,23533.14
50.8,-5.080521,-0.7961797,0.03102672,0,0,0,0,0,5.080521,23.85221,0.7961797,0,27.24942,-5.080521,23626.16
51.2,-5.120521,-0.7878856,0.0307035,0,0,0,0,0,5.120521,24.04,0.7878856,0,27.49634,-5.120521,23322.38
51.6,-5.159988,-0.7993785,0.03115137,0,0,0,0,0,5.159987,24.22529,0.7993785,0,27.74056,-5.159988,23604.86
52,-5.200654,-0.8098276,0.03155857,0,0,0,0,0,5.200654,24.41622,0.8098276,0,27.99284,-5.200654,23853.16
52.4,-5.240254,-0.8160807,0.03180225,0,0,0,0,0,5.240254,24.60213,0.8160807,0,28.23912,-5.240254,23978.22
52.8,-5.280254,-0.822644,0.03205802,0,0,0,0,0,5.280254,24.78992,0.822644,0,28.4885,-5.280254,24110.86
53.2,-5.320521,-0.822126,0.03203783,0,0,0,0,0,5.32052,24.97897,0.822126,0,28.74017,-5.320521,24035.11
53.6,-5.360387,-0.81833,0.0318899,0,0,0,0,0,5.360387,25.16614,0.81833,0,28.98997,-5.360387,23864.45
54,-5.400387,-0.8228594,0.03206641,0,0,0,0,0,5.400387,25.35393,0.8228593,0,29.24123,-5.400387,23936.32
54.4,-5.440387,-0.825686,0.03217657,0,0,0,0,0,5.440387,25.54172,0.825686,0,29.49313,-5.440387,23958.12
54.8,-5.480387,-0.8275782,0.0322503,0,0,0,0,0,5.480387,25.72952,0.8275782,0,29.74566,-5.480387,23952.45
55.2,-5.52012,-0.8187432,0.03190601,0,0,0,0,0,5.52012,25.91606,0.8187432,0,29.99713,-5.52012,23637.23
55.6,-5.560386,-0.8152746,0.03177084,0,0,0,0,0,5.560387,26.1051,0.8152746,0,30.25264,-5.560386,23477.03
56,-5.600386,-0.8069746,0.03144739,0,0,0,0,0,5.600386,26.29289,0.8069745,0,30.5071,-5.600386,23178.96
56.4,-5.64052,-0.8056808,0.03139697,0,0,0,0,0,5.64052,26.48131,0.8056808,0,30.76306,-5.64052,23082.64
56.8,-5.68052,-0.7918712,0.03085882,0,0,0,0,0,5.68052,26.66911,0.7918712,0,31.01882,-5.68052,22629.05
57.2,-5.720119,-0.7993208,0.03114912,0,0,0,0,0,5.720119,26.85502,0.7993208,0,31.27267,-5.720119,22784.02
57.6,-5.760519,-0.8018458,0.03124752,0,0,0,0,0,5.76052,27.04469,0.8018458,0,31.53231,-5.760519,22796.73
58,-5.800119,-0.8075924,0.03147146,0,0,0,0,0,5.800119,27.23061,0.8075925,0,31.78747,-5.800119,22901.6
58.4,-5.840253,-0.8088632,0.03152099,0,0,0,0,0,5.840252,27.41903,0.8088632,0,32.04674,-5.840253,22878.24
58.8,-5.880386,-0.7919472,0.03086178,0,0,0,0,0,5.880385,27.60744,0.7919472,0,32.30667,-5.880386,22341.63
59.2,-5.920385,-0.7962393,0.03102904,0,0,0,0,0,5.920385,27.79524,0.7962393,0,32.56642,-5.920385,22404.44
59.6,-5.960252,-0.8041478,0.03133723,0,0,0,0,0,5.960252,27.9824,0.8041478,0,32.82597,-5.960252,22568.32
60,-6.000385,-0.8163649,0.03181333,0,0,0,0,0,6.000385,28.17082,0.8163649,0,33.08794,-6.000385,22851.25
60.4,-6.040519,-0.8281822,0.03227384,0,0,0,0,0,6.040519,28.35924,0.8281822,0,33.3506,-6.040519,23121.22
60.8,-6.080118,-0.8379728,0.03265538,0,0,0,0,0,6.080119,28.54516,0.8379728,0,33.61045,-6.080118,23333.85
61.2,-6.120652,-0.8436649,0.03287719,0,0,0,0,0,6.120652,28.73545,0.8436649,0,33.87713,-6.120652,23429.78
61.6,-6.160385,-0.8523977,0.0332175,0,0,0,0,0,6.160385,28.922,0.8523977,0,34.13923,-6.160385,23610.34
62,-6.200118,-0.8630474,0.03363252,0,0,0,0,0,6.200118,29.10854,0.8630474,0,34.40201,-6.200118,23842.58
62.4,-6.240518,-0.8756665,0.03412428,0,0,0,0,0,6.240518,29.29821,0.8756665,0,34.66993,-6.240518,24126.48
62.8,-6.280118,-0.8820216,0.03437193,0,0,0,0,0,6.280118,29.48412,0.8820216,0,34.93323,-6.280118,24237.67
63.2,-6.320251,-0.8951816,0.03488477,0,0,0,0,0,6.320251,29.67254,0.8951815,0,35.20079,-6.320251,24533.57
63.6,-6.360251,-0.9095772,0.03544576,0,0,0,0,0,6.360251,29.86033,0.9095772,0,35.46817,-6.360251,24861.54
64,-6.400384,-0.9263143,0.036098,0,0,0,0,0,6.400384,30.04875,0.9263143,0,35.73717,-6.400384,25251
64.4,-6.440517,-0.9408295,0.03666365,0,0,0,0,0,6.440517,30.23717,0.9408295,0,36.00689,-6.440517,25577.6
64.8,-6.480251,-0.9532783,0.03714877,0,0,0,0,0,6.480251,30.42371,0.9532784,0,36.27464,-6.480251,25846.74
65.2,-6.520518,-0.9564745,0.03727333,0,0,0,0,0,6.520518,30.61276,0.9564745,0,36.54672,-6.520518,25862.93
65.60001,-6.560384,-0.9722161,0.03788677,0,0,0,0,0,6.560384,30.79992,0.9722161,0,36.81682,-6.560384,26217.67
66,-6.600517,-0.9821638,0.03827442,0,0,0,0,0,6.600517,30.98834,0.9821637,0,37.08948,-6.600517,26413.81
66.4,-6.64025,-0.9939457,0.03873356,0,0,0,0,0,6.64025,31.17488,0.9939457,0,37.36015,-6.64025,26658.42
66.8,-6.680517,-1.004415,0.03914154,0,0,0,0,0,6.680517,31.36393,1.004415,0,37.6352,-6.680517,26865.21
67.20001,-6.720517,-1.011987,0.03943662,0,0,0,0,0,6.720517,31.55172,1.011987,0,37.90918,-6.720517,26993.68
67.60001,-6.760117,-1.002209,0.03905559,0,0,0,0,0,6.760117,31.73764,1.002209,0,38.18116,-6.760117,26660.27
68,-6.80065,-0.7476166,0.02913424,0,0,0,0,0,6.80065,31.92793,0.7476166,0,38.46033,-6.80065,19832.28
68.4,-6.84025,-0.7729741,0.03012241,0,0,0,0,0,6.84025,32.11385,0.7729741,0,38.73381,-6.84025,20448.94
68.8,-6.88025,-0.7857698,0.03062105,0,0,0,0,0,6.88025,32.30164,0.7857698,0,39.01083,-6.88025,20729.95
69.20001,-6.920383,-0.7962216,0.03102835,0,0,0,0,0,6.920383,32.49006,0.7962216,0,39.28954,-6.920383,20947.22
69.60001,-6.960383,-0.8074873,0.03146737,0,0,0,0,0,6.960383,32.67786,0.8074873,0,39.5681,-6.960383,21184.51
70,-7.000383,-0.829275,0.03231642,0,0,0,0,0,7.000382,32.86565,0.829275,0,39.84743,-7.000383,21695.42
70.4,-7.040383,-0.8481008,0.03305006,0,0,0,0,0,7.040383,33.05344,0.8481008,0,40.12755,-7.040383,22125.87
70.8,-7.080516,-0.8717677,0.03397234,0,0,0,0,0,7.080516,33.24186,0.8717676,0,40.40939,-7.080516,22679.3
71.20001,-7.120249,-0.8879737,0.03460389,0,0,0,0,0,7.12025,33.4284,0.8879737,0,40.68922,-7.120249,23036.36
71.60001,-7.160382,-0.8945945,0.03486189,0,0,0,0,0,7.160382,33.61682,0.8945945,0,40.97265,-7.160382,23142.43
72,-7.200382,-0.8882963,0.03461645,0,0,0,0,0,7.200382,33.80461,0.8882962,0,41.25594,-7.200382,22914.5
72.4,-7.240382,-0.9142563,0.0356281,0,0,0,0,0,7.240382,33.9924,0.9142563,0,41.54004,-7.240382,23517.25
72.8,-7.280516,-0.9453627,0.0368403,0,0,0,0,0,7.280516,34.18082,0.9453627,0,41.8259,-7.280516,24247.98
73.20001,-7.320115,-0.9751165,0.03799979,0,0,0,0,0,7.320115,34.36674,0.9751166,0,42.10876,-7.320115,24940.51
73.60001,-7.360515,-0.9963829,0.03882854,0,0,0,0,0,7.360515,34.55641,0.9963829,0,42.39816,-7.360515,25410.79
74,-7.400249,-1.006155,0.03920935,0,0,0,0,0,7.400249,34.74295,1.006155,0,42.68361,-7.400249,25586.86
74.4,-7.440115,-1.00011,0.03897376,0,0,0,0,0,7.440115,34.93012,1.00011,0,42.97084,-7.440115,25360.18
74.8,-7.480515,-1.005429,0.03918106,0,0,0,0,0,7.480515,35.11979,1.005429,0,43.26275,-7.480515,25420.75
75.20001,-7.520382,-1.002252,0.03905724,0,0,0,0,0,7.520382,35.30696,1.002252,0,43.55165,-7.520382,25267.31
75.60001,-7.560248,-1.008017,0.03928191,0,0,0,0,0,7.560248,35.49412,1.008017,0,43.84138,-7.560248,25339.14
76,-7.600382,-1.028015,0.04006124,0,0,0,0,0,7.600381,35.68254,1.028015,0,44.13391,-7.600382,25766.37
76.4,-7.640381,-1.043267,0.04065557,0,0,0,0,0,7.640381,35.87033,1.043267,0,44.42631,-7.640381,26072.28
76.8,-7.680248,-1.058188,0.04123703,0,0,0,0,0,7.680248,36.0575,1.058187,0,44.7186,-7.680248,26367.98
77.20001,-7.720515,-1.073552,0.0418358,0,0,0,0,0,7.720515,36.24655,1.073552,0,45.01469,-7.720515,26671.76
77.60001,-7.760381,-1.080924,0.04212307,0,0,0,0,0,7.760381,36.43371,1.080924,0,45.30869,-7.760381,26776.07
78,-7.800381,-1.078768,0.04203904,0,0,0,0,0,7.800381,36.62151,1.078768,0,45.60456,-7.800381,26643.71
78.4,-7.840647,-1.090212,0.04248502,0,0,0,0,0,7.840647,36.81055,1.090212,0,45.90328,-7.840647,26846.05
78.8,-7.880114,-1.101411,0.04292145,0,0,0,0,0,7.880114,36.99584,1.101411,0,46.19694,-7.880114,27042.3
79.20001,-7.920381,-0.8490014,0.03308515,0,0,0,0,0,7.920381,37.18489,0.8490014,0,46.49745,-7.920381,20782.48
79.60001,-7.960114,-0.7989592,0.03113503,0,0,0,0,0,7.960114,37.37143,0.7989592,0,46.79486,-7.960114,19499.43
80,-8.00038,-0.8035131,0.0313125,0,0,0,0,0,8.000381,37.56047,0.8035131,0,47.09716,-8.00038,19551.37
80.4,-8.040381,-0.8147728,0.03175128,0,0,0,0,0,8.04038,37.74826,0.8147728,0,47.39838,-8.040381,19765.72
80.8,-8.080247,-0.8148501,0.03175429,0,0,0,0,0,8.080247,37.93543,0.8148501,0,47.69949,-8.080247,19708.17
81.20001,-8.12038,-0.8226625,0.03205874,0,0,0,0,0,8.12038,38.12385,0.8226625,0,48.00354,-8.12038,19836.71
81.60001,-8.160381,-0.8298402,0.03233845,0,0,0,0,0,8.16038,38.31165,0.8298402,0,48.3075,-8.160381,19949.06
82.00001,-8.20038,-0.8352517,0.03254933,0,0,0,0,0,8.20038,38.49944,0.8352517,0,48.61239,-8.20038,20018.02
82.4,-8.240247,-0.8133881,0.03169732,0,0,0,0,0,8.240247,38.68661,0.813388,0,48.91719,-8.240247,19434.7
82.8,-8.280513,-0.8196798,0.03194251,0,0,0,0,0,8.280513,38.87565,0.8196798,0,49.22598,-8.280513,19524.65
83.20001,-8.32038,-0.8287987,0.03229786,0,0,0,0,0,8.32038,39.06282,0.8287987,0,49.53266,-8.32038,19681.41
83.60001,-8.360113,-0.8375032,0.03263707,0,0,0,0,0,8.360113,39.24936,0.8375032,0,49.83925,-8.360113,19827.23
84.00001,-8.400646,-0.8495703,0.03310732,0,0,0,0,0,8.400646,39.43965,0.8495703,0,50.15298,-8.400646,20049.91
84.4,-8.440113,-0.8567488,0.03338706,0,0,0,0,0,8.440113,39.62494,0.8567488,0,50.45941,-8.440113,20157.46
84.8,-8.480113,-0.863344,0.03364408,0,0,0,0,0,8.480113,39.81274,0.863344,0,50.77094,-8.480113,20249.45
85.20001,-8.520513,-0.8098515,0.0315595,0,0,0,0,0,8.520513,40.00241,0.8098515,0,51.08658,-8.520513,18934.94
85.60001,-8.560113,-0.825172,0.03215653,0,0,0,0,0,8.560113,40.18832,0.8251721,0,51.39693,-8.560113,19233.36
86.00001,-8.600379,-0.8281865,0.03227401,0,0,0,0,0,8.600379,40.37737,0.8281865,0,51.71349,-8.600379,19242.61
86.4,-8.640379,-0.832956,0.03245987,0,0,0,0,0,8.640379,40.56516,0.832956,0,52.02896,-8.640379,19292.47
86.8,-8.680379,-0.8333307,0.03247447,0,0,0,0,0,8.680379,40.75295,0.8333307,0,52.34542,-8.680379,19240.17
87.20001,-8.720245,-0.8485969,0.03306939,0,0,0,0,0,8.720245,40.94012,0.8485969,0,52.66183,-8.720245,19530.74
87.60001,-8.760379,-0.8699221,0.03390042,0,0,0,0,0,8.760379,41.12854,0.8699222,0,52.98137,-8.760379,19957.67
88.00001,-8.800379,-0.8801681,0.0342997,0,0,0,0,0,8.800379,41.31633,0.8801681,0,53.30087,-8.800379,20128.32
88.4,-8.840512,-0.8820191,0.03437184,0,0,0,0,0,8.840511,41.50475,0.8820191,0,53.62246,-8.840512,20105.89
88.8,-8.880379,-0.8888921,0.03463967,0,0,0,0,0,8.880379,41.69192,0.8888921,0,53.94295,-8.880379,20197.73
89.20001,-8.920245,-0.9024304,0.03516725,0,0,0,0,0,8.920245,41.87909,0.9024304,0,54.26446,-8.920245,20439.53
89.60001,-8.960378,-0.9190446,0.0358147,0,0,0,0,0,8.960379,42.0675,0.9190446,0,54.58917,-8.960378,20748.35
90.00001,-9.000245,-0.9258412,0.03607956,0,0,0,0,0,9.000244,42.25467,0.9258412,0,54.91277,-9.000245,20834.26
90.4,-9.040112,-0.912876,0.03557431,0,0,0,0,0,9.040112,42.44184,0.912876,0,55.23743,-9.040112,20475.92
90.8,-9.080512,-0.9163933,0.03571138,0,0,0,0,0,9.080511,42.63151,0.9163933,0,55.5675,-9.080512,20487.08
91.20001,-9.120245,-0.8905446,0.03470407,0,0,0,0,0,9.120245,42.81805,0.8905447,0,55.89319,-9.120245,19844.47
91.60001,-9.160245,-0.8955292,0.03489832,0,0,0,0,0,9.160245,43.00584,0.8955293,0,56.22215,-9.160245,19890
92.00001,-9.200377,-0.9079911,0.03538395,0,0,0,0,0,9.200377,43.19426,0.9079911,0,56.55328,-9.200377,20100.12
92.4,-9.240378,-0.9269459,0.03612261,0,0,0,0,0,9.240377,43.38205,0.9269459,0,56.88442,-9.240378,20451.88
92.8,-9.280111,-0.9413916,0.03668555,0,0,0,0,0,9.28011,43.5686,0.9413916,0,57.21444,-9.280111,20702.17
93.20001,-9.320644,-0.9535996,0.03716129,0,0,0,0,0,9.320643,43.75889,0.9535996,0,57.55222,-9.320644,20899.92
93.60001,-9.360378,-0.9663406,0.0376578,0,0,0,0,0,9.360377,43.94543,0.9663406,0,57.88446,-9.360378,21108.92
94.00001,-9.400111,-0.9775149,0.03809326,0,0,0,0,0,9.40011,44.13197,0.9775149,0,58.2178,-9.400111,21281.95
94.4,-9.440644,-0.9890025,0.03854093,0,0,0,0,0,9.440643,44.32227,0.9890025,0,58.559,-9.440644,21458.71
94.8,-9.48011,-0.9966747,0.0388399,0,0,0,0,0,9.48011,44.50756,0.9966747,0,58.89234,-9.48011,21553.21
95.20001,-9.520244,-1.000301,0.03898121,0,0,0,0,0,9.520244,44.69598,1.000301,0,59.23246,-9.520244,21558.17
95.60001,-9.560243,-1.009923,0.03935618,0,0,0,0,0,9.560244,44.88377,1.009923,0,59.5726,-9.560243,21691.64
96.00001,-9.600377,-1.003577,0.03910888,0,0,0,0,0,9.600377,45.07219,1.003577,0,59.91504,-9.600377,21481.65
96.4,-9.640377,-1.006338,0.0392165,0,0,0,0,0,9.640377,45.25999,1.006338,0,60.25752,-9.640377,21467.12
96.8,-9.680376,-1.012901,0.03947225,0,0,0,0,0,9.680376,45.44778,1.012901,0,60.60117,-9.680376,21532.99
97.20001,-9.720377,-1.006404,0.03921907,0,0,0,0,0,9.720377,45.63557,1.006404,0,60.94601,-9.720377,21321.22
97.60001,-9.760376,-1.010989,0.03939773,0,0,0,0,0,9.760376,45.82336,1.010989,0,61.29204,-9.760376,21344.36
98.00001,-9.800376,-1.009357,0.03933412,0,0,0,0,0,9.800376,46.01116,1.009357,0,61.63928,-9.800376,21236.04
98.4,-9.840376,-1.01869,0.03969784,0,0,0,0,0,9.840376,46.19895,1.01869,0,61.98771,-9.840376,21357.85
98.8,-9.880376,-1.022323,0.03983941,0,0,0,0,0,9.880376,46.38674,1.022323,0,62.33738,-9.880376,21359.21
99.20001,-9.92051,-1.036931,0.04040866,0,0,0,0,0,9.920509,46.57516,1.036931,0,62.68944,-9.92051,21588.26
99.60001,-9.960109,-1.036137,0.04037772,0,0,0,0,0,9.96011,46.76108,1.036137,0,63.03804,-9.960109,21496.66
100,-10.00064,-1.039172,0.04049601,0,0,0,0,0,10.00064,46.95137,1.039172,0,63.39612,-10.00064,21482.58
100.4,-10.04024,-1.048129,0.04084504,0,0,0,0,0,10.04024,47.13729,1.048129,0,63.7472,-10.04024,21591.79
100.8,-10.08011,-1.052678,0.04102232,0,0,0,0,0,10.08011,47.32445,1.052678,0,64.10188,-10.08011,21608.73
101.2,-10.12038,-1.054536,0.04109475,0,0,0,0,0,10.12037,47.5135,1.054536,0,64.46142,-10.12038,21569.19
101.6,-10.16038,-1.061353,0.04136039,0,0,0,0,0,10.16038,47.70129,1.061353,0,64.81985,-10.16038,21630.95
102,-10.20024,-1.060556,0.04132933,0,0,0,0,0,10.20024,47.88846,1.060556,0,65.17837,-10.20024,21537.35
102.4,-10.24038,-1.063254,0.04143445,0,0,0,0,0,10.24038,48.07688,1.063254,0,65.5406,-10.24038,21514.06
102.8,-10.28038,-1.058062,0.04123213,0,0,0,0,0,10.28038,48.26467,1.058062,0,65.90293,-10.28038,21331.58
103.2,-10.32024,-1.049257,0.040889,0,0,0,0,0,10.32024,48.45184,1.049257,0,66.26536,-10.32024,21077.53
103.6,-10.36038,-1.045097,0.04072688,0,0,0,0,0,10.36038,48.64026,1.045097,0,66.63156,-10.36038,20917.22
104,-10.40037,-1.0468,0.04079327,0,0,0,0,0,10.40037,48.82805,1.0468,0,66.99786,-10.40037,20874.71
104.4,-10.44051,-1.055712,0.04114058,0,0,0,0,0,10.44051,49.01647,1.055712,0,67.36675,-10.44051,20974.92
104.8,-10.48051,-1.048246,0.0408496,0,0,0,0,0,10.48051,49.20427,1.048246,0,67.73578,-10.48051,20749.85
105.2,-10.52024,-1.051426,0.04097353,0,0,0,0,0,10.52024,49.3908,1.051426,0,68.10369,-10.52024,20736.37
105.6,-10.56037,-1.048009,0.04084039,0,0,0,0,0,10.56037,49.57922,1.048009,0,68.47669,-10.56037,20592.04
106,-10.60037,-1.045598,0.04074642,0,0,0,0,0,10.60037,49.76701,1.045598,0,68.84983,-10.60037,20468.15
106.4,-10.64011,-1.04497,0.04072193,0,0,0,0,0,10.64011,49.95356,1.04497,0,69.22187,-10.64011,20379.88
106.8,-10.68037,-1.046478,0.04078073,0,0,0,0,0,10.68037,50.1426,1.046478,0,69.60033,-10.68037,20332.21
107.2,-10.72037,-1.039806,0.04052069,0,0,0,0,0,10.72037,50.33039,1.039806,0,69.9777,-10.72037,20126.47
107.6,-10.76024,-1.037769,0.04044131,0,0,0,0,0,10.76024,50.51756,1.037769,0,70.35523,-10.76024,20011.35
108,-10.80037,-1.035429,0.04035013,0,0,0,0,0,10.80037,50.70598,1.035429,0,70.73674,-10.80037,19890.2
108.4,-10.84051,-1.032595,0.04023971,0,0,0,0,0,10.84051,50.8944,1.032595,0,71.11971,-10.84051,19759.95
108.8,-10.88024,-1.022539,0.03984784,0,0,0,0,0,10.88024,51.08094,1.022539,0,71.50031,-10.88024,19493.19
109.2,-10.92064,-1.031424,0.04019409,0,0,0,0,0,10.92064,51.27061,1.031425,0,71.88879,-10.92064,19586.34
109.6,-10.96051,-1.028423,0.04007712,0,0,0,0,0,10.96051,51.45778,1.028423,0,72.27362,-10.96051,19454.33
110,-11.00024,-1.018512,0.03969091,0,0,0,0,0,11.00024,51.64432,1.018512,0,72.65865,-11.00024,19192.81
110.4,-11.04064,-1.021258,0.03979791,0,0,0,0,0,11.04064,51.83399,1.021258,0,73.05166,-11.04064,19169.07
110.8,-11.08024,-1.014357,0.03952898,0,0,0,0,0,11.08024,52.01991,1.014357,0,73.4384,-11.08024,18966.04
111.2,-11.12051,-1.017224,0.03964068,0,0,0,0,0,11.12051,52.20895,1.017224,0,73.83318,-11.12051,18944.7
111.6,-11.16024,-1.0105,0.03937868,0,0,0,0,0,11.16024,52.39549,1.0105,0,74.22427,-11.16024,18746.03
112,-11.20024,-1.014105,0.03951914,0,0,0,0,0,11.20024,52.58328,1.014104,0,74.61953,-11.20024,18738.68
112.4,-11.24064,-1.018174,0.03967772,0,0,0,0,0,11.24064,52.77296,1.018174,0,75.02035,-11.24064,18738.61
112.8,-11.28037,-1.021524,0.03980827,0,0,0,0,0,11.28037,52.9595,1.021524,0,75.41612,-11.28037,18726.01
113.2,-11.32051,-1.023351,0.03987946,0,0,0,0,0,11.32051,53.14791,1.023351,0,75.81747,-11.32051,18684.36
113.6,-11.36051,-1.019772,0.03974,0,0,0,0,0,11.36051,53.33571,1.019772,0,76.21909,-11.36051,18544.39
114,-11.40037,-1.026681,0.04000924,0,0,0,0,0,11.40037,53.52287,1.026681,0,76.62099,-11.40037,18595.14
114.4,-11.44024,-1.026881,0.04001703,0,0,0,0,0,11.44024,53.71004,1.026881,0,77.02451,-11.44024,18523.87
114.8,-11.48051,-1.025141,0.03994922,0,0,0,0,0,11.48051,53.89909,1.025141,0,77.43374,-11.48051,18416.96
115.2,-11.52064,-1.034113,0.04029886,0,0,0,0,0,11.52064,54.08751,1.034113,0,77.84329,-11.52064,18502.21
115.6,-11.5601,-1.024027,0.03990579,0,0,0,0,0,11.5601,54.27279,1.024027,0,78.24767,-11.5601,18247.8
116,-11.60064,-1.028818,0.04009252,0,0,0,0,0,11.60064,54.46309,1.028818,0,78.6647,-11.60064,18256.89
116.4,-11.64024,-1.029945,0.04013643,0,0,0,0,0,11.64024,54.64901,1.029945,0,79.07381,-11.64024,18202.27
116.8,-11.68037,-1.035226,0.04034225,0,0,0,0,0,11.68037,54.83742,1.035226,0,79.49014,-11.68037,18219.6
117.2,-11.7205,-1.03574,0.04036226,0,0,0,0,0,11.7205,55.02584,1.03574,0,79.90822,-11.7205,18152.59
117.6,-11.76037,-1.038905,0.0404856,0,0,0,0,0,11.76037,55.21301,1.038905,0,80.32526,-11.76037,18132.28
118,-11.80024,-1.041361,0.0405813,0,0,0,0,0,11.80024,55.40018,1.041361,0,80.74403,-11.80024,18099.19
118.4,-11.84037,-1.046841,0.04079487,0,0,0,0,0,11.84037,55.5886,1.046841,0,81.1674,-11.84037,18117.57
118.8,-11.88024,-1.047231,0.04081005,0,0,0,0,0,11.88024,55.77576,1.047231,0,81.58972,-11.88024,18047.93
119.2,-11.92024,-1.060445,0.041325,0,0,0,0,0,11.92024,55.96356,1.060445,0,82.01527,-11.92024,18198.06
119.6,-11.96037,-1.052586,0.04101874,0,0,0,0,0,11.96037,56.15197,1.052586,0,82.44405,-11.96037,17985.91
120,-12.00037,-1.053096,0.04103863,0,0,0,0,0,12.00037,56.33977,1.053096,0,82.87325,-12.00037,17917.56
120.4,-12.04064,-1.050742,0.04094687,0,0,0,0,0,12.04064,56.52881,1.050742,0,83.30719,-12.04064,17800.09
120.8,-12.0805,-1.054692,0.04110081,0,0,0,0,0,12.0805,56.71598,1.054692,0,83.73867,-12.0805,17790.08
121.2,-12.1201,-1.059758,0.04129821,0,0,0,0,0,12.1201,56.90189,1.059758,0,84.16911,-12.1201,17798.75
121.6,-12.16064,-1.059528,0.04128927,0,0,0,0,0,12.16064,57.09219,1.059528,0,84.61164,-12.16064,17716.32
122,-12.20037,-1.066391,0.04155671,0,0,0,0,0,12.20037,57.27874,1.066391,0,85.04734,-12.20037,17753.55
122.4,-12.24024,-1.055672,0.04113901,0,0,0,0,0,12.24024,57.4659,1.055672,0,85.48641,-12.24024,17498.11
122.8,-12.28064,-1.059692,0.04129566,0,0,0,0,0,12.28064,57.65557,1.059692,0,85.93333,-12.28064,17486.41
123.2,-12.32037,-1.060787,0.04133835,0,0,0,0,0,12.32037,57.84211,1.060787,0,86.37484,-12.32037,17427.37
123.6,-12.36024,-1.059977,0.04130675,0,0,0,0,0,12.36024,58.02928,1.059977,0,86.8198,-12.36024,17336.74
124,-12.4005,-1.063584,0.04144733,0,0,0,0,0,12.4005,58.21833,1.063584,0,87.27123,-12.4005,17317.39
124.4,-12.44037,-1.062352,0.04139931,0,0,0,0,0,12.44037,58.40549,1.062352,0,87.7202,-12.44037,17219.84
124.8,-12.48024,-1.068803,0.0416507,0,0,0,0,0,12.48024,58.59266,1.068803,0,88.1712,-12.48024,17246.45
125.2,-12.5205,-1.065958,0.04153984,0,0,0,0,0,12.5205,58.7817,1.065958,0,88.6288,-12.5205,17122.01
125.6,-12.5605,-1.071557,0.04175803,0,0,0,0,0,12.5605,58.9695,1.071557,0,89.08544,-12.5605,17133.53
126,-12.60037,-1.075272,0.0419028,0,0,0,0,0,12.60037,59.15666,1.075272,0,89.54264,-12.60037,17114.5
126.4,-12.6405,-1.074279,0.04186412,0,0,0,0,0,12.6405,59.34508,1.074279,0,90.00504,-12.6405,17019.82
126.8,-12.6801,-1.078933,0.04204549,0,0,0,0,0,12.6801,59.53099,1.078933,0,90.46338,-12.6801,17015.39
127.2,-12.72037,-1.076858,0.0419646,0,0,0,0,0,12.72037,59.72004,1.076858,0,90.93161,-12.72037,16903.32
127.6,-12.76024,-1.080972,0.04212492,0,0,0,0,0,12.76024,59.90721,1.080972,0,91.39737,-12.76024,16889.05
128,-12.80037,-1.084601,0.04226635,0,0,0,0,0,12.80037,60.09563,1.084601,0,91.86843,-12.80037,16866.12
128.4,-12.8405,-1.086759,0.04235046,0,0,0,0,0,12.8405,60.28405,1.086759,0,92.34172,-12.8405,16819.89
128.8,-12.88037,-1.088848,0.04243185,0,0,0,0,0,12.88037,60.47121,1.088848,0,92.8141,-12.88037,16772.8
129.2,-12.9205,-1.090271,0.04248731,0,0,0,0,0,12.9205,60.65963,1.090271,0,93.2919,-12.9205,16714.66
129.6,-12.96037,-1.093375,0.04260826,0,0,0,0,0,12.96037,60.8468,1.093375,0,93.76881,-12.96037,16682.5
130,-13.00037,-1.094759,0.04266221,0,0,0,0,0,13.00037,61.03459,1.094759,0,94.24959,-13.00037,16623.5
130.4,-13.04024,-1.104459,0.0430402,0,0,0,0,0,13.04024,61.22176,1.104459,0,94.7311,-13.04024,16690.23
130.8,-13.08064,-1.112251,0.04334384,0,0,0,0,0,13.08064,61.41143,1.112251,0,95.22141,-13.08064,16725.77
131.2,-13.1205,-1.108612,0.04320204,0,0,0,0,0,13.1205,61.5986,1.108612,0,95.70762,-13.1205,16590.19
131.6,-13.1601,-1.102877,0.04297857,0,0,0,0,0,13.1601,61.78451,1.102877,0,96.19293,-13.1601,16424.47
132,-13.20063,-1.110286,0.04326727,0,0,0,0,0,13.20063,61.97481,1.110286,0,96.69213,-13.20063,16452.46
132.4,-13.24023,-1.111752,0.04332441,0,0,0,0,0,13.24023,62.16072,1.111752,0,97.18225,-13.24023,16393.64
132.8,-13.28023,-1.120056,0.04364801,0,0,0,0,0,13.28023,62.34852,1.120056,0,97.67979,-13.28023,16434.12
133.2,-13.3205,-1.123114,0.04376718,0,0,0,0,0,13.3205,62.53756,1.123114,0,98.18314,-13.3205,16396.25
133.6,-13.36037,-1.127616,0.04394264,0,0,0,0,0,13.36037,62.72473,1.127616,0,98.684,-13.36037,16379.74
134,-13.40037,-1.131379,0.04408925,0,0,0,0,0,13.40037,62.91253,1.131379,0,99.18908,-13.40037,16351.59
134.4,-13.44037,-1.134414,0.04420754,0,0,0,0,0,13.44037,63.10032,1.134414,0,99.69671,-13.44037,16312.44
134.8,-13.48037,-1.134246,0.04420101,0,0,0,0,0,13.48037,63.28811,1.134246,0,100.2069,-13.48037,16227.03
135.2,-13.52037,-1.137682,0.04433488,0,0,0,0,0,13.52037,63.4759,1.137682,0,100.7198,-13.52037,16192.92
135.6,-13.56037,-1.141668,0.04449024,0,0,0,0,0,13.56037,63.66369,1.141668,0,101.2353,-13.56037,16166.11
136,-13.60037,-1.145382,0.04463497,0,0,0,0,0,13.60037,63.85149,1.145382,0,101.7534,-13.60037,16134.88
136.4,-13.6405,-1.149014,0.0447765,0,0,0,0,0,13.6405,64.0399,1.149014,0,102.276,-13.6405,16101.68
136.8,-13.6805,-1.156363,0.04506287,0,0,0,0,0,13.6805,64.2277,1.156363,0,102.7996,-13.6805,16120.03
137.2,-13.72023,-1.164473,0.04537894,0,0,0,0,0,13.72023,64.41424,1.164473,0,103.3225,-13.72023,16148.44
137.6,-13.76063,-1.168521,0.04553665,0,0,0,0,0,13.76063,64.60391,1.168521,0,103.8569,-13.76063,16118.19
138,-13.80023,-1.172734,0.04570084,0,0,0,0,0,13.80023,64.78983,1.172734,0,104.3835,-13.80023,16091.35
138.4,-13.84023,-1.180661,0.04600976,0,0,0,0,0,13.84023,64.97762,1.180661,0,104.9183,-13.84023,16113.71
138.8,-13.8805,-1.18844,0.04631292,0,0,0,0,0,13.8805,65.16666,1.18844,0,105.4595,-13.8805,16132.33
139.2,-13.92037,-1.194688,0.04655639,0,0,0,0,0,13.92037,65.35383,1.194688,0,105.9983,-13.92037,16130.01
139.6,-13.96023,-1.199499,0.04674388,0,0,0,0,0,13.96023,65.541,1.199499,0,106.54,-13.96023,16107.48
140,-14.00037,-1.208488,0.04709415,0,0,0,0,0,14.00037,65.72942,1.208488,0,107.0883,-14.00037,16139.44
140.4,-14.0405,-1.21362,0.04729417,0,0,0,0,0,14.0405,65.91784,1.21362,0,107.6396,-14.0405,16118.87
140.8,-14.08023,-1.21847,0.04748316,0,0,0,0,0,14.08023,66.10438,1.21847,0,108.1884,-14.08023,16094.71
[...]
84.4,-8.43998,-0.6145249,0.02241955,0,0,0,0,0,8.43998,40.19038,0.614525,0,51.40036,-8.43998,13409.05
84.8,-8.480113,-0.614765,0.02242831,0,0,0,0,0,8.480113,40.38149,0.614765,0,51.72041,-8.480113,13371.42
85.20001,-8.519979,-0.6160165,0.02247396,0,0,0,0,0,8.519979,40.57133,0.6160165,0,52.03934,-8.519979,13355.98
85.60001,-8.559979,-0.6161979,0.02248058,0,0,0,0,0,8.559979,40.76181,0.6161979,0,52.36037,-8.559979,13317.09
86.00001,-8.600246,-0.6177445,0.02253701,0,0,0,0,0,8.600246,40.95355,0.6177445,0,52.68458,-8.600246,13307.3
86.4,-8.639979,-0.6177679,0.02253786,0,0,0,0,0,8.639979,41.14276,0.6177679,0,53.00553,-8.639979,13265.16
86.8,-8.679979,-0.6182226,0.02255445,0,0,0,0,0,8.679978,41.33323,0.6182227,0,53.32967,-8.679979,13231.97
87.20001,-8.720245,-0.617999,0.02254629,0,0,0,0,0,8.720245,41.52498,0.617999,0,53.65705,-8.720245,13183.95
87.60001,-8.760112,-0.6166192,0.02249595,0,0,0,0,0,8.760113,41.71482,0.6166192,0,53.98223,-8.760112,13111.81
88.00001,-8.799712,-0.6178211,0.0225398,0,0,0,0,0,8.799712,41.90339,0.617821,0,54.30629,-8.799712,13094.86
88.4,-8.840378,-0.6188544,0.0225775,0,0,0,0,0,8.840379,42.09704,0.6188544,0,54.64017,-8.840378,13073.04
88.8,-8.879978,-0.6187903,0.02257516,0,0,0,0,0,8.879978,42.28561,0.6187903,0,54.96637,-8.879978,13029.12
89.20001,-8.919845,-0.6199298,0.02261673,0,0,0,0,0,8.919846,42.47545,0.6199299,0,55.29584,-8.919845,13010.17
89.60001,-8.960245,-0.6188075,0.02257579,0,0,0,0,0,8.960245,42.66784,0.6188075,0,55.63084,-8.960245,12943.19
90.00001,-8.999978,-0.6186252,0.02256913,0,0,0,0,0,8.999978,42.85704,0.6186252,0,55.9614,-8.999978,12896.67
90.4,-9.040112,-0.6186144,0.02256874,0,0,0,0,0,9.040112,43.04815,0.6186144,0,56.2964,-9.040112,12853.32
90.8,-9.080111,-0.6191819,0.02258945,0,0,0,0,0,9.080112,43.23862,0.6191819,0,56.63141,-9.080111,12822.08
91.20001,-9.120111,-0.6178244,0.02253992,0,0,0,0,0,9.120111,43.4291,0.6178244,0,56.96755,-9.120111,12751.04
91.60001,-9.159844,-0.6163706,0.02248688,0,0,0,0,0,9.159844,43.61831,0.6163706,0,57.30257,-9.159844,12678.48
92.00001,-9.200111,-0.6170474,0.02251158,0,0,0,0,0,9.200111,43.81005,0.6170474,0,57.64323,-9.200111,12649.24
92.4,-9.240111,-0.6175796,0.02253099,0,0,0,0,0,9.240111,44.00053,0.6175796,0,57.9828,-9.240111,12617.24
92.8,-9.279978,-0.6177372,0.02253674,0,0,0,0,0,9.279978,44.19037,0.6177372,0,58.32237,-9.279978,12577.67
93.20001,-9.320111,-0.6200285,0.02262033,0,0,0,0,0,9.320111,44.38148,0.6200285,0,58.6654,-9.320111,12581.09
93.60001,-9.359844,-0.6195093,0.02260139,0,0,0,0,0,9.359844,44.57069,0.6195093,0,59.00616,-9.359844,12527.8
94.00001,-9.400111,-0.6206307,0.02264231,0,0,0,0,0,9.40011,44.76243,0.6206307,0,59.35269,-9.400111,12507.06
94.4,-9.439977,-0.6196888,0.02260794,0,0,0,0,0,9.439977,44.95227,0.6196889,0,59.69696,-9.439977,12445.16
94.8,-9.479977,-0.6199473,0.02261737,0,0,0,0,0,9.479978,45.14275,0.6199473,0,60.04358,-9.479977,12407.27
95.20001,-9.520244,-0.6208163,0.02264907,0,0,0,0,0,9.520244,45.3345,0.6208163,0,60.39373,-9.520244,12381.23
95.60001,-9.559844,-0.6207642,0.02264717,0,0,0,0,0,9.559844,45.52306,0.6207642,0,60.73928,-9.559844,12337.49
96.00001,-9.599976,-0.6230008,0.02272877,0,0,0,0,0,9.599977,45.71417,0.6230008,0,61.0907,-9.599976,12338.5
96.4,-9.640243,-0.6241358,0.02277018,0,0,0,0,0,9.640243,45.90592,0.6241359,0,61.44454,-9.640243,12317.32
96.8,-9.679977,-0.6245164,0.02278407,0,0,0,0,0,9.679976,46.09513,0.6245164,0,61.79493,-9.679977,12281.72
97.20001,-9.719976,-0.6263114,0.02284955,0,0,0,0,0,9.719976,46.2856,0.6263114,0,62.14891,-9.719976,12273.5
97.60001,-9.760243,-0.6265701,0.02285899,0,0,0,0,0,9.760242,46.47735,0.6265701,0,62.50652,-9.760243,12234.74
98.00001,-9.800109,-0.6272429,0.02288353,0,0,0,0,0,9.800109,46.66719,0.6272429,0,62.86184,-9.800109,12204.43
98.4,-9.83971,-0.6283257,0.02292304,0,0,0,0,0,9.83971,46.85576,0.6283256,0,63.21605,-9.83971,12182.27
98.8,-9.880243,-0.6314633,0.02303751,0,0,0,0,0,9.880243,47.04877,0.6314633,0,63.5799,-9.880243,12198.64
99.20001,-9.919976,-0.6336389,0.02311688,0,0,0,0,0,9.919976,47.23798,0.6336389,0,63.93786,-9.919976,12196.93
99.60001,-9.959976,-0.6341227,0.02313453,0,0,0,0,0,9.959976,47.42846,0.6341227,0,64.29952,-9.959976,12162.18
100,-10.00011,-0.6365616,0.0232235,0,0,0,0,0,10.00011,47.61956,0.6365616,0,64.66371,-10.00011,12164.57
100.4,-10.03998,-0.6369446,0.02323748,0,0,0,0,0,10.03998,47.80941,0.6369446,0,65.0268,-10.03998,12127.78
100.8,-10.08011,-0.6396472,0.02333608,0,0,0,0,0,10.08011,48.00051,0.6396472,0,65.39364,-10.08011,12134.64
101.2,-10.11998,-0.6420328,0.02342311,0,0,0,0,0,10.11998,48.19036,0.6420328,0,65.75939,-10.11998,12135.43
101.6,-10.16011,-0.643264,0.02346803,0,0,0,0,0,10.16011,48.38147,0.643264,0,66.12895,-10.16011,12113.85
102,-10.20011,-0.6462092,0.02357548,0,0,0,0,0,10.20011,48.57195,0.6462092,0,66.49863,-10.20011,12124.41
102.4,-10.24011,-0.6483102,0.02365213,0,0,0,0,0,10.24011,48.76242,0.6483102,0,66.8697,-10.24011,12118.78
102.8,-10.27997,-0.6489803,0.02367657,0,0,0,0,0,10.27997,48.95226,0.6489803,0,67.24089,-10.27997,12086.35
103.2,-10.32024,-0.6512598,0.02375974,0,0,0,0,0,10.32024,49.14401,0.6512598,0,67.61722,-10.32024,12083.25
103.6,-10.36011,-0.6526408,0.02381012,0,0,0,0,0,10.36011,49.33385,0.6526408,0,67.99121,-10.36011,12063.67
104,-10.39971,-0.6557419,0.02392325,0,0,0,0,0,10.39971,49.52242,0.6557419,0,68.36409,-10.39971,12075.88
104.4,-10.44024,-0.6575016,0.02398746,0,0,0,0,0,10.44024,49.71544,0.6575016,0,68.7472,-10.44024,12061.99
104.8,-10.47997,-0.6603766,0.02409234,0,0,0,0,0,10.47997,49.90464,0.6603765,0,69.12418,-10.47997,12069.14
105.2,-10.51997,-0.6626282,0.02417449,0,0,0,0,0,10.51997,50.09512,0.6626282,0,69.50514,-10.51997,12064.25
105.6,-10.56011,-0.6632084,0.02419565,0,0,0,0,0,10.56011,50.28622,0.6632084,0,69.88881,-10.56011,12028.57
106,-10.60011,-0.6660848,0.02430059,0,0,0,0,0,10.60011,50.4767,0.6660848,0,70.2727,-10.60011,12034.45
106.4,-10.64011,-0.6675953,0.0243557,0,0,0,0,0,10.64011,50.66718,0.6675953,0,70.65805,-10.64011,12015.35
106.8,-10.68011,-0.6673103,0.0243453,0,0,0,0,0,10.68011,50.85765,0.6673102,0,71.04491,-10.68011,11963.85
107.2,-10.72011,-0.6702752,0.02445347,0,0,0,0,0,10.72011,51.04813,0.6702752,0,71.43327,-10.72011,11970.43
107.6,-10.75997,-0.670257,0.0244528,0,0,0,0,0,10.75997,51.23797,0.670257,0,71.82183,-10.75997,11923.68
108,-10.80024,-0.673079,0.02455576,0,0,0,0,0,10.80024,51.42972,0.673079,0,72.21583,-10.80024,11926.8
108.4,-10.84011,-0.6735072,0.02457138,0,0,0,0,0,10.84011,51.61956,0.6735072,0,72.60745,-10.84011,11887.74
108.8,-10.87997,-0.6748573,0.02462064,0,0,0,0,0,10.87997,51.8094,0.6748573,0,73.00062,-10.87997,11864.83
109.2,-10.92011,-0.6764739,0.02467961,0,0,0,0,0,10.92011,52.00051,0.6764739,0,73.39797,-10.92011,11846.09
109.6,-10.95984,-0.678516,0.02475412,0,0,0,0,0,10.95984,52.18972,0.678516,0,73.79294,-10.95984,11835.01
110,-11.00011,-0.6794428,0.02478793,0,0,0,0,0,11.00011,52.38146,0.6794428,0,74.1948,-11.00011,11803.65
110.4,-11.03997,-0.6812001,0.02485204,0,0,0,0,0,11.03997,52.5713,0.6812001,0,74.59427,-11.03997,11787
110.8,-11.07997,-0.6821613,0.02488711,0,0,0,0,0,11.07997,52.76178,0.6821613,0,74.99668,-11.07997,11756.23
111.2,-11.12024,-0.6851297,0.0249954,0,0,0,0,0,11.12024,52.95352,0.6851297,0,75.40341,-11.12024,11759.46
111.6,-11.15997,-0.6857474,0.02501794,0,0,0,0,0,11.15997,53.14273,0.6857474,0,75.8064,-11.15997,11722.72
112,-11.20011,-0.6885991,0.02512198,0,0,0,0,0,11.20011,53.33384,0.6885991,0,76.21508,-11.20011,11723.46
112.4,-11.24011,-0.6900576,0.02517519,0,0,0,0,0,11.24011,53.52431,0.6900576,0,76.62409,-11.24011,11700.34
112.8,-11.28011,-0.6922521,0.02525525,0,0,0,0,0,11.28011,53.71479,0.6922521,0,77.03477,-11.28011,11689.45
113.2,-11.31997,-0.6948417,0.02534972,0,0,0,0,0,11.31997,53.90463,0.6948417,0,77.44577,-11.31997,11685.05
113.6,-11.36024,-0.6950976,0.02535906,0,0,0,0,0,11.36024,54.09638,0.6950976,0,77.86261,-11.36024,11640.73
114,-11.40011,-0.698806,0.02549435,0,0,0,0,0,11.40011,54.28622,0.698806,0,78.27703,-11.40011,11654.43
114.4,-11.43971,-0.7003818,0.02555184,0,0,0,0,0,11.4397,54.47479,0.7003818,0,78.69039,-11.43971,11632.53
114.8,-11.48024,-0.7010753,0.02557714,0,0,0,0,0,11.48024,54.6678,0.7010753,0,79.11526,-11.48024,11594.68
115.2,-11.51997,-0.6993991,0.02551599,0,0,0,0,0,11.51997,54.85701,0.6993991,0,79.53352,-11.51997,11518.68
115.6,-11.55997,-0.7027744,0.02563913,0,0,0,0,0,11.55997,55.04749,0.7027744,0,79.95634,-11.55997,11525.43
116,-11.60024,-0.7044544,0.02570042,0,0,0,0,0,11.60024,55.23923,0.7044544,0,80.38381,-11.60024,11503.71
116.4,-11.63997,-0.7069721,0.02579227,0,0,0,0,0,11.63997,55.42844,0.7069721,0,80.80741,-11.63997,11496.02
116.8,-11.6801,-0.7073742,0.02580694,0,0,0,0,0,11.68011,55.61954,0.7073742,0,81.23711,-11.6801,11453.24
117.2,-11.71997,-0.7016239,0.02559716,0,0,0,0,0,11.71997,55.80939,0.7016239,0,81.66579,-11.71997,11311.54
117.6,-11.7601,-0.7031369,0.02565235,0,0,0,0,0,11.7601,56.0005,0.7031369,0,82.09919,-11.7601,11286.91
118,-11.8001,-0.7054168,0.02573553,0,0,0,0,0,11.80011,56.19098,0.7054168,0,82.53303,-11.8001,11274.49
118.4,-11.8401,-0.7070922,0.02579665,0,0,0,0,0,11.8401,56.38145,0.7070922,0,82.96876,-11.8401,11252.13
118.8,-11.87997,-0.7091975,0.02587346,0,0,0,0,0,11.87997,56.57129,0.7091975,0,83.40495,-11.87997,11236.51
119.2,-11.92024,-0.7107892,0.02593153,0,0,0,0,0,11.92024,56.76304,0.7107892,0,83.84744,-11.92024,11212.01
119.6,-11.96024,-0.7123773,0.02598947,0,0,0,0,0,11.96024,56.95351,0.7123773,0,84.28895,-11.96024,11187.55
120,-11.9997,-0.7156175,0.02610768,0,0,0,0,0,11.9997,57.14145,0.7156175,0,84.7265,-11.9997,11189.37
120.4,-12.04024,-0.7168868,0.02615399,0,0,0,0,0,12.04024,57.33446,0.7168869,0,85.17787,-12.04024,11158.74
120.8,-12.0801,-0.718443,0.02621076,0,0,0,0,0,12.0801,57.5243,0.718443,0,85.62382,-12.0801,11133.2
121.2,-12.11997,-0.7206045,0.02628962,0,0,0,0,0,12.11997,57.71415,0.7206045,0,86.07175,-12.11997,11116.79
121.6,-12.16024,-0.722459,0.02635728,0,0,0,0,0,12.16024,57.90589,0.722459,0,86.52624,-12.16024,11094.86
122,-12.19997,-0.7260808,0.02648941,0,0,0,0,0,12.19997,58.0951,0.7260808,0,86.97673,-12.19997,11100.36
122.4,-12.23997,-0.7286438,0.02658291,0,0,0,0,0,12.23997,58.28557,0.7286438,0,87.43231,-12.23997,11088.91
122.8,-12.2801,-0.7313927,0.0266832,0,0,0,0,0,12.2801,58.47668,0.7313927,0,87.89151,-12.2801,11079.75
123.2,-12.31997,-0.7323242,0.02671719,0,0,0,0,0,12.31997,58.66652,0.7323242,0,88.34974,-12.31997,11043.14
123.6,-12.35997,-0.7343393,0.0267907,0,0,0,0,0,12.35997,58.857,0.7343394,0,88.81164,-12.35997,11022.5
124,-12.40024,-0.7386173,0.02694678,0,0,0,0,0,12.40024,59.04874,0.7386172,0,89.27877,-12.40024,11035.04
124.4,-12.4401,-0.7417543,0.02706122,0,0,0,0,0,12.4401,59.23859,0.7417544,0,89.74343,-12.4401,11030.54
124.8,-12.47984,-0.7439624,0.02714178,0,0,0,0,0,12.47984,59.42779,0.7439623,0,90.20869,-12.47984,11012.02
125.2,-12.52024,-0.7481838,0.02729579,0,0,0,0,0,12.52024,59.62017,0.7481838,0,90.68398,-12.52024,11021.99
125.6,-12.5597,-0.7507522,0.02738949,0,0,0,0,0,12.5597,59.80811,0.7507522,0,91.15049,-12.5597,11008.36
126,-12.6001,-0.7541091,0.02751196,0,0,0,0,0,12.6001,60.00049,0.7541091,0,91.63029,-12.6001,11004.65
126.4,-12.63997,-0.7564403,0.02759701,0,0,0,0,0,12.63997,60.19033,0.7564403,0,92.10604,-12.63997,10986.28
126.8,-12.67997,-0.7581516,0.02765944,0,0,0,0,0,12.67997,60.38081,0.7581517,0,92.58565,-12.67997,10958.45
127.2,-12.72024,-0.7616752,0.02778799,0,0,0,0,0,12.72024,60.57255,0.7616752,0,93.07079,-12.72024,10956.1
127.6,-12.75997,-0.7647361,0.02789966,0,0,0,0,0,12.75997,60.76176,0.7647361,0,93.55183,-12.75997,10947.34
128,-12.8001,-0.7678845,0.02801452,0,0,0,0,0,12.8001,60.95287,0.7678845,0,94.04007,-12.8001,10938.87
128.4,-12.8401,-0.7700484,0.02809347,0,0,0,0,0,12.8401,61.14334,0.7700484,0,94.52908,-12.8401,10916.18
128.8,-12.8801,-0.7732105,0.02820883,0,0,0,0,0,12.8801,61.33382,0.7732105,0,95.02048,-12.8801,10907.28
129.2,-12.91997,-0.7767476,0.02833787,0,0,0,0,0,12.91997,61.52366,0.7767476,0,95.51267,-12.91997,10903.38
129.6,-12.96023,-0.7788966,0.02841627,0,0,0,0,0,12.96023,61.7154,0.7788966,0,96.01225,-12.96023,10879.06
130,-13.00023,-0.7825796,0.02855064,0,0,0,0,0,13.00023,61.90588,0.7825796,0,96.51103,-13.00023,10876.12
130.4,-13.03983,-0.7854071,0.0286538,0,0,0,0,0,13.03983,62.09445,0.7854071,0,97.00727,-13.03983,10861.38
130.8,-13.0801,-0.7870218,0.02871271,0,0,0,0,0,13.0801,62.2862,0.7870218,0,97.5144,-13.0801,10828.65
131.2,-13.1201,-0.7902986,0.02883225,0,0,0,0,0,13.1201,62.47668,0.7902986,0,98.02074,-13.1201,10818.82
131.6,-13.15997,-0.7924954,0.0289124,0,0,0,0,0,13.15997,62.66652,0.7924954,0,98.52795,-13.15997,10794.01
132,-13.2001,-0.7969452,0.02907474,0,0,0,0,0,13.2001,62.85762,0.7969452,0,99.04117,-13.2001,10799.05
132.4,-13.2401,-0.7995375,0.02916931,0,0,0,0,0,13.2401,63.0481,0.7995375,0,99.55531,-13.2401,10778.61
132.8,-13.28023,-0.8017045,0.02924837,0,0,0,0,0,13.28023,63.23921,0.8017045,0,100.0738,-13.28023,10751.93
133.2,-13.31997,-0.8044623,0.02934898,0,0,0,0,0,13.31997,63.42842,0.8044623,0,100.5899,-13.31997,10733.39
133.6,-13.3601,-0.8065991,0.02942694,0,0,0,0,0,13.3601,63.61953,0.8065991,0,101.1138,-13.3601,10705.66
134,-13.4001,-0.8102608,0.02956052,0,0,0,0,0,13.4001,63.81,0.8102608,0,101.6387,-13.4001,10697.95
134.4,-13.4401,-0.8121939,0.02963105,0,0,0,0,0,13.4401,64.00048,0.8121939,0,102.1665,-13.4401,10667.04
134.8,-13.47997,-0.8013107,0.02923401,0,0,0,0,0,13.47997,64.19032,0.8013107,0,102.6952,-13.47997,10468.61
135.2,-13.52023,-0.8015072,0.02924117,0,0,0,0,0,13.52023,64.38206,0.8015072,0,103.2321,-13.52023,10415.1
135.6,-13.5601,-0.8064232,0.02942052,0,0,0,0,0,13.5601,64.57191,0.8064232,0,103.7665,-13.5601,10423.13
136,-13.59983,-0.8104111,0.02956601,0,0,0,0,0,13.59983,64.76111,0.8104111,0,104.302,-13.59983,10418.73
136.4,-13.64023,-0.8131131,0.02966459,0,0,0,0,0,13.64023,64.95349,0.8131132,0,104.8494,-13.64023,10396.4
136.8,-13.67997,-0.8055003,0.02938685,0,0,0,0,0,13.67997,65.1427,0.8055003,0,105.3908,-13.67997,10243.46
137.2,-13.71997,-0.8108273,0.0295812,0,0,0,0,0,13.71997,65.33318,0.8108273,0,105.9387,-13.71997,10254.86
137.6,-13.76023,-0.8139441,0.0296949,0,0,0,0,0,13.76023,65.52492,0.8139441,0,106.4933,-13.76023,10237.34
138,-13.79997,-0.8173504,0.02981918,0,0,0,0,0,13.79997,65.71413,0.8173504,0,107.0437,-13.79997,10223.77
138.4,-13.8401,-0.8207054,0.02994157,0,0,0,0,0,13.8401,65.90524,0.8207054,0,107.6026,-13.8401,10208.51
138.8,-13.87997,-0.8225422,0.03000858,0,0,0,0,0,13.87997,66.09508,0.8225422,0,108.161,-13.87997,10174.39
139.2,-13.91997,-0.8220954,0.02999229,0,0,0,0,0,13.91997,66.28555,0.8220955,0,108.7244,-13.91997,10111.73
139.6,-13.95997,-0.8152625,0.029743,0,0,0,0,0,13.95997,66.47603,0.8152624,0,109.2909,-13.95997,9971.036
140,-14.00023,-0.8205419,0.02993561,0,0,0,0,0,14.00023,66.66777,0.8205419,0,109.8645,-14.00023,9978.206
140.4,-14.0401,-0.8224907,0.03000671,0,0,0,0,0,14.0401,66.85762,0.8224907,0,110.4357,-14.0401,9944.937
140.8,-14.07997,-0.824447,0.03007808,0,0,0,0,0,14.07997,67.04745,0.824447,0,111.0102,-14.07997,9911.493
141.2,-14.12023,-0.8271245,0.03017576,0,0,0,0,0,14.12023,67.2392,0.8271245,0,111.5938,-14.12023,9885.819
141.6,-14.15997,-0.8300301,0.03028176,0,0,0,0,0,14.15997,67.42841,0.8300301,0,112.173,-14.15997,9863.253
142,-14.2001,-0.832125,0.03035819,0,0,0,0,0,14.2001,67.61951,0.8321249,0,112.7614,-14.2001,9830.13
142.4,-14.23983,-0.8383799,0.03058639,0,0,0,0,0,14.23983,67.80872,0.8383799,0,113.3475,-14.23983,9846.149
142.8,-14.27997,-0.842567,0.03073915,0,0,0,0,0,14.27996,67.99983,0.842567,0,113.9429,-14.27997,9836.579
143.2,-14.32023,-0.8471613,0.03090676,0,0,0,0,0,14.32023,68.19158,0.8471614,0,114.5439,-14.32023,9830.951
143.6,-14.35983,-0.8520688,0.0310858,0,0,0,0,0,14.35983,68.38015,0.8520688,0,115.1385,-14.35983,9829.282
144,-14.4001,-0.8577947,0.03129469,0,0,0,0,0,14.4001,68.5719,0.8577946,0,115.7468,-14.4001,9835.328
144.4,-14.44023,-0.8611564,0.03141734,0,0,0,0,0,14.44023,68.76301,0.8611563,0,116.3567,-14.44023,9813.83
144.8,-14.4801,-0.8645836,0.03154237,0,0,0,0,0,14.4801,68.95285,0.8645836,0,116.9663,-14.4801,9793.008
145.2,-14.51996,-0.8679721,0.031666,0,0,0,0,0,14.51996,69.14268,0.8679721,0,117.5796,-14.51996,9771.276
145.6,-14.56023,-0.8730089,0.03184975,0,0,0,0,0,14.56023,69.33443,0.8730089,0,118.203,-14.56023,9766.906
146,-14.60023,-0.8803534,0.03211769,0,0,0,0,0,14.60023,69.52491,0.8803534,0,118.8261,-14.60023,9787.896
146.4,-14.6397,-0.8842171,0.03225865,0,0,0,0,0,14.6397,69.71284,0.8842171,0,119.4446,-14.6397,9770.229
146.8,-14.68023,-0.8881166,0.03240092,0,0,0,0,0,14.68023,69.90586,0.8881166,0,120.084,-14.68023,9750.777
147.2,-14.71983,-0.8937138,0.03260512,0,0,0,0,0,14.71983,70.09443,0.8937138,0,120.7125,-14.71983,9750.748
147.6,-14.75996,-0.8982659,0.0327712,0,0,0,0,0,14.75996,70.28555,0.898266,0,121.3537,-14.75996,9737.782
148,-14.8001,-0.9044084,0.03299529,0,0,0,0,0,14.8001,70.47665,0.9044084,0,121.9989,-14.8001,9741.313
148.4,-14.83996,-0.9096354,0.03318598,0,0,0,0,0,14.83996,70.6665,0.9096354,0,122.644,-14.83996,9734.612
148.8,-14.8801,-0.9158242,0.03341177,0,0,0,0,0,14.8801,70.8576,0.9158242,0,123.2976,-14.8801,9736.989
149.2,-14.91996,-0.9185746,0.03351211,0,0,0,0,0,14.91996,71.04745,0.9185746,0,123.9512,-14.91996,9702.612
149.6,-14.95996,-0.9233214,0.03368529,0,0,0,0,0,14.95996,71.23792,0.9233214,0,124.6112,-14.95996,9688.588
150,-15.0001,-0.9287001,0.03388152,0,0,0,0,0,15.0001,71.42903,0.9287001,0,125.2779,-15.0001,9680.278
150.4,-15.03996,-0.9331934,0.03404544,0,0,0,0,0,15.03996,71.61887,0.9331934,0,125.9446,-15.03996,9662.48
150.8,-15.0801,-0.9377126,0.03421032,0,0,0,0,0,15.0801,71.80998,0.9377126,0,126.6202,-15.0801,9643.895
151.2,-15.12023,-0.9439712,0.03443865,0,0,0,0,0,15.12023,72.00109,0.9439712,0,127.3005,-15.12023,9642.447
151.6,-15.1601,-0.9484099,0.03460058,0,0,0,0,0,15.1601,72.19093,0.9484099,0,127.9808,-15.1601,9622.099
152,-15.1997,-0.9557961,0.03487005,0,0,0,0,0,15.1997,72.3795,0.9557961,0,128.6612,-15.1997,9631.282
152.4,-15.24023,-0.9605599,0.03504385,0,0,0,0,0,15.24023,72.57253,0.96056,0,129.3625,-15.24023,9611.643
152.8,-15.27996,-0.9662525,0.03525153,0,0,0,0,0,15.27996,72.76173,0.9662524,0,130.0547,-15.27996,9601.908
153.2,-15.31996,-0.972727,0.03548774,0,0,0,0,0,15.31996,72.9522,0.972727,0,130.7565,-15.31996,9598.652
153.6,-15.36036,-0.9780624,0.03568239,0,0,0,0,0,15.36036,73.14458,0.9780625,0,131.4703,-15.36036,9582.654
154,-15.4001,-0.9854643,0.03595243,0,0,0,0,0,15.40009,73.33379,0.9854643,0,132.1773,-15.4001,9587.152
154.4,-15.43996,-0.9911694,0.03616057,0,0,0,0,0,15.43996,73.52363,0.9911695,0,132.8918,-15.43996,9574.006
154.8,-15.4801,-0.9947309,0.0362905,0,0,0,0,0,15.48009,73.71474,0.9947309,0,133.6162,-15.4801,9539.054
155.2,-15.5201,-1.000795,0.03651174,0,0,0,0,0,15.5201,73.90522,1.000795,0,134.3435,-15.5201,9527.658
155.6,-15.55996,-1.007839,0.03676871,0,0,0,0,0,15.55996,74.09505,1.007839,0,135.0736,-15.55996,9524.915
156,-15.60023,-1.014726,0.03701999,0,0,0,0,0,15.60023,74.2868,1.014726,0,135.8166,-15.60023,9519.023
156.4,-15.64009,-1.017041,0.03710441,0,0,0,0,0,15.64009,74.47664,1.01704,0,136.5576,-15.64009,9470.292
156.8,-15.67996,-1.013969,0.03699236,0,0,0,0,0,15.67996,74.66649,1.013969,0,137.3042,-15.67996,9371.464
157.2,-15.72023,-1.023829,0.03735208,0,0,0,0,0,15.72023,74.85824,1.023829,0,138.064,-15.72023,9390.972
157.6,-15.75996,-1.030177,0.03758369,0,0,0,0,0,15.75996,75.04744,1.030177,0,138.8194,-15.75996,9378.093
158,-15.80009,-1.037099,0.0378362,0,0,0,0,0,15.80009,75.23854,1.037099,0,139.5882,-15.80009,9368.794
158.4,-15.83996,-1.044149,0.03809341,0,0,0,0,0,15.83996,75.42839,1.044149,0,140.3579,-15.83996,9360.165
158.8,-15.87996,-1.050613,0.03832923,0,0,0,0,0,15.87996,75.61886,1.050613,0,141.136,-15.87996,9345.102
159.2,-15.92023,-1.056024,0.03852663,0,0,0,0,0,15.92023,75.81061,1.056024,0,141.9256,-15.92023,9319.358
159.6,-15.95983,-1.06221,0.03875231,0,0,0,0,0,15.95983,75.99918,1.06221,0,142.7082,-15.95983,9300.873
160,-16.00009,-1.069627,0.0390229,0,0,0,0,0,16.00009,76.19093,1.069627,0,143.5103,-16.00009,9290.993
160.012,-16.00116,-1.069716,0.03902618,0,0,0,0,0,16.00116,76.19601,1.069716,0,143.5317,-16.00116,9289.789